Workbook

Sheet wft_table
A1: basis | B1: CBS | C1: CBS | D1: CBS | E1: CBS | F1: CBS | G1: CBS | H1: CBS | I1: CBS | J1: CBS | K1: CBS | L1: CBS | M1: CBS | N1: 5Z | O1: 5Z | P1: 5Z | Q1: 5Z | R1: 5Z | S1: 5Z | T1: 5Z | U1: 5Z | V1: 5Z | W1: 5Z | X1: 5Z | Y1: 5Z | Z1: QZ | AA1: QZ | AB1: QZ | AC1: QZ | AD1: QZ | AE1: QZ | AF1: QZ | AG1: QZ | AH1: QZ | AI1: QZ | AJ1: QZ | AK1: QZ | AL1: TZ | AM1: TZ | AN1: TZ | AO1: TZ | AP1: TZ | AQ1: TZ | AR1: TZ | AS1: TZ | AT1: TZ | AU1: TZ | AV1: TZ | AW1: TZ
A2: method | B2: HF | C2: HF | D2: HF | E2: MP2 | F2: MP2 | G2: MP2 | H2: CCSD | I2: CCSD | J2: CCSD | K2: CCSD(T) | L2: CCSD(T) | M2: CCSD(T) | N2: HF | O2: HF | P2: HF | Q2: MP2 | R2: MP2 | S2: MP2 | T2: CCSD | U2: CCSD | V2: CCSD | W2: CCSD(T) | X2: CCSD(T) | Y2: CCSD(T) | Z2: HF | AA2: HF | AB2: HF | AC2: MP2 | AD2: MP2 | AE2: MP2 | AF2: CCSD | AG2: CCSD | AH2: CCSD | AI2: CCSD(T) | AJ2: CCSD(T) | AK2: CCSD(T) | AL2: HF | AM2: HF | AN2: HF | AO2: MP2 | AP2: MP2 | AQ2: MP2 | AR2: CCSD | AS2: CCSD | AT2: CCSD | AU2: CCSD(T) | AV2: CCSD(T) | AW2: CCSD(T)
A3: component | B3: XX | C3: YY | D3: ZZ | E3: XX | F3: YY | G3: ZZ | H3: XX | I3: YY | J3: ZZ | K3: XX | L3: YY | M3: ZZ | N3: XX | O3: YY | P3: ZZ | Q3: XX | R3: YY | S3: ZZ | T3: XX | U3: YY | V3: ZZ | W3: XX | X3: YY | Y3: ZZ | Z3: XX | AA3: YY | AB3: ZZ | AC3: XX | AD3: YY | AE3: ZZ | AF3: XX | AG3: YY | AH3: ZZ | AI3: XX | AJ3: YY | AK3: ZZ | AL3: XX | AM3: YY | AN3: ZZ | AO3: XX | AP3: YY | AQ3: ZZ | AR3: XX | AS3: YY | AT3: ZZ | AU3: XX | AV3: YY | AW3: ZZ
A4: molecule
A5: AlF | B5: 0.53077499 | C5: 0.53077499 | D5: 3.105327 | E5: 0.53342843 | F5: 0.53342843 | G5: 3.0680835 | H5: 0.52890766 | I5: 0.52890766 | J5: 3.0691615 | K5: 0.53115417 | L5: 0.53115417 | M5: 3.0638868 | N5: 0.53077499 | O5: 0.53077499 | P5: 3.105327 | Q5: 0 | R5: 0 | S5: 0 | T5: 0 | U5: 0 | V5: 0 | W5: 0 | X5: 0 | Y5: 0 | Z5: 0.53088651 | AA5: 0.53088651 | AB5: 3.1054536 | AC5: 0.53504858 | AD5: 0.53504858 | AE5: 3.0706032 | AF5: 0.5304963 | AG5: 0.5304963 | AH5: 3.0710806 | AI5: 0.53280085 | AJ5: 0.53280085 | AK5: 3.0662301 | AL5: 0.53170096 | AM5: 0.53170096 | AN5: 3.1060382 | AO5: 0.5379304 | AP5: 0.5379304 | AQ5: 3.0744673 | AR5: 0.53333494 | AS5: 0.53333494 | AT5: 3.0741216 | AU5: 0.53571904 | AV5: 0.53571904 | AW5: 3.0698524
A6: Ar | B6: 0.48219027 | C6: 0.48219027 | D6: 0.48219027 | E6: 0.48112273 | F6: 0.48112273 | G6: 0.48112273 | H6: 0.47950576 | I6: 0.47950576 | J6: 0.47950576 | K6: 0.48009052 | L6: 0.48009052 | M6: 0.48009052 | N6: 0.48219027 | O6: 0.48219027 | P6: 0.48219027 | Q6: 0.48144799 | R6: 0.48144799 | S6: 0.48144799 | T6: 0.48015077 | U6: 0.48015077 | V6: 0.48015077 | W6: 0.48072299 | X6: 0.48072299 | Y6: 0.48072299 | Z6: 0.48229766 | AA6: 0.48229766 | AB6: 0.48229766 | AC6: 0.48216744 | AD6: 0.48216744 | AE6: 0.48216744 | AF6: 0.48086466 | AG6: 0.48086466 | AH6: 0.48086466 | AI6: 0.48147577 | AJ6: 0.48147577 | AK6: 0.48147577 | AL6: 0.48274375 | AM6: 0.48274375 | AN6: 0.48274375 | AO6: 0.483898 | AP6: 0.483898 | AQ6: 0.483898 | AR6: 0.48302577 | AS6: 0.48302577 | AT6: 0.48302577 | AU6: 0.48367299 | AV6: 0.48367299 | AW6: 0.48367299
A7: BF | B7: 0.55273267 | C7: 0.55273267 | D7: 2.094493 | E7: 0.56248528 | F7: 0.56248528 | G7: 2.0695614 | H7: 0.55499897 | I7: 0.55499897 | J7: 2.0580441 | K7: 0.55769608 | L7: 0.55769608 | M7: 2.0541193 | N7: 0.55273267 | O7: 0.55273267 | P7: 2.094493 | Q7: 0.5630509 | R7: 0.5630509 | S7: 2.070382 | T7: 0.55569017 | U7: 0.55569017 | V7: 2.0587334 | W7: 0.55837946 | X7: 0.55837946 | Y7: 2.0549589 | Z7: 0.55296633 | AA7: 0.55296633 | AB7: 2.0945418 | AC7: 0.56389019 | AD7: 0.56389019 | AE7: 2.0710628 | AF7: 0.55647946 | AG7: 0.55647946 | AH7: 2.0592618 | AI7: 0.55916875 | AJ7: 0.55916875 | AK7: 2.0556106 | AL7: 0.55353987 | AM7: 0.55353987 | AN7: 2.0952838 | AO7: 0.56606876 | AP7: 0.56606876 | AQ7: 2.0737956 | AR7: 0.55876161 | AS7: 0.55876161 | AT7: 2.0616056 | AU7: 0.56144018 | AV7: 0.56144018 | AW7: 2.0583294
A8: BH2 | B8: 0.69879403 | C8: 1.1893496 | D8: 2.0674166 | E8: 0.70282317 | F8: 1.1817772 | G8: 2.0513431 | H8: 0.7033056 | I8: 1.1777792 | J8: 2.0480923 | K8: 0.7049836 | L8: 1.178443 | M8: 2.0478529 | N8: 0.69879403 | O8: 1.1893496 | P8: 2.0674166 | Q8: 0.70347255 | R8: 1.1830667 | S8: 2.0530954 | T8: 0.70417255 | U8: 1.1791461 | V8: 2.0500668 | W8: 0.70582256 | X8: 1.1798535 | Y8: 2.0498954 | Z8: 0.69899583 | AA8: 1.1896842 | AB8: 2.0674166 | AC8: 0.70420827 | AD8: 1.1843553 | AE8: 2.0546097 | AF8: 0.70489398 | AG8: 1.1802686 | AH8: 2.0512025 | AI8: 0.70655113 | AJ8: 1.1810053 | AK8: 2.0510882 | AL8: 0.69982428 | AM8: 1.1908419 | AN8: 2.0675759 | AO8: 0.70665827 | AP8: 1.1885876 | AQ8: 2.0592454 | AR8: 0.70762256 | AS8: 1.1843792 | AT8: 2.055624 | AU8: 0.70925113 | AV8: 1.1852159 | AW8: 2.0556811
A9: BH2F | B9: 0.49650323 | C9: 1.0878995 | D9: 2.622779 | E9: 0.50624947 | F9: 1.0895864 | G9: 2.6181586 | H9: 0.5023612 | I9: 1.0851804 | J9: 2.6155825 | K9: 0.50452573 | L9: 1.0867402 | M9: 2.6157257 | N9: 0.49650323 | O9: 1.0878995 | P9: 2.622779 | Q9: 0 | R9: 0 | S9: 0 | T9: 0 | U9: 0 | V9: 0 | W9: 0 | X9: 0 | Y9: 0 | Z9: 0.49660082 | AA9: 1.0880714 | AB9: 2.6228952 | AC9: 0.50721331 | AD9: 1.0915081 | AE9: 2.6198757 | AF9: 0.5035508 | AG9: 1.0871956 | AH9: 2.617337 | AI9: 0.50570393 | AJ9: 1.0887987 | AK9: 2.6175636 | AL9: 0.49708872 | AM9: 1.0883549 | AN9: 2.6234114 | AO9: 0.50888831 | AP9: 1.0941894 | AQ9: 2.6225858 | AR9: 0.50553518 | AS9: 1.090005 | AT9: 2.6200982 | AU9: 0.50767269 | AV9: 1.0916675 | AW9: 2.6204391
A10: BH3 | B10: 1.8239941 | C10: 1.8239486 | D10: 0.66095105 | E10: 1.8095462 | F10: 1.8094916 | G10: 0.66180655 | H10: 1.8064842 | I10: 1.8064495 | J10: 0.66072614 | K10: 1.8064702 | L10: 1.8064309 | M10: 0.66202158 | N10: 1.8239941 | O10: 1.8239486 | P10: 0.66095105 | Q10: 1.8110946 | R10: 1.8110461 | S10: 0.66241981 | T10: 1.8081633 | U10: 1.8081086 | V10: 0.66150106 | W10: 1.8082258 | X10: 1.8081773 | Y10: 0.66278856 | Z10: 1.8240777 | AA10: 1.8240229 | AB10: 0.66103469 | AC10: 1.8123696 | AD10: 1.8123148 | AE10: 0.66305106 | AF10: 1.8091571 | AG10: 1.8091086 | AH10: 0.66205731 | AI10: 1.8092571 | AJ10: 1.8092086 | AK10: 0.66335731 | AL10: 1.8242357 | AM10: 1.8241809 | AN10: 0.66176888 | AO10: 1.8162821 | AP10: 1.8162398 | AQ10: 0.66537606 | AR10: 1.8128633 | AS10: 1.8128086 | AT10: 0.66450106 | AU10: 1.8131196 | AV10: 1.8130711 | AW10: 0.66580731
A11: BHF2 | B11: 0.43806284 | C11: 3.9740953 | D11: 1.1697916 | E11: 0.44955305 | F11: 3.9651788 | G11: 1.1751374 | H11: 0.44519065 | I11: 3.9651109 | J11: 1.1709367 | K11: 0.44735507 | L11: 3.9633939 | M11: 1.1725781 | N11: 0.43806284 | O11: 3.9740953 | P11: 1.1697916 | Q11: 0 | R11: 0 | S11: 0 | T11: 0 | U11: 0 | V11: 0 | W11: 0 | X11: 0 | Y11: 0 | Z11: 0.43818676 | AA11: 3.9742316 | AB11: 1.1699558 | AC11: 0.45042155 | AD11: 3.9660915 | AE11: 1.1766504 | AF11: 0.44630696 | AG11: 3.9659977 | AH11: 1.1726171 | AI11: 0.4484653 | AJ11: 3.9643644 | AK11: 1.1742899 | AL11: 0.43860806 | AM11: 3.9749905 | AN11: 1.1703629 | AO11: 0.45186322 | AP11: 3.9679144 | AQ11: 1.178906 | AR11: 0.44808822 | AS11: 3.9677852 | AT11: 1.1751019 | AU11: 0.45023822 | AV11: 3.9662665 | AW11: 1.1768178
A12: BO | B12: 0.58894817 | C12: 0.58894817 | D12: 1.7992171 | E12: 0.59491551 | F12: 0.59491551 | G12: 1.8109481 | H12: 0.59242371 | I12: 0.59242371 | J12: 1.8052026 | K12: 0.59414773 | L12: 0.59414773 | M12: 1.809595 | N12: 0.58894817 | O12: 0.58894817 | P12: 1.7992171 | Q12: 0 | R12: 0 | S12: 0 | T12: 0 | U12: 0 | V12: 0 | W12: 0 | X12: 0 | Y12: 0 | Z12: 0.58914833 | AA12: 0.58914833 | AB12: 1.7993748 | AC12: 0.59640095 | AD12: 0.59640095 | AE12: 1.8126651 | AF12: 0.59406633 | AG12: 0.59406633 | AH12: 1.8071629 | AI12: 0.59582403 | AJ12: 0.59582403 | AK12: 1.8115868 | AL12: 0.5895601 | AM12: 0.5895601 | AN12: 1.8000249 | AO12: 0.59857403 | AP12: 0.59857403 | AQ12: 1.8154521 | AR12: 0.5964548 | AS12: 0.5964548 | AT12: 1.8102831 | AU12: 0.59825865 | AV12: 0.59825865 | AW12: 1.8147503
A13: BS | B13: 0.68843846 | C13: 0.68843846 | D13: 2.2556975 | E13: 0.68151902 | F13: 0.68151902 | G13: 2.2510154 | H13: 0.6768775 | I13: 0.6768775 | J13: 2.2620586 | K13: 0.67610369 | L13: 0.67610369 | M13: 2.2680859 | N13: 0.68843846 | O13: 0.68843846 | P13: 2.2556975 | Q13: 0.68217966 | R13: 0.68217966 | S13: 2.2522315 | T13: 0.67778442 | U13: 0.67778442 | V13: 2.2636282 | W13: 0.67707013 | X13: 0.67707013 | Y13: 2.2697118 | Z13: 0.68861194 | AA13: 0.68861194 | AB13: 2.2556233 | AC13: 0.68327728 | AD13: 0.68327728 | AE13: 2.2540522 | AF13: 0.67881299 | AG13: 0.67881299 | AH13: 2.2650485 | AI13: 0.67816775 | AJ13: 0.67816775 | AK13: 2.2711932 | AL13: 0.68905448 | AM13: 0.68905448 | AN13: 2.2560202 | AO13: 0.68589157 | AP13: 0.68589157 | AQ13: 2.2587124 | AR13: 0.68167014 | AS13: 0.68167014 | AT13: 2.2696442 | AU13: 0.68120109 | AV13: 0.68120109 | AW13: 2.2759501
A14: Be | B14: 1.4435349 | C14: 1.4435349 | D14: 1.4435349 | E14: 1.3879865 | F14: 1.3879865 | G14: 1.3879865 | H14: 1.3547915 | I14: 1.3547915 | J14: 1.3547915 | K14: 1.352929 | L14: 1.352929 | M14: 1.352929 | N14: 1.4435349 | O14: 1.4435349 | P14: 1.4435349 | Q14: 0 | R14: 0 | S14: 0 | T14: 0 | U14: 0 | V14: 0 | W14: 0 | X14: 0 | Y14: 0 | Z14: 1.4436093 | AA14: 1.4436093 | AB14: 1.4436093 | AC14: 1.3919022 | AD14: 1.3919022 | AE14: 1.3919022 | AF14: 1.3568647 | AG14: 1.3568647 | AH14: 1.3568647 | AI14: 1.3553397 | AJ14: 1.3553397 | AK14: 1.3553397 | AL14: 1.4437952 | AM14: 1.4437952 | AN14: 1.4437952 | AO14: 1.3973522 | AP14: 1.3973522 | AQ14: 1.3973522 | AR14: 1.3597897 | AS14: 1.3597897 | AT14: 1.3597897 | AU14: 1.3587272 | AV14: 1.3587272 | AW14: 1.3587272
A15: BeH | B15: 0.97841573 | C15: 0.97841573 | D15: 2.7111094 | E15: 0.97926473 | F15: 0.97926473 | G15: 2.6672125 | H15: 0.98480853 | I15: 0.98480853 | J15: 2.6456196 | K15: 0.98657583 | L15: 0.98657583 | M15: 2.6413143 | N15: 0.97841573 | O15: 0.97841573 | P15: 2.7111094 | Q15: 0 | R15: 0 | S15: 0 | T15: 0 | U15: 0 | V15: 0 | W15: 0 | X15: 0 | Y15: 0 | Z15: 0.97837112 | AA15: 0.97837112 | AB15: 2.7117581 | AC15: 0.98088157 | AD15: 0.98088157 | AE15: 2.6721373 | AF15: 0.98665158 | AG15: 0.98665158 | AH15: 2.6498294 | AI15: 0.98841158 | AJ15: 0.98841158 | AK15: 2.6458099 | AL15: 0.97914434 | AM15: 0.97914434 | AN15: 2.7139046 | AO15: 0.98393157 | AP15: 0.98393157 | AQ15: 2.6801438 | AR15: 0.99001158 | AS15: 0.99001158 | AT15: 2.6568561 | AU15: 0.99176158 | AV15: 0.99176158 | AW15: 2.6532283
A16: BeH2 | B16: 0.81305406 | C16: 0.81305406 | D16: 3.6105651 | E16: 0.80960299 | F16: 0.80960299 | G16: 3.5713523 | H16: 0.81105299 | I16: 0.81105299 | J16: 3.5612574 | K16: 0.81212191 | L16: 0.81212191 | M16: 3.5580212 | N16: 0.81305406 | O16: 0.81305406 | P16: 3.6105651 | Q16: 0 | R16: 0 | S16: 0 | T16: 0 | U16: 0 | V16: 0 | W16: 0 | X16: 0 | Y16: 0 | Z16: 0.81306645 | AA16: 0.81306645 | AB16: 3.6104784 | AC16: 0.81120963 | AD16: 0.81120963 | AE16: 3.5760545 | AF16: 0.81265963 | AG16: 0.81265963 | AH16: 3.5655461 | AI16: 0.81373463 | AJ16: 0.81373463 | AK16: 3.5625044 | AL16: 0.8136984 | AM16: 0.8136984 | AN16: 3.6119157 | AO16: 0.8140263 | AP16: 0.8140263 | AQ16: 3.5840545 | AR16: 0.8154763 | AS16: 0.8154763 | AT16: 3.5729795 | AU16: 0.81655964 | AV16: 0.81655964 | AW16: 3.5702044
... A88: SiO | B88: 0.54350196 | C88: 0.54350196 | D88: 2.5978585 | E88: 0.55917666 | F88: 0.55917666 | G88: 2.5660719 | H88: 0.54856061 | I88: 0.54856061 | J88: 2.5697255 | K88: 0.55265601 | L88: 0.55265601 | M88: 2.5654737 | N88: 0.54350196 | O88: 0.54350196 | P88: 2.5978585 | Q88: 0.55995544 | R88: 0.55995544 | S88: 2.5665761 | T88: 0.54946679 | U88: 0.54946679 | V88: 2.5701919 | W88: 0.55362134 | X88: 0.55362134 | Y88: 2.5660837 | Z88: 0.54365066 | AA88: 0.54365066 | AB88: 2.5979757 | AC88: 0.56088953 | AD88: 0.56088953 | AE88: 2.5677369 | AF88: 0.55037133 | AG88: 0.55037133 | AH88: 2.5711347 | AI88: 0.55454634 | AJ88: 0.55454634 | AK88: 2.567172 | AL88: 0.54420489 | AM88: 0.54420489 | AN88: 2.599329 | AO88: 0.56358726 | AP88: 0.56358726 | AQ88: 2.5712113 | AR88: 0.55320316 | AS88: 0.55320316 | AT88: 2.5742587 | AU88: 0.55748725 | AV88: 0.55748725 | AW88: 2.5706921
A90: RMSE | N90: {=SQRT(AVERAGE((N5:N88-Z5:Z88)^2))} -> 0.00028376017 | O90: {=SQRT(AVERAGE((O5:O88-AA5:AA88)^2))} -> 0.0002468211 | P90: {=SQRT(AVERAGE((P5:P88-AB5:AB88)^2))} -> 0.00021942151
P91: {=SQRT(AVERAGE(N90:P90^2))} -> 0.00025138701
N92: {=MAX(ABS(N5:N88-Z5:Z88))} -> 0.0009665201 | O92: {=MAX(ABS(O5:O88-AA5:AA88))} -> 0.0009665201 | P92: {=MAX(ABS(P5:P88-AB5:AB88))} -> 0.0009665201

Sheet dft_values
A1: method | B1: Slater | C1: Slater | D1: Slater | E1: SPW92 | F1: SPW92 | G1: SPW92 | H1: B97-D3 | I1: B97-D3 | J1: B97-D3 | K1: BLYP | L1: BLYP | M1: BLYP | N1: BPBE | O1: BPBE | P1: BPBE | Q1: mPW91 | R1: mPW91 | S1: mPW91 | T1: N12 | U1: N12 | V1: N12 | W1: PBE | X1: PBE | Y1: PBE | Z1: SOGGA11 | AA1: SOGGA11 | AB1: SOGGA11 | AC1: B97M-V | AD1: B97M-V | AE1: B97M-V | AF1: M06-L | AG1: M06-L | AH1: M06-L | AI1: M11-L | AJ1: M11-L | AK1: M11-L | AL1: mBEEF | AM1: mBEEF | AN1: mBEEF | AO1: MGGA_MS2 | AP1: MGGA_MS2 | AQ1: MGGA_MS2 | AR1: MN15-L | AS1: MN15-L | AT1: MN15-L | AU1: revM06-L | AV1: revM06-L | AW1: revM06-L | AX1: SCAN | AY1: SCAN | AZ1: SCAN | BA1: TPSS | BB1: TPSS | BC1: TPSS | BD1: B3LYP | BE1: B3LYP | BF1: B3LYP | BG1: B97 | BH1: B97 | BI1: B97 | BJ1: B97-2 | BK1: B97-2 | BL1: B97-2 | BM1: HFLYP | BN1: HFLYP | BO1: HFLYP | BP1: M06-2X | BQ1: M06-2X | BR1: M06-2X | BS1: PBE0 | BT1: PBE0 | BU1: PBE0 | BV1: SOGGA11-X | BW1: SOGGA11-X | BX1: SOGGA11-X | BY1: M06 | BZ1: M06 | CA1: M06 | CB1: M08-HX | CC1: M08-HX | CD1: M08-HX | CE1: MN15 | CF1: MN15 | CG1: MN15 | CH1: PW6B95 | CI1: PW6B95 | CJ1: PW6B95 | CK1: SCAN0 | CL1: SCAN0 | CM1: SCAN0 | CN1: TPSSh | CO1: TPSSh | CP1: TPSSh | CQ1: CAM-B3LYP | CR1: CAM-B3LYP | CS1: CAM-B3LYP | CT1: HSE-HJS | CU1: HSE-HJS | CV1: HSE-HJS | CW1: LRC-wPBEh | CX1: LRC-wPBEh | CY1: LRC-wPBEh | CZ1: wB97X-D | DA1: wB97X-D | DB1: wB97X-D | DC1: wB97X-V | DD1: wB97X-V | DE1: wB97X-V | DF1: M11 | DG1: M11 | DH1: M11 | DI1: wB97M-V | DJ1: wB97M-V | DK1: wB97M-V | DL1: wM05-D | DM1: wM05-D | DN1: wM05-D
A2: component | B2: XX | C2: YY | D2: ZZ | E2: XX | F2: YY | G2: ZZ | H2: XX | I2: YY | J2: ZZ | K2: XX | L2: YY | M2: ZZ | N2: XX | O2: YY | P2: ZZ | Q2: XX | R2: YY | S2: ZZ | T2: XX | U2: YY | V2: ZZ | W2: XX | X2: YY | Y2: ZZ | Z2: XX | AA2: YY | AB2: ZZ | AC2: XX | AD2: YY | AE2: ZZ | AF2: XX | AG2: YY | AH2: ZZ | AI2: XX | AJ2: YY | AK2: ZZ | AL2: XX | AM2: YY | AN2: ZZ | AO2: XX | AP2: YY | AQ2: ZZ | AR2: XX | AS2: YY | AT2: ZZ | AU2: XX | AV2: YY | AW2: ZZ | AX2: XX | AY2: YY | AZ2: ZZ | BA2: XX | BB2: YY | BC2: ZZ | BD2: XX | BE2: YY | BF2: ZZ | BG2: XX | BH2: YY | BI2: ZZ | BJ2: XX | BK2: YY | BL2: ZZ | BM2: XX | BN2: YY | BO2: ZZ | BP2: XX | BQ2: YY | BR2: ZZ | BS2: XX | BT2: YY | BU2: ZZ | BV2: XX | BW2: YY | BX2: ZZ | BY2: XX | BZ2: YY | CA2: ZZ | CB2: XX | CC2: YY | CD2: ZZ | CE2: XX | CF2: YY | CG2: ZZ | CH2: XX | CI2: YY | CJ2: ZZ | CK2: XX | CL2: YY | CM2: ZZ | CN2: XX | CO2: YY | CP2: ZZ | CQ2: XX | CR2: YY | CS2: ZZ | CT2: XX | CU2: YY | CV2: ZZ | CW2: XX | CX2: YY | CY2: ZZ | CZ2: XX | DA2: YY | DB2: ZZ | DC2: XX | DD2: YY | DE2: ZZ | DF2: XX | DG2: YY | DH2: ZZ | DI2: XX | DJ2: YY | DK2: ZZ | DL2: XX | DM2: YY | DN2: ZZ
A3: molecule
A4: AlF | B4: 0.56004433 | C4: 0.56004433 | D4: 3.0700231 | E4: 0.54110932 | F4: 0.54110932 | G4: 3.0524086 | H4: 0.53893634 | I4: 0.53893634 | J4: 3.0641374 | K4: 0.54240365 | L4: 0.54240365 | M4: 3.0630231 | N4: 0.53715875 | O4: 0.53715875 | P4: 3.0586333 | Q4: 0.53907828 | R4: 0.53907828 | S4: 3.0596605 | T4: 0.53514799 | U4: 0.53514799 | V4: 3.0652797 | W4: 0.54144726 | X4: 0.54144726 | Y4: 3.0610046 | Z4: 0.57221369 | AA4: 0.57221369 | AB4: 3.0729288 | AC4: 0.53802727 | AD4: 0.53802727 | AE4: 3.0761272 | AF4: 0.52538478 | AG4: 0.52538478 | AH4: 3.0585058 | AI4: 0.54652656 | AJ4: 0.54652656 | AK4: 3.0541276 | AL4: 0.53377593 | AM4: 0.53377593 | AN4: 3.0691675 | AO4: 0.53586105 | AP4: 0.53586105 | AQ4: 3.0677067 | AR4: 0.55629653 | AS4: 0.55629653 | AT4: 3.0967214 | AU4: 0.53076147 | AV4: 0.53076147 | AW4: 3.0918562 | AX4: 0.53607733 | AY4: 0.53607733 | AZ4: 3.0660642 | BA4: 0.53820976 | BB4: 0.53820976 | BC4: 3.0669402 | BD4: 0.5359185 | BE4: 0.5359185 | BF4: 3.0667893 | BG4: 0.53556028 | BH4: 0.53556028 | BI4: 3.0696869 | BJ4: 0.53309667 | BK4: 0.53309667 | BL4: 3.0688493 | BM4: 0.52139028 | BN4: 0.52139028 | BO4: 3.0895483 | BP4: 0.53012614 | BQ4: 0.53012614 | BR4: 3.0629144 | BS4: 0.53424567 | BT4: 0.53424567 | BU4: 3.0678186 | BV4: 0.53248499 | BW4: 0.53248499 | BX4: 3.0764611 | BY4: 0.52402287 | BZ4: 0.52402287 | CA4: 3.0540837 | CB4: 0.53413415 | CC4: 0.53413415 | CD4: 3.077711 | CE4: 0.5437588 | CF4: 0.5437588 | CG4: 3.0656611 | CH4: 0.53311356 | CI4: 0.53311356 | CJ4: 3.0625737 | CK4: 0.53187669 | CL4: 0.53187669 | CM4: 3.0706158 | CN4: 0.53571235 | CO4: 0.53571235 | CP4: 3.0692949 | CQ4: 0.53487763 | CR4: 0.53487763 | CS4: 3.0708951 | CT4: 0.53419836 | CU4: 0.53419836 | CV4: 3.0673534 | CW4: 0.53398546 | CX4: 0.53398546 | CY4: 3.0706786 | CZ4: 0.53210649 | DA4: 0.53210649 | DB4: 3.0717711 | DC4: 0.53521895 | DD4: 0.53521895 | DE4: 3.0778845 | DF4: 0.53064657 | DG4: 0.53064657 | DH4: 3.0795042 | DI4: 0.53825031 | DJ4: 0.53825031 | DK4: 3.0651044 | DL4: 0.53271479 | DM4: 0.53271479 | DN4: 3.062532
A5: Ar | B5: 0.49635764 | C5: 0.49635764 | D5: 0.49635764 | E5: 0.48707243 | F5: 0.48707243 | G5: 0.48707243 | H5: 0.48083136 | I5: 0.48083136 | J5: 0.48083136 | K5: 0.48871635 | L5: 0.48871635 | M5: 0.48871635 | N5: 0.48305353 | O5: 0.48305353 | P5: 0.48305353 | Q5: 0.48444135 | R5: 0.48444135 | S5: 0.48444135 | T5: 0.47781202 | U5: 0.47781202 | V5: 0.47781202 | W5: 0.48570939 | X5: 0.48570939 | Y5: 0.48570939 | Z5: 0.4826157 | AA5: 0.4826157 | AB5: 0.4826157 | AC5: 0.48146744 | AD5: 0.48146744 | AE5: 0.48146744 | AF5: 0.47687028 | AG5: 0.47687028 | AH5: 0.47687028 | AI5: 0.47210376 | AJ5: 0.47210376 | AK5: 0.47210376 | AL5: 0.47748571 | AM5: 0.47748571 | AN5: 0.47748571 | AO5: 0.48028614 | AP5: 0.48028614 | AQ5: 0.48028614 | AR5: 0.48488331 | AS5: 0.48488331 | AT5: 0.48488331 | AU5: 0.47860919 | AV5: 0.47860919 | AW5: 0.47860919 | AX5: 0.48128571 | AY5: 0.48128571 | AZ5: 0.48128571 | BA5: 0.48316092 | BB5: 0.48316092 | BC5: 0.48316092 | BD5: 0.48550287 | BE5: 0.48550287 | BF5: 0.48550287 | BG5: 0.48307418 | BH5: 0.48307418 | BI5: 0.48307418 | BJ5: 0.47948071 | BK5: 0.47948071 | BL5: 0.47948071 | BM5: 0.47886941 | BN5: 0.47886941 | BO5: 0.47886941 | BP5: 0.48294201 | BQ5: 0.48294201 | BR5: 0.48294201 | BS5: 0.48233896 | BT5: 0.48233896 | BU5: 0.48233896 | BV5: 0.48197549 | BW5: 0.48197549 | BX5: 0.48197549 | BY5: 0.48005897 | BZ5: 0.48005897 | CA5: 0.48005897 | CB5: 0.48395396 | CC5: 0.48395396 | CD5: 0.48395396 | CE5: 0.4784068 | CF5: 0.4784068 | CG5: 0.4784068 | CH5: 0.48204983 | CI5: 0.48204983 | CJ5: 0.48204983 | CK5: 0.48042245 | CL5: 0.48042245 | CM5: 0.48042245 | CN5: 0.48211179 | CO5: 0.48211179 | CP5: 0.48211179 | CQ5: 0.48609765 | CR5: 0.48609765 | CS5: 0.48609765 | CT5: 0.4823431 | CU5: 0.4823431 | CV5: 0.4823431 | CW5: 0.48237614 | CX5: 0.48237614 | CY5: 0.48237614 | CZ5: 0.48069505 | DA5: 0.48069505 | DB5: 0.48069505 | DC5: 0.48370201 | DD5: 0.48370201 | DE5: 0.48370201 | DF5: 0.48410679 | DG5: 0.48410679 | DH5: 0.48410679 | DI5: 0.48659744 | DJ5: 0.48659744 | DK5: 0.48659744 | DL5: 0.48269418 | DM5: 0.48269418 | DN5: 0.48269418
A6: BF | B6: 0.59672526 | C6: 0.59672526 | D6: 2.0863465 | E6: 0.57708685 | F6: 0.57708685 | G6: 2.0666787 | H6: 0.56741103 | I6: 0.56741103 | J6: 2.0687921 | K6: 0.57496263 | L6: 0.57496263 | M6: 2.0723461 | N6: 0.56731012 | O6: 0.56731012 | P6: 2.0647961 | Q6: 0.56990698 | R6: 0.56990698 | S6: 2.0661319 | T6: 0.56537708 | U6: 0.56537708 | V6: 2.0625454 | W6: 0.57257288 | X6: 0.57257288 | Y6: 2.0673495 | Z6: 0.58729904 | AA6: 0.58729904 | AB6: 2.0802281 | AC6: 0.56547267 | AD6: 0.56547267 | AE6: 2.0761657 | AF6: 0.55321061 | AG6: 0.55321061 | AH6: 2.0641028 | AI6: 0.55699173 | AJ6: 0.55699173 | AK6: 2.0850483 | AL6: 0.56048076 | AM6: 0.56048076 | AN6: 2.0664943 | AO6: 0.56180308 | AP6: 0.56180308 | AQ6: 2.0698201 | AR6: 0.57374651 | AS6: 0.57374651 | AT6: 2.0915386 | AU6: 0.55466571 | AV6: 0.55466571 | AW6: 2.0871045 | AX6: 0.56378923 | AY6: 0.56378923 | AZ6: 2.0686034 | BA6: 0.56481417 | BB6: 0.56481417 | BC6: 2.0694041 | BD6: 0.56697025 | BE6: 0.56697025 | BF6: 2.0723002 | BG6: 0.56413442 | BH6: 0.56413442 | BI6: 2.0694445 | BJ6: 0.56064007 | BK6: 0.56064007 | BL6: 2.0680511 | BM6: 0.54577584 | BN6: 0.54577584 | BO6: 2.0813652 | BP6: 0.56213234 | BQ6: 0.56213234 | BR6: 2.0642152 | BS6: 0.56338032 | BT6: 0.56338032 | BU6: 2.0689634 | BV6: 0.56129858 | BW6: 0.56129858 | BX6: 2.0724911 | BY6: 0.55917967 | BZ6: 0.55917967 | CA6: 2.0635922 | CB6: 0.56194647 | CC6: 0.56194647 | CD6: 2.0750673 | CE6: 0.56638078 | CF6: 0.56638078 | CG6: 2.0679399 | CH6: 0.56267401 | CI6: 0.56267401 | CJ6: 2.0634042 | CK6: 0.55921685 | CL6: 0.55921685 | CM6: 2.0699512 | CN6: 0.56205799 | CO6: 0.56205799 | CP6: 2.0698964 | CQ6: 0.56732075 | CR6: 0.56732075 | CS6: 2.075635 | CT6: 0.56328473 | CU6: 0.56328473 | CV6: 2.0686915 | CW6: 0.5640282 | CX6: 0.5640282 | CY6: 2.0708117 | CZ6: 0.56159597 | DA6: 0.56159597 | DB6: 2.0726011 | DC6: 0.56511687 | DD6: 0.56511687 | DE6: 2.0764934 | DF6: 0.55980632 | DG6: 0.55980632 | DH6: 2.0751612 | DI6: 0.57073543 | DJ6: 0.57073543 | DK6: 2.0711823 | DL6: 0.56351839 | DM6: 0.56351839 | DN6: 2.069368
A7: BH2 | B7: 0.76138417 | C7: 1.2563611 | D7: 2.0949678 | E7: 0.73625465 | F7: 1.2107214 | G7: 2.060566 | H7: 0.71275016 | I7: 1.1880542 | J7: 2.0599394 | K7: 0.72367927 | L7: 1.200961 | M7: 2.0741823 | N7: 0.71384413 | O7: 1.1883804 | P7: 2.0543208 | Q7: 0.71803947 | R7: 1.1925545 | S7: 2.0586011 | T7: 0.7283738 | U7: 1.2198062 | V7: 2.072058 | W7: 0.72236225 | X7: 1.1984034 | Y7: 2.0605448 | Z7: 0.74084297 | AA7: 1.2053695 | AB7: 2.0773049 | AC7: 0.71875108 | AD7: 1.2058273 | AE7: 2.0864178 | AF7: 0.68332971 | AG7: 1.1598239 | AH7: 2.0493714 | AI7: 0.71657375 | AJ7: 1.2002117 | AK7: 2.0933109 | AL7: 0.70176794 | AM7: 1.1792853 | AN7: 2.0600881 | AO7: 0.70150241 | AP7: 1.1815052 | AQ7: 2.047672 | AR7: 0.72596281 | AS7: 1.220763 | AT7: 2.1087964 | AU7: 0.69086007 | AV7: 1.1786444 | AW7: 2.0815427 | AX7: 0.7054747 | AY7: 1.1798306 | AZ7: 2.0544589 | BA7: 0.70627129 | BB7: 1.1837709 | BC7: 2.0544907 | BD7: 0.71518239 | BE7: 1.1907091 | BF7: 2.0650694 | BG7: 0.71151811 | BH7: 1.1901773 | BI7: 2.0568061 | BJ7: 0.70731215 | BK7: 1.1857322 | BL7: 2.0505609 | BM7: 0.69367466 | BN7: 1.1698227 | BO7: 2.0487023 | BP7: 0.71893164 | BQ7: 1.1886025 | BR7: 2.0594402 | BS7: 0.71199606 | BT7: 1.1870228 | BU7: 2.0522922 | BV7: 0.71150749 | BW7: 1.1976867 | BX7: 2.0562432 | BY7: 0.71272892 | BZ7: 1.1855234 | CA7: 2.0598863 | CB7: 0.72236225 | CC7: 1.1909825 | CD7: 2.0692966 | CE7: 0.72935094 | CF7: 1.2002651 | CG7: 2.0800664 | CH7: 0.71432208 | CI7: 1.1883697 | CJ7: 2.0594933 | CK7: 0.70342483 | CL7: 1.1762255 | CM7: 2.0518036 | CN7: 0.70399837 | CO7: 1.1807309 | CP7: 2.0522285 | CQ7: 0.71832624 | CR7: 1.1918368 | CS7: 2.0651225 | CT7: 0.71173053 | CU7: 1.1867734 | CV7: 2.0523028 | CW7: 0.71348301 | CX7: 1.1868932 | CY7: 2.0514637 | CZ7: 0.70972314 | DA7: 1.1874573 | DB7: 2.0537791 | DC7: 0.71627636 | DD7: 1.1959459 | DE7: 2.0603642 | DF7: 0.71646754 | DG7: 1.1923475 | DH7: 2.0526958 | DI7: 0.73368435 | DJ7: 1.2093828 | DK7: 2.0767313 | DL7: 0.71485314 | DM7: 1.1852224 | DN7: 2.0581019
A8: BH2F | B8: 0.53523839 | C8: 1.1152966 | D8: 2.6399971 | E8: 0.52112162 | F8: 1.0960034 | G8: 2.6232289 | H8: 0.50882172 | I8: 1.0950462 | J8: 2.6226945 | K8: 0.51636801 | L8: 1.1025925 | M8: 2.6300035 | N8: 0.51088487 | O8: 1.0927786 | P8: 2.6204622 | Q8: 0.51292014 | R8: 1.0947488 | S8: 2.6223824 | T8: 0.50621026 | U8: 1.0891959 | V8: 2.6199092 | W8: 0.51535502 | X8: 1.0966075 | Y8: 2.623856 | Z8: 0.5194395 | AA8: 1.1010916 | AB8: 2.6284663 | AC8: 0.50710707 | AD8: 1.1033034 | AE8: 2.6284403 | AF8: 0.4970562 | AG8: 1.0890054 | AH8: 2.6164015 | AI8: 0.4969772 | AJ8: 1.0998276 | AK8: 2.6204539 | AL8: 0.5036592 | AM8: 1.0931317 | AN8: 2.6194968 | AO8: 0.5061452 | AP8: 1.089642 | AQ8: 2.6161572 | AR8: 0.5114843 | AS8: 1.1132149 | AT8: 2.6360569 | AU8: 0.50061559 | AV8: 1.1049948 | AW8: 2.6290915 | AX8: 0.50645653 | AY8: 1.0906922 | AZ8: 2.6185346 | BA8: 0.50837563 | BB8: 1.0926438 | BC8: 2.6197896 | BD8: 0.51018321 | BE8: 1.0949858 | BF8: 2.6245844 | BG8: 0.50764145 | BH8: 1.091826 | BI8: 2.6211861 | BJ8: 0.50422145 | BK8: 1.0876253 | BL8: 2.6175156 | BM8: 0.49293454 | BN8: 1.0778533 | BO8: 2.6134081 | BP8: 0.50689797 | BQ8: 1.0891216 | BR8: 2.6200792 | BS8: 0.5077855 | BT8: 1.0886662 | BU8: 2.6185798 | BV8: 0.50567123 | BW8: 1.0903576 | BX8: 2.6203549 | BY8: 0.50339434 | BZ8: 1.0901996 | CA8: 2.6188207 | CB8: 0.50976965 | CC8: 1.0945025 | CD8: 2.6266929 | CE8: 0.50929569 | CF8: 1.0959987 | CG8: 2.6236083 | CH8: 0.50754851 | CI8: 1.0903111 | CJ8: 2.6192292 | CK8: 0.50313877 | CL8: 1.0865008 | CM8: 2.6165684 | CN8: 0.50616379 | CO8: 1.0901113 | CP8: 2.618296 | CQ8: 0.51234394 | CR8: 1.0951949 | CS8: 2.6252408 | CT8: 0.50769256 | CU8: 1.0886894 | CV8: 2.618578 | CW8: 0.50921204 | CX8: 1.0889775 | CY8: 2.6189182 | CZ8: 0.50539243 | DA8: 1.0878855 | DB8: 2.6180763 | DC8: 0.51058748 | DD8: 1.0934849 | DE8: 2.6399169 | DF8: 0.50908194 | DG8: 1.0895165 | DH8: 2.6239244 | DI8: 0.51466731 | DJ8: 1.0994698 | DK8: 2.6424804 | DL8: 0.5084918 | DM8: 1.0920908 | DN8: 2.622583
A9: BH3 | B9: 1.852051 | C9: 1.8519962 | D9: 0.71129374 | E9: 1.8198956 | F9: 1.8198409 | G9: 0.68830171 | H9: 1.8194217 | I9: 1.8193669 | J9: 0.66682452 | K9: 1.8279903 | L9: 1.8279355 | M9: 0.67480761 | N9: 1.8113271 | O9: 1.8112723 | P9: 0.66719626 | Q9: 1.8150816 | R9: 1.8150269 | S9: 0.67077424 | T9: 1.818037 | U9: 1.8179822 | V9: 0.66879474 | W9: 1.8177396 | X9: 1.8176941 | Y9: 0.67456598 | Z9: 1.8312987 | AA9: 1.8312532 | AB9: 0.6898909 | AC9: 1.8329251 | AD9: 1.8328703 | AE9: 0.66547697 | AF9: 1.8045243 | AG9: 1.8044695 | AH9: 0.64606293 | AI9: 1.83365 | AJ9: 1.8335859 | AK9: 0.66296773 | AL9: 1.8168939 | AM9: 1.8168112 | AN9: 0.65916671 | AO9: 1.8073402 | AP9: 1.8072389 | AQ9: 0.65854405 | AR9: 1.8538818 | AS9: 1.8538271 | AT9: 0.67414777 | AU9: 1.8338451 | AV9: 1.8337904 | AW9: 0.65276351 | AX9: 1.8121356 | AY9: 1.8121366 | AZ9: 0.66294915 | BA9: 1.8123308 | BB9: 1.8122853 | BC9: 0.66061649 | BD9: 1.8205462 | BE9: 1.8204914 | BF9: 0.66937093 | BG9: 1.8148679 | BH9: 1.8148224 | BI9: 0.66570931 | BJ9: 1.8098401 | BK9: 1.8097853 | BL9: 0.66209415 | BM9: 1.8075446 | BN9: 1.8074899 | BO9: 0.65575601 | BP9: 1.814682 | BQ9: 1.8146272 | BR9: 0.67017017 | BS9: 1.8107695 | BT9: 1.810724 | BU9: 0.66760517 | BV9: 1.8148958 | BW9: 1.8148503 | BX9: 0.66473349 | BY9: 1.8109275 | BZ9: 1.8108727 | CA9: 0.66280045 | CB9: 1.8225164 | CC9: 1.8224523 | CD9: 0.67464962 | CE9: 1.8264382 | CF9: 1.8263835 | CG9: 0.67262364 | CH9: 1.8150909 | CI9: 1.8150454 | CJ9: 0.66800479 | CK9: 1.8100539 | CL9: 1.8100456 | CM9: 0.66221496 | CN9: 1.8105093 | CO9: 1.8104638 | CP9: 0.65951986 | CQ9: 1.8224328 | CR9: 1.822378 | CS9: 0.67433364 | CT9: 1.8107416 | CU9: 1.8106868 | CV9: 0.66736354 | CW9: 1.8107973 | CX9: 1.8107519 | CY9: 0.66968691 | CZ9: 1.8113921 | DA9: 1.8113466 | DB9: 0.66485431 | DC9: 1.8181949 | DD9: 1.8181402 | DE9: 0.67060696 | DF9: 1.8161597 | DG9: 1.8160956 | DH9: 0.67286527 | DI9: 1.8287244 | DJ9: 1.8286697 | DK9: 0.67968667 | DL9: 1.8173399 | DM9: 1.8172945 | DN9: 0.67128538
A10: BHF2 | B10: 0.470686 | C10: 3.9683736 | D10: 1.1940773 | E10: 0.45989319 | F10: 3.9599351 | G10: 1.1802945 | H10: 0.45074532 | I10: 3.9584482 | J10: 1.1793896 | K10: 0.4580314 | L10: 3.9656816 | M10: 1.1864652 | N10: 0.45317401 | O10: 3.9564625 | P10: 1.1792829 | Q10: 0.4547508 | R10: 3.9585783 | S10: 1.1805943 | T10: 0.44695049 | U10: 3.9624753 | V10: 1.1724991 | W10: 0.45669004 | X10: 3.9595076 | Y10: 1.1820054 | Z10: 0.45898243 | AA10: 3.9615956 | AB10: 1.1833777 | AC10: 0.44888973 | AD10: 3.9595572 | AE10: 1.1837322 | AF10: 0.4420993 | AG10: 3.9496194 | AH10: 1.1761256 | AI10: 0.43681442 | AJ10: 3.94356 | AK10: 1.1770733 | AL10: 0.44647962 | AM10: 3.9561217 | AN10: 1.1766661 | AO10: 0.4496456 | AP10: 3.9543436 | AQ10: 1.176196 | AR10: 0.45153527 | AS10: 3.962655 | AT10: 1.1893645 | AU10: 0.4441005 | AV10: 3.9556818 | AW10: 1.1855439 | AX10: 0.44891761 | AY10: 3.9574383 | AZ10: 1.1757562 | BA10: 0.4520526 | BB10: 3.9581291 | BC10: 1.1789623 | BD10: 0.45201853 | BE10: 3.9660967 | BF10: 1.1793345 | BG10: 0.44980359 | BH10: 3.9615708 | BI10: 1.1771597 | BJ10: 0.44656636 | BK10: 3.959424 | BL10: 1.1732779 | BM10: 0.43520975 | BN10: 3.9707341 | BO10: 1.1619735 | BP10: 0.44819582 | BQ10: 3.9661989 | BR10: 1.17406 | BS10: 0.44943804 | BT10: 3.9609574 | BU10: 1.1743587 | BV10: 0.44783957 | BW10: 3.9647182 | BX10: 1.1748783 | BY10: 0.44544495 | BZ10: 3.9572989 | CA10: 1.1758872 | CB10: 0.45053157 | CC10: 3.9706567 | CD10: 1.1784976 | CE10: 0.4494969 | CF10: 3.9622399 | CG10: 1.1783068 | CH10: 0.44899815 | CI10: 3.9620447 | CJ10: 1.1746361 | CK10: 0.44524669 | CL10: 3.9604772 | CM10: 1.1714716 | CN10: 0.44967657 | CO10: 3.9589717 | CP10: 1.1763381 | CQ10: 0.4533351 | CR10: 3.9688104 | CS10: 1.1789985 | CT10: 0.44939777 | CU10: 3.9609202 | CV10: 1.1743931 | CW10: 0.45055016 | CX10: 3.9612517 | CY10: 1.1748436 | CZ10: 0.4472231 | DA10: 3.9600126 | DB10: 1.1734634 | DC10: 0.45213624 | DD10: 3.9655608 | DE10: 1.1781964 | DF10: 0.4503519 | DG10: 3.9709789 | DH10: 1.1744514 | DI10: 0.45458042 | DJ10: 3.9663662 | DK10: 1.1816976 | DL10: 0.44933581 | DM10: 3.9629896 | DN10: 1.1768447
A11: BO | B11: 0.61934494 | C11: 0.61934494 | D11: 1.8400559 | E11: 0.60512165 | F11: 0.60512165 | G11: 1.8198569 | H11: 0.59731514 | I11: 0.59731514 | J11: 1.8167433 | K11: 0.60476135 | L11: 0.60476135 | M11: 1.8213178 | N11: 0.59745812 | O11: 0.59745812 | P11: 1.8135995 | Q11: 0.59959704 | R11: 0.59959704 | S11: 1.8157543 | T11: 0.59607411 | U11: 0.59607411 | V11: 1.8110105 | W11: 0.60194757 | X11: 0.60194757 | Y11: 1.8183084 | Z11: 0.60278828 | AA11: 0.60278828 | AB11: 1.8302596 | AC11: 0.59945979 | AD11: 0.59945979 | AE11: 1.8116124 | AF11: 0.58357797 | AG11: 0.58357797 | AH11: 1.8053005 | AI11: 0.58619158 | AJ11: 0.58619158 | AK11: 1.793247 | AL11: 0.59037793 | AM11: 0.59037793 | AN11: 1.8045722 | AO11: 0.59322602 | AP11: 0.59322602 | AQ11: 1.8103703 | AR11: 0.60503014 | AS11: 0.60503014 | AT11: 1.8160174 | AU11: 0.5878787 | AV11: 0.5878787 | AW11: 1.8084488 | AX11: 0.59412391 | AY11: 0.59412391 | AZ11: 1.8049762 | BA11: 0.59715501 | BB11: 0.59715501 | BC11: 1.8146752 | BD11: 0.59863624 | BE11: 0.59863624 | BF11: 1.8114809 | BG11: 0.59603979 | BH11: 0.59603979 | BI11: 1.8115868 | BJ11: 0.59257976 | BK11: 0.59257976 | BL11: 1.8083681 | BM11: 0.58242272 | BN11: 0.58242272 | BO11: 1.7858032 | BP11: 0.59690337 | BQ11: 0.59690337 | BR11: 1.8015851 | BS11: 0.59507899 | BT11: 0.59507899 | BU11: 1.8069689 | BV11: 0.59669748 | BW11: 0.59669748 | BX11: 1.8116126 | BY11: 0.59061813 | BZ11: 0.59061813 | CA11: 1.8076348 | CB11: 0.59970571 | CC11: 0.59970571 | CD11: 1.8065466 | CE11: 0.59987156 | CF11: 0.59987156 | CG11: 1.8019557 | CH11: 0.5949932 | CI11: 0.5949932 | CJ11: 1.8064377 | CK11: 0.5913902 | CL11: 0.5913902 | CM11: 1.7985563 | CN11: 0.59499892 | CO11: 0.59499892 | CP11: 1.8104757 | CQ11: 0.59958561 | CR11: 0.59958561 | CS11: 1.8107625 | CT11: 0.59501036 | CU11: 0.59501036 | CV11: 1.806954 | CW11: 0.59571952 | CX11: 0.59571952 | CY11: 1.8076819 | CZ11: 0.59371786 | DA11: 0.59371786 | DB11: 1.8047974 | DC11: 0.59907089 | DD11: 0.59907089 | DE11: 1.8116448 | DF11: 0.59569093 | DG11: 0.59569093 | DH11: 1.8037899 | DI11: 0.60560205 | DJ11: 0.60560205 | DK11: 1.8105573 | DL11: 0.59641153 | DM11: 0.59641153 | DN11: 1.8054674
A12: BS | B12: 0.69721503 | C12: 0.69721503 | D12: 2.2996227 | E12: 0.68104971 | F12: 0.68104971 | G12: 2.280621 | H12: 0.67505941 | I12: 0.67505941 | J12: 2.2766903 | K12: 0.68232425 | L12: 0.68232425 | M12: 2.2829214 | N12: 0.67389817 | O12: 0.67389817 | P12: 2.2721995 | Q12: 0.67616755 | R12: 0.67616755 | S12: 2.2747986 | T12: 0.67232625 | U12: 0.67232625 | V12: 2.2697811 | W12: 0.6781891 | X12: 0.6781891 | Y12: 2.277733 | Z12: 0.69267982 | AA12: 0.69267982 | AB12: 2.2933833 | AC12: 0.67917686 | AD12: 0.67917686 | AE12: 2.271262 | AF12: 0.66401701 | AG12: 0.66401701 | AH12: 2.2624262 | AI12: 0.67821034 | AJ12: 0.67821034 | AK12: 2.2547055 | AL12: 0.66908328 | AM12: 0.66908328 | AN12: 2.2609329 | AO12: 0.67182352 | AP12: 0.67182352 | AQ12: 2.2668269 | AR12: 0.69125659 | AS12: 0.69125659 | AT12: 2.2745307 | AU12: 0.6701383 | AV12: 0.6701383 | AW12: 2.2650333 | AX12: 0.67519395 | AY12: 0.67519395 | AZ12: 2.263712 | BA12: 0.67467351 | BB12: 0.67467351 | BC12: 2.2732821 | BD12: 0.68097537 | BE12: 0.68097537 | BF12: 2.2712706 | BG12: 0.67827761 | BH12: 0.67827761 | BI12: 2.2711984 | BJ12: 0.67428053 | BK12: 0.67428053 | BL12: 2.2664355 | BM12: 0.68247648 | BN12: 0.68247648 | BO12: 2.2387776 | BP12: 0.68134711 | BQ12: 0.68134711 | BR12: 2.2620453 | BS12: 0.67742084 | BT12: 0.67742084 | BU12: 2.2645941 | BV12: 0.68037704 | BW12: 0.68037704 | BX12: 2.2680614 | BY12: 0.67274401 | BZ12: 0.67274401 | CA12: 2.2647083 | CB12: 0.68516008 | CC12: 0.68516008 | CD12: 2.2670201 | CE12: 0.68096829 | CF12: 0.68096829 | CG12: 2.2596182 | CH12: 0.67702078 | CI12: 0.67702078 | CJ12: 2.2659288 | CK12: 0.67718363 | CL12: 0.67718363 | CM12: 2.2566975 | CN12: 0.67481159 | CO12: 0.67481159 | CP12: 2.2686928 | CQ12: 0.68250481 | CR12: 0.68250481 | CS12: 2.2663029 | CT12: 0.677435 | CU12: 0.677435 | CV12: 2.264919 | CW12: 0.67659593 | CX12: 0.67659593 | CY12: 2.2616614 | CZ12: 0.67734649 | DA12: 0.67734649 | DB12: 2.2594674 | DC12: 0.6811276 | DD12: 0.6811276 | DE12: 2.2631956 | DF12: 0.68029916 | DG12: 0.68029916 | DH12: 2.2599633 | DI12: 0.68790386 | DJ12: 0.68790386 | DK12: 2.267832 | DL12: 0.68016462 | DM12: 0.68016462 | DN12: 2.2639313
A13: Be | B13: 1.4936825 | C13: 1.4936825 | D13: 1.4936825 | E13: 1.4174017 | F13: 1.4174017 | G13: 1.4174017 | H13: 1.4132568 | I13: 1.4132568 | J13: 1.4132568 | K13: 1.4059894 | L13: 1.4059894 | M13: 1.4059894 | N13: 1.3863801 | O13: 1.3863801 | P13: 1.3863801 | Q13: 1.3945398 | R13: 1.3945398 | S13: 1.3945398 | T13: 1.4171787 | U13: 1.4171787 | V13: 1.4171787 | W13: 1.3984245 | X13: 1.3984245 | Y13: 1.3984245 | Z13: 1.5244438 | AA13: 1.5244438 | AB13: 1.5244438 | AC13: 1.4251153 | AD13: 1.4251153 | AE13: 1.4251153 | AF13: 1.3872537 | AG13: 1.3872537 | AH13: 1.3872537 | AI13: 1.456267 | AJ13: 1.456267 | AK13: 1.456267 | AL13: 1.3863801 | AM13: 1.3863801 | AN13: 1.3863801 | AO13: 1.3842055 | AP13: 1.3842055 | AQ13: 1.3842055 | AR13: 1.4822329 | AS13: 1.4822329 | AT13: 1.4822329 | AU13: 1.4061566 | AV13: 1.4061566 | AW13: 1.4061566 | AX13: 1.4019002 | AY13: 1.4052645 | AZ13: 1.4019002 | BA13: 1.3876069 | BB13: 1.3876069 | BC13: 1.3876069 | BD13: 1.4002274 | BE13: 1.4002274 | BF13: 1.4002274 | BG13: 1.3953762 | BH13: 1.3953762 | BI13: 1.3953762 | BJ13: 1.3967888 | BK13: 1.3967888 | BL13: 1.3967888 | BM13: 1.4041307 | BN13: 1.4041307 | BO13: 1.4041307 | BP13: 1.3854694 | BQ13: 1.3854694 | BR13: 1.3854694 | BS13: 1.3952647 | BT13: 1.3952647 | BU13: 1.3952647 | BV13: 1.3884247 | BW13: 1.3884247 | BX13: 1.3884247 | BY13: 1.400469 | BZ13: 1.400469 | CA13: 1.400469 | CB13: 1.3975137 | CC13: 1.3975137 | CD13: 1.3975137 | CE13: 1.4463416 | CF13: 1.4463416 | CG13: 1.4463416 | CH13: 1.3906737 | CI13: 1.3906737 | CJ13: 1.3906737 | CK13: 1.4000973 | CL13: 1.4000973 | CM13: 1.4000973 | CN13: 1.3880158 | CO13: 1.3880158 | CP13: 1.3880158 | CQ13: 1.401324 | CR13: 1.401324 | CS13: 1.401324 | CT13: 1.3945584 | CU13: 1.3945584 | CV13: 1.3945584 | CW13: 1.3927369 | CX13: 1.3927369 | CY13: 1.3927369 | CZ13: 1.4166768 | DA13: 1.4166768 | DB13: 1.4166768 | DC13: 1.3955807 | DD13: 1.3955807 | DE13: 1.3955807 | DF13: 1.4038333 | DG13: 1.4038333 | DH13: 1.4038333 | DI13: 1.4171973 | DJ13: 1.4171973 | DK13: 1.4171973 | DL13: 1.4077923 | DM13: 1.4077923 | DN13: 1.4077923
A14: BeH | B14: 1.0808669 | C14: 1.0808669 | D14: 2.7183015 | E14: 1.0424737 | F14: 1.0424737 | G14: 2.634094 | H14: 1.0241247 | I14: 1.0241247 | J14: 2.6317615 | K14: 1.0196936 | L14: 1.0196936 | M14: 2.6309713 | N14: 1.0067273 | O14: 1.0067273 | P14: 2.6182175 | Q14: 1.0135822 | R14: 1.0135822 | S14: 2.6219249 | T14: 1.0364218 | U14: 1.0364218 | V14: 2.6851892 | W14: 1.0207047 | X14: 1.0207047 | Y14: 2.6253252 | Z14: 1.0635141 | AA14: 1.0635141 | AB14: 2.630238 | AC14: 1.0553953 | AD14: 1.0553953 | AE14: 2.6983115 | AF14: 0.96818549 | AG14: 0.96818549 | AH14: 2.6103727 | AI14: 1.0571648 | AJ14: 1.0571648 | AK14: 2.6769723 | AL14: 0.99556031 | AM14: 0.99556031 | AN14: 2.6367599 | AO14: 0.9901478 | AP14: 0.9901478 | AQ14: 2.6230037 | AR14: 1.0455368 | AS14: 1.0455368 | AT14: 2.7239734 | AU14: 0.99642274 | AV14: 0.99642274 | AW14: 2.6923828 | AX14: 1.0026382 | AY14: 1.0026382 | AZ14: 2.6237823 | BA14: 1.0015676 | BB14: 1.0015676 | BC14: 2.6133018 | BD14: 1.0054932 | BE14: 1.0054932 | BF14: 2.6325696 | BG14: 1.00585 | BH14: 1.00585 | BI14: 2.6418297 | BJ14: 1.0043333 | BK14: 1.0043333 | BL14: 2.6462248 | BM14: 0.96980627 | BN14: 0.96980627 | BO14: 2.6538041 | BP14: 1.0137904 | BQ14: 1.0137904 | BR14: 2.612046 | BS14: 1.0040062 | BT14: 1.0040062 | BU14: 2.630544 | BV14: 1.0045415 | BW14: 1.0045415 | BX14: 2.6665894 | BY14: 1.0065786 | BZ14: 1.0065786 | CA14: 2.6245998 | CB14: 1.0144149 | CC14: 1.0144149 | CD14: 2.6696001 | CE14: 1.0668449 | CF14: 1.0668449 | CG14: 2.6472898 | CH14: 1.006653 | CI14: 1.006653 | CJ14: 2.6333705 | CK14: 0.99712161 | CL14: 0.99712161 | CM14: 2.6259271 | CN14: 0.99837065 | CO14: 0.99837065 | CP14: 2.6157097 | CQ14: 1.0051512 | CR14: 1.0051512 | CS14: 2.6420386 | CT14: 1.0035155 | CU14: 1.0035155 | CV14: 2.6294019 | CW14: 1.0031735 | CX14: 1.0031735 | CY14: 2.6360378 | CZ14: 1.0056121 | DA14: 1.0056121 | DB14: 2.6702562 | DC14: 1.0018947 | DD14: 1.0018947 | DE14: 2.6684327 | DF14: 1.000378 | DG14: 1.000378 | DH14: 2.6711641 | DI14: 1.0509642 | DJ14: 1.0509642 | DK14: 2.6591928 | DL14: 1.0151732 | DM14: 1.0151732 | DN14: 2.6464946
A15: BeH2 | B15: 0.89717848 | C15: 0.89717848 | D15: 3.5840849 | E15: 0.85828224 | F15: 0.85828224 | G15: 3.5413722 | H15: 0.83087272 | I15: 0.83087272 | J15: 3.5767121 | K15: 0.83838184 | L15: 0.83838184 | M15: 3.5758943 | N15: 0.82872903 | O15: 0.82872903 | P15: 3.5480511 | Q15: 0.83367315 | R15: 0.83367315 | S15: 3.5525243 | T15: 0.8335988 | U15: 0.8335988 | V15: 3.5666256 | W15: 0.83905097 | X15: 0.83905097 | Y15: 3.5519543 | Z15: 0.85373464 | AA15: 0.85373464 | AB15: 3.6005158 | AC15: 0.83187642 | AD15: 0.83187642 | AE15: 3.6594487 | AF15: 0.80001843 | AG15: 0.80001843 | AH15: 3.5537015 | AI15: 0.82988142 | AJ15: 0.82988142 | AK15: 3.6198214 | AL15: 0.81828318 | AM15: 0.81828318 | AN15: 3.5863525 | AO15: 0.81659796 | AP15: 0.81659796 | AQ15: 3.5472209 | AR15: 0.84392074 | AS15: 0.84392074 | AT15: 3.6783826 | AU15: 0.80934906 | AV15: 0.80934906 | AW15: 3.6492011 | AX15: 0.82341317 | AY15: 0.82341317 | AZ15: 3.5662291 | BA15: 0.8169697 | BB15: 0.8169697 | BC15: 3.5485219 | BD15: 0.82808468 | BE15: 0.82808468 | BF15: 3.5725734 | BG15: 0.82387165 | BH15: 0.82387165 | BI15: 3.5633667 | BJ15: 0.82011709 | BK15: 0.82011709 | BL15: 3.563156 | BM15: 0.80171603 | BN15: 0.80171603 | BO15: 3.5782115 | BP15: 0.82504882 | BQ15: 0.82504882 | BR15: 3.5481626 | BS15: 0.82617642 | BT15: 0.82617642 | BU15: 3.5535032 | BV15: 0.81872926 | BW15: 0.81872926 | BX15: 3.5631065 | BY15: 0.81532166 | BZ15: 0.81532166 | CA15: 3.537122 | CB15: 0.83026555 | CC15: 0.83026555 | CD15: 3.599859 | CE15: 0.83788619 | CF15: 0.83788619 | CG15: 3.617529 | CH15: 0.82620121 | CI15: 0.82620121 | CJ15: 3.5664769 | CK15: 0.81897709 | CL15: 0.81897709 | CM15: 3.5670965 | CN15: 0.81457818 | CO15: 0.81457818 | CP15: 3.5507772 | CQ15: 0.83248359 | CR15: 0.83248359 | CS15: 3.5762165 | CT15: 0.82573034 | CU15: 0.82573034 | CV15: 3.553243 | CW15: 0.82889012 | CX15: 0.82889012 | CY15: 3.5547424 | CZ15: 0.82665969 | DA15: 0.82665969 | DB15: 3.5737382 | DC15: 0.82757664 | DD15: 0.82757664 | DE15: 3.574333 | DF15: 0.82582947 | DG15: 0.82582947 | DH15: 3.6205896 | DI15: 0.8411327 | DJ15: 0.8411327 | DK15: 3.5917923 | DL15: 0.83300402 | DM15: 0.83300402 | DN15: 3.5813217
... A87: SiO | B87: 0.57530926 | C87: 0.57530926 | D87: 2.5796615 | E87: 0.55894939 | F87: 0.55894939 | G87: 2.5642875 | H87: 0.5547555 | I87: 0.5547555 | J87: 2.5678156 | K87: 0.56058842 | L87: 0.56058842 | M87: 2.5728949 | N87: 0.5544277 | O87: 0.5544277 | P87: 2.5636499 | Q87: 0.55628639 | R87: 0.55628639 | S87: 2.5656452 | T87: 0.54995332 | U87: 0.54995332 | V87: 2.5658813 | W87: 0.55851006 | X87: 0.55851006 | Y87: 2.567329 | Z87: 0.57147022 | AA87: 0.57147022 | AB87: 2.5793471 | AC87: 0.5536538 | AD87: 0.5536538 | AE87: 2.5779433 | AF87: 0.54391426 | AG87: 0.54391426 | AH87: 2.5651536 | AI87: 0.54883134 | AJ87: 0.54883134 | AK87: 2.5533997 | AL87: 0.54928757 | AM87: 0.54928757 | AN87: 2.5689492 | AO87: 0.55272108 | AP87: 0.55272108 | AQ87: 2.5688222 | AR87: 0.5645525 | AS87: 0.5645525 | AT87: 2.5947175 | AU87: 0.54598247 | AV87: 0.54598247 | AW87: 2.5814822 | AX87: 0.55283598 | AY87: 0.55283598 | AZ87: 2.5679492 | BA87: 0.55483323 | BB87: 0.55483323 | BC87: 2.5683036 | BD87: 0.55421479 | BE87: 0.55421479 | BF87: 2.5733676 | BG87: 0.55256224 | BH87: 0.55256224 | BI87: 2.5707312 | BJ87: 0.54940585 | BK87: 0.54940585 | BL87: 2.56885 | BM87: 0.53623617 | BN87: 0.53623617 | BO87: 2.5886258 | BP87: 0.55001077 | BQ87: 0.55001077 | BR87: 2.5663153 | BS87: 0.55139972 | BT87: 0.55139972 | BU87: 2.569523 | BV87: 0.54999049 | BW87: 0.54999049 | BX87: 2.5762451 | BY87: 0.54384329 | BZ87: 0.54384329 | CA87: 2.5659116 | CB87: 0.55116654 | CC87: 0.55116654 | CD87: 2.5749366 | CE87: 0.55487378 | CF87: 0.55487378 | CG87: 2.5710435 | CH87: 0.55071707 | CI87: 0.55071707 | CJ87: 2.5671017 | CK87: 0.54889555 | CL87: 0.54889555 | CM87: 2.5703251 | CN87: 0.55244058 | CO87: 0.55244058 | CP87: 2.5692057 | CQ87: 0.55340373 | CR87: 0.55340373 | CS87: 2.5759955 | CT87: 0.55137944 | CU87: 0.55137944 | CV87: 2.5694606 | CW87: 0.55135916 | CX87: 0.55135916 | CY87: 2.5695733 | CZ87: 0.54909832 | DA87: 0.54909832 | DB87: 2.5704393 | DC87: 0.55274811 | DD87: 0.55274811 | DE87: 2.5761375 | DF87: 0.54885838 | DG87: 0.54885838 | DH87: 2.5707295 | DI87: 0.55661757 | DJ87: 0.55661757 | DK87: 2.571377 | DL87: 0.55147406 | DM87: 0.55147406 | DN87: 2.5650062

Sheet combine_values
A1: method | B1: CCSD\(T\) | C1: CCSD\(T\) | D1: CCSD\(T\) | F1: HF | G1: HF | H1: HF | I1: MP2 | J1: MP2 | K1: MP2 | L1: CCSD | M1: CCSD | N1: CCSD | O1: Slater | P1: Slater | Q1: Slater | R1: SPW92 | S1: SPW92 | T1: SPW92 | U1: B97-D3 | V1: B97-D3 | W1: B97-D3 | X1: BLYP | Y1: BLYP | Z1: BLYP | AA1: BPBE | AB1: BPBE | AC1: BPBE | AD1: mPW91 | AE1: mPW91 | AF1: mPW91 | AG1: N12 | AH1: N12 | AI1: N12 | AJ1: PBE | AK1: PBE | AL1: PBE | AM1: SOGGA11 | AN1: SOGGA11 | AO1: SOGGA11 | AP1: B97M-V | AQ1: B97M-V | AR1: B97M-V | AS1: M06-L | AT1: M06-L | AU1: M06-L | AV1: M11-L | AW1: M11-L | AX1: M11-L | AY1: mBEEF | AZ1: mBEEF | BA1: mBEEF | BB1: MGGA_MS2 | BC1: MGGA_MS2 | BD1: MGGA_MS2 | BE1: MN15-L | BF1: MN15-L | BG1: MN15-L | BH1: revM06-L | BI1: revM06-L | BJ1: revM06-L | BK1: SCAN | BL1: SCAN | BM1: SCAN | BN1: TPSS | BO1: TPSS | BP1: TPSS | BQ1: B3LYP | BR1: B3LYP | BS1: B3LYP | BT1: B97 | BU1: B97 | BV1: B97 | BW1: B97-2 | BX1: B97-2 | BY1: B97-2 | BZ1: HFLYP | CA1: HFLYP | CB1: HFLYP | CC1: M06-2X | CD1: M06-2X | CE1: M06-2X | CF1: PBE0 | CG1: PBE0 | CH1: PBE0 | CI1: SOGGA11-X | CJ1: SOGGA11-X | CK1: SOGGA11-X | CL1: M06 | CM1: M06 | CN1: M06 | CO1: M08-HX | CP1: M08-HX | CQ1: M08-HX | CR1: MN15 | CS1: MN15 | CT1: MN15 | CU1: PW6B95 | CV1: PW6B95 | CW1: PW6B95 | CX1: SCAN0 | CY1: SCAN0 | CZ1: SCAN0 | DA1: TPSSh | DB1: TPSSh | DC1: TPSSh | DD1: CAM-B3LYP | DE1: CAM-B3LYP | DF1: CAM-B3LYP | DG1: HSE-HJS | DH1: HSE-HJS | DI1: HSE-HJS | DJ1: LRC-wPBEh | DK1: LRC-wPBEh | DL1: LRC-wPBEh | DM1: wB97X-D | DN1: wB97X-D | DO1: wB97X-D | DP1: wB97X-V | DQ1: wB97X-V | DR1: wB97X-V | DS1: M11 | DT1: M11 | DU1: M11 | DV1: wB97M-V | DW1: wB97M-V | DX1: wB97M-V | DY1: wM05-D | DZ1: wM05-D | EA1: wM05-D | EB1: B2GPPLYP | EC1: B2GPPLYP | ED1: B2GPPLYP | EE1: DSDPBE | EF1: DSDPBE | EG1: DSDPBE | EH1: PTPSS | EI1: PTPSS | EJ1: PTPSS | EK1: wB97X-2TQZ | EL1: wB97X-2TQZ | EM1: wB97X-2TQZ | EN1: B2PLYP | EO1: B2PLYP | EP1: B2PLYP | EQ1: XYG3 | ER1: XYG3 | ES1: XYG3 | ET1: XYGJOS | EU1: XYGJOS | EV1: XYGJOS | EW1: wB97M2 | EX1: wB97M2 | EY1: wB97M2
A2: component | B2: XX | C2: YY | D2: ZZ | F2: XX | G2: YY | H2: ZZ | I2: XX | J2: YY | K2: ZZ | L2: XX | M2: YY | N2: ZZ | O2: XX | P2: YY | Q2: ZZ | R2: XX | S2: YY | T2: ZZ | U2: XX | V2: YY | W2: ZZ | X2: XX | Y2: YY | Z2: ZZ | AA2: XX | AB2: YY | AC2: ZZ | AD2: XX | AE2: YY | AF2: ZZ | AG2: XX | AH2: YY | AI2: ZZ | AJ2: XX | AK2: YY | AL2: ZZ | AM2: XX | AN2: YY | AO2: ZZ | AP2: XX | AQ2: YY | AR2: ZZ | AS2: XX | AT2: YY | AU2: ZZ | AV2: XX | AW2: YY | AX2: ZZ | AY2: XX | AZ2: YY | BA2: ZZ | BB2: XX | BC2: YY | BD2: ZZ | BE2: XX | BF2: YY | BG2: ZZ | BH2: XX | BI2: YY | BJ2: ZZ | BK2: XX | BL2: YY | BM2: ZZ | BN2: XX | BO2: YY | BP2: ZZ | BQ2: XX | BR2: YY | BS2: ZZ | BT2: XX | BU2: YY | BV2: ZZ | BW2: XX | BX2: YY | BY2: ZZ | BZ2: XX | CA2: YY | CB2: ZZ | CC2: XX | CD2: YY | CE2: ZZ | CF2: XX | CG2: YY | CH2: ZZ | CI2: XX | CJ2: YY | CK2: ZZ | CL2: XX | CM2: YY | CN2: ZZ | CO2: XX | CP2: YY | CQ2: ZZ | CR2: XX | CS2: YY | CT2: ZZ | CU2: XX | CV2: YY | CW2: ZZ | CX2: XX | CY2: YY | CZ2: ZZ | DA2: XX | DB2: YY | DC2: ZZ | DD2: XX | DE2: YY | DF2: ZZ | DG2: XX | DH2: YY | DI2: ZZ | DJ2: XX | DK2: YY | DL2: ZZ | DM2: XX | DN2: YY | DO2: ZZ | DP2: XX | DQ2: YY | DR2: ZZ | DS2: XX | DT2: YY | DU2: ZZ | DV2: XX | DW2: YY | DX2: ZZ | DY2: XX | DZ2: YY | EA2: ZZ | EB2: XX | EC2: YY | ED2: ZZ | EE2: XX | EF2: YY | EG2: ZZ | EH2: XX | EI2: YY | EJ2: ZZ | EK2: XX | EL2: YY | EM2: ZZ | EN2: XX | EO2: YY | EP2: ZZ | EQ2: XX | ER2: YY | ES2: ZZ | ET2: XX | EU2: YY | EV2: ZZ | EW2: XX | EX2: YY | EY2: ZZ
A3: molecule
A4: AlF | B4: =wft_table!K5 -> 0.53115417 | C4: =wft_table!L5 -> 0.53115417 | D4: =wft_table!M5 -> 3.0638868 | F4: =wft_table!B5 -> 0.53077499 | G4: =wft_table!C5 -> 0.53077499 | H4: =wft_table!D5 -> 3.105327 | I4: =wft_table!E5 -> 0.53342843 | J4: =wft_table!F5 -> 0.53342843 | K4: =wft_table!G5 -> 3.0680835 | L4: =wft_table!H5 -> 0.52890766 | M4: =wft_table!I5 -> 0.52890766 | N4: =wft_table!J5 -> 3.0691615 | O4: 0.56004433 | P4: 0.56004433 | Q4: 3.0700231 | R4: 0.54110932 | S4: 0.54110932 | T4: 3.0524086 | U4: 0.53893634 | V4: 0.53893634 | W4: 3.0641374 | X4: 0.54240365 | Y4: 0.54240365 | Z4: 3.0630231 | AA4: 0.53715875 | AB4: 0.53715875 | AC4: 3.0586333 | AD4: 0.53907828 | AE4: 0.53907828 | AF4: 3.0596605 | AG4: 0.53514799 | AH4: 0.53514799 | AI4: 3.0652797 | AJ4: 0.54144726 | AK4: 0.54144726 | AL4: 3.0610046 | AM4: 0.57221369 | AN4: 0.57221369 | AO4: 3.0729288 | AP4: 0.53802727 | AQ4: 0.53802727 | AR4: 3.0761272 | AS4: 0.52538478 | AT4: 0.52538478 | AU4: 3.0585058 | AV4: 0.54652656 | AW4: 0.54652656 | AX4: 3.0541276 | AY4: 0.53377593 | AZ4: 0.53377593 | BA4: 3.0691675 | BB4: 0.53586105 | BC4: 0.53586105 | BD4: 3.0677067 | BE4: 0.55629653 | BF4: 0.55629653 | BG4: 3.0967214 | BH4: 0.53076147 | BI4: 0.53076147 | BJ4: 3.0918562 | BK4: 0.53607733 | BL4: 0.53607733 | BM4: 3.0660642 | BN4: 0.53820976 | BO4: 0.53820976 | BP4: 3.0669402 | BQ4: 0.5359185 | BR4: 0.5359185 | BS4: 3.0667893 | BT4: 0.53556028 | BU4: 0.53556028 | BV4: 3.0696869 | BW4: 0.53309667 | BX4: 0.53309667 | BY4: 3.0688493 | BZ4: 0.52139028 | CA4: 0.52139028 | CB4: 3.0895483 | CC4: 0.53012614 | CD4: 0.53012614 | CE4: 3.0629144 | CF4: 0.53424567 | CG4: 0.53424567 | CH4: 3.0678186 | CI4: 0.53248499 | CJ4: 0.53248499 | CK4: 3.0764611 | CL4: 0.52402287 | CM4: 0.52402287 | CN4: 3.0540837 | CO4: 0.53413415 | CP4: 0.53413415 | CQ4: 3.077711 | CR4: 0.5437588 | CS4: 0.5437588 | CT4: 3.0656611 | CU4: 0.53311356 | CV4: 0.53311356 | CW4: 3.0625737 | CX4: 0.53187669 | CY4: 0.53187669 | CZ4: 3.0706158 | DA4: 0.53571235 | DB4: 0.53571235 | DC4: 3.0692949 | DD4: 0.53487763 | DE4: 0.53487763 | DF4: 3.0708951 | DG4: 0.53419836 | DH4: 0.53419836 | DI4: 3.0673534 | DJ4: 0.53398546 | DK4: 0.53398546 | DL4: 3.0706786 | DM4: 0.53210649 | DN4: 0.53210649 | DO4: 3.0717711 | DP4: 0.53521895 | DQ4: 0.53521895 | DR4: 3.0778845 | DS4: 0.53064657 | DT4: 0.53064657 | DU4: 3.0795042 | DV4: 0.53825031 | DW4: 0.53825031 | DX4: 3.0651044 | DY4: 0.53271479 | DZ4: 0.53271479 | EA4: 3.062532 | EB4: =OFFSET(B2GPPLYP_extrap!F$7,(ROW(B2GPPLYP_extrap!F1)-1)*4,0) -> 0.53377355 | EC4: =OFFSET(B2GPPLYP_extrap!G$7,(ROW(B2GPPLYP_extrap!G1)-1)*4,0) -> 0.53377355 | ED4: =OFFSET(B2GPPLYP_extrap!H$7,(ROW(B2GPPLYP_extrap!H1)-1)*4,0) -> 3.0698804 | EE4: =OFFSET(DSDPBE_extrap!F$7,(ROW(DSDPBE_extrap!F1)-1)*4,0) -> 0.53309919 | EF4: =OFFSET(DSDPBE_extrap!G$7,(ROW(DSDPBE_extrap!G1)-1)*4,0) -> 0.53309919 | EG4: =OFFSET(DSDPBE_extrap!H$7,(ROW(DSDPBE_extrap!H1)-1)*4,0) -> 3.0696474 | EH4: =OFFSET(PTPSS_extrap!F$7,(ROW(PTPSS_extrap!F1)-1)*4,0) -> 0.53359389 | EI4: =OFFSET(PTPSS_extrap!G$7,(ROW(PTPSS_extrap!G1)-1)*4,0) -> 0.53359389 | EJ4: =OFFSET(PTPSS_extrap!H$7,(ROW(PTPSS_extrap!H1)-1)*4,0) -> 3.0658167 | EK4: =OFFSET(wB97X2TQZ_extrap!F$7,(ROW(wB97X2TQZ_extrap!F1)-1)*4,0) -> 0.53626846 | EL4: =OFFSET(wB97X2TQZ_extrap!G$7,(ROW(wB97X2TQZ_extrap!G1)-1)*4,0) -> 0.53626846 | EM4: =OFFSET(wB97X2TQZ_extrap!H$7,(ROW(wB97X2TQZ_extrap!H1)-1)*4,0) -> 3.0751269 | EN4: =OFFSET(B2PLYP_extrap!F$7,(ROW(B2PLYP_extrap!F1)-1)*4,0) -> 0.53535101 | EO4: =OFFSET(B2PLYP_extrap!G$7,(ROW(B2PLYP_extrap!G1)-1)*4,0) -> 0.53535101 | EP4: =OFFSET(B2PLYP_extrap!H$7,(ROW(B2PLYP_extrap!H1)-1)*4,0) -> 3.0683295 | EQ4: =OFFSET(XYG3_extrap!F$7,(ROW(XYG3_extrap!F1)-1)*4,0) -> 0.53295629 | ER4: =OFFSET(XYG3_extrap!G$7,(ROW(XYG3_extrap!G1)-1)*4,0) -> 0.5329563 | ES4: =OFFSET(XYG3_extrap!H$7,(ROW(XYG3_extrap!H1)-1)*4,0) -> 3.0693412 | ET4: =OFFSET(XYGJOS_extrap!F$7,(ROW(XYGJOS_extrap!F1)-1)*4,0) -> 0.53315339 | EU4: =OFFSET(XYGJOS_extrap!G$7,(ROW(XYGJOS_extrap!G1)-1)*4,0) -> 0.53315338 | EV4: =OFFSET(XYGJOS_extrap!H$7,(ROW(XYGJOS_extrap!H1)-1)*4,0) -> 3.0682496 | EW4: =OFFSET(wB97M2_extrap!F$7,(ROW(wB97M2_extrap!F1)-1)*4,0) -> 0.53355749 | EX4: =OFFSET(wB97M2_extrap!G$7,(ROW(wB97M2_extrap!G1)-1)*4,0) -> 0.53355749 | EY4: =OFFSET(wB97M2_extrap!H$7,(ROW(wB97M2_extrap!H1)-1)*4,0) -> 3.0630274
A5: Ar | B5: =wft_table!K6 -> 0.48009052 | C5: =wft_table!L6 -> 0.48009052 | D5: =wft_table!M6 -> 0.48009052 | F5: =wft_table!B6 -> 0.48219027 | G5: =wft_table!C6 -> 0.48219027 | H5: =wft_table!D6 -> 0.48219027 | I5: =wft_table!E6 -> 0.48112273 | J5: =wft_table!F6 -> 0.48112273 | K5: =wft_table!G6 -> 0.48112273 | L5: =wft_table!H6 -> 0.47950576 | M5: =wft_table!I6 -> 0.47950576 | N5: =wft_table!J6 -> 0.47950576 | O5: 0.49635764 | P5: 0.49635764 | Q5: 0.49635764 | R5: 0.48707243 | S5: 0.48707243 | T5: 0.48707243 | U5: 0.48083136 | V5: 0.48083136 | W5: 0.48083136 | X5: 0.48871635 | Y5: 0.48871635 | Z5: 0.48871635 | AA5: 0.48305353 | AB5: 0.48305353 | AC5: 0.48305353 | AD5: 0.48444135 | AE5: 0.48444135 | AF5: 0.48444135 | AG5: 0.47781202 | AH5: 0.47781202 | AI5: 0.47781202 | AJ5: 0.48570939 | AK5: 0.48570939 | AL5: 0.48570939 | AM5: 0.4826157 | AN5: 0.4826157 | AO5: 0.4826157 | AP5: 0.48146744 | AQ5: 0.48146744 | AR5: 0.48146744 | AS5: 0.47687028 | AT5: 0.47687028 | AU5: 0.47687028 | AV5: 0.47210376 | AW5: 0.47210376 | AX5: 0.47210376 | AY5: 0.47748571 | AZ5: 0.47748571 | BA5: 0.47748571 | BB5: 0.48028614 | BC5: 0.48028614 | BD5: 0.48028614 | BE5: 0.48488331 | BF5: 0.48488331 | BG5: 0.48488331 | BH5: 0.47860919 | BI5: 0.47860919 | BJ5: 0.47860919 | BK5: 0.48128571 | BL5: 0.48128571 | BM5: 0.48128571 | BN5: 0.48316092 | BO5: 0.48316092 | BP5: 0.48316092 | BQ5: 0.48550287 | BR5: 0.48550287 | BS5: 0.48550287 | BT5: 0.48307418 | BU5: 0.48307418 | BV5: 0.48307418 | BW5: 0.47948071 | BX5: 0.47948071 | BY5: 0.47948071 | BZ5: 0.47886941 | CA5: 0.47886941 | CB5: 0.47886941 | CC5: 0.48294201 | CD5: 0.48294201 | CE5: 0.48294201 | CF5: 0.48233896 | CG5: 0.48233896 | CH5: 0.48233896 | CI5: 0.48197549 | CJ5: 0.48197549 | CK5: 0.48197549 | CL5: 0.48005897 | CM5: 0.48005897 | CN5: 0.48005897 | CO5: 0.48395396 | CP5: 0.48395396 | CQ5: 0.48395396 | CR5: 0.4784068 | CS5: 0.4784068 | CT5: 0.4784068 | CU5: 0.48204983 | CV5: 0.48204983 | CW5: 0.48204983 | CX5: 0.48042245 | CY5: 0.48042245 | CZ5: 0.48042245 | DA5: 0.48211179 | DB5: 0.48211179 | DC5: 0.48211179 | DD5: 0.48609765 | DE5: 0.48609765 | DF5: 0.48609765 | DG5: 0.4823431 | DH5: 0.4823431 | DI5: 0.4823431 | DJ5: 0.48237614 | DK5: 0.48237614 | DL5: 0.48237614 | DM5: 0.48069505 | DN5: 0.48069505 | DO5: 0.48069505 | DP5: 0.48370201 | DQ5: 0.48370201 | DR5: 0.48370201 | DS5: 0.48410679 | DT5: 0.48410679 | DU5: 0.48410679 | DV5: 0.48659744 | DW5: 0.48659744 | DX5: 0.48659744 | DY5: 0.48269418 | DZ5: 0.48269418 | EA5: 0.48269418 | EB5: =OFFSET(B2GPPLYP_extrap!F$7,(ROW(B2GPPLYP_extrap!F2)-1)*4,0) -> 0.48297056 | EC5: =OFFSET(B2GPPLYP_extrap!G$7,(ROW(B2GPPLYP_extrap!G2)-1)*4,0) -> 0.48297056 | ED5: =OFFSET(B2GPPLYP_extrap!H$7,(ROW(B2GPPLYP_extrap!H2)-1)*4,0) -> 0.48297056 | EE5: =OFFSET(DSDPBE_extrap!F$7,(ROW(DSDPBE_extrap!F2)-1)*4,0) -> 0.48131522 | EF5: =OFFSET(DSDPBE_extrap!G$7,(ROW(DSDPBE_extrap!G2)-1)*4,0) -> 0.48131522 | EG5: =OFFSET(DSDPBE_extrap!H$7,(ROW(DSDPBE_extrap!H2)-1)*4,0) -> 0.48131522 | EH5: =OFFSET(PTPSS_extrap!F$7,(ROW(PTPSS_extrap!F2)-1)*4,0) -> 0.48216507 | EI5: =OFFSET(PTPSS_extrap!G$7,(ROW(PTPSS_extrap!G2)-1)*4,0) -> 0.48216507 | EJ5: =OFFSET(PTPSS_extrap!H$7,(ROW(PTPSS_extrap!H2)-1)*4,0) -> 0.48216507 | EK5: =OFFSET(wB97X2TQZ_extrap!F$7,(ROW(wB97X2TQZ_extrap!F2)-1)*4,0) -> 0.48469514 | EL5: =OFFSET(wB97X2TQZ_extrap!G$7,(ROW(wB97X2TQZ_extrap!G2)-1)*4,0) -> 0.48469514 | EM5: =OFFSET(wB97X2TQZ_extrap!H$7,(ROW(wB97X2TQZ_extrap!H2)-1)*4,0) -> 0.48469514 | EN5: =OFFSET(B2PLYP_extrap!F$7,(ROW(B2PLYP_extrap!F2)-1)*4,0) -> 0.4839387 | EO5: =OFFSET(B2PLYP_extrap!G$7,(ROW(B2PLYP_extrap!G2)-1)*4,0) -> 0.4839387 | EP5: =OFFSET(B2PLYP_extrap!H$7,(ROW(B2PLYP_extrap!H2)-1)*4,0) -> 0.4839387 | EQ5: =OFFSET(XYG3_extrap!F$7,(ROW(XYG3_extrap!F2)-1)*4,0) -> 0.48137981 | ER5: =OFFSET(XYG3_extrap!G$7,(ROW(XYG3_extrap!G2)-1)*4,0) -> 0.48137989 | ES5: =OFFSET(XYG3_extrap!H$7,(ROW(XYG3_extrap!H2)-1)*4,0) -> 0.48137989 | ET5: =OFFSET(XYGJOS_extrap!F$7,(ROW(XYGJOS_extrap!F2)-1)*4,0) -> 0.4817306 | EU5: =OFFSET(XYGJOS_extrap!G$7,(ROW(XYGJOS_extrap!G2)-1)*4,0) -> 0.48173068 | EV5: =OFFSET(XYGJOS_extrap!H$7,(ROW(XYGJOS_extrap!H2)-1)*4,0) -> 0.48173068 | EW5: =OFFSET(wB97M2_extrap!F$7,(ROW(wB97M2_extrap!F2)-1)*4,0) -> 0.48197524 | EX5: =OFFSET(wB97M2_extrap!G$7,(ROW(wB97M2_extrap!G2)-1)*4,0) -> 0.48196969 | EY5: =OFFSET(wB97M2_extrap!H$7,(ROW(wB97M2_extrap!H2)-1)*4,0) -> 0.48196969
A6: BF | B6: =wft_table!K7 -> 0.55769608 | C6: =wft_table!L7 -> 0.55769608 | D6: =wft_table!M7 -> 2.0541193 | F6: =wft_table!B7 -> 0.55273267 | G6: =wft_table!C7 -> 0.55273267 | H6: =wft_table!D7 -> 2.094493 | I6: =wft_table!E7 -> 0.56248528 | J6: =wft_table!F7 -> 0.56248528 | K6: =wft_table!G7 -> 2.0695614 | L6: =wft_table!H7 -> 0.55499897 | M6: =wft_table!I7 -> 0.55499897 | N6: =wft_table!J7 -> 2.0580441 | O6: 0.59672526 | P6: 0.59672526 | Q6: 2.0863465 | R6: 0.57708685 | S6: 0.57708685 | T6: 2.0666787 | U6: 0.56741103 | V6: 0.56741103 | W6: 2.0687921 | X6: 0.57496263 | Y6: 0.57496263 | Z6: 2.0723461 | AA6: 0.56731012 | AB6: 0.56731012 | AC6: 2.0647961 | AD6: 0.56990698 | AE6: 0.56990698 | AF6: 2.0661319 | AG6: 0.56537708 | AH6: 0.56537708 | AI6: 2.0625454 | AJ6: 0.57257288 | AK6: 0.57257288 | AL6: 2.0673495 | AM6: 0.58729904 | AN6: 0.58729904 | AO6: 2.0802281 | AP6: 0.56547267 | AQ6: 0.56547267 | AR6: 2.0761657 | AS6: 0.55321061 | AT6: 0.55321061 | AU6: 2.0641028 | AV6: 0.55699173 | AW6: 0.55699173 | AX6: 2.0850483 | AY6: 0.56048076 | AZ6: 0.56048076 | BA6: 2.0664943 | BB6: 0.56180308 | BC6: 0.56180308 | BD6: 2.0698201 | BE6: 0.57374651 | BF6: 0.57374651 | BG6: 2.0915386 | BH6: 0.55466571 | BI6: 0.55466571 | BJ6: 2.0871045 | BK6: 0.56378923 | BL6: 0.56378923 | BM6: 2.0686034 | BN6: 0.56481417 | BO6: 0.56481417 | BP6: 2.0694041 | BQ6: 0.56697025 | BR6: 0.56697025 | BS6: 2.0723002 | BT6: 0.56413442 | BU6: 0.56413442 | BV6: 2.0694445 | BW6: 0.56064007 | BX6: 0.56064007 | BY6: 2.0680511 | BZ6: 0.54577584 | CA6: 0.54577584 | CB6: 2.0813652 | CC6: 0.56213234 | CD6: 0.56213234 | CE6: 2.0642152 | CF6: 0.56338032 | CG6: 0.56338032 | CH6: 2.0689634 | CI6: 0.56129858 | CJ6: 0.56129858 | CK6: 2.0724911 | CL6: 0.55917967 | CM6: 0.55917967 | CN6: 2.0635922 | CO6: 0.56194647 | CP6: 0.56194647 | CQ6: 2.0750673 | CR6: 0.56638078 | CS6: 0.56638078 | CT6: 2.0679399 | CU6: 0.56267401 | CV6: 0.56267401 | CW6: 2.0634042 | CX6: 0.55921685 | CY6: 0.55921685 | CZ6: 2.0699512 | DA6: 0.56205799 | DB6: 0.56205799 | DC6: 2.0698964 | DD6: 0.56732075 | DE6: 0.56732075 | DF6: 2.075635 | DG6: 0.56328473 | DH6: 0.56328473 | DI6: 2.0686915 | DJ6: 0.5640282 | DK6: 0.5640282 | DL6: 2.0708117 | DM6: 0.56159597 | DN6: 0.56159597 | DO6: 2.0726011 | DP6: 0.56511687 | DQ6: 0.56511687 | DR6: 2.0764934 | DS6: 0.55980632 | DT6: 0.55980632 | DU6: 2.0751612 | DV6: 0.57073543 | DW6: 0.57073543 | DX6: 2.0711823 | DY6: 0.56351839 | DZ6: 0.56351839 | EA6: 2.069368 | EB6: =OFFSET(B2GPPLYP_extrap!F$7,(ROW(B2GPPLYP_extrap!F3)-1)*4,0) -> 0.5630087 | EC6: =OFFSET(B2GPPLYP_extrap!G$7,(ROW(B2GPPLYP_extrap!G3)-1)*4,0) -> 0.5630087 | ED6: =OFFSET(B2GPPLYP_extrap!H$7,(ROW(B2GPPLYP_extrap!H3)-1)*4,0) -> 2.0716481 | EE6: =OFFSET(DSDPBE_extrap!F$7,(ROW(DSDPBE_extrap!F3)-1)*4,0) -> 0.56113089 | EF6: =OFFSET(DSDPBE_extrap!G$7,(ROW(DSDPBE_extrap!G3)-1)*4,0) -> 0.56113089 | EG6: =OFFSET(DSDPBE_extrap!H$7,(ROW(DSDPBE_extrap!H3)-1)*4,0) -> 2.0687418 | EH6: =OFFSET(PTPSS_extrap!F$7,(ROW(PTPSS_extrap!F3)-1)*4,0) -> 0.56190753 | EI6: =OFFSET(PTPSS_extrap!G$7,(ROW(PTPSS_extrap!G3)-1)*4,0) -> 0.56190753 | EJ6: =OFFSET(PTPSS_extrap!H$7,(ROW(PTPSS_extrap!H3)-1)*4,0) -> 2.0679326 | EK6: =OFFSET(wB97X2TQZ_extrap!F$7,(ROW(wB97X2TQZ_extrap!F3)-1)*4,0) -> 0.56561253 | EL6: =OFFSET(wB97X2TQZ_extrap!G$7,(ROW(wB97X2TQZ_extrap!G3)-1)*4,0) -> 0.56561253 | EM6: =OFFSET(wB97X2TQZ_extrap!H$7,(ROW(wB97X2TQZ_extrap!H3)-1)*4,0) -> 2.0751066 | EN6: =OFFSET(B2PLYP_extrap!F$7,(ROW(B2PLYP_extrap!F3)-1)*4,0) -> 0.56511576 | EO6: =OFFSET(B2PLYP_extrap!G$7,(ROW(B2PLYP_extrap!G3)-1)*4,0) -> 0.56511576 | EP6: =OFFSET(B2PLYP_extrap!H$7,(ROW(B2PLYP_extrap!H3)-1)*4,0) -> 2.0713464 | EQ6: =OFFSET(XYG3_extrap!F$7,(ROW(XYG3_extrap!F3)-1)*4,0) -> 0.56033389 | ER6: =OFFSET(XYG3_extrap!G$7,(ROW(XYG3_extrap!G3)-1)*4,0) -> 0.56033375 | ES6: =OFFSET(XYG3_extrap!H$7,(ROW(XYG3_extrap!H3)-1)*4,0) -> 2.0681859 | ET6: =OFFSET(XYGJOS_extrap!F$7,(ROW(XYGJOS_extrap!F3)-1)*4,0) -> 0.56076782 | EU6: =OFFSET(XYGJOS_extrap!G$7,(ROW(XYGJOS_extrap!G3)-1)*4,0) -> 0.56076764 | EV6: =OFFSET(XYGJOS_extrap!H$7,(ROW(XYGJOS_extrap!H3)-1)*4,0) -> 2.0666486 | EW6: =OFFSET(wB97M2_extrap!F$7,(ROW(wB97M2_extrap!F3)-1)*4,0) -> 0.56372262 | EX6: =OFFSET(wB97M2_extrap!G$7,(ROW(wB97M2_extrap!G3)-1)*4,0) -> 0.56371644 | EY6: =OFFSET(wB97M2_extrap!H$7,(ROW(wB97M2_extrap!H3)-1)*4,0) -> 2.0607753
