Workbook

Sheet wft_table
A1: method | C1: hf | D1: hf | E1: hf | F1: MP2 | G1: MP2 | H1: MP2 | I1: CCSD | J1: CCSD | K1: CCSD | L1: CCSD\(T\) | M1: CCSD\(T\) | N1: CCSD\(T\)
A2: component | C2: XX | D2: YY | E2: ZZ | F2: XX | G2: YY | H2: ZZ | I2: XX | J2: YY | K2: ZZ | L2: XX | M2: YY | N2: ZZ
A3: molecule | B3: basis
A4: AlF | B4: 5Z | C4: 0.72854306 | D4: 0.72854306 | E4: 1.7621938 | F4: 0 | G4: 0 | H4: 0 | I4: 0 | J4: 0 | K4: 0 | L4: 0 | M4: 0 | N4: 0
A5: AlF | B5: QZ | C5: 0.72861959 | D5: 0.72861959 | E5: 1.7622297 | F5: 0.73147015 | G5: 0.73147015 | H5: 1.7523137 | I5: 0.72835177 | J5: 0.72835177 | K5: 1.7524499 | L5: 0.72993209 | M5: 0.72993209 | N5: 1.7510654
A6: AlF | B6: TZ | C6: 0.72917827 | D6: 0.72917827 | E6: 1.7623956 | F6: 0.73343739 | G6: 0.73343739 | H6: 1.7534159 | I6: 0.73029785 | J6: 0.73029785 | K6: 1.7533173 | L6: 0.7319283 | M6: 0.7319283 | N6: 1.7520994
A7: AlF | B7: CBS | C7: 0.72854306 | D7: 0.72854306 | E7: 1.7621938 | F7: 0.73036575 | G7: 0.73036575 | H7: 1.7515945 | I7: 0.72726282 | J7: 0.72726282 | K7: 1.751902 | L7: 0.72880654 | M7: 0.72880654 | N7: 1.750396
A8: Ar | B8: 5Z | C8: 0.69439921 | D8: 0.69439921 | E8: 0.69439921 | F8: 0.69386453 | G8: 0.69386453 | H8: 0.69386453 | I8: 0.69292912 | J8: 0.69292912 | K8: 0.69292912 | L8: 0.6933419 | M8: 0.6933419 | N8: 0.6933419
A9: Ar | B9: QZ | C9: 0.69447654 | D9: 0.69447654 | E9: 0.69447654 | F9: 0.69438277 | G9: 0.69438277 | H9: 0.69438277 | I9: 0.69344405 | J9: 0.69344405 | K9: 0.69344405 | L9: 0.69388455 | M9: 0.69388455 | N9: 0.69388455
A10: Ar | B10: TZ | C10: 0.69479763 | D10: 0.69479763 | E10: 0.69479763 | F10: 0.69562777 | G10: 0.69562777 | H10: 0.69562777 | I10: 0.69500056 | J10: 0.69500056 | K10: 0.69500056 | L10: 0.69546603 | M10: 0.69546603 | N10: 0.69546603
A11: Ar | B11: CBS | C11: 0.69439921 | D11: 0.69439921 | E11: 0.69439921 | F11: 0.69340193 | G11: 0.69340193 | H11: 0.69340193 | I11: 0.69246999 | J11: 0.69246999 | K11: 0.69246999 | L11: 0.69285369 | M11: 0.69285369 | N11: 0.69285369
A12: BeH | B12: 5Z | C12: 0.98914899 | D12: 0.98914899 | E12: 1.6465447 | F12: 0.99014219 | G12: 0.99014219 | H12: 1.6340304 | I12: 0.99306172 | J12: 0.99306172 | K12: 1.6273622 | L12: 0.9939525 | M12: 0.9939525 | N12: 1.6261185
A13: BeH | B13: QZ | C13: 0.98912644 | D13: 0.98912644 | E13: 1.6467417 | F13: 0.99039465 | G13: 0.99039465 | H13: 1.6346673 | I13: 0.99330337 | J13: 0.99330337 | K13: 1.6278297 | L13: 0.9941889 | M13: 0.9941889 | N13: 1.6265946
A14: BeH | B14: TZ | C14: 0.98951723 | D14: 0.98951723 | E14: 1.6473933 | F14: 0.99193325 | G14: 0.99193325 | H14: 1.6390438 | I14: 0.99499326 | J14: 0.99499326 | K14: 1.6299186 | L14: 0.99587227 | M14: 0.99587227 | N14: 1.6288733
A15: BeH | B15: CBS | C15: 0.98914899 | D15: 0.98914899 | E15: 1.6465447 | F15: 0.98985366 | G15: 0.98985366 | H15: 1.6335688 | I15: 0.99278453 | J15: 0.99278453 | K15: 1.6270783 | L15: 0.99368082 | M15: 0.99368082 | N15: 1.6258257
... A72: CN | B72: 5Z | C72: 0.79423291 | D72: 0.79423291 | E72: 1.3449232 | F72: 0.80454064 | G72: 0.80454064 | H72: 1.3301664 | I72: 0.79183152 | J72: 0.79183152 | K72: 1.3438848 | L72: 0.79242874 | M72: 0.79242874 | N72: 1.345286
A73: CN | B73: QZ | C73: 0.79441291 | D73: 0.79441291 | E73: 1.3449275 | F73: 0.80495406 | G73: 0.80495645 | H73: 1.3306168 | I73: 0.79234137 | J73: 0.79234137 | K73: 1.3442121 | L73: 0.79298186 | M73: 0.79298186 | N73: 1.3455965 | T73: 0.761014 | U73: 0.761014 | V73: 1.596252 | W73: 0.766903 | X73: 0.766903 | Y73: 1.598887 | Z73: 0.763161 | AA73: 0.763161 | AB73: 1.5967 | AC73: 0.764286 | AD73: 0.764286 | AE73: 1.597599
A74: CN | B74: TZ | C74: 0.79470802 | D74: 0.79470802 | E74: 1.3451762 | F74: 0.80587809 | G74: 0.80587809 | H74: 1.3319041 | I74: 0.79360245 | J74: 0.79360245 | K74: 1.3453473 | L74: 0.79435572 | M74: 0.79435814 | N74: 1.3467083 | T74: 0.761262 | U74: 0.761262 | V74: 1.596361 | W74: 0.768257 | X74: 0.768257 | Y74: 1.599782 | Z74: 0.764681 | AA74: 0.764681 | AB74: 1.597664 | AC74: 0.765833 | AD74: 0.765833 | AE74: 1.598608
A75: CN | B75: CBS | C75: 0.79423291 | D75: 0.79423291 | E75: 1.3449232 | F75: 0.80429575 | G75: 0.80429324 | H75: 1.3296984 | I75: 0.79148544 | J75: 0.79148544 | K75: 1.3435458 | L75: 0.79203727 | M75: 0.79203727 | N75: 1.3449648
A76: CO | B76: 5Z | C76: 0.73637602 | D76: 0.73637602 | E76: 1.328403 | F76: 0 | G76: 0 | H76: 0 | I76: 0 | J76: 0 | K76: 0 | L76: 0 | M76: 0 | N76: 0
A77: CO | B77: QZ | C77: 0.73651303 | D77: 0.73651303 | E77: 1.3284592 | F77: 0.73983648 | G77: 0.73983648 | H77: 1.3150287 | I77: 0.73710399 | J77: 0.73710399 | K77: 1.3238018 | L77: 0.73784978 | M77: 0.73784978 | N77: 1.3211711
A78: CO | B78: TZ | C78: 0.73670768 | D78: 0.73670768 | E78: 1.3288576 | F78: 0.74100377 | G78: 0.74100377 | H78: 1.3158997 | I78: 0.73836268 | J78: 0.73836268 | K78: 1.3261847 | L78: 0.73913619 | M78: 0.73913619 | N78: 1.3234634
A79: CO | B79: CBS | C79: 0.73637602 | D79: 0.73637602 | E79: 1.328403 | F79: 0.73898971 | G79: 0.73898971 | H79: 1.3146277 | I79: 0.73619053 | J79: 0.73619053 | K79: 1.3222974 | L79: 0.73691609 | M79: 0.73691609 | N79: 1.3197329
A80: CO2 | B80: 5Z | C80: 0.70734459 | D80: 0.70734459 | E80: 2.0445844 | F80: 0 | G80: 0 | H80: 0 | I80: 0 | J80: 0 | K80: 0 | L80: 0 | M80: 0 | N80: 0
A81: CO2 | B81: QZ | C81: 0.70744969 | D81: 0.70744969 | E81: 2.0446068 | F81: 0.71037339 | G81: 0.71037339 | H81: 2.0373719 | I81: 0.70834691 | J81: 0.70834691 | K81: 2.0391899 | L81: 0.70895947 | M81: 0.70895947 | N81: 2.0381096
A82: CO2 | B82: TZ | C82: 0.70757626 | D82: 0.70757626 | E82: 2.0448803 | F82: 0.71135491 | G82: 0.71135491 | H82: 2.0379608 | I82: 0.70944978 | J82: 0.70944978 | K82: 2.0397281 | L82: 0.71009339 | M82: 0.71009339 | N82: 2.0386972
A83: CO2 | B83: CBS | C83: 0.70734459 | D83: 0.70734459 | E83: 2.0445844 | F83: 0.70964441 | G83: 0.70964441 | H83: 2.0371194 | I83: 0.70752938 | J83: 0.70752938 | K83: 2.0389744 | L83: 0.70811928 | M83: 0.70811928 | N83: 2.0378582
A84: F2 | B84: 5Z | C84: 0.62537814 | D84: 0.62537814 | E84: 1.4616788 | F84: 0.63268438 | G84: 0.63268438 | H84: 1.4666657 | I84: 0.63093456 | J84: 0.63093456 | K84: 1.463076 | L84: 0.63221662 | M84: 0.63221662 | N84: 1.4629526
A85: F2 | B85: QZ | C85: 0.62589639 | D85: 0.62589639 | E85: 1.4616053 | F85: 0.63342375 | G85: 0.63342375 | H85: 1.4666846 | I85: 0.63172654 | J85: 0.63172654 | K85: 1.4631311 | L85: 0.63298506 | M85: 0.63298506 | N85: 1.4630229
A86: F2 | B86: TZ | C86: 0.62673723 | D86: 0.62673723 | E86: 1.4616081 | F86: 0.63475549 | G86: 0.63475549 | H86: 1.4669204 | I86: 0.63329217 | J86: 0.63329217 | K86: 1.4634737 | L86: 0.63449943 | M86: 0.63449943 | N86: 1.4634101
... A139: Mg | B139: CBS | C139: 0.90697042 | D139: 0.90697042 | E139: 0.90697042 | F139: 0.88451912 | G139: 0.88451912 | H139: 0.88451912 | I139: 0.88475302 | J139: 0.88475302 | K139: 0.88475302 | L139: 0.88342042 | M139: 0.88342042 | N139: 0.88342042
A140: Mg2 | B140: 5Z | C140: 0.9000342 | D140: 0.9000342 | E140: 3.7941872 | F140: 0 | G140: 0 | I140: 0 | J140: 0 | L140: 0 | M140: 0
A141: Mg2 | B141: QZ | C141: 0.9000428 | D141: 0.9000428 | E141: 3.7941863 | F141: 0.88245231 | G141: 0.88245231 | H141: 3.7856981 | I141: 0.8822705 | J141: 0.8822705 | K141: 3.7859702 | L141: 0.88144365 | M141: 0.88144365 | N141: 3.7852
A142: Mg2 | B142: TZ | C142: 0.90014433 | D142: 0.90014433 | E142: 3.7941729 | F142: 0.88517136 | G142: 0.88517136 | H142: 3.7866275 | I142: 0.88435546 | J142: 0.88435546 | K142: 3.7865922 | L142: 0.88377929 | M142: 0.88377929 | N142: 3.7859559
A143: Mg2 | B143: CBS | C143: 0.9000342 | D143: 0.9000342 | E143: 3.7941872 | F143: 0.88053362 | G143: 0.88053362 | H143: =((H141-E141)*64-(H142-E142)*27)/(64-27)+E143 -> 3.7850109 | I143: 0.88081453 | J143: 0.88081453 | K143: =((K141-E141)*64-(K142-E142)*27)/(64-27)+E143 -> 3.7855073 | L143: 0.87980475 | M143: 0.87980475 | N143: =((N141-E141)*64-(N142-E142)*27)/(64-27)+E143 -> 3.7846394
A144: N | B144: 5Z | C144: 0.75839596 | D144: 0.75839596 | E144: 0.75839596 | F144: 0.76110413 | G144: 0.76110413 | H144: 0.76110413 | I144: 0.76122612 | J144: 0.76122612 | K144: 0.76122612 | L144: 0.76200455 | M144: 0.76200455 | N144: 0.76200455
A145: N | B145: QZ | C145: 0.758697 | D145: 0.758697 | E145: 0.758697 | F145: 0.76168108 | G145: 0.76168108 | H145: 0.76168108 | I145: 0.76180298 | J145: 0.76180298 | K145: 0.76180298 | L145: 0.76258082 | M145: 0.76258082 | N145: 0.76258082
A146: N | B146: TZ | C146: 0.75927075 | D146: 0.75927075 | E146: 0.75927075 | F146: 0.76298816 | G146: 0.76298816 | H146: 0.76298816 | I146: 0.76316601 | J146: 0.76316601 | K146: 0.76316601 | L146: 0.76393778 | M146: 0.76393778 | N146: 0.76393778
A147: N | B147: CBS | C147: 0.75839596 | D147: 0.75839596 | E147: 0.75839596 | F147: 0.76081465 | G147: 0.76081465 | H147: 0.76081465 | I147: 0.76093674 | J147: 0.76093674 | K147: 0.76093674 | L147: 0.76171578 | M147: 0.76171578 | N147: 0.76171578
A148: N2 | B148: 5Z | C148: 0.7425093 | D148: 0.7425093 | E148: 1.3012616 | F148: 0.73666295 | G148: 0.73666295 | H148: 1.3050455 | I148: 0.73698043 | J148: 0.73698043 | K148: 1.3027954 | L148: 0.73736075 | M148: 0.73736317 | N148: 1.3034929
...

Sheet dft_values
A1: method | B1: Slater | C1: Slater | D1: Slater | E1: SPW92 | F1: SPW92 | G1: SPW92 | H1: B97-D3 | I1: B97-D3 | J1: B97-D3 | K1: BLYP | L1: BLYP | M1: BLYP | N1: BPBE | O1: BPBE | P1: BPBE | Q1: mPW91 | R1: mPW91 | S1: mPW91 | T1: N12 | U1: N12 | V1: N12 | W1: PBE | X1: PBE | Y1: PBE | Z1: SOGGA11 | AA1: SOGGA11 | AB1: SOGGA11 | AC1: B97M-V | AD1: B97M-V | AE1: B97M-V | AF1: M06-L | AG1: M06-L | AH1: M06-L | AI1: mBEEF | AJ1: mBEEF | AK1: mBEEF | AL1: MGGA_MS2 | AM1: MGGA_MS2 | AN1: MGGA_MS2 | AO1: MN15-L | AP1: MN15-L | AQ1: MN15-L | AR1: revM06-L | AS1: revM06-L | AT1: revM06-L | AU1: SCAN | AV1: SCAN | AW1: SCAN | AX1: TPSS | AY1: TPSS | AZ1: TPSS | BA1: B3LYP | BB1: B3LYP | BC1: B3LYP | BD1: B97-2 | BE1: B97-2 | BF1: B97-2 | BG1: HFLYP | BH1: HFLYP | BI1: HFLYP | BJ1: M06-2X | BK1: M06-2X | BL1: M06-2X | BM1: PBE0 | BN1: PBE0 | BO1: PBE0 | BP1: M06 | BQ1: M06 | BR1: M06 | BS1: M08-HX | BT1: M08-HX | BU1: M08-HX | BV1: MN15 | BW1: MN15 | BX1: MN15 | BY1: SCAN0 | BZ1: SCAN0 | CA1: SCAN0 | CB1: TPSSh | CC1: TPSSh | CD1: TPSSh | CE1: CAM-B3LYP | CF1: CAM-B3LYP | CG1: CAM-B3LYP | CH1: wB97X-D | CI1: wB97X-D | CJ1: wB97X-D | CK1: wB97X-V | CL1: wB97X-V | CM1: wB97X-V | CN1: wB97M-V | CO1: wB97M-V | CP1: wB97M-V | CQ1: wM05-D | CR1: wM05-D | CS1: wM05-D
A2: component | B2: XX | C2: YY | D2: ZZ | E2: XX | F2: YY | G2: ZZ | H2: XX | I2: YY | J2: ZZ | K2: XX | L2: YY | M2: ZZ | N2: XX | O2: YY | P2: ZZ | Q2: XX | R2: YY | S2: ZZ | T2: XX | U2: YY | V2: ZZ | W2: XX | X2: YY | Y2: ZZ | Z2: XX | AA2: YY | AB2: ZZ | AC2: XX | AD2: YY | AE2: ZZ | AF2: XX | AG2: YY | AH2: ZZ | AI2: XX | AJ2: YY | AK2: ZZ | AL2: XX | AM2: YY | AN2: ZZ | AO2: XX | AP2: YY | AQ2: ZZ | AR2: XX | AS2: YY | AT2: ZZ | AU2: XX | AV2: YY | AW2: ZZ | AX2: XX | AY2: YY | AZ2: ZZ | BA2: XX | BB2: YY | BC2: ZZ | BD2: XX | BE2: YY | BF2: ZZ | BG2: XX | BH2: YY | BI2: ZZ | BJ2: XX | BK2: YY | BL2: ZZ | BM2: XX | BN2: YY | BO2: ZZ | BP2: XX | BQ2: YY | BR2: ZZ | BS2: XX | BT2: YY | BU2: ZZ | BV2: XX | BW2: YY | BX2: ZZ | BY2: XX | BZ2: YY | CA2: ZZ | CB2: XX | CC2: YY | CD2: ZZ | CE2: XX | CF2: YY | CG2: ZZ | CH2: XX | CI2: YY | CJ2: ZZ | CK2: XX | CL2: YY | CM2: ZZ | CN2: XX | CO2: YY | CP2: ZZ | CQ2: XX | CR2: YY | CS2: ZZ
A3: molecule
A4: AlF | B4: 0.74836109 | C4: 0.74836109 | D4: 1.7521481 | E4: 0.73560133 | F4: 0.73560133 | G4: 1.7471144 | H4: 0.73412284 | I4: 0.73412284 | J4: 1.7504678 | K4: 0.73648058 | L4: 0.73648058 | M4: 1.7501495 | N4: 0.73291115 | O4: 0.73291115 | P4: 1.7488949 | Q4: 0.7342195 | R4: 0.7342195 | S4: 1.7491885 | T4: 0.7315381 | U4: 0.7315381 | V4: 1.750794 | W4: 0.735831 | X4: 0.735831 | Y4: 1.7495727 | Z4: 0.75644808 | AA4: 0.75644808 | AB4: 1.7529771 | AC4: 0.73350342 | AD4: 0.73350342 | AE4: 1.7538892 | AF4: 0.72483431 | AG4: 0.72483431 | AH4: 1.7488584 | AI4: 0.73059971 | AJ4: 0.73059971 | AK4: 1.751904 | AL4: 0.73202531 | AM4: 0.73202531 | AN4: 1.751487 | AO4: 0.74585289 | AP4: 0.74585289 | AQ4: 1.7597504 | AR4: 0.72853378 | AS4: 0.72853378 | AT4: 1.7583675 | AU4: 0.73217302 | AV4: 0.73217302 | AW4: 1.7510181 | AX4: 0.73362781 | AY4: 0.73362781 | AZ4: 1.7512682 | BA4: 0.73206455 | BB4: 0.73206455 | BC4: 1.7512251 | BD4: 0.73013469 | BE4: 0.73013469 | BF4: 1.7518132 | BG4: 0.7220736 | BH4: 0.7220736 | BI4: 1.7577111 | BJ4: 0.72809761 | BK4: 0.72809761 | BL4: 1.7501184 | BM4: 0.73092111 | BN4: 0.73092111 | BO4: 1.7515189 | BP4: 0.72389424 | BQ4: 0.72389424 | BR4: 1.7475937 | BS4: 0.73084482 | BT4: 0.73084482 | BU4: 1.7543406 | BV4: 0.73740003 | BW4: 0.73740003 | BX4: 1.7509029 | BY4: 0.72929876 | BZ4: 0.72929876 | CA4: 1.7523173 | CB4: 0.73192373 | CC4: 0.73192373 | CD4: 1.7519403 | CE4: 0.73135329 | CF4: 0.73135329 | CG4: 1.7523969 | CH4: 0.7294563 | CI4: 0.7294563 | CJ4: 1.7526469 | CK4: 0.7315866 | CL4: 0.7315866 | CM4: 1.7543901 | CN4: 0.73365545 | CO4: 0.73365545 | CP4: 1.7507439 | CQ4: 0.72987313 | CR4: 0.72987313 | CS4: 1.7500091
A5: Ar | B5: 0.70452653 | C5: 0.70452653 | D5: 0.70452653 | E5: 0.69790575 | F5: 0.69790575 | G5: 0.69790575 | H5: 0.69342004 | I5: 0.69342004 | J5: 0.69342004 | K5: 0.6990825 | L5: 0.6990825 | M5: 0.6990825 | N5: 0.69502052 | O5: 0.69502052 | P5: 0.69502052 | Q5: 0.69601821 | R5: 0.69601821 | S5: 0.69601821 | T5: 0.69123948 | U5: 0.69123948 | V5: 0.69123948 | W5: 0.69692854 | X5: 0.69692854 | Y5: 0.69692854 | Z5: 0.69470548 | AA5: 0.69470548 | AB5: 0.69470548 | AC5: 0.69387855 | AD5: 0.69387855 | AE5: 0.69387855 | AF5: 0.69055795 | AG5: 0.69055795 | AH5: 0.69055795 | AI5: 0.69100341 | AJ5: 0.69100341 | AK5: 0.69100341 | AL5: 0.6930268 | AM5: 0.6930268 | AN5: 0.6930268 | AO5: 0.69633563 | AP5: 0.69633563 | AQ5: 0.69633563 | AR5: 0.69181586 | AS5: 0.69181586 | AT5: 0.69181586 | AU5: 0.69374758 | AV5: 0.69374758 | AW5: 0.69374758 | AX5: 0.69509778 | AY5: 0.69509778 | AZ5: 0.69509778 | BA5: 0.69678036 | BB5: 0.69678036 | BC5: 0.69678036 | BD5: 0.69244546 | BE5: 0.69244546 | BF5: 0.69244546 | BG5: 0.69200391 | BH5: 0.69200391 | BI5: 0.69200391 | BJ5: 0.69494029 | BK5: 0.69494029 | BL5: 0.69494029 | BM5: 0.69450627 | BN5: 0.69450627 | BO5: 0.69450627 | BP5: 0.69286288 | BQ5: 0.69286288 | BR5: 0.69286288 | BS5: 0.695668 | BT5: 0.695668 | BU5: 0.695668 | BV5: 0.69166957 | BW5: 0.69166957 | BX5: 0.69166957 | BY5: 0.69312513 | BZ5: 0.69312513 | CA5: 0.69312513 | CB5: 0.6943427 | CC5: 0.6943427 | CD5: 0.6943427 | CE5: 0.69720704 | CF5: 0.69720704 | CG5: 0.69720704 | CH5: 0.69332175 | CI5: 0.69332175 | CJ5: 0.69332175 | CK5: 0.69548688 | CL5: 0.69548688 | CM5: 0.69548688 | CN5: 0.69756536 | CO5: 0.69756536 | CP5: 0.69756536 | CQ5: 0.69476196 | CR5: 0.69476196 | CS5: 0.69476196
A6: BeH | B6: 1.0396475 | C6: 1.0396475 | D6: 1.6487272 | E6: 1.021016 | F6: 1.021016 | G6: 1.6229892 | H6: 1.0119905 | I6: 1.0119905 | J6: 1.6222705 | K6: 1.0097988 | L6: 1.0097988 | M6: 1.6220269 | N6: 1.003358 | O6: 1.003358 | P6: 1.6180907 | Q6: 1.0067682 | R6: 1.0067682 | S6: 1.6192359 | T6: 1.018048 | U6: 1.018048 | V6: 1.6386547 | W6: 1.0102993 | X6: 1.0102993 | Y6: 1.6202855 | Z6: 1.0312682 | AA6: 1.0312682 | AB6: 1.6218009 | AC6: 1.0273244 | AD6: 1.0273244 | AE6: 1.6426538 | AF6: 0.98396417 | AG6: 0.98396417 | AH6: 1.6156648 | AI6: 0.99777769 | AJ6: 0.99777769 | AK6: 1.6238103 | AL6: 0.99506171 | AM6: 0.99506171 | AN6: 1.619569 | AO6: 1.022515 | AP6: 1.022515 | AQ6: 1.6504464 | AR6: 0.99820977 | AS6: 0.99820977 | AT6: 1.6408482 | AU6: 1.0013182 | AV6: 1.0013182 | AW6: 1.6198093 | AX6: 1.0007835 | AY6: 1.0007835 | AZ6: 1.616571 | BA6: 1.0027428 | BB6: 1.0027428 | BC6: 1.6225195 | BD6: 1.0021643 | BE6: 1.0021643 | BF6: 1.6267221 | BG6: 0.98478742 | BH6: 0.98478742 | BI6: 1.6290501 | BJ6: 1.0068716 | BK6: 1.0068716 | BL6: 1.6161825 | BM6: 1.0020011 | BN6: 1.0020011 | BO6: 1.6218952 | BP6: 1.0032839 | BQ6: 1.0032839 | BR6: 1.6200617 | BS6: 1.0071817 | BT6: 1.0071817 | BU6: 1.6338911 | BV6: 1.0328818 | BW6: 1.0328818 | BX6: 1.6270494 | BY6: 0.99855977 | BZ6: 0.99855977 | CA6: 1.6204713 | CB6: 0.999185 | CC6: 0.999185 | CD6: 1.6173156 | CE6: 1.0025723 | CF6: 1.0025723 | CG6: 1.6254349 | CH6: 1.0028021 | CI6: 1.0028021 | CJ6: 1.6340919 | CK6: 1.0009469 | CL6: 1.0009469 | CM6: 1.6335338 | CN6: 1.0251655 | CO6: 1.0251655 | CP6: 1.6307032 | CQ6: 1.0075581 | CR6: 1.0075581 | CS6: 1.626805
A7: BeH2 | B7: 0.94719506 | C7: 0.94719506 | D7: 1.893168 | E7: 0.92643523 | F7: 0.92643523 | G7: 1.8818534 | H7: 0.9115222 | I7: 0.9115222 | J7: 1.8912197 | K7: 0.91563193 | L7: 0.91563193 | M7: 1.8910035 | N7: 0.91034555 | O7: 0.91034555 | P7: 1.8836271 | Q7: 0.91305704 | R7: 0.91305704 | S7: 1.8848141 | T7: 0.91301632 | U7: 0.91301632 | V7: 1.8885512 | W7: 0.91599725 | X7: 0.91599725 | Y7: 1.8846629 | Z7: 0.92397762 | AA7: 0.92397762 | AB7: 1.8975025 | AC7: 0.91207259 | AD7: 0.91207259 | AE7: 1.9129686 | AF7: 0.89443749 | AG7: 0.89443749 | AH7: 1.8851264 | AI7: 0.90459006 | AJ7: 0.90459006 | AK7: 1.8937668 | AL7: 0.9036581 | AM7: 0.9036581 | AN7: 1.8834067 | AO7: 0.91865159 | AP7: 0.91865159 | AQ7: 1.917911 | AR7: 0.8996383 | AS7: 0.8996383 | AT7: 1.9102882 | AU7: 0.90742116 | AV7: 0.90742116 | AW7: 1.8884462 | AX7: 0.90386376 | AY7: 0.90386376 | AZ7: 1.8837521 | BA7: 0.90999158 | BB7: 0.90999158 | BC7: 1.8901252 | BD7: 0.90560316 | BE7: 0.90560316 | BF7: 1.8876324 | BG7: 0.89538597 | BH7: 0.89538597 | BI7: 1.8916161 | BJ7: 0.90832198 | BK7: 0.90832198 | BL7: 1.8836567 | BM7: 0.90894248 | BN7: 0.90894248 | BO7: 1.8850738 | BP7: 0.90295164 | BQ7: 0.90295164 | BR7: 1.8807238 | BS7: 0.91118908 | BT7: 0.91118908 | BU7: 1.8973294 | BV7: 0.91536123 | BW7: 0.91536123 | BX7: 1.9019803 | BY7: 0.90497353 | BZ7: 0.90497353 | CA7: 1.8886759 | CB7: 0.90253985 | CC7: 0.90253985 | CD7: 1.8843506 | CE7: 0.91240539 | CF7: 0.91240539 | CG7: 1.8910887 | CH7: 0.90920827 | CI7: 0.90920827 | CJ7: 1.8904333 | CK7: 0.90971239 | CL7: 0.90971239 | CM7: 1.8905906 | CN7: 0.91713287 | CO7: 0.91713287 | CP7: 1.8952024 | CQ7: 0.91269054 | CR7: 0.91269054 | CS7: 1.892438
A8: BF | B8: 0.77247994 | C8: 0.77247994 | D8: 1.4444191 | E8: 0.75966232 | F8: 0.75966232 | G8: 1.4375948 | H8: 0.7532669 | I8: 0.7532669 | J8: 1.4383296 | K8: 0.7582629 | L8: 0.7582629 | M8: 1.4395646 | N8: 0.75319992 | O8: 0.75319992 | P8: 1.4369398 | Q8: 0.75492184 | R8: 0.75492184 | S8: 1.4374046 | T8: 0.75191561 | U8: 0.75191561 | V8: 1.4361565 | W8: 0.75668546 | X8: 0.75668546 | Y8: 1.4378281 | Z8: 0.76635438 | AA8: 0.76635438 | AB8: 1.4422996 | AC8: 0.75197917 | AD8: 0.75197917 | AE8: 1.4408906 | AF8: 0.74378129 | AG8: 0.74378129 | AH8: 1.4366986 | AI8: 0.74865263 | AJ8: 0.74865263 | AK8: 1.4375306 | AL8: 0.74953525 | AM8: 0.74953525 | AN8: 1.4386869 | AO8: 0.75746057 | AP8: 0.75746057 | AQ8: 1.4462153 | AR8: 0.74475882 | AS8: 0.74475882 | AT8: 1.4446815 | AU8: 0.75085899 | AV8: 0.75085899 | AW8: 1.438264 | AX8: 0.75154119 | AY8: 0.75154119 | AZ8: 1.4385424 | BA8: 0.75297427 | BB8: 0.75297427 | BC8: 1.4395486 | BD8: 0.74875902 | BE8: 0.74875902 | BF8: 1.438072 | BG8: 0.73876643 | BH8: 0.73876643 | BI8: 1.4426937 | BJ8: 0.74975485 | BK8: 0.74975485 | BL8: 1.4367377 | BM8: 0.75058665 | BN8: 0.75058665 | BO8: 1.4383892 | BP8: 0.74778317 | BQ8: 0.74778317 | BR8: 1.4365209 | BS8: 0.74963089 | BT8: 0.74963089 | BU8: 1.4405094 | BV8: 0.75258274 | BW8: 0.75258274 | BX8: 1.4380334 | BY8: 0.74780803 | BZ8: 0.74780803 | CA8: 1.4387325 | CB8: 0.74970527 | CC8: 0.74970527 | CD8: 1.4387135 | CE8: 0.75320697 | CF8: 0.75320697 | CG8: 1.4407064 | CH8: 0.74939707 | CI8: 0.74939707 | CJ8: 1.4396531 | CK8: 0.75174255 | CL8: 0.75174255 | CM8: 1.4410043 | CN8: 0.75547034 | CO8: 0.75547034 | CP8: 1.4391603 | CQ8: 0.75067862 | CR8: 0.75067862 | CS8: 1.4385298
A9: BH2 | B9: 0.87257331 | C9: 1.1208751 | D9: 1.4474003 | E9: 0.85805283 | F9: 1.1003279 | G9: 1.4354672 | H9: 0.84424532 | I9: 1.089979 | J9: 1.4352489 | K9: 0.85069341 | L9: 1.0958837 | M9: 1.4402022 | N9: 0.84489297 | O9: 1.0901286 | P9: 1.4332902 | Q9: 0.84737209 | R9: 1.0920414 | S9: 1.4347826 | T9: 0.85344818 | U9: 1.1044484 | V9: 1.4394645 | W9: 0.84991897 | X9: 1.0947161 | Y9: 1.4354598 | Z9: 0.86072235 | AA9: 1.0978932 | AB9: 1.4412858 | AC9: 0.8471151 | AD9: 1.0975841 | AE9: 1.4443114 | AF9: 0.82663759 | AG9: 1.0769512 | AH9: 1.4315626 | AI9: 0.83771591 | AJ9: 1.085949 | AK9: 1.4353007 | AL9: 0.83755741 | AM9: 1.0869707 | AN9: 1.4309689 | AO9: 0.85203451 | AP9: 1.1048814 | AQ9: 1.4521696 | AR9: 0.83117993 | AS9: 1.0856539 | AT9: 1.4427552 | AU9: 0.83992542 | AV9: 1.0862001 | AW9: 1.4333384 | AX9: 0.84039948 | AY9: 1.0880124 | AZ9: 1.4333495 | BA9: 0.84568457 | BB9: 1.0911962 | BC9: 1.4370349 | BD9: 0.84101852 | BE9: 1.0889133 | BF9: 1.431978 | BG9: 0.83287134 | BH9: 1.0815834 | BI9: 1.4313288 | BJ9: 0.84789837 | BK9: 1.0902305 | BL9: 1.435075 | BM9: 0.84379859 | BN9: 1.0895058 | BO9: 1.4325823 | BP9: 0.84423274 | BQ9: 1.0888175 | BR9: 1.4352304 | BS9: 0.84991897 | BT9: 1.0913214 | BU9: 1.438505 | BV9: 0.85402045 | BW9: 1.0955661 | BX9: 1.4422435 | BY9: 0.83870426 | BZ9: 1.0845393 | CA9: 1.4324118 | CB9: 0.83904611 | CC9: 1.0866144 | CD9: 1.4325601 | CE9: 0.84754129 | CF9: 1.0917128 | CG9: 1.4370534 | CH9: 0.84245068 | CI9: 1.0897051 | CJ9: 1.4331012 | CK9: 0.84633112 | CL9: 1.0935931 | CM9: 1.4353969 | CN9: 0.85655376 | CO9: 1.0997194 | CP9: 1.4410869 | CQ9: 0.84548988 | CR9: 1.0886792 | CS9: 1.4346086
A10: BH2F | B10: 0.73159988 | C10: 1.056076 | D10: 1.6248068 | E10: 0.72188754 | F10: 1.0469018 | G10: 1.6196385 | H10: 0.7133174 | I10: 1.0464445 | J10: 1.6194735 | K10: 0.71858751 | L10: 1.050044 | M10: 1.6217286 | N10: 0.71476211 | O10: 1.0453605 | P10: 1.6187842 | Q10: 0.71618443 | R10: 1.0463024 | S10: 1.6193772 | T10: 0.71148454 | U10: 1.0436455 | V10: 1.6186134 | W10: 0.71788232 | X10: 1.0471903 | Y10: 1.6198321 | Z10: 0.72072151 | AA10: 1.0493291 | AB10: 1.6212545 | AC10: 0.71211451 | AD10: 1.0503825 | AE10: 1.6212465 | AF10: 0.70502212 | AG10: 1.0435542 | AH10: 1.6175295 | AI10: 0.70968951 | AJ10: 1.0455294 | AK10: 1.6184859 | AL10: 0.71143882 | AM10: 1.0438592 | AN10: 1.6174539 | AO10: 0.7151813 | AP10: 1.05509 | AQ10: 1.6235938 | AR10: 0.70754194 | AS10: 1.0511873 | AT10: 1.6214473 | AU10: 0.71165759 | AV10: 1.0443621 | AW10: 1.6181887 | AX10: 0.71300465 | AY10: 1.045296 | AZ10: 1.6185764 | BA10: 0.7142711 | BB10: 1.0464157 | BC10: 1.6200569 | BD10: 0.71008553 | BE10: 1.0428928 | BF10: 1.6178738 | BG10: 0.70209297 | BH10: 1.0381971 | BI10: 1.6166039 | BJ10: 0.71196768 | BK10: 1.0436099 | BL10: 1.6186659 | BM10: 0.71259069 | BN10: 1.0433917 | BO10: 1.6182027 | BP10: 0.70950288 | BQ10: 1.0441262 | BR10: 1.6182771 | BS10: 0.71398155 | BT10: 1.0461847 | BU10: 1.6207075 | BV10: 0.71364955 | BW10: 1.0468996 | BX10: 1.6197556 | BY10: 0.70932275 | BZ10: 1.0423535 | CA10: 1.617581 | CB10: 0.71145189 | CC10: 1.044084 | CD10: 1.618115 | CE10: 0.71578205 | CF10: 1.0465156 | CG10: 1.6202595 | CH10: 0.71090958 | CI10: 1.0430175 | CJ10: 1.6180471 | CK10: 0.73847794 | CL10: 1.065409 | CM10: 1.6308994 | CN10: 0.73919806 | CO10: 1.0664966 | CP10: 1.6311311 | CQ10: 0.71308611 | CR10: 1.0450315 | CS10: 1.6194391
A11: BH3 | B11: 1.3609008 | C11: 1.3608807 | D11: 0.84338232 | E11: 1.3490351 | F11: 1.3490148 | G11: 0.82963951 | H11: 1.3488594 | I11: 1.3488391 | J11: 0.81659324 | K11: 1.3520319 | L11: 1.3520116 | M11: 0.82146674 | N11: 1.3458555 | O11: 1.3458352 | P11: 0.81682082 | Q11: 1.3472497 | R11: 1.3472293 | S11: 0.81900808 | T11: 1.348346 | U11: 1.3483257 | V11: 0.81779871 | W11: 1.3482357 | X11: 1.3482189 | Y11: 0.82131965 | Z11: 1.3532549 | AA11: 1.3532381 | AB11: 0.83059671 | AC11: 1.3538556 | AD11: 1.3538354 | AE11: 0.81576772 | AF11: 1.3433258 | AG11: 1.3433054 | AH11: 0.8037804 | AI11: 1.3479221 | AJ11: 1.3478914 | AK11: 0.81189082 | AL11: 1.3443735 | AM11: 1.3443359 | AN11: 0.81150727 | AO11: 1.3615733 | AP11: 1.3615532 | AQ11: 0.82106502 | AR11: 1.3541954 | AS11: 1.3541752 | AT11: 0.80793781 | AU11: 1.3461559 | AV11: 1.3461562 | AW11: 0.81421689 | AX11: 1.3462283 | AY11: 1.3462115 | AZ11: 0.81278317 | BA11: 1.3492762 | BB11: 1.3492559 | BC11: 0.81815092 | BD11: 1.345303 | BE11: 1.3452826 | BF11: 0.81369168 | BG11: 1.3444496 | BH11: 1.3444292 | BI11: 0.80978763 | BJ11: 1.3471013 | BK11: 1.347081 | BL11: 0.81863922 | BM11: 1.3456483 | BN11: 1.3456314 | BO11: 0.81707109 | BP11: 1.345707 | BQ11: 1.3456867 | BR11: 0.81412558 | BS11: 1.3500061 | BT11: 1.3499823 | BU11: 0.82137057 | BV11: 1.3514578 | BW11: 1.3514376 | BX11: 0.82013636 | BY11: 1.3453824 | BZ11: 1.3453793 | CA11: 0.81376591 | CB11: 1.3455517 | CC11: 1.3455347 | CD11: 0.81210828 | CE11: 1.3499751 | CF11: 1.3499548 | CG11: 0.8211782 | CH11: 1.3458797 | CI11: 1.3458628 | CJ11: 0.81538599 | CK11: 1.3685889 | CL11: 1.3685689 | CM11: 0.84519855 | CN11: 1.3523034 | CO11: 1.3522831 | CP11: 0.82443112 | CQ11: 1.3480875 | CR11: 1.3480706 | CS11: 0.81932007
A12: BO | B12: 0.78698471 | C12: 0.78698471 | D12: 1.3564866 | E12: 0.77789565 | F12: 0.77789565 | G12: 1.3490207 | H12: 0.77286166 | I12: 0.77286166 | J12: 1.3478662 | K12: 0.77766403 | L12: 0.77766403 | M12: 1.3495621 | N12: 0.77295415 | O12: 0.77295415 | P12: 1.3466995 | Q12: 0.77433652 | R12: 0.77433652 | S12: 1.3474993 | T12: 0.77205836 | U12: 0.77205836 | V12: 1.3457379 | W12: 0.7758528 | X12: 0.7758528 | Y12: 1.3484466 | Z12: 0.77639441 | AA12: 0.77639441 | AB12: 1.3528709 | AC12: 0.77424788 | AD12: 0.77424788 | AE12: 1.3459615 | AF12: 0.76392275 | AG12: 0.76392275 | AH12: 1.3436147 | AI12: 0.76836055 | AJ12: 0.76836055 | AK12: 1.3433437 | AL12: 0.77021167 | AM12: 0.77021167 | AN12: 1.3455 | AO12: 0.77783684 | AP12: 0.77783684 | AQ12: 1.3475969 | AR12: 0.76673248 | AS12: 0.76673248 | AT12: 1.3447858 | AU12: 0.77079434 | AV12: 0.77079434 | AW12: 1.343494 | AX12: 0.77275805 | AY12: 0.77275805 | AZ12: 1.3470988 | BA12: 0.77371587 | BB12: 0.77371587 | BC12: 1.3459127 | BD12: 0.76979203 | BE12: 0.76979203 | BF12: 1.3447558 | BG12: 0.76316625 | BH12: 0.76316625 | BI12: 1.3363395 | BJ12: 0.77259522 | BK12: 0.77259522 | BL12: 1.3422314 | BM12: 0.77141363 | BN12: 0.77141363 | BO12: 1.3442355 | BP12: 0.76851684 | BQ12: 0.76851684 | BR12: 1.3444831 | BS12: 0.77440668 | BT12: 0.77440668 | BU12: 1.3440784 | BV12: 0.77451376 | BW12: 0.77451376 | BX12: 1.3423694 | BY12: 0.76901899 | BZ12: 0.76901899 | CA12: 1.3411026 | CB12: 0.77136173 | CC12: 0.77136173 | CD12: 1.3455392 | CE12: 0.77432913 | CF12: 0.77432913 | CG12: 1.3456458 | CH12: 0.77053089 | CI12: 0.77053089 | CJ12: 1.3434275 | CK12: 0.7739967 | CL12: 0.7739967 | CM12: 1.3459736 | CN12: 0.77820438 | CO12: 0.77820438 | CP12: 1.3455695 | CQ12: 0.77227685 | CR12: 0.77227685 | CS12: 1.3436768
A13: BS | B13: 0.83499403 | C13: 0.83499403 | D13: 1.5164507 | E13: 0.82525736 | F13: 0.82525736 | G13: 1.5101725 | H13: 0.82161999 | I13: 0.82161999 | J13: 1.5088705 | K13: 0.8260292 | L13: 0.8260292 | M13: 1.510934 | N13: 0.82091301 | O13: 0.82091301 | P13: 1.5073817 | Q13: 0.82229408 | R13: 0.82229408 | S13: 1.5082435 | T13: 0.81995503 | U13: 0.81995503 | V13: 1.5065793 | W13: 0.82352237 | X13: 0.82352237 | Y13: 1.509216 | Z13: 0.83227388 | AA13: 0.83227388 | AB13: 1.5143921 | AC13: 0.82412187 | AD13: 0.82412187 | AE13: 1.5070707 | AF13: 0.81487239 | AG13: 0.81487239 | AH13: 1.5041364 | AI13: 0.81797511 | AJ13: 0.81797511 | AK13: 1.5036399 | AL13: 0.81964841 | AM13: 0.81964841 | AN13: 1.5055985 | AO13: 0.83141842 | AP13: 0.83141842 | AQ13: 1.5081547 | AR13: 0.81861976 | AS13: 0.81861976 | AT13: 1.5050028 | AU13: 0.82170186 | AV13: 0.82170186 | AW13: 1.5045637 | AX13: 0.82138512 | AY13: 0.82138512 | AZ13: 1.5077407 | BA13: 0.82521232 | BB13: 0.82521232 | BC13: 1.5070735 | BD13: 0.82114587 | BE13: 0.82114587 | BF13: 1.5054685 | BG13: 0.82612135 | BH13: 0.82612135 | BI13: 1.4962545 | BJ13: 0.82543752 | BK13: 0.82543752 | BL13: 1.5040098 | BM13: 0.82305579 | BN13: 0.82305579 | BO13: 1.5048568 | BP13: 0.82020974 | BQ13: 0.82020974 | BR13: 1.5048948 | BS13: 0.82774397 | BT13: 0.82774397 | BU13: 1.5056627 | BV13: 0.82520803 | BW13: 0.82520803 | BX13: 1.5032026 | BY13: 0.82291168 | BZ13: 0.82291168 | CA13: 1.5022308 | CB13: 0.82146916 | CC13: 0.82146916 | CD13: 1.506218 | CE13: 0.82613849 | CF13: 0.82613849 | CG13: 1.5054245 | CH13: 0.82301063 | CI13: 0.82301063 | CJ13: 1.5031525 | CK13: 0.82530455 | CL13: 0.82530455 | CM13: 1.5043921 | CN13: 0.8293997 | CO13: 0.8293997 | CP13: 1.5059323 | CQ13: 0.82472094 | CR13: 0.82472094 | CS13: 1.5046366
A14: C2H | B14: 0.87268425 | C14: 0.87268425 | D14: 1.5542355 | E14: 0.8607774 | F14: 0.8607774 | G14: 1.5476206 | H14: 0.85644454 | I14: 0.85644454 | J14: 1.5465062 | K14: 0.86110954 | L14: 0.86110954 | M14: 1.5502138 | N14: 0.8555125 | O14: 0.8555125 | P14: 1.5458932 | Q14: 0.8570987 | R14: 0.8570987 | S14: 1.5468959 | T14: 0.85641783 | U14: 0.85641783 | V14: 1.5461646 | W14: 0.85859539 | X14: 0.85859539 | Y14: 1.5475259 | Z14: 0.86166061 | AA14: 0.86166061 | AB14: 1.5557421 | AC14: 0.85928785 | AD14: 0.85928785 | AE14: 1.5449144 | AF14: 0.84767864 | AG14: 0.84767864 | AH14: 1.5427839 | AI14: 0.85298185 | AJ14: 0.85298185 | AK14: 1.5428353 | AL14: 0.85478353 | AM14: 0.85478353 | AN14: 1.5436219 | AO14: 0.86863468 | AP14: 0.86863468 | AQ14: 1.5474372 | AR14: 0.85254257 | AS14: 0.85254257 | AT14: 1.5424924 | AU14: 0.85613063 | AV14: 0.85613063 | AW14: 1.542885 | AX14: 0.85648461 | AY14: 0.85648461 | AZ14: 1.5455952 | BA14: 0.86024239 | BB14: 0.86024239 | BC14: 1.5464047 | BD14: 0.85603377 | BE14: 0.85603377 | BF14: 1.5430787 | BG14: 0.86045511 | BH14: 0.86045511 | BI14: 1.5366674 | BJ14: 0.86057806 | BK14: 0.86057806 | BL14: 1.5440491 | BM14: 0.85803569 | BN14: 0.85803569 | BO14: 1.5433064 | BP14: 0.85318632 | BQ14: 0.85318632 | BR14: 1.5458059 | BS14: 0.8617668 | BT14: 0.8617668 | BU14: 1.5444026 | BV14: 0.85944091 | BW14: 0.85944091 | BX14: 1.5463041 | BY14: 0.85723548 | BZ14: 0.85723548 | CA14: 1.5411847 | CB14: 0.85651131 | CC14: 0.85651131 | CD14: 1.5441558 | CE14: 0.86152786 | CF14: 0.86152786 | CG14: 1.5455975 | CH14: 0.85749896 | CI14: 0.85749896 | CJ14: 1.5420896 | CK14: 0.86076744 | CL14: 0.86076744 | CM14: 1.5442492 | CN14: 0.86443384 | CO14: 0.86443384 | CP14: 1.5464392 | CQ14: 0.85826561 | CR14: 0.85826561 | CS14: 1.5438975
A15: C2H2 | B15: 0.86817721 | C15: 0.86817721 | D15: 1.7087401 | E15: 0.85557672 | F15: 0.85557672 | G15: 1.7027797 | H15: 0.85132679 | I15: 0.85132679 | J15: 1.7037743 | K15: 0.85569464 | L15: 0.85569464 | M15: 1.7073643 | N15: 0.84986898 | O15: 0.84986898 | P15: 1.7026144 | Q15: 0.85158875 | R15: 0.85158875 | S15: 1.7035685 | T15: 0.8504905 | U15: 0.8504905 | V15: 1.7026939 | W15: 0.85314634 | X15: 0.85314634 | Y15: 1.7040392 | Z15: 0.8552539 | AA15: 0.8552539 | AB15: 1.7109965 | AC15: 0.8531619 | AD15: 0.8531619 | AE15: 1.7022728 | AF15: 0.8420976 | AG15: 0.8420976 | AH15: 1.7005998 | AI15: 0.8480925 | AJ15: 0.8480925 | AK15: 1.7009058 | AL15: 0.84978774 | AM15: 0.84978774 | AN15: 1.7009136 | AO15: 0.86242971 | AP15: 0.86242971 | AQ15: 1.7052838 | AR15: 0.84664166 | AS15: 0.84664166 | AT15: 1.7011665 | AU15: 0.85101172 | AV15: 0.85101172 | AW15: 1.6991628 | AX15: 0.85097428 | AY15: 0.85097428 | AZ15: 1.7025317 | BA15: 0.85500238 | BB15: 0.85500238 | BC15: 1.7032256 | BD15: 0.85069965 | BE15: 0.85069965 | BF15: 1.699669 | BG15: 0.85740582 | BH15: 0.85740582 | BI15: 1.6917802 | BJ15: 0.85449291 | BK15: 0.85449291 | BL15: 1.6998252 | BM15: 0.85285061 | BN15: 0.85285061 | BO15: 1.6995534 | BP15: 0.84797039 | BQ15: 0.84797039 | BR15: 1.7027937 | BS15: 0.85548982 | BT15: 0.85548982 | BU15: 1.6999346 | BV15: 0.85336728 | BW15: 0.85336728 | BX15: 1.7033051 | BY15: 0.85267002 | BZ15: 0.85267002 | CA15: 1.6970362 | CB15: 0.8511178 | CC15: 0.8511178 | CD15: 1.7009417 | CE15: 0.85644836 | CF15: 0.85644836 | CG15: 1.7018984 | CH15: 0.85203139 | CI15: 0.85203139 | CJ15: 1.6981811 | CK15: 0.85509865 | CL15: 0.85509865 | CM15: 1.7001501 | CN15: 0.85864059 | CO15: 0.85864059 | CP15: 1.7020341 | CQ15: 0.85254856 | CR15: 0.85254856 | CS15: 1.7002891
... A82: BN | B82: 0.87023667 | C82: 0.8273905 | D82: 1.5137429 | E82: 0.85817454 | F82: 0.81778356 | G82: 1.5070808 | H82: 0.83250037 | I82: 0.83250037 | J82: 1.5065726 | K82: 0.80125587 | L82: 0.87161321 | M82: 1.5079805 | N82: 0.79612834 | O82: 0.86625489 | P82: 1.5035623 | Q82: 0.79782306 | R82: 0.86774127 | S82: 1.5045371 | T82: 0.7989134 | U82: 0.86723776 | V82: 1.5061852 | W82: 0.86876882 | X82: 0.80024229 | Y82: 1.5056841 | Z82: 0.80807775 | AA82: 0.87195434 | AB82: 1.5131523 | AC82: 0.87032922 | AD82: 0.79723654 | AE82: 1.5046237 | AF82: 0.81136029 | AG82: 0.83331489 | AH82: 1.5001574 | AI82: 0.79043867 | AJ82: 0.86329597 | AK82: 1.5010203 | AL82: 0.8551297 | AM82: 0.80130227 | AN82: 1.5023898 | AO82: 0.85152847 | AP82: 0.83040648 | AQ82: 1.5065006 | AR82: 0.82541501 | AS82: 0.82541501 | AT82: 1.5021384 | AU82: 0.82637523 | AV82: 0.83377573 | AW82: 1.5010168 | AX82: 0.79486662 | AY82: 0.8667554 | AZ82: 1.5047847 | BA82: 0.79760559 | BB82: 0.868833 | BC82: 1.503601 | BD82: 0.79367706 | BE82: 0.86517065 | BF82: 1.5028453 | BG82: 0.78737976 | BH82: 0.86352201 | BI82: 1.4929987 | BJ82: 0.86748063 | BK82: 0.80049387 | BL82: 1.4985453 | BM82: 0.79579753 | BN82: 0.86608322 | BO82: 1.5009166 | BP82: 0.81851812 | BQ82: 0.83972517 | BR82: 1.5011255 | BS82: 0.80116308 | BT82: 0.87015124 | BU82: 1.5009324 | BV82: 0.80275456 | BW82: 0.86848351 | BX82: 1.4992215 | BY82: 0.8596821 | BZ82: 0.79790071 | CA82: 1.498314 | CB82: 0.79370438 | CC82: 0.86598306 | CD82: 1.5030932 | CE82: 0.79932043 | CF82: 0.86866897 | CG82: 1.5025718 | CH82: 0.79458207 | CI82: 0.86595444 | CJ82: 1.5004028 | CK82: 0.7987893 | CL82: 0.86922155 | CM82: 1.5026954 | CN82: 0.85128833 | CO82: 0.82836339 | CP82: 1.5026332 | CQ82: 0.79752791 | CR82: 0.86729491 | CS82: 1.5005492

Sheet combine_values
A1: method | B1: CCSD\(T\) | C1: CCSD\(T\) | D1: CCSD\(T\) | F1: HF | G1: HF | H1: HF | I1: MP2 | J1: MP2 | K1: MP2 | L1: CCSD | M1: CCSD | N1: CCSD | O1: Slater | P1: Slater | Q1: Slater | R1: SPW92 | S1: SPW92 | T1: SPW92 | U1: B97-D3 | V1: B97-D3 | W1: B97-D3 | X1: BLYP | Y1: BLYP | Z1: BLYP | AA1: BPBE | AB1: BPBE | AC1: BPBE | AD1: mPW91 | AE1: mPW91 | AF1: mPW91 | AG1: N12 | AH1: N12 | AI1: N12 | AJ1: PBE | AK1: PBE | AL1: PBE | AM1: SOGGA11 | AN1: SOGGA11 | AO1: SOGGA11 | AP1: B97M-V | AQ1: B97M-V | AR1: B97M-V | AS1: M06-L | AT1: M06-L | AU1: M06-L | AV1: mBEEF | AW1: mBEEF | AX1: mBEEF | AY1: MGGA_MS2 | AZ1: MGGA_MS2 | BA1: MGGA_MS2 | BB1: MN15-L | BC1: MN15-L | BD1: MN15-L | BE1: revM06-L | BF1: revM06-L | BG1: revM06-L | BH1: SCAN | BI1: SCAN | BJ1: SCAN | BK1: TPSS | BL1: TPSS | BM1: TPSS | BN1: B3LYP | BO1: B3LYP | BP1: B3LYP | BQ1: B97-2 | BR1: B97-2 | BS1: B97-2 | BT1: HFLYP | BU1: HFLYP | BV1: HFLYP | BW1: M06-2X | BX1: M06-2X | BY1: M06-2X | BZ1: PBE0 | CA1: PBE0 | CB1: PBE0 | CC1: M06 | CD1: M06 | CE1: M06 | CF1: M08-HX | CG1: M08-HX | CH1: M08-HX | CI1: MN15 | CJ1: MN15 | CK1: MN15 | CL1: SCAN0 | CM1: SCAN0 | CN1: SCAN0 | CO1: TPSSh | CP1: TPSSh | CQ1: TPSSh | CR1: CAM-B3LYP | CS1: CAM-B3LYP | CT1: CAM-B3LYP | CU1: wB97X-D | CV1: wB97X-D | CW1: wB97X-D | CX1: wB97X-V | CY1: wB97X-V | CZ1: wB97X-V | DA1: wB97M-V | DB1: wB97M-V | DC1: wB97M-V | DD1: wM05-D | DE1: wM05-D | DF1: wM05-D
A2: component | B2: XX | C2: YY | D2: ZZ | F2: XX | G2: YY | H2: ZZ | I2: XX | J2: YY | K2: ZZ | L2: XX | M2: YY | N2: ZZ | O2: XX | P2: YY | Q2: ZZ | R2: XX | S2: YY | T2: ZZ | U2: XX | V2: YY | W2: ZZ | X2: XX | Y2: YY | Z2: ZZ | AA2: XX | AB2: YY | AC2: ZZ | AD2: XX | AE2: YY | AF2: ZZ | AG2: XX | AH2: YY | AI2: ZZ | AJ2: XX | AK2: YY | AL2: ZZ | AM2: XX | AN2: YY | AO2: ZZ | AP2: XX | AQ2: YY | AR2: ZZ | AS2: XX | AT2: YY | AU2: ZZ | AV2: XX | AW2: YY | AX2: ZZ | AY2: XX | AZ2: YY | BA2: ZZ | BB2: XX | BC2: YY | BD2: ZZ | BE2: XX | BF2: YY | BG2: ZZ | BH2: XX | BI2: YY | BJ2: ZZ | BK2: XX | BL2: YY | BM2: ZZ | BN2: XX | BO2: YY | BP2: ZZ | BQ2: XX | BR2: YY | BS2: ZZ | BT2: XX | BU2: YY | BV2: ZZ | BW2: XX | BX2: YY | BY2: ZZ | BZ2: XX | CA2: YY | CB2: ZZ | CC2: XX | CD2: YY | CE2: ZZ | CF2: XX | CG2: YY | CH2: ZZ | CI2: XX | CJ2: YY | CK2: ZZ | CL2: XX | CM2: YY | CN2: ZZ | CO2: XX | CP2: YY | CQ2: ZZ | CR2: XX | CS2: YY | CT2: ZZ | CU2: XX | CV2: YY | CW2: ZZ | CX2: XX | CY2: YY | CZ2: ZZ | DA2: XX | DB2: YY | DC2: ZZ | DD2: XX | DE2: YY | DF2: ZZ
A3: molecule
A4: AlF | B4: =OFFSET(wft_table!L$7,(ROW(wft_table!L1)-1)*4,0) -> 0.72880654 | C4: =OFFSET(wft_table!M$7,(ROW(wft_table!M1)-1)*4,0) -> 0.72880654 | D4: =OFFSET(wft_table!N$7,(ROW(wft_table!N1)-1)*4,0) -> 1.750396 | F4: =OFFSET(wft_table!C$7,(ROW(wft_table!C1)-1)*4,0) -> 0.72854306 | G4: =OFFSET(wft_table!D$7,(ROW(wft_table!D1)-1)*4,0) -> 0.72854306 | H4: =OFFSET(wft_table!E$7,(ROW(wft_table!E1)-1)*4,0) -> 1.7621938 | I4: =OFFSET(wft_table!F$7,(ROW(wft_table!F1)-1)*4,0) -> 0.73036575 | J4: =OFFSET(wft_table!G$7,(ROW(wft_table!G1)-1)*4,0) -> 0.73036575 | K4: =OFFSET(wft_table!H$7,(ROW(wft_table!H1)-1)*4,0) -> 1.7515945 | L4: =OFFSET(wft_table!I$7,(ROW(wft_table!I1)-1)*4,0) -> 0.72726282 | M4: =OFFSET(wft_table!J$7,(ROW(wft_table!J1)-1)*4,0) -> 0.72726282 | N4: =OFFSET(wft_table!K$7,(ROW(wft_table!K1)-1)*4,0) -> 1.751902 | O4: 0.74836109 | P4: 0.74836109 | Q4: 1.7521481 | R4: 0.73560133 | S4: 0.73560133 | T4: 1.7471144 | U4: 0.73412284 | V4: 0.73412284 | W4: 1.7504678 | X4: 0.73648058 | Y4: 0.73648058 | Z4: 1.7501495 | AA4: 0.73291115 | AB4: 0.73291115 | AC4: 1.7488949 | AD4: 0.7342195 | AE4: 0.7342195 | AF4: 1.7491885 | AG4: 0.7315381 | AH4: 0.7315381 | AI4: 1.750794 | AJ4: 0.735831 | AK4: 0.735831 | AL4: 1.7495727 | AM4: 0.75644808 | AN4: 0.75644808 | AO4: 1.7529771 | AP4: 0.73350342 | AQ4: 0.73350342 | AR4: 1.7538892 | AS4: 0.72483431 | AT4: 0.72483431 | AU4: 1.7488584 | AV4: 0.73059971 | AW4: 0.73059971 | AX4: 1.751904 | AY4: 0.73202531 | AZ4: 0.73202531 | BA4: 1.751487 | BB4: 0.74585289 | BC4: 0.74585289 | BD4: 1.7597504 | BE4: 0.72853378 | BF4: 0.72853378 | BG4: 1.7583675 | BH4: 0.73217302 | BI4: 0.73217302 | BJ4: 1.7510181 | BK4: 0.73362781 | BL4: 0.73362781 | BM4: 1.7512682 | BN4: 0.73206455 | BO4: 0.73206455 | BP4: 1.7512251 | BQ4: 0.73013469 | BR4: 0.73013469 | BS4: 1.7518132 | BT4: 0.7220736 | BU4: 0.7220736 | BV4: 1.7577111 | BW4: 0.72809761 | BX4: 0.72809761 | BY4: 1.7501184 | BZ4: 0.73092111 | CA4: 0.73092111 | CB4: 1.7515189 | CC4: 0.72389424 | CD4: 0.72389424 | CE4: 1.7475937 | CF4: 0.73084482 | CG4: 0.73084482 | CH4: 1.7543406 | CI4: 0.73740003 | CJ4: 0.73740003 | CK4: 1.7509029 | CL4: 0.72929876 | CM4: 0.72929876 | CN4: 1.7523173 | CO4: 0.73192373 | CP4: 0.73192373 | CQ4: 1.7519403 | CR4: 0.73135329 | CS4: 0.73135329 | CT4: 1.7523969 | CU4: 0.7294563 | CV4: 0.7294563 | CW4: 1.7526469 | CX4: 0.7315866 | CY4: 0.7315866 | CZ4: 1.7543901 | DA4: 0.73365545 | DB4: 0.73365545 | DC4: 1.7507439 | DD4: 0.72987313 | DE4: 0.72987313 | DF4: 1.7500091
A5: Ar | B5: =OFFSET(wft_table!L$7,(ROW(wft_table!L2)-1)*4,0) -> 0.69285369 | C5: =OFFSET(wft_table!M$7,(ROW(wft_table!M2)-1)*4,0) -> 0.69285369 | D5: =OFFSET(wft_table!N$7,(ROW(wft_table!N2)-1)*4,0) -> 0.69285369 | F5: =OFFSET(wft_table!C$7,(ROW(wft_table!C2)-1)*4,0) -> 0.69439921 | G5: =OFFSET(wft_table!D$7,(ROW(wft_table!D2)-1)*4,0) -> 0.69439921 | H5: =OFFSET(wft_table!E$7,(ROW(wft_table!E2)-1)*4,0) -> 0.69439921 | I5: =OFFSET(wft_table!F$7,(ROW(wft_table!F2)-1)*4,0) -> 0.69340193 | J5: =OFFSET(wft_table!G$7,(ROW(wft_table!G2)-1)*4,0) -> 0.69340193 | K5: =OFFSET(wft_table!H$7,(ROW(wft_table!H2)-1)*4,0) -> 0.69340193 | L5: =OFFSET(wft_table!I$7,(ROW(wft_table!I2)-1)*4,0) -> 0.69246999 | M5: =OFFSET(wft_table!J$7,(ROW(wft_table!J2)-1)*4,0) -> 0.69246999 | N5: =OFFSET(wft_table!K$7,(ROW(wft_table!K2)-1)*4,0) -> 0.69246999 | O5: 0.70452653 | P5: 0.70452653 | Q5: 0.70452653 | R5: 0.69790575 | S5: 0.69790575 | T5: 0.69790575 | U5: 0.69342004 | V5: 0.69342004 | W5: 0.69342004 | X5: 0.6990825 | Y5: 0.6990825 | Z5: 0.6990825 | AA5: 0.69502052 | AB5: 0.69502052 | AC5: 0.69502052 | AD5: 0.69601821 | AE5: 0.69601821 | AF5: 0.69601821 | AG5: 0.69123948 | AH5: 0.69123948 | AI5: 0.69123948 | AJ5: 0.69692854 | AK5: 0.69692854 | AL5: 0.69692854 | AM5: 0.69470548 | AN5: 0.69470548 | AO5: 0.69470548 | AP5: 0.69387855 | AQ5: 0.69387855 | AR5: 0.69387855 | AS5: 0.69055795 | AT5: 0.69055795 | AU5: 0.69055795 | AV5: 0.69100341 | AW5: 0.69100341 | AX5: 0.69100341 | AY5: 0.6930268 | AZ5: 0.6930268 | BA5: 0.6930268 | BB5: 0.69633563 | BC5: 0.69633563 | BD5: 0.69633563 | BE5: 0.69181586 | BF5: 0.69181586 | BG5: 0.69181586 | BH5: 0.69374758 | BI5: 0.69374758 | BJ5: 0.69374758 | BK5: 0.69509778 | BL5: 0.69509778 | BM5: 0.69509778 | BN5: 0.69678036 | BO5: 0.69678036 | BP5: 0.69678036 | BQ5: 0.69244546 | BR5: 0.69244546 | BS5: 0.69244546 | BT5: 0.69200391 | BU5: 0.69200391 | BV5: 0.69200391 | BW5: 0.69494029 | BX5: 0.69494029 | BY5: 0.69494029 | BZ5: 0.69450627 | CA5: 0.69450627 | CB5: 0.69450627 | CC5: 0.69286288 | CD5: 0.69286288 | CE5: 0.69286288 | CF5: 0.695668 | CG5: 0.695668 | CH5: 0.695668 | CI5: 0.69166957 | CJ5: 0.69166957 | CK5: 0.69166957 | CL5: 0.69312513 | CM5: 0.69312513 | CN5: 0.69312513 | CO5: 0.6943427 | CP5: 0.6943427 | CQ5: 0.6943427 | CR5: 0.69720704 | CS5: 0.69720704 | CT5: 0.69720704 | CU5: 0.69332175 | CV5: 0.69332175 | CW5: 0.69332175 | CX5: 0.69548688 | CY5: 0.69548688 | CZ5: 0.69548688 | DA5: 0.69756536 | DB5: 0.69756536 | DC5: 0.69756536 | DD5: 0.69476196 | DE5: 0.69476196 | DF5: 0.69476196
A6: BeH | B6: =OFFSET(wft_table!L$7,(ROW(wft_table!L3)-1)*4,0) -> 0.99368082 | C6: =OFFSET(wft_table!M$7,(ROW(wft_table!M3)-1)*4,0) -> 0.99368082 | D6: =OFFSET(wft_table!N$7,(ROW(wft_table!N3)-1)*4,0) -> 1.6258257 | F6: =OFFSET(wft_table!C$7,(ROW(wft_table!C3)-1)*4,0) -> 0.98914899 | G6: =OFFSET(wft_table!D$7,(ROW(wft_table!D3)-1)*4,0) -> 0.98914899 | H6: =OFFSET(wft_table!E$7,(ROW(wft_table!E3)-1)*4,0) -> 1.6465447 | I6: =OFFSET(wft_table!F$7,(ROW(wft_table!F3)-1)*4,0) -> 0.98985366 | J6: =OFFSET(wft_table!G$7,(ROW(wft_table!G3)-1)*4,0) -> 0.98985366 | K6: =OFFSET(wft_table!H$7,(ROW(wft_table!H3)-1)*4,0) -> 1.6335688 | L6: =OFFSET(wft_table!I$7,(ROW(wft_table!I3)-1)*4,0) -> 0.99278453 | M6: =OFFSET(wft_table!J$7,(ROW(wft_table!J3)-1)*4,0) -> 0.99278453 | N6: =OFFSET(wft_table!K$7,(ROW(wft_table!K3)-1)*4,0) -> 1.6270783 | O6: 1.0396475 | P6: 1.0396475 | Q6: 1.6487272 | R6: 1.021016 | S6: 1.021016 | T6: 1.6229892 | U6: 1.0119905 | V6: 1.0119905 | W6: 1.6222705 | X6: 1.0097988 | Y6: 1.0097988 | Z6: 1.6220269 | AA6: 1.003358 | AB6: 1.003358 | AC6: 1.6180907 | AD6: 1.0067682 | AE6: 1.0067682 | AF6: 1.6192359 | AG6: 1.018048 | AH6: 1.018048 | AI6: 1.6386547 | AJ6: 1.0102993 | AK6: 1.0102993 | AL6: 1.6202855 | AM6: 1.0312682 | AN6: 1.0312682 | AO6: 1.6218009 | AP6: 1.0273244 | AQ6: 1.0273244 | AR6: 1.6426538 | AS6: 0.98396417 | AT6: 0.98396417 | AU6: 1.6156648 | AV6: 0.99777769 | AW6: 0.99777769 | AX6: 1.6238103 | AY6: 0.99506171 | AZ6: 0.99506171 | BA6: 1.619569 | BB6: 1.022515 | BC6: 1.022515 | BD6: 1.6504464 | BE6: 0.99820977 | BF6: 0.99820977 | BG6: 1.6408482 | BH6: 1.0013182 | BI6: 1.0013182 | BJ6: 1.6198093 | BK6: 1.0007835 | BL6: 1.0007835 | BM6: 1.616571 | BN6: 1.0027428 | BO6: 1.0027428 | BP6: 1.6225195 | BQ6: 1.0021643 | BR6: 1.0021643 | BS6: 1.6267221 | BT6: 0.98478742 | BU6: 0.98478742 | BV6: 1.6290501 | BW6: 1.0068716 | BX6: 1.0068716 | BY6: 1.6161825 | BZ6: 1.0020011 | CA6: 1.0020011 | CB6: 1.6218952 | CC6: 1.0032839 | CD6: 1.0032839 | CE6: 1.6200617 | CF6: 1.0071817 | CG6: 1.0071817 | CH6: 1.6338911 | CI6: 1.0328818 | CJ6: 1.0328818 | CK6: 1.6270494 | CL6: 0.99855977 | CM6: 0.99855977 | CN6: 1.6204713 | CO6: 0.999185 | CP6: 0.999185 | CQ6: 1.6173156 | CR6: 1.0025723 | CS6: 1.0025723 | CT6: 1.6254349 | CU6: 1.0028021 | CV6: 1.0028021 | CW6: 1.6340919 | CX6: 1.0009469 | CY6: 1.0009469 | CZ6: 1.6335338 | DA6: 1.0251655 | DB6: 1.0251655 | DC6: 1.6307032 | DD6: 1.0075581 | DE6: 1.0075581 | DF6: 1.626805
A7: BeH2 | B7: =OFFSET(wft_table!L$7,(ROW(wft_table!L4)-1)*4,0) -> 0.90145481 | C7: =OFFSET(wft_table!M$7,(ROW(wft_table!M4)-1)*4,0) -> 0.90145481 | D7: =OFFSET(wft_table!N$7,(ROW(wft_table!N4)-1)*4,0) -> 1.8867482 | F7: =OFFSET(wft_table!C$7,(ROW(wft_table!C4)-1)*4,0) -> 0.9016951 | G7: =OFFSET(wft_table!D$7,(ROW(wft_table!D4)-1)*4,0) -> 0.9016951 | H7: =OFFSET(wft_table!E$7,(ROW(wft_table!E4)-1)*4,0) -> 1.9001487 | I7: =OFFSET(wft_table!F$7,(ROW(wft_table!F4)-1)*4,0) -> 0.89990146 | J7: =OFFSET(wft_table!G$7,(ROW(wft_table!G4)-1)*4,0) -> 0.89990146 | K7: =OFFSET(wft_table!H$7,(ROW(wft_table!H4)-1)*4,0) -> 1.8900465 | L7: =OFFSET(wft_table!I$7,(ROW(wft_table!I4)-1)*4,0) -> 0.90086783 | M7: =OFFSET(wft_table!J$7,(ROW(wft_table!J4)-1)*4,0) -> 0.90086783 | N7: =OFFSET(wft_table!K$7,(ROW(wft_table!K4)-1)*4,0) -> 1.8875948 | O7: 0.94719506 | P7: 0.94719506 | Q7: 1.893168 | R7: 0.92643523 | S7: 0.92643523 | T7: 1.8818534 | U7: 0.9115222 | V7: 0.9115222 | W7: 1.8912197 | X7: 0.91563193 | Y7: 0.91563193 | Z7: 1.8910035 | AA7: 0.91034555 | AB7: 0.91034555 | AC7: 1.8836271 | AD7: 0.91305704 | AE7: 0.91305704 | AF7: 1.8848141 | AG7: 0.91301632 | AH7: 0.91301632 | AI7: 1.8885512 | AJ7: 0.91599725 | AK7: 0.91599725 | AL7: 1.8846629 | AM7: 0.92397762 | AN7: 0.92397762 | AO7: 1.8975025 | AP7: 0.91207259 | AQ7: 0.91207259 | AR7: 1.9129686 | AS7: 0.89443749 | AT7: 0.89443749 | AU7: 1.8851264 | AV7: 0.90459006 | AW7: 0.90459006 | AX7: 1.8937668 | AY7: 0.9036581 | AZ7: 0.9036581 | BA7: 1.8834067 | BB7: 0.91865159 | BC7: 0.91865159 | BD7: 1.917911 | BE7: 0.8996383 | BF7: 0.8996383 | BG7: 1.9102882 | BH7: 0.90742116 | BI7: 0.90742116 | BJ7: 1.8884462 | BK7: 0.90386376 | BL7: 0.90386376 | BM7: 1.8837521 | BN7: 0.90999158 | BO7: 0.90999158 | BP7: 1.8901252 | BQ7: 0.90560316 | BR7: 0.90560316 | BS7: 1.8876324 | BT7: 0.89538597 | BU7: 0.89538597 | BV7: 1.8916161 | BW7: 0.90832198 | BX7: 0.90832198 | BY7: 1.8836567 | BZ7: 0.90894248 | CA7: 0.90894248 | CB7: 1.8850738 | CC7: 0.90295164 | CD7: 0.90295164 | CE7: 1.8807238 | CF7: 0.91118908 | CG7: 0.91118908 | CH7: 1.8973294 | CI7: 0.91536123 | CJ7: 0.91536123 | CK7: 1.9019803 | CL7: 0.90497353 | CM7: 0.90497353 | CN7: 1.8886759 | CO7: 0.90253985 | CP7: 0.90253985 | CQ7: 1.8843506 | CR7: 0.91240539 | CS7: 0.91240539 | CT7: 1.8910887 | CU7: 0.90920827 | CV7: 0.90920827 | CW7: 1.8904333 | CX7: 0.90971239 | CY7: 0.90971239 | CZ7: 1.8905906 | DA7: 0.91713287 | DB7: 0.91713287 | DC7: 1.8952024 | DD7: 0.91269054 | DE7: 0.91269054 | DF7: 1.892438
A8: BF | B8: =OFFSET(wft_table!L$7,(ROW(wft_table!L5)-1)*4,0) -> 0.74685888 | C8: =OFFSET(wft_table!M$7,(ROW(wft_table!M5)-1)*4,0) -> 0.74685888 | D8: =OFFSET(wft_table!N$7,(ROW(wft_table!N5)-1)*4,0) -> 1.433292 | F8: =OFFSET(wft_table!C$7,(ROW(wft_table!C5)-1)*4,0) -> 0.74345993 | G8: =OFFSET(wft_table!D$7,(ROW(wft_table!D5)-1)*4,0) -> 0.74345993 | H8: =OFFSET(wft_table!E$7,(ROW(wft_table!E5)-1)*4,0) -> 1.4472363 | I8: =OFFSET(wft_table!F$7,(ROW(wft_table!F5)-1)*4,0) -> 0.7499455 | J8: =OFFSET(wft_table!G$7,(ROW(wft_table!G5)-1)*4,0) -> 0.7499455 | K8: =OFFSET(wft_table!H$7,(ROW(wft_table!H5)-1)*4,0) -> 1.4386517 | L8: =OFFSET(wft_table!I$7,(ROW(wft_table!I5)-1)*4,0) -> 0.7450559 | M8: =OFFSET(wft_table!J$7,(ROW(wft_table!J5)-1)*4,0) -> 0.7450559 | N8: =OFFSET(wft_table!K$7,(ROW(wft_table!K5)-1)*4,0) -> 1.4346532 | O8: 0.77247994 | P8: 0.77247994 | Q8: 1.4444191 | R8: 0.75966232 | S8: 0.75966232 | T8: 1.4375948 | U8: 0.7532669 | V8: 0.7532669 | W8: 1.4383296 | X8: 0.7582629 | Y8: 0.7582629 | Z8: 1.4395646 | AA8: 0.75319992 | AB8: 0.75319992 | AC8: 1.4369398 | AD8: 0.75492184 | AE8: 0.75492184 | AF8: 1.4374046 | AG8: 0.75191561 | AH8: 0.75191561 | AI8: 1.4361565 | AJ8: 0.75668546 | AK8: 0.75668546 | AL8: 1.4378281 | AM8: 0.76635438 | AN8: 0.76635438 | AO8: 1.4422996 | AP8: 0.75197917 | AQ8: 0.75197917 | AR8: 1.4408906 | AS8: 0.74378129 | AT8: 0.74378129 | AU8: 1.4366986 | AV8: 0.74865263 | AW8: 0.74865263 | AX8: 1.4375306 | AY8: 0.74953525 | AZ8: 0.74953525 | BA8: 1.4386869 | BB8: 0.75746057 | BC8: 0.75746057 | BD8: 1.4462153 | BE8: 0.74475882 | BF8: 0.74475882 | BG8: 1.4446815 | BH8: 0.75085899 | BI8: 0.75085899 | BJ8: 1.438264 | BK8: 0.75154119 | BL8: 0.75154119 | BM8: 1.4385424 | BN8: 0.75297427 | BO8: 0.75297427 | BP8: 1.4395486 | BQ8: 0.74875902 | BR8: 0.74875902 | BS8: 1.438072 | BT8: 0.73876643 | BU8: 0.73876643 | BV8: 1.4426937 | BW8: 0.74975485 | BX8: 0.74975485 | BY8: 1.4367377 | BZ8: 0.75058665 | CA8: 0.75058665 | CB8: 1.4383892 | CC8: 0.74778317 | CD8: 0.74778317 | CE8: 1.4365209 | CF8: 0.74963089 | CG8: 0.74963089 | CH8: 1.4405094 | CI8: 0.75258274 | CJ8: 0.75258274 | CK8: 1.4380334 | CL8: 0.74780803 | CM8: 0.74780803 | CN8: 1.4387325 | CO8: 0.74970527 | CP8: 0.74970527 | CQ8: 1.4387135 | CR8: 0.75320697 | CS8: 0.75320697 | CT8: 1.4407064 | CU8: 0.74939707 | CV8: 0.74939707 | CW8: 1.4396531 | CX8: 0.75174255 | CY8: 0.75174255 | CZ8: 1.4410043 | DA8: 0.75547034 | DB8: 0.75547034 | DC8: 1.4391603 | DD8: 0.75067862 | DE8: 0.75067862 | DF8: 1.4385298
A9: BH2 | B9: =OFFSET(wft_table!L$7,(ROW(wft_table!L6)-1)*4,0) -> 0.83980428 | C9: =OFFSET(wft_table!M$7,(ROW(wft_table!M6)-1)*4,0) -> 1.0858154 | D9: =OFFSET(wft_table!N$7,(ROW(wft_table!N6)-1)*4,0) -> 1.4313086 | F9: =OFFSET(wft_table!C$7,(ROW(wft_table!C6)-1)*4,0) -> 0.83593901 | G9: =OFFSET(wft_table!D$7,(ROW(wft_table!D6)-1)*4,0) -> 1.0905731 | H9: =OFFSET(wft_table!E$7,(ROW(wft_table!E6)-1)*4,0) -> 1.4378514 | I9: =OFFSET(wft_table!F$7,(ROW(wft_table!F6)-1)*4,0) -> 0.8383993 | J9: =OFFSET(wft_table!G$7,(ROW(wft_table!G6)-1)*4,0) -> 1.0872283 | K9: =OFFSET(wft_table!H$7,(ROW(wft_table!H6)-1)*4,0) -> 1.4323084 | L9: =OFFSET(wft_table!I$7,(ROW(wft_table!I6)-1)*4,0) -> 0.83882565 | M9: =OFFSET(wft_table!J$7,(ROW(wft_table!J6)-1)*4,0) -> 1.0855037 | N9: =OFFSET(wft_table!K$7,(ROW(wft_table!K6)-1)*4,0) -> 1.4313894 | O9: 0.87257331 | P9: 1.1208751 | Q9: 1.4474003 | R9: 0.85805283 | S9: 1.1003279 | T9: 1.4354672 | U9: 0.84424532 | V9: 1.089979 | W9: 1.4352489 | X9: 0.85069341 | Y9: 1.0958837 | Z9: 1.4402022 | AA9: 0.84489297 | AB9: 1.0901286 | AC9: 1.4332902 | AD9: 0.84737209 | AE9: 1.0920414 | AF9: 1.4347826 | AG9: 0.85344818 | AH9: 1.1044484 | AI9: 1.4394645 | AJ9: 0.84991897 | AK9: 1.0947161 | AL9: 1.4354598 | AM9: 0.86072235 | AN9: 1.0978932 | AO9: 1.4412858 | AP9: 0.8471151 | AQ9: 1.0975841 | AR9: 1.4443114 | AS9: 0.82663759 | AT9: 1.0769512 | AU9: 1.4315626 | AV9: 0.83771591 | AW9: 1.085949 | AX9: 1.4353007 | AY9: 0.83755741 | AZ9: 1.0869707 | BA9: 1.4309689 | BB9: 0.85203451 | BC9: 1.1048814 | BD9: 1.4521696 | BE9: 0.83117993 | BF9: 1.0856539 | BG9: 1.4427552 | BH9: 0.83992542 | BI9: 1.0862001 | BJ9: 1.4333384 | BK9: 0.84039948 | BL9: 1.0880124 | BM9: 1.4333495 | BN9: 0.84568457 | BO9: 1.0911962 | BP9: 1.4370349 | BQ9: 0.84101852 | BR9: 1.0889133 | BS9: 1.431978 | BT9: 0.83287134 | BU9: 1.0815834 | BV9: 1.4313288 | BW9: 0.84789837 | BX9: 1.0902305 | BY9: 1.435075 | BZ9: 0.84379859 | CA9: 1.0895058 | CB9: 1.4325823 | CC9: 0.84423274 | CD9: 1.0888175 | CE9: 1.4352304 | CF9: 0.84991897 | CG9: 1.0913214 | CH9: 1.438505 | CI9: 0.85402045 | CJ9: 1.0955661 | CK9: 1.4422435 | CL9: 0.83870426 | CM9: 1.0845393 | CN9: 1.4324118 | CO9: 0.83904611 | CP9: 1.0866144 | CQ9: 1.4325601 | CR9: 0.84754129 | CS9: 1.0917128 | CT9: 1.4370534 | CU9: 0.84245068 | CV9: 1.0897051 | CW9: 1.4331012 | CX9: 0.84633112 | CY9: 1.0935931 | CZ9: 1.4353969 | DA9: 0.85655376 | DB9: 1.0997194 | DC9: 1.4410869 | DD9: 0.84548988 | DE9: 1.0886792 | DF9: 1.4346086
A10: BH2F | B10: =OFFSET(wft_table!L$7,(ROW(wft_table!L7)-1)*4,0) -> 0.71030281 | C10: =OFFSET(wft_table!M$7,(ROW(wft_table!M7)-1)*4,0) -> 1.0424695 | D10: =OFFSET(wft_table!N$7,(ROW(wft_table!N7)-1)*4,0) -> 1.6173207 | F10: =OFFSET(wft_table!C$7,(ROW(wft_table!C7)-1)*4,0) -> 0.70462986 | G10: =OFFSET(wft_table!D$7,(ROW(wft_table!D7)-1)*4,0) -> 1.0430242 | H10: =OFFSET(wft_table!E$7,(ROW(wft_table!E7)-1)*4,0) -> 1.6194996 | I10: =OFFSET(wft_table!F$7,(ROW(wft_table!F7)-1)*4,0) -> 0.71151499 | J10: =OFFSET(wft_table!G$7,(ROW(wft_table!G7)-1)*4,0) -> 1.0438336 | K10: =OFFSET(wft_table!H$7,(ROW(wft_table!H7)-1)*4,0) -> 1.6180727 | L10: =OFFSET(wft_table!I$7,(ROW(wft_table!I7)-1)*4,0) -> 0.70877714 | M10: =OFFSET(wft_table!J$7,(ROW(wft_table!J7)-1)*4,0) -> 1.041721 | N10: =OFFSET(wft_table!K$7,(ROW(wft_table!K7)-1)*4,0) -> 1.6172764 | O10: 0.73159988 | P10: 1.056076 | Q10: 1.6248068 | R10: 0.72188754 | S10: 1.0469018 | T10: 1.6196385 | U10: 0.7133174 | V10: 1.0464445 | W10: 1.6194735 | X10: 0.71858751 | Y10: 1.050044 | Z10: 1.6217286 | AA10: 0.71476211 | AB10: 1.0453605 | AC10: 1.6187842 | AD10: 0.71618443 | AE10: 1.0463024 | AF10: 1.6193772 | AG10: 0.71148454 | AH10: 1.0436455 | AI10: 1.6186134 | AJ10: 0.71788232 | AK10: 1.0471903 | AL10: 1.6198321 | AM10: 0.72072151 | AN10: 1.0493291 | AO10: 1.6212545 | AP10: 0.71211451 | AQ10: 1.0503825 | AR10: 1.6212465 | AS10: 0.70502212 | AT10: 1.0435542 | AU10: 1.6175295 | AV10: 0.70968951 | AW10: 1.0455294 | AX10: 1.6184859 | AY10: 0.71143882 | AZ10: 1.0438592 | BA10: 1.6174539 | BB10: 0.7151813 | BC10: 1.05509 | BD10: 1.6235938 | BE10: 0.70754194 | BF10: 1.0511873 | BG10: 1.6214473 | BH10: 0.71165759 | BI10: 1.0443621 | BJ10: 1.6181887 | BK10: 0.71300465 | BL10: 1.045296 | BM10: 1.6185764 | BN10: 0.7142711 | BO10: 1.0464157 | BP10: 1.6200569 | BQ10: 0.71008553 | BR10: 1.0428928 | BS10: 1.6178738 | BT10: 0.70209297 | BU10: 1.0381971 | BV10: 1.6166039 | BW10: 0.71196768 | BX10: 1.0436099 | BY10: 1.6186659 | BZ10: 0.71259069 | CA10: 1.0433917 | CB10: 1.6182027 | CC10: 0.70950288 | CD10: 1.0441262 | CE10: 1.6182771 | CF10: 0.71398155 | CG10: 1.0461847 | CH10: 1.6207075 | CI10: 0.71364955 | CJ10: 1.0468996 | CK10: 1.6197556 | CL10: 0.70932275 | CM10: 1.0423535 | CN10: 1.617581 | CO10: 0.71145189 | CP10: 1.044084 | CQ10: 1.618115 | CR10: 0.71578205 | CS10: 1.0465156 | CT10: 1.6202595 | CU10: 0.71090958 | CV10: 1.0430175 | CW10: 1.6180471 | CX10: 0.73847794 | CY10: 1.065409 | CZ10: 1.6308994 | DA10: 0.73919806 | DB10: 1.0664966 | DC10: 1.6311311 | DD10: 0.71308611 | DE10: 1.0450315 | DF10: 1.6194391
A11: BH3 | B11: =OFFSET(wft_table!L$7,(ROW(wft_table!L8)-1)*4,0) -> 1.3443331 | C11: =OFFSET(wft_table!M$7,(ROW(wft_table!M8)-1)*4,0) -> 1.3443115 | D11: =OFFSET(wft_table!N$7,(ROW(wft_table!N8)-1)*4,0) -> 0.81380583 | F11: =OFFSET(wft_table!C$7,(ROW(wft_table!C8)-1)*4,0) -> 1.3505532 | G11: =OFFSET(wft_table!D$7,(ROW(wft_table!D8)-1)*4,0) -> 1.3505364 | H11: =OFFSET(wft_table!E$7,(ROW(wft_table!E8)-1)*4,0) -> 0.81298896 | I11: =OFFSET(wft_table!F$7,(ROW(wft_table!F8)-1)*4,0) -> 1.3453047 | J11: =OFFSET(wft_table!G$7,(ROW(wft_table!G8)-1)*4,0) -> 1.3452855 | K11: =OFFSET(wft_table!H$7,(ROW(wft_table!H8)-1)*4,0) -> 0.81353896 | L11: =OFFSET(wft_table!I$7,(ROW(wft_table!I8)-1)*4,0) -> 1.3443245 | M11: =OFFSET(wft_table!J$7,(ROW(wft_table!J8)-1)*4,0) -> 1.3442981 | N11: =OFFSET(wft_table!K$7,(ROW(wft_table!K8)-1)*4,0) -> 0.81302242 | O11: 1.3609008 | P11: 1.3608807 | Q11: 0.84338232 | R11: 1.3490351 | S11: 1.3490148 | T11: 0.82963951 | U11: 1.3488594 | V11: 1.3488391 | W11: 0.81659324 | X11: 1.3520319 | Y11: 1.3520116 | Z11: 0.82146674 | AA11: 1.3458555 | AB11: 1.3458352 | AC11: 0.81682082 | AD11: 1.3472497 | AE11: 1.3472293 | AF11: 0.81900808 | AG11: 1.348346 | AH11: 1.3483257 | AI11: 0.81779871 | AJ11: 1.3482357 | AK11: 1.3482189 | AL11: 0.82131965 | AM11: 1.3532549 | AN11: 1.3532381 | AO11: 0.83059671 | AP11: 1.3538556 | AQ11: 1.3538354 | AR11: 0.81576772 | AS11: 1.3433258 | AT11: 1.3433054 | AU11: 0.8037804 | AV11: 1.3479221 | AW11: 1.3478914 | AX11: 0.81189082 | AY11: 1.3443735 | AZ11: 1.3443359 | BA11: 0.81150727 | BB11: 1.3615733 | BC11: 1.3615532 | BD11: 0.82106502 | BE11: 1.3541954 | BF11: 1.3541752 | BG11: 0.80793781 | BH11: 1.3461559 | BI11: 1.3461562 | BJ11: 0.81421689 | BK11: 1.3462283 | BL11: 1.3462115 | BM11: 0.81278317 | BN11: 1.3492762 | BO11: 1.3492559 | BP11: 0.81815092 | BQ11: 1.345303 | BR11: 1.3452826 | BS11: 0.81369168 | BT11: 1.3444496 | BU11: 1.3444292 | BV11: 0.80978763 | BW11: 1.3471013 | BX11: 1.347081 | BY11: 0.81863922 | BZ11: 1.3456483 | CA11: 1.3456314 | CB11: 0.81707109 | CC11: 1.345707 | CD11: 1.3456867 | CE11: 0.81412558 | CF11: 1.3500061 | CG11: 1.3499823 | CH11: 0.82137057 | CI11: 1.3514578 | CJ11: 1.3514376 | CK11: 0.82013636 | CL11: 1.3453824 | CM11: 1.3453793 | CN11: 0.81376591 | CO11: 1.3455517 | CP11: 1.3455347 | CQ11: 0.81210828 | CR11: 1.3499751 | CS11: 1.3499548 | CT11: 0.8211782 | CU11: 1.3458797 | CV11: 1.3458628 | CW11: 0.81538599 | CX11: 1.3685889 | CY11: 1.3685689 | CZ11: 0.84519855 | DA11: 1.3523034 | DB11: 1.3522831 | DC11: 0.82443112 | DD11: 1.3480875 | DE11: 1.3480706 | DF11: 0.81932007
A12: BO | B12: =OFFSET(wft_table!L$7,(ROW(wft_table!L9)-1)*4,0) -> 0.77081205 | C12: =OFFSET(wft_table!M$7,(ROW(wft_table!M9)-1)*4,0) -> 0.77081205 | D12: =OFFSET(wft_table!N$7,(ROW(wft_table!N9)-1)*4,0) -> 1.3452128 | F12: =OFFSET(wft_table!C$7,(ROW(wft_table!C9)-1)*4,0) -> 0.76742958 | G12: =OFFSET(wft_table!D$7,(ROW(wft_table!D9)-1)*4,0) -> 0.76742958 | H12: =OFFSET(wft_table!E$7,(ROW(wft_table!E9)-1)*4,0) -> 1.341349 | I12: =OFFSET(wft_table!F$7,(ROW(wft_table!F9)-1)*4,0) -> 0.77130955 | J12: =OFFSET(wft_table!G$7,(ROW(wft_table!G9)-1)*4,0) -> 0.77130955 | K12: =OFFSET(wft_table!H$7,(ROW(wft_table!H9)-1)*4,0) -> 1.3457156 | L12: =OFFSET(wft_table!I$7,(ROW(wft_table!I9)-1)*4,0) -> 0.76969276 | M12: =OFFSET(wft_table!J$7,(ROW(wft_table!J9)-1)*4,0) -> 0.76969276 | N12: =OFFSET(wft_table!K$7,(ROW(wft_table!K9)-1)*4,0) -> 1.3435791 | O12: 0.78698471 | P12: 0.78698471 | Q12: 1.3564866 | R12: 0.77789565 | S12: 0.77789565 | T12: 1.3490207 | U12: 0.77286166 | V12: 0.77286166 | W12: 1.3478662 | X12: 0.77766403 | Y12: 0.77766403 | Z12: 1.3495621 | AA12: 0.77295415 | AB12: 0.77295415 | AC12: 1.3466995 | AD12: 0.77433652 | AE12: 0.77433652 | AF12: 1.3474993 | AG12: 0.77205836 | AH12: 0.77205836 | AI12: 1.3457379 | AJ12: 0.7758528 | AK12: 0.7758528 | AL12: 1.3484466 | AM12: 0.77639441 | AN12: 0.77639441 | AO12: 1.3528709 | AP12: 0.77424788 | AQ12: 0.77424788 | AR12: 1.3459615 | AS12: 0.76392275 | AT12: 0.76392275 | AU12: 1.3436147 | AV12: 0.76836055 | AW12: 0.76836055 | AX12: 1.3433437 | AY12: 0.77021167 | AZ12: 0.77021167 | BA12: 1.3455 | BB12: 0.77783684 | BC12: 0.77783684 | BD12: 1.3475969 | BE12: 0.76673248 | BF12: 0.76673248 | BG12: 1.3447858 | BH12: 0.77079434 | BI12: 0.77079434 | BJ12: 1.343494 | BK12: 0.77275805 | BL12: 0.77275805 | BM12: 1.3470988 | BN12: 0.77371587 | BO12: 0.77371587 | BP12: 1.3459127 | BQ12: 0.76979203 | BR12: 0.76979203 | BS12: 1.3447558 | BT12: 0.76316625 | BU12: 0.76316625 | BV12: 1.3363395 | BW12: 0.77259522 | BX12: 0.77259522 | BY12: 1.3422314 | BZ12: 0.77141363 | CA12: 0.77141363 | CB12: 1.3442355 | CC12: 0.76851684 | CD12: 0.76851684 | CE12: 1.3444831 | CF12: 0.77440668 | CG12: 0.77440668 | CH12: 1.3440784 | CI12: 0.77451376 | CJ12: 0.77451376 | CK12: 1.3423694 | CL12: 0.76901899 | CM12: 0.76901899 | CN12: 1.3411026 | CO12: 0.77136173 | CP12: 0.77136173 | CQ12: 1.3455392 | CR12: 0.77432913 | CS12: 0.77432913 | CT12: 1.3456458 | CU12: 0.77053089 | CV12: 0.77053089 | CW12: 1.3434275 | CX12: 0.7739967 | CY12: 0.7739967 | CZ12: 1.3459736 | DA12: 0.77820438 | DB12: 0.77820438 | DC12: 1.3455695 | DD12: 0.77227685 | DE12: 0.77227685 | DF12: 1.3436768
