Workbook
Name quadrupoles: quadrupoles_dft!$A$2:$G$67
Name totalenergies: energies!$A$2:$H$67

Sheet q,d_sum
B1: X | C1: Y | D1: Z | E1: XX | F1: YY | G1: ZZ | S1: Ang to bohr | U1: Ang2 to bohr2
A2: C2H_ccsd | B2: =K2*$S$2 -> 0 | C2: =L2*$S$2 -> 0 | D2: =M2*$S$2 -> -11.815537 | E2: =N2*$U$2 -> 0 | F2: =O2*$U$2 -> 0 | G2: =P2*$U$2 -> 35.61936 | K2: 0 | L2: 0 | M2: -6.2525 | N2: 0 | O2: 0 | P2: 9.9743957 | S2: 1.88973 | U2: =S2^2 -> 3.5710795
A3: C2H_pbe0 | B3: =K3*$S$2 -> 0 | C3: =L3*$S$2 -> 0 | D3: =M3*$S$2 -> -11.815537 | E3: =N3*$U$2 -> 0 | F3: =O3*$U$2 -> 0 | G3: =P3*$U$2 -> 35.61936 | K3: 0 | L3: 0 | M3: -6.2525 | N3: 0 | O3: 0 | P3: 9.9743957
A4: C2H_pbe | B4: =K4*$S$2 -> 0 | C4: =L4*$S$2 -> 0 | D4: =M4*$S$2 -> -11.815537 | E4: =N4*$U$2 -> 0 | F4: =O4*$U$2 -> 0 | G4: =P4*$U$2 -> 35.61936 | K4: 0 | L4: 0 | M4: -6.2525 | N4: 0 | O4: 0 | P4: 9.9743957
A5: C2H_scan0 | B5: =K5*$S$2 -> 0 | C5: =L5*$S$2 -> 0 | D5: =M5*$S$2 -> -11.815537 | E5: =N5*$U$2 -> 0 | F5: =O5*$U$2 -> 0 | G5: =P5*$U$2 -> 35.61936 | K5: 0 | L5: 0 | M5: -6.2525 | N5: 0 | O5: 0 | P5: 9.9743957
A6: C2H_scan | B6: =K6*$S$2 -> 0 | C6: =L6*$S$2 -> 0 | D6: =M6*$S$2 -> -11.815537 | E6: =N6*$U$2 -> 0 | F6: =O6*$U$2 -> 0 | G6: =P6*$U$2 -> 35.61936 | K6: 0 | L6: 0 | M6: -6.2525 | N6: 0 | O6: 0 | P6: 9.9743957
A7: C2H_spw92 | B7: =K7*$S$2 -> 0 | C7: =L7*$S$2 -> 0 | D7: =M7*$S$2 -> -11.815537 | E7: =N7*$U$2 -> 0 | F7: =O7*$U$2 -> 0 | G7: =P7*$U$2 -> 35.61936 | K7: 0 | L7: 0 | M7: -6.2525 | N7: 0 | O7: 0 | P7: 9.9743957
A8: CH4_ccsd | B8: =K8*$S$2 -> 0 | C8: =L8*$S$2 -> 0 | D8: =M8*$S$2 -> 0 | E8: =N8*$U$2 -> 5.6263323 | F8: =O8*$U$2 -> 5.6263323 | G8: =P8*$U$2 -> 5.6263323 | K8: 0 | L8: 0 | M8: 0 | N8: 1.575527 | O8: 1.575527 | P8: 1.575527
A9: CH4_pbe0 | B9: =K9*$S$2 -> 0 | C9: =L9*$S$2 -> 0 | D9: =M9*$S$2 -> 0 | E9: =N9*$U$2 -> 5.6263323 | F9: =O9*$U$2 -> 5.6263323 | G9: =P9*$U$2 -> 5.6263323 | K9: 0 | L9: 0 | M9: 0 | N9: 1.575527 | O9: 1.575527 | P9: 1.575527
A10: CH4_pbe | B10: =K10*$S$2 -> 0 | C10: =L10*$S$2 -> 0 | D10: =M10*$S$2 -> 0 | E10: =N10*$U$2 -> 5.6263323 | F10: =O10*$U$2 -> 5.6263323 | G10: =P10*$U$2 -> 5.6263323 | K10: 0 | L10: 0 | M10: 0 | N10: 1.575527 | O10: 1.575527 | P10: 1.575527
A11: CH4_scan0 | B11: =K11*$S$2 -> 0 | C11: =L11*$S$2 -> 0 | D11: =M11*$S$2 -> 0 | E11: =N11*$U$2 -> 5.6263323 | F11: =O11*$U$2 -> 5.6263323 | G11: =P11*$U$2 -> 5.6263323 | K11: 0 | L11: 0 | M11: 0 | N11: 1.575527 | O11: 1.575527 | P11: 1.575527
A12: CH4_scan | B12: =K12*$S$2 -> 0 | C12: =L12*$S$2 -> 0 | D12: =M12*$S$2 -> 0 | E12: =N12*$U$2 -> 5.6263323 | F12: =O12*$U$2 -> 5.6263323 | G12: =P12*$U$2 -> 5.6263323 | K12: 0 | L12: 0 | M12: 0 | N12: 1.575527 | O12: 1.575527 | P12: 1.575527
A13: CH4_spw92 | B13: =K13*$S$2 -> 0 | C13: =L13*$S$2 -> 0 | D13: =M13*$S$2 -> 0 | E13: =N13*$U$2 -> 5.6263323 | F13: =O13*$U$2 -> 5.6263323 | G13: =P13*$U$2 -> 5.6263323 | K13: 0 | L13: 0 | M13: 0 | N13: 1.575527 | O13: 1.575527 | P13: 1.575527
A14: CN_ccsd | B14: =K14*$S$2 -> 0 | C14: =L14*$S$2 -> 0 | D14: =M14*$S$2 -> 13.286314 | E14: =N14*$U$2 -> 0 | F14: =O14*$U$2 -> 0 | G14: =P14*$U$2 -> 29.421022 | K14: 0 | L14: 0 | M14: 7.0308 | N14: 0 | O14: 0 | P14: 8.2386914
... A67: OH_spw92 | B67: =K67*$S$2 -> 0 | C67: =L67*$S$2 -> 0 | D67: =M67*$S$2 -> 14.659769 | E67: =N67*$U$2 -> 0 | F67: =O67*$U$2 -> 0 | G67: =P67*$U$2 -> 26.863605 | K67: 0 | L67: 0 | M67: 7.7576 | N67: 0 | O67: 0 | P67: 7.5225447

Sheet dipoles_dft
A1: molecule_method | B1: X | C1: Y | D1: Z | E1: total | F1: Column1 | G1: electronic part: | H1: X | I1: Y | J1: Z | O1: debye to e
A2: C2H_ccsd | B2: 0 | C2: 0 | D2: -0.767 | E2: 0.767 | H2: =dipoles[[#This Row],[X]]*$O$2-'q,d_sum'!B2 -> 0 | I2: =dipoles[[#This Row],[Y]]*$O$2-'q,d_sum'!C2 -> 0 | J2: =dipoles[[#This Row],[Z]]*$O$2-'q,d_sum'!D2 -> 11.513776 | O2: 0.3934303
A3: C2H_pbe0 | B3: 0.0000 | C3: -0.0000 | D3: 0.7553 | E3: 0.7553 | H3: =dipoles[[#This Row],[X]]*$O$2-'q,d_sum'!B3 -> 0 | I3: =dipoles[[#This Row],[Y]]*$O$2-'q,d_sum'!C3 -> 0 | J3: =dipoles[[#This Row],[Z]]*$O$2-'q,d_sum'!D3 -> 12.112695
A4: C2H_pbe | B4: 0.0000 | C4: -0.0000 | D4: 0.7654 | E4: 0.7654 | H4: =dipoles[[#This Row],[X]]*$O$2-'q,d_sum'!B4 -> 0 | I4: =dipoles[[#This Row],[Y]]*$O$2-'q,d_sum'!C4 -> 0 | J4: =dipoles[[#This Row],[Z]]*$O$2-'q,d_sum'!D4 -> 12.116668
A5: C2H_scan0 | B5: -0.0000 | C5: -0.0000 | D5: 0.7451 | E5: 0.7451 | H5: =dipoles[[#This Row],[X]]*$O$2-'q,d_sum'!B5 -> 0 | I5: =dipoles[[#This Row],[Y]]*$O$2-'q,d_sum'!C5 -> 0 | J5: =dipoles[[#This Row],[Z]]*$O$2-'q,d_sum'!D5 -> 12.108682
A6: C2H_scan | B6: 0.0000 | C6: 0.0000 | D6: 0.7502 | E6: 0.7502 | H6: =dipoles[[#This Row],[X]]*$O$2-'q,d_sum'!B6 -> 0 | I6: =dipoles[[#This Row],[Y]]*$O$2-'q,d_sum'!C6 -> 0 | J6: =dipoles[[#This Row],[Z]]*$O$2-'q,d_sum'!D6 -> 12.110688
A7: C2H_spw92 | B7: 0.0000 | C7: 0.0000 | D7: 0.7654 | E7: 0.7654 | H7: =dipoles[[#This Row],[X]]*$O$2-'q,d_sum'!B7 -> 0 | I7: =dipoles[[#This Row],[Y]]*$O$2-'q,d_sum'!C7 -> 0 | J7: =dipoles[[#This Row],[Z]]*$O$2-'q,d_sum'!D7 -> 12.116668
A8: CH4_ccsd | B8: 0 | C8: 0 | D8: 0 | E8: 0 | H8: =dipoles[[#This Row],[X]]*$O$2-'q,d_sum'!B8 -> 0 | I8: =dipoles[[#This Row],[Y]]*$O$2-'q,d_sum'!C8 -> 0 | J8: =dipoles[[#This Row],[Z]]*$O$2-'q,d_sum'!D8 -> 0
A9: CH4_pbe0 | B9: -0.0000 | C9: -0.0000 | D9: -0.0000 | E9: 0.0000 | H9: =dipoles[[#This Row],[X]]*$O$2-'q,d_sum'!B9 -> 0 | I9: =dipoles[[#This Row],[Y]]*$O$2-'q,d_sum'!C9 -> 0 | J9: =dipoles[[#This Row],[Z]]*$O$2-'q,d_sum'!D9 -> 0
A10: CH4_pbe | B10: -0.0000 | C10: -0.0000 | D10: 0.0000 | E10: 0.0000 | H10: =dipoles[[#This Row],[X]]*$O$2-'q,d_sum'!B10 -> 0 | I10: =dipoles[[#This Row],[Y]]*$O$2-'q,d_sum'!C10 -> 0 | J10: =dipoles[[#This Row],[Z]]*$O$2-'q,d_sum'!D10 -> 0
A11: CH4_scan0 | B11: -0.0000 | C11: 0.0000 | D11: -0.0000 | E11: 0.0000 | H11: =dipoles[[#This Row],[X]]*$O$2-'q,d_sum'!B11 -> 0 | I11: =dipoles[[#This Row],[Y]]*$O$2-'q,d_sum'!C11 -> 0 | J11: =dipoles[[#This Row],[Z]]*$O$2-'q,d_sum'!D11 -> 0
A12: CH4_scan | B12: -0.0000 | C12: -0.0000 | D12: -0.0000 | E12: 0.0000 | H12: =dipoles[[#This Row],[X]]*$O$2-'q,d_sum'!B12 -> 0 | I12: =dipoles[[#This Row],[Y]]*$O$2-'q,d_sum'!C12 -> 0 | J12: =dipoles[[#This Row],[Z]]*$O$2-'q,d_sum'!D12 -> 0
A13: CH4_spw92 | B13: 0.0000 | C13: -0.0000 | D13: -0.0000 | E13: 0.0000 | H13: =dipoles[[#This Row],[X]]*$O$2-'q,d_sum'!B13 -> 0 | I13: =dipoles[[#This Row],[Y]]*$O$2-'q,d_sum'!C13 -> 0 | J13: =dipoles[[#This Row],[Z]]*$O$2-'q,d_sum'!D13 -> 0
A14: CN_ccsd | B14: 0 | C14: 0 | D14: -1.566 | E14: 1.566 | H14: =dipoles[[#This Row],[X]]*$O$2-'q,d_sum'!B14 -> 0 | I14: =dipoles[[#This Row],[Y]]*$O$2-'q,d_sum'!C14 -> 0 | J14: =dipoles[[#This Row],[Z]]*$O$2-'q,d_sum'!D14 -> -13.902426
A15: CN_pbe0 | B15: -0.0000 | C15: -0.0000 | D15: 1.4805 | E15: 1.4805 | H15: =dipoles[[#This Row],[X]]*$O$2-'q,d_sum'!B15 -> 0 | I15: =dipoles[[#This Row],[Y]]*$O$2-'q,d_sum'!C15 -> 0 | J15: =dipoles[[#This Row],[Z]]*$O$2-'q,d_sum'!D15 -> -12.70384
A16: CN_pbe | B16: 0.0000 | C16: -0.0000 | D16: 1.1524 | E16: 1.1524 | H16: =dipoles[[#This Row],[X]]*$O$2-'q,d_sum'!B16 -> 0 | I16: =dipoles[[#This Row],[Y]]*$O$2-'q,d_sum'!C16 -> 0 | J16: =dipoles[[#This Row],[Z]]*$O$2-'q,d_sum'!D16 -> -12.832925
A17: CN_scan0 | B17: -0.0000 | C17: 0.0000 | D17: 1.7024 | E17: 1.7024 | H17: =dipoles[[#This Row],[X]]*$O$2-'q,d_sum'!B17 -> 0 | I17: =dipoles[[#This Row],[Y]]*$O$2-'q,d_sum'!C17 -> 0 | J17: =dipoles[[#This Row],[Z]]*$O$2-'q,d_sum'!D17 -> -12.616538
A18: CN_scan | B18: 0.0000 | C18: -0.0000 | D18: 1.4404 | E18: 1.4404 | H18: =dipoles[[#This Row],[X]]*$O$2-'q,d_sum'!B18 -> 0 | I18: =dipoles[[#This Row],[Y]]*$O$2-'q,d_sum'!C18 -> 0 | J18: =dipoles[[#This Row],[Z]]*$O$2-'q,d_sum'!D18 -> -12.719617
A19: CN_spw92 | B19: 0.0000 | C19: -0.0000 | D19: 1.1524 | E19: 1.1524 | H19: =dipoles[[#This Row],[X]]*$O$2-'q,d_sum'!B19 -> 0 | I19: =dipoles[[#This Row],[Y]]*$O$2-'q,d_sum'!C19 -> 0 | J19: =dipoles[[#This Row],[Z]]*$O$2-'q,d_sum'!D19 -> -12.832925
A20: CO_ccsd | B20: 0 | C20: 0 | D20: 0.068 | E20: 0.068 | H20: =dipoles[[#This Row],[X]]*$O$2-'q,d_sum'!B20 -> 0 | I20: =dipoles[[#This Row],[Y]]*$O$2-'q,d_sum'!C20 -> 0 | J20: =dipoles[[#This Row],[Z]]*$O$2-'q,d_sum'!D20 -> 0.02675326
A21: CO_pbe0 | B21: 0.0000 | C21: -0.0000 | D21: 0.1018 | E21: 0.1018 | H21: =dipoles[[#This Row],[X]]*$O$2-'q,d_sum'!B21 -> 0 | I21: =dipoles[[#This Row],[Y]]*$O$2-'q,d_sum'!C21 -> 0 | J21: =dipoles[[#This Row],[Z]]*$O$2-'q,d_sum'!D21 -> 0.040051205
A22: CO_pbe | B22: -0.0000 | C22: 0.0000 | D22: 0.2239 | E22: 0.2239 | H22: =dipoles[[#This Row],[X]]*$O$2-'q,d_sum'!B22 -> 0 | I22: =dipoles[[#This Row],[Y]]*$O$2-'q,d_sum'!C22 -> 0 | J22: =dipoles[[#This Row],[Z]]*$O$2-'q,d_sum'!D22 -> 0.088089044
A23: CO_scan0 | B23: 0.0000 | C23: 0.0000 | D23: 0.0322 | E23: 0.0322 | H23: =dipoles[[#This Row],[X]]*$O$2-'q,d_sum'!B23 -> 0 | I23: =dipoles[[#This Row],[Y]]*$O$2-'q,d_sum'!C23 -> 0 | J23: =dipoles[[#This Row],[Z]]*$O$2-'q,d_sum'!D23 -> 0.012668456
A24: CO_scan | B24: -0.0000 | C24: -0.0000 | D24: 0.1318 | E24: 0.1318 | H24: =dipoles[[#This Row],[X]]*$O$2-'q,d_sum'!B24 -> 0 | I24: =dipoles[[#This Row],[Y]]*$O$2-'q,d_sum'!C24 -> 0 | J24: =dipoles[[#This Row],[Z]]*$O$2-'q,d_sum'!D24 -> 0.051854114
A25: CO_spw92 | B25: -0.0000 | C25: 0.0000 | D25: 0.2290 | E25: 0.2290 | H25: =dipoles[[#This Row],[X]]*$O$2-'q,d_sum'!B25 -> 0 | I25: =dipoles[[#This Row],[Y]]*$O$2-'q,d_sum'!C25 -> 0 | J25: =dipoles[[#This Row],[Z]]*$O$2-'q,d_sum'!D25 -> 0.090095539
A26: CO2_ccsd | B26: 0 | C26: 0 | D26: 0 | E26: 0 | H26: =dipoles[[#This Row],[X]]*$O$2-'q,d_sum'!B26 -> 0 | I26: =dipoles[[#This Row],[Y]]*$O$2-'q,d_sum'!C26 -> 0 | J26: =dipoles[[#This Row],[Z]]*$O$2-'q,d_sum'!D26 -> -17.055947
A27: CO2_pbe0 | B27: -0.0000 | C27: -0.0000 | D27: 0.0000 | E27: 0.0000 | H27: =dipoles[[#This Row],[X]]*$O$2-'q,d_sum'!B27 -> 0 | I27: =dipoles[[#This Row],[Y]]*$O$2-'q,d_sum'!C27 -> 0 | J27: =dipoles[[#This Row],[Z]]*$O$2-'q,d_sum'!D27 -> -17.055947
A28: CO2_pbe | B28: 0.0000 | C28: 0.0000 | D28: -0.0000 | E28: 0.0000 | H28: =dipoles[[#This Row],[X]]*$O$2-'q,d_sum'!B28 -> 0 | I28: =dipoles[[#This Row],[Y]]*$O$2-'q,d_sum'!C28 -> 0 | J28: =dipoles[[#This Row],[Z]]*$O$2-'q,d_sum'!D28 -> -17.055947
A29: CO2_scan0 | B29: 0.0000 | C29: 0.0000 | D29: 0.0000 | E29: 0.0000 | H29: =dipoles[[#This Row],[X]]*$O$2-'q,d_sum'!B29 -> 0 | I29: =dipoles[[#This Row],[Y]]*$O$2-'q,d_sum'!C29 -> 0 | J29: =dipoles[[#This Row],[Z]]*$O$2-'q,d_sum'!D29 -> -17.055947
A30: CO2_scan | B30: -0.0000 | C30: -0.0000 | D30: 0.0000 | E30: 0.0000 | H30: =dipoles[[#This Row],[X]]*$O$2-'q,d_sum'!B30 -> 0 | I30: =dipoles[[#This Row],[Y]]*$O$2-'q,d_sum'!C30 -> 0 | J30: =dipoles[[#This Row],[Z]]*$O$2-'q,d_sum'!D30 -> -17.055947
A31: CO2_spw92 | B31: 0.0000 | C31: -0.0000 | D31: 0.0000 | E31: 0.0000 | H31: =dipoles[[#This Row],[X]]*$O$2-'q,d_sum'!B31 -> 0 | I31: =dipoles[[#This Row],[Y]]*$O$2-'q,d_sum'!C31 -> 0 | J31: =dipoles[[#This Row],[Z]]*$O$2-'q,d_sum'!D31 -> -17.055947
A32: H2O_ccsd | B32: 0 | C32: 0 | D32: -1.863 | E32: 1.863 | H32: =dipoles[[#This Row],[X]]*$O$2-'q,d_sum'!B32 -> 0 | I32: =dipoles[[#This Row],[Y]]*$O$2-'q,d_sum'!C32 -> 0 | J32: =dipoles[[#This Row],[Z]]*$O$2-'q,d_sum'!D32 -> -0.73296065
A33: H2O_pbe0 | B33: 0.0000 | C33: -0.0000 | D33: -1.8579 | E33: 1.8579 | H33: =dipoles[[#This Row],[X]]*$O$2-'q,d_sum'!B33 -> 0 | I33: =dipoles[[#This Row],[Y]]*$O$2-'q,d_sum'!C33 -> 0 | J33: =dipoles[[#This Row],[Z]]*$O$2-'q,d_sum'!D33 -> -0.73095415
A34: H2O_pbe | B34: -0.0000 | C34: -0.0000 | D34: -1.7949 | E34: 1.7949 | H34: =dipoles[[#This Row],[X]]*$O$2-'q,d_sum'!B34 -> 0 | I34: =dipoles[[#This Row],[Y]]*$O$2-'q,d_sum'!C34 -> 0 | J34: =dipoles[[#This Row],[Z]]*$O$2-'q,d_sum'!D34 -> -0.70616805
A35: H2O_scan0 | B35: -0.0000 | C35: 0.0000 | D35: -1.8853 | E35: 1.8853 | H35: =dipoles[[#This Row],[X]]*$O$2-'q,d_sum'!B35 -> 0 | I35: =dipoles[[#This Row],[Y]]*$O$2-'q,d_sum'!C35 -> 0 | J35: =dipoles[[#This Row],[Z]]*$O$2-'q,d_sum'!D35 -> -0.74173414
A36: H2O_scan | B36: -0.0000 | C36: -0.0000 | D36: -1.8396 | E36: 1.8396 | H36: =dipoles[[#This Row],[X]]*$O$2-'q,d_sum'!B36 -> 0 | I36: =dipoles[[#This Row],[Y]]*$O$2-'q,d_sum'!C36 -> 0 | J36: =dipoles[[#This Row],[Z]]*$O$2-'q,d_sum'!D36 -> -0.72375438
A37: H2O_spw92 | B37: -0.0000 | C37: 0.0000 | D37: -1.7949 | E37: 1.7949 | H37: =dipoles[[#This Row],[X]]*$O$2-'q,d_sum'!B37 -> 0 | I37: =dipoles[[#This Row],[Y]]*$O$2-'q,d_sum'!C37 -> 0 | J37: =dipoles[[#This Row],[Z]]*$O$2-'q,d_sum'!D37 -> -0.70616805
A38: HCO_ccsd | H38: =dipoles[[#This Row],[X]]*$O$2-'q,d_sum'!B38 -> #VALUE! | I38: =dipoles[[#This Row],[Y]]*$O$2-'q,d_sum'!C38 -> #VALUE! | J38: =dipoles[[#This Row],[Z]]*$O$2-'q,d_sum'!D38 -> #VALUE!
A39: HCO_pbe0 | B39: 1.5806 | C39: -0.6828 | D39: 0.0000 | E39: 1.7218 | H39: =dipoles[[#This Row],[X]]*$O$2-'q,d_sum'!B39 -> 7.4989613 | I39: =dipoles[[#This Row],[Y]]*$O$2-'q,d_sum'!C39 -> -16.032006 | J39: =dipoles[[#This Row],[Z]]*$O$2-'q,d_sum'!D39 -> 0
A40: HCO_pbe | B40: 1.4661 | C40: -0.5192 | D40: -0.0000 | E40: 1.5553 | H40: =dipoles[[#This Row],[X]]*$O$2-'q,d_sum'!B40 -> 7.4539136 | I40: =dipoles[[#This Row],[Y]]*$O$2-'q,d_sum'!C40 -> -15.967641 | J40: =dipoles[[#This Row],[Z]]*$O$2-'q,d_sum'!D40 -> 0
...

Sheet quadrupoles_dft
B1: XX | C1: XY | D1: YY | E1: XZ | F1: YZ | G1: ZZ | I1: electronic part: | J1: XX | K1: YY | L1: ZZ | N1: ea02 to debye-ang
A2: C2H_ccsd | B2: =(energies!C2-energies!D2)/(2*$N$5)*$N$2 -> -12.967347 | C2: 0 | D2: =(energies!E2-energies!F2)/(2*$N$5)*$N$2 -> -12.967347 | E2: 0 | F2: 0 | G2: =(energies!G2-energies!H2)/(2*$N$5)*$N$2 -> -8.9708897 | J2: =B2*$N$2-'q,d_sum'!E2 -> -17.441518 | K2: =D2*$N$2-'q,d_sum'!F2 -> -17.441518 | L2: =G2*$N$2-'q,d_sum'!G2 -> -47.685509 | N2: 1.3450337
A3: C2H_pbe0 | B3: =(energies!C3-energies!D3)/(2*$N$5)*$N$2 -> -12.887028 | C3: 0 | D3: -12.887 | E3: 0 | F3: 0 | G3: -8.9179 | J3: =B3*$N$2-'q,d_sum'!E3 -> -17.333486 | K3: =D3*$N$2-'q,d_sum'!F3 -> -17.333449 | L3: =G3*$N$2-'q,d_sum'!G3 -> -47.614236
A4: C2H_pbe | B4: =(energies!C4-energies!D4)/(2*$N$5)*$N$2 -> -12.900974 | C4: 0 | D4: -12.901 | E4: 0 | F4: 0 | G4: -9.1582 | J4: =B4*$N$2-'q,d_sum'!E4 -> -17.352244 | K4: =D4*$N$2-'q,d_sum'!F4 -> -17.352279 | L4: =G4*$N$2-'q,d_sum'!G4 -> -47.937447 | N4: step size
A5: C2H_scan0 | B5: =(energies!C5-energies!D5)/(2*$N$5)*$N$2 -> -12.866433 | C5: 0 | D5: -12.8664 | E5: 0 | F5: 0 | G5: -8.7862 | J5: =B5*$N$2-'q,d_sum'!E5 -> -17.305785 | K5: =D5*$N$2-'q,d_sum'!F5 -> -17.305741 | L5: =G5*$N$2-'q,d_sum'!G5 -> -47.437095 | N5: 0.0001
A6: C2H_scan | B6: =(energies!C6-energies!D6)/(2*$N$5)*$N$2 -> -12.830029 | C6: 0 | D6: -12.83 | E6: 0 | F6: 0 | G6: -8.8822 | J6: =B6*$N$2-'q,d_sum'!E6 -> -17.256821 | K6: =D6*$N$2-'q,d_sum'!F6 -> -17.256782 | L6: =G6*$N$2-'q,d_sum'!G6 -> -47.566218
A7: C2H_spw92 | B7: =(energies!C7-energies!D7)/(2*$N$5)*$N$2 -> -12.900974 | C7: 0 | D7: -12.901 | E7: 0 | F7: 0 | G7: -9.1582 | J7: =B7*$N$2-'q,d_sum'!E7 -> -17.352244 | K7: =D7*$N$2-'q,d_sum'!F7 -> -17.352279 | L7: =G7*$N$2-'q,d_sum'!G7 -> -47.937447
A8: CH4_ccsd | B8: =(energies!C8-energies!D8)/(2*$N$5)*$N$2 -> -8.4109421 | C8: 0 | D8: =(energies!E8-energies!F8)/(2*$N$5)*$N$2 -> -8.4109421 | E8: 0 | F8: 0 | G8: =(energies!G8-energies!H8)/(2*$N$5)*$N$2 -> -8.4109421 | J8: =B8*$N$2-'q,d_sum'!E8 -> -16.939333 | K8: =D8*$N$2-'q,d_sum'!F8 -> -16.939333 | L8: =G8*$N$2-'q,d_sum'!G8 -> -16.939333
A9: CH4_pbe0 | B9: -8.3942 | C9: 0 | D9: -8.3942 | E9: 0 | F9: 0 | G9: -8.3942 | J9: =B9*$N$2-'q,d_sum'!E9 -> -16.916814 | K9: =D9*$N$2-'q,d_sum'!F9 -> -16.916814 | L9: =G9*$N$2-'q,d_sum'!G9 -> -16.916814
A10: CH4_pbe | B10: -8.4939 | C10: 0 | D10: -8.4939 | E10: 0 | F10: 0 | G10: -8.4939 | J10: =B10*$N$2-'q,d_sum'!E10 -> -17.050914 | K10: =D10*$N$2-'q,d_sum'!F10 -> -17.050914 | L10: =G10*$N$2-'q,d_sum'!G10 -> -17.050914
A11: CH4_scan0 | B11: -8.347 | C11: 0 | D11: -8.347 | E11: 0 | F11: 0 | G11: -8.347 | J11: =B11*$N$2-'q,d_sum'!E11 -> -16.853328 | K11: =D11*$N$2-'q,d_sum'!F11 -> -16.853328 | L11: =G11*$N$2-'q,d_sum'!G11 -> -16.853328
A12: CH4_scan | B12: -8.3783 | C12: 0 | D12: -8.3783 | E12: 0 | F12: 0 | G12: -8.3783 | J12: =B12*$N$2-'q,d_sum'!E12 -> -16.895428 | K12: =D12*$N$2-'q,d_sum'!F12 -> -16.895428 | L12: =G12*$N$2-'q,d_sum'!G12 -> -16.895428
A13: CH4_spw92 | B13: -8.4939 | C13: 0 | D13: -8.4939 | E13: 0 | F13: 0 | G13: -8.4939 | J13: =B13*$N$2-'q,d_sum'!E13 -> -17.050914 | K13: =D13*$N$2-'q,d_sum'!F13 -> -17.050914 | L13: =G13*$N$2-'q,d_sum'!G13 -> -17.050914
A14: CN_ccsd | B14: =(energies!C14-energies!D14)/(2*$N$5)*$N$2 -> -11.043129 | C14: 0 | D14: =(energies!E14-energies!F14)/(2*$N$5)*$N$2 -> -11.043129 | E14: 0 | F14: 0 | G14: =(energies!G14-energies!H14)/(2*$N$5)*$N$2 -> -8.0484333 | J14: =B14*$N$2-'q,d_sum'!E14 -> -14.85338 | K14: =D14*$N$2-'q,d_sum'!F14 -> -14.85338 | L14: =G14*$N$2-'q,d_sum'!G14 -> -40.246436
A15: CN_pbe0 | B15: -11.0323 | C15: 0 | D15: -11.0323 | E15: 0 | F15: 0 | G15: -8.7607 | J15: =B15*$N$2-'q,d_sum'!E15 -> -14.838815 | K15: =D15*$N$2-'q,d_sum'!F15 -> -14.838815 | L15: =G15*$N$2-'q,d_sum'!G15 -> -41.204458
A16: CN_pbe | B16: -11.0544 | C16: 0 | D16: -11.0544 | E16: 0 | F16: 0 | G16: -9.3233 | J16: =B16*$N$2-'q,d_sum'!E16 -> -14.86854 | K16: =D16*$N$2-'q,d_sum'!F16 -> -14.86854 | L16: =G16*$N$2-'q,d_sum'!G16 -> -41.961174
A17: CN_scan0 | B17: -10.9977 | C17: 0 | D17: -10.9977 | E17: 0 | F17: 0 | G17: -8.3959 | J17: =B17*$N$2-'q,d_sum'!E17 -> -14.792277 | K17: =D17*$N$2-'q,d_sum'!F17 -> -14.792277 | L17: =G17*$N$2-'q,d_sum'!G17 -> -40.71379
A18: CN_scan | B18: -10.9701 | C18: 0 | D18: -10.9701 | E18: 0 | F18: 0 | G18: -8.7925 | J18: =B18*$N$2-'q,d_sum'!E18 -> -14.755154 | K18: =D18*$N$2-'q,d_sum'!F18 -> -14.755154 | L18: =G18*$N$2-'q,d_sum'!G18 -> -41.24723
A19: CN_spw92 | B19: -11.0544 | C19: 0 | D19: -11.0544 | E19: 0 | F19: 0 | G19: -9.3233 | J19: =B19*$N$2-'q,d_sum'!E19 -> -14.86854 | K19: =D19*$N$2-'q,d_sum'!F19 -> -14.86854 | L19: =G19*$N$2-'q,d_sum'!G19 -> -41.961174
A20: CO2_ccsd | B20: =(energies!C20-energies!D20)/(2*$N$5)*$N$2 -> -14.814998 | C20: 0 | D20: =(energies!E20-energies!F20)/(2*$N$5)*$N$2 -> -14.814998 | E20: 0 | F20: 0 | G20: =(energies!G20-energies!H20)/(2*$N$5)*$N$2 -> -19.948552 | J20: =B20*$N$2-'q,d_sum'!E20 -> -19.926671 | K20: =D20*$N$2-'q,d_sum'!F20 -> -19.926671 | L20: =G20*$N$2-'q,d_sum'!G20 -> -103.99401
A21: CO2_pbe0 | B21: -14.8102 | C21: 0 | D21: -14.8102 | E21: 0 | F21: 0 | G21: -19.1668 | J21: =B21*$N$2-'q,d_sum'!E21 -> -19.920218 | K21: =D21*$N$2-'q,d_sum'!F21 -> -19.920218 | L21: =G21*$N$2-'q,d_sum'!G21 -> -102.94253
A22: CO2_pbe | B22: -14.8972 | C22: 0 | D22: -14.8972 | E22: 0 | F22: 0 | G22: -19.0559 | J22: =B22*$N$2-'q,d_sum'!E22 -> -20.037236 | K22: =D22*$N$2-'q,d_sum'!F22 -> -20.037236 | L22: =G22*$N$2-'q,d_sum'!G22 -> -102.79336
A23: CO2_scan0 | B23: -14.7407 | C23: 0 | D23: -14.7407 | E23: 0 | F23: 0 | G23: -19.2046 | J23: =B23*$N$2-'q,d_sum'!E23 -> -19.826738 | K23: =D23*$N$2-'q,d_sum'!F23 -> -19.826738 | L23: =G23*$N$2-'q,d_sum'!G23 -> -102.99337
A24: CO2_scan | B24: -14.7535 | C24: 0 | D24: -14.7535 | E24: 0 | F24: 0 | G24: -19.0756 | J24: =B24*$N$2-'q,d_sum'!E24 -> -19.843954 | K24: =D24*$N$2-'q,d_sum'!F24 -> -19.843954 | L24: =G24*$N$2-'q,d_sum'!G24 -> -102.81986
A25: CO2_spw92 | B25: -14.8972 | C25: 0 | D25: -14.8972 | E25: 0 | F25: 0 | G25: -19.0559 | J25: =B25*$N$2-'q,d_sum'!E25 -> -20.037236 | K25: =D25*$N$2-'q,d_sum'!F25 -> -20.037236 | L25: =G25*$N$2-'q,d_sum'!G25 -> -102.79336
A26: CO_ccsd | B26: =(energies!C26-energies!D26)/(2*$N$5)*$N$2 -> -10.219992 | C26: 0 | D26: =(energies!E26-energies!F26)/(2*$N$5)*$N$2 -> -10.219992 | E26: 0 | F26: 0 | G26: =(energies!G26-energies!H26)/(2*$N$5)*$N$2 -> -12.636292 | J26: =B26*$N$2-'q,d_sum'!E26 -> -13.746233 | K26: =D26*$N$2-'q,d_sum'!F26 -> -13.746233 | L26: =G26*$N$2-'q,d_sum'!G26 -> -53.359405
A27: CO_pbe0 | B27: -10.2495 | C27: -0.0000 | D27: -10.2495 | E27: -0.0000 | F27: 0.0000 | G27: -12.1149 | J27: =B27*$N$2-'q,d_sum'!E27 -> -13.785923 | K27: =D27*$N$2-'q,d_sum'!F27 -> -13.785923 | L27: =G27*$N$2-'q,d_sum'!G27 -> -52.658115
A28: CO_pbe | B28: -10.3366 | C28: 0.0000 | D28: -10.3366 | E28: -0.0000 | F28: -0.0000 | G28: -12.0609 | J28: =B28*$N$2-'q,d_sum'!E28 -> -13.903075 | K28: =D28*$N$2-'q,d_sum'!F28 -> -13.903075 | L28: =G28*$N$2-'q,d_sum'!G28 -> -52.585483
A29: CO_scan0 | B29: -10.1947 | C29: -0.0000 | D29: -10.1947 | E29: -0.0000 | F29: -0.0000 | G29: -12.1498 | J29: =B29*$N$2-'q,d_sum'!E29 -> -13.712215 | K29: =D29*$N$2-'q,d_sum'!F29 -> -13.712215 | L29: =G29*$N$2-'q,d_sum'!G29 -> -52.705056
A30: CO_scan | B30: -10.2171 | C30: -0.0000 | D30: -10.2171 | E30: -0.0000 | F30: 0.0000 | G30: -12.0790 | J30: =B30*$N$2-'q,d_sum'!E30 -> -13.742343 | K30: =D30*$N$2-'q,d_sum'!F30 -> -13.742343 | L30: =G30*$N$2-'q,d_sum'!G30 -> -52.609828
A31: CO_spw92 | B31: -10.3949 | C31: -0.0000 | D31: -10.3949 | E31: -0.0000 | F31: -0.0000 | G31: -12.0857 | J31: =B31*$N$2-'q,d_sum'!E31 -> -13.98149 | K31: =D31*$N$2-'q,d_sum'!F31 -> -13.98149 | L31: =G31*$N$2-'q,d_sum'!G31 -> -52.61884
A32: H2O_ccsd | B32: =(energies!C32-energies!D32)/(2*$N$5)*$N$2 -> -7.5589514 | C32: 0 | D32: =(energies!E32-energies!F32)/(2*$N$5)*$N$2 -> -4.2447117 | E32: 0 | F32: 0 | G32: =(energies!G32-energies!H32)/(2*$N$5)*$N$2 -> -6.2426147 | J32: =B32*$N$2-'q,d_sum'!E32 -> -10.167044 | K32: =D32*$N$2-'q,d_sum'!F32 -> -9.8042502 | L32: =G32*$N$2-'q,d_sum'!G32 -> -10.361948
A33: H2O_pbe0 | B33: -7.726 | C33: 0 | D33: -4.4247 | E33: 0 | F33: 0 | G33: -6.4106 | J33: =B33*$N$2-'q,d_sum'!E33 -> -10.39173 | K33: =D33*$N$2-'q,d_sum'!F33 -> -10.04634 | L33: =G33*$N$2-'q,d_sum'!G33 -> -10.587894
A34: H2O_pbe | B34: -7.8672 | C34: 0 | D34: -4.5662 | E34: 0 | F34: 0 | G34: -6.549 | J34: =B34*$N$2-'q,d_sum'!E34 -> -10.581649 | K34: =D34*$N$2-'q,d_sum'!F34 -> -10.236663 | L34: =G34*$N$2-'q,d_sum'!G34 -> -10.774046
A35: H2O_scan0 | B35: -7.6496 | C35: 0 | D35: -4.3385 | E35: 0 | F35: 0 | G35: -6.338 | J35: =B35*$N$2-'q,d_sum'!E35 -> -10.28897 | K35: =D35*$N$2-'q,d_sum'!F35 -> -9.9303985 | L35: =G35*$N$2-'q,d_sum'!G35 -> -10.490244
A36: H2O_scan | B36: -7.7149 | C36: 0 | D36: -4.4075 | E36: 0 | F36: 0 | G36: -6.4065 | J36: =B36*$N$2-'q,d_sum'!E36 -> -10.3768 | K36: =D36*$N$2-'q,d_sum'!F36 -> -10.023206 | L36: =G36*$N$2-'q,d_sum'!G36 -> -10.582379
A37: H2O_spw92 | B37: -7.8672 | C37: 0 | D37: -4.5662 | E37: 0 | F37: 0 | G37: -6.549 | J37: =B37*$N$2-'q,d_sum'!E37 -> -10.581649 | K37: =D37*$N$2-'q,d_sum'!F37 -> -10.236663 | L37: =G37*$N$2-'q,d_sum'!G37 -> -10.774046
A38: HCO_ccsd | B38: =(energies!C38-energies!D38)/(2*$N$5)*$N$2 -> -11.287553 | D38: =(energies!E38-energies!F38)/(2*$N$5)*$N$2 -> -13.754912 | G38: =(energies!G38-energies!H38)/(2*$N$5)*$N$2 -> -10.980702 | J38: =B38*$N$2-'q,d_sum'!E38 -> -29.288818 | K38: =D38*$N$2-'q,d_sum'!F38 -> -49.561306 | L38: =G38*$N$2-'q,d_sum'!G38 -> -14.769414
A39: HCO_pbe0 | B39: -11.2044 | C39: 0.6098 | D39: -13.4142 | E39: 0 | F39: 0 | G39: -11.0017 | J39: =B39*$N$2-'q,d_sum'!E39 -> -29.176974 | K39: =D39*$N$2-'q,d_sum'!F39 -> -49.103037 | L39: =G39*$N$2-'q,d_sum'!G39 -> -14.797657
A40: HCO_pbe | B40: -11.3376 | C40: 0.5275 | D40: -13.4217 | E40: 0 | F40: 0 | G40: -11.085 | J40: =B40*$N$2-'q,d_sum'!E40 -> -29.356132 | K40: =D40*$N$2-'q,d_sum'!F40 -> -49.113125 | L40: =G40*$N$2-'q,d_sum'!G40 -> -14.909698
...

Sheet stdev
B1: tot_e | C1: XX | D1: YY | E1: ZZ | M1: Conversion factor: | Q1: Sorted: | S1: ZZ
A2: C2H_ccsd | B2: 13 | C2: =SQRT((quadrupoles_dft!J2/-stdev!B2)-(dipoles_dft!H2/-stdev!B2)^2) -> 1.1582984 | D2: =SQRT((quadrupoles_dft!K2/-stdev!B2)-(dipoles_dft!I2/-stdev!B2)^2) -> 1.1582984 | E2: =SQRT((quadrupoles_dft!L2/-stdev!B2)-(dipoles_dft!J2/-stdev!B2)^2) -> 1.6981448 | M2: ea0 to debye-ang | N2: =1/0.3934303*0.529177 -> 1.3450337 | R2: HF_ccsd | S2: 0.81785934
A3: C2H_pbe0 | B3: 13 | C3: =SQRT((quadrupoles_dft!J3/-stdev!B3)-(dipoles_dft!H3/-stdev!B3)^2) -> 1.1547056 | D3: =SQRT((quadrupoles_dft!K3/-stdev!B3)-(dipoles_dft!I3/-stdev!B3)^2) -> 1.1547044 | E3: =SQRT((quadrupoles_dft!L3/-stdev!B3)-(dipoles_dft!J3/-stdev!B3)^2) -> 1.6716708 | R3: HF_scan0 | S3: 0.85837319
A4: C2H_pbe | B4: 13 | C4: =SQRT((quadrupoles_dft!J4/-stdev!B4)-(dipoles_dft!H4/-stdev!B4)^2) -> 1.1553303 | D4: =SQRT((quadrupoles_dft!K4/-stdev!B4)-(dipoles_dft!I4/-stdev!B4)^2) -> 1.1553314 | E4: =SQRT((quadrupoles_dft!L4/-stdev!B4)-(dipoles_dft!J4/-stdev!B4)^2) -> 1.6789211 | R4: HF_scan | S4: 0.86415389
A5: C2H_scan0 | B5: 13 | C5: =SQRT((quadrupoles_dft!J5/-stdev!B5)-(dipoles_dft!H5/-stdev!B5)^2) -> 1.1537826 | D5: =SQRT((quadrupoles_dft!K5/-stdev!B5)-(dipoles_dft!I5/-stdev!B5)^2) -> 1.1537811 | E5: =SQRT((quadrupoles_dft!L5/-stdev!B5)-(dipoles_dft!J5/-stdev!B5)^2) -> 1.6677627 | R5: HF_pbe0 | S5: 0.86484406
A6: C2H_scan | B6: 13 | C6: =SQRT((quadrupoles_dft!J6/-stdev!B6)-(dipoles_dft!H6/-stdev!B6)^2) -> 1.1521492 | D6: =SQRT((quadrupoles_dft!K6/-stdev!B6)-(dipoles_dft!I6/-stdev!B6)^2) -> 1.1521479 | E6: =SQRT((quadrupoles_dft!L6/-stdev!B6)-(dipoles_dft!J6/-stdev!B6)^2) -> 1.6706518 | M6: debye to e | N6: 0.3934303 | R6: HF_pbe | S6: 0.8752982
A7: C2H_spw92 | B7: 13 | C7: =SQRT((quadrupoles_dft!J7/-stdev!B7)-(dipoles_dft!H7/-stdev!B7)^2) -> 1.1553303 | D7: =SQRT((quadrupoles_dft!K7/-stdev!B7)-(dipoles_dft!I7/-stdev!B7)^2) -> 1.1553314 | E7: =SQRT((quadrupoles_dft!L7/-stdev!B7)-(dipoles_dft!J7/-stdev!B7)^2) -> 1.6789211 | R7: HF_spw92 | S7: 0.8752982
A8: CH4_ccsd | B8: 10 | C8: =SQRT((quadrupoles_dft!J8/-stdev!B8)-(dipoles_dft!H8/-stdev!B8)^2) -> 1.3015119 | D8: =SQRT((quadrupoles_dft!K8/-stdev!B8)-(dipoles_dft!I8/-stdev!B8)^2) -> 1.3015119 | E8: =SQRT((quadrupoles_dft!L8/-stdev!B8)-(dipoles_dft!J8/-stdev!B8)^2) -> 1.3015119 | R8: HO2_ccsd | S8: 0.92994696
A9: CH4_pbe0 | B9: 10 | C9: =SQRT((quadrupoles_dft!J9/-stdev!B9)-(dipoles_dft!H9/-stdev!B9)^2) -> 1.3006465 | D9: =SQRT((quadrupoles_dft!K9/-stdev!B9)-(dipoles_dft!I9/-stdev!B9)^2) -> 1.3006465 | E9: =SQRT((quadrupoles_dft!L9/-stdev!B9)-(dipoles_dft!J9/-stdev!B9)^2) -> 1.3006465 | R9: HO2_scan0 | S9: 0.93295812
A10: CH4_pbe | B10: 10 | C10: =SQRT((quadrupoles_dft!J10/-stdev!B10)-(dipoles_dft!H10/-stdev!B10)^2) -> 1.3057915 | D10: =SQRT((quadrupoles_dft!K10/-stdev!B10)-(dipoles_dft!I10/-stdev!B10)^2) -> 1.3057915 | E10: =SQRT((quadrupoles_dft!L10/-stdev!B10)-(dipoles_dft!J10/-stdev!B10)^2) -> 1.3057915 | R10: HO2_scan | S10: 0.93452993
A11: CH4_scan0 | B11: 10 | C11: =SQRT((quadrupoles_dft!J11/-stdev!B11)-(dipoles_dft!H11/-stdev!B11)^2) -> 1.2982037 | D11: =SQRT((quadrupoles_dft!K11/-stdev!B11)-(dipoles_dft!I11/-stdev!B11)^2) -> 1.2982037 | E11: =SQRT((quadrupoles_dft!L11/-stdev!B11)-(dipoles_dft!J11/-stdev!B11)^2) -> 1.2982037 | R11: HO2_pbe0 | S11: 0.93650471
A12: CH4_scan | B12: 10 | C12: =SQRT((quadrupoles_dft!J12/-stdev!B12)-(dipoles_dft!H12/-stdev!B12)^2) -> 1.2998241 | D12: =SQRT((quadrupoles_dft!K12/-stdev!B12)-(dipoles_dft!I12/-stdev!B12)^2) -> 1.2998241 | E12: =SQRT((quadrupoles_dft!L12/-stdev!B12)-(dipoles_dft!J12/-stdev!B12)^2) -> 1.2998241 | M12: A to Bohr | N12: 1.88973 | R12: HO2_pbe | S12: 0.94113565
A13: CH4_spw92 | B13: 10 | C13: =SQRT((quadrupoles_dft!J13/-stdev!B13)-(dipoles_dft!H13/-stdev!B13)^2) -> 1.3057915 | D13: =SQRT((quadrupoles_dft!K13/-stdev!B13)-(dipoles_dft!I13/-stdev!B13)^2) -> 1.3057915 | E13: =SQRT((quadrupoles_dft!L13/-stdev!B13)-(dipoles_dft!J13/-stdev!B13)^2) -> 1.3057915 | R13: HO2_spw92 | S13: 0.94113565
A14: CN_ccsd | B14: 13 | C14: =SQRT((quadrupoles_dft!J14/-stdev!B14)-(dipoles_dft!H14/-stdev!B14)^2) -> 1.0689096 | D14: =SQRT((quadrupoles_dft!K14/-stdev!B14)-(dipoles_dft!I14/-stdev!B14)^2) -> 1.0689096 | E14: =SQRT((quadrupoles_dft!L14/-stdev!B14)-(dipoles_dft!J14/-stdev!B14)^2) -> 1.3972209 | R14: HCO_scan0 | S14: 0.99048855
A15: CN_pbe0 | B15: 13 | C15: =SQRT((quadrupoles_dft!J15/-stdev!B15)-(dipoles_dft!H15/-stdev!B15)^2) -> 1.0683854 | D15: =SQRT((quadrupoles_dft!K15/-stdev!B15)-(dipoles_dft!I15/-stdev!B15)^2) -> 1.0683854 | E15: =SQRT((quadrupoles_dft!L15/-stdev!B15)-(dipoles_dft!J15/-stdev!B15)^2) -> 1.4881592 | R15: HCO_scan | S15: 0.99099538
A16: CN_pbe | B16: 13 | C16: =SQRT((quadrupoles_dft!J16/-stdev!B16)-(dipoles_dft!H16/-stdev!B16)^2) -> 1.0694549 | D16: =SQRT((quadrupoles_dft!K16/-stdev!B16)-(dipoles_dft!I16/-stdev!B16)^2) -> 1.0694549 | E16: =SQRT((quadrupoles_dft!L16/-stdev!B16)-(dipoles_dft!J16/-stdev!B16)^2) -> 1.5011067 | N16: =0.9697*N12 -> 1.8324712 | R16: HCO_pbe0 | S16: 0.99323233
A17: CN_scan0 | B17: 13 | C17: =SQRT((quadrupoles_dft!J17/-stdev!B17)-(dipoles_dft!H17/-stdev!B17)^2) -> 1.0667087 | D17: =SQRT((quadrupoles_dft!K17/-stdev!B17)-(dipoles_dft!I17/-stdev!B17)^2) -> 1.0667087 | E17: =SQRT((quadrupoles_dft!L17/-stdev!B17)-(dipoles_dft!J17/-stdev!B17)^2) -> 1.4798493 | R17: HCO_pbe | S17: 0.9969854
A18: CN_scan | B18: 13 | C18: =SQRT((quadrupoles_dft!J18/-stdev!B18)-(dipoles_dft!H18/-stdev!B18)^2) -> 1.0653693 | D18: =SQRT((quadrupoles_dft!K18/-stdev!B18)-(dipoles_dft!I18/-stdev!B18)^2) -> 1.0653693 | E18: =SQRT((quadrupoles_dft!L18/-stdev!B18)-(dipoles_dft!J18/-stdev!B18)^2) -> 1.4884672 | R18: HCO_spw92 | S18: 0.9969854
A19: CN_spw92 | B19: 13 | C19: =SQRT((quadrupoles_dft!J19/-stdev!B19)-(dipoles_dft!H19/-stdev!B19)^2) -> 1.0694549 | D19: =SQRT((quadrupoles_dft!K19/-stdev!B19)-(dipoles_dft!I19/-stdev!B19)^2) -> 1.0694549 | E19: =SQRT((quadrupoles_dft!L19/-stdev!B19)-(dipoles_dft!J19/-stdev!B19)^2) -> 1.5011067 | R19: H2O_ccsd | S19: 1.0152943
A20: CO2_ccsd | B20: 22 | C20: =SQRT((quadrupoles_dft!J20/-stdev!B20)-(dipoles_dft!H20/-stdev!B20)^2) -> 0.95171307 | D20: =SQRT((quadrupoles_dft!K20/-stdev!B20)-(dipoles_dft!I20/-stdev!B20)^2) -> 0.95171307 | E20: =SQRT((quadrupoles_dft!L20/-stdev!B20)-(dipoles_dft!J20/-stdev!B20)^2) -> 2.1741663 | R20: H2O_scan0 | S20: 1.0215296
A21: CO2_pbe0 | B21: 22 | C21: =SQRT((quadrupoles_dft!J21/-stdev!B21)-(dipoles_dft!H21/-stdev!B21)^2) -> 0.95155895 | D21: =SQRT((quadrupoles_dft!K21/-stdev!B21)-(dipoles_dft!I21/-stdev!B21)^2) -> 0.95155895 | E21: =SQRT((quadrupoles_dft!L21/-stdev!B21)-(dipoles_dft!J21/-stdev!B21)^2) -> 2.1631464 | R21: H2O_scan | S21: 1.0261577
A22: CO2_pbe | B22: 22 | C22: =SQRT((quadrupoles_dft!J22/-stdev!B22)-(dipoles_dft!H22/-stdev!B22)^2) -> 0.95434974 | D22: =SQRT((quadrupoles_dft!K22/-stdev!B22)-(dipoles_dft!I22/-stdev!B22)^2) -> 0.95434974 | E22: =SQRT((quadrupoles_dft!L22/-stdev!B22)-(dipoles_dft!J22/-stdev!B22)^2) -> 2.1615757 | R22: H2O_pbe0 | S22: 1.0263754
A23: CO2_scan0 | B23: 22 | C23: =SQRT((quadrupoles_dft!J23/-stdev!B23)-(dipoles_dft!H23/-stdev!B23)^2) -> 0.94932363 | D23: =SQRT((quadrupoles_dft!K23/-stdev!B23)-(dipoles_dft!I23/-stdev!B23)^2) -> 0.94932363 | E23: =SQRT((quadrupoles_dft!L23/-stdev!B23)-(dipoles_dft!J23/-stdev!B23)^2) -> 2.1636812 | R23: H2O_pbe | S23: 1.0355761
A24: CO2_scan | B24: 22 | C24: =SQRT((quadrupoles_dft!J24/-stdev!B24)-(dipoles_dft!H24/-stdev!B24)^2) -> 0.94973571 | D24: =SQRT((quadrupoles_dft!K24/-stdev!B24)-(dipoles_dft!I24/-stdev!B24)^2) -> 0.94973571 | E24: =SQRT((quadrupoles_dft!L24/-stdev!B24)-(dipoles_dft!J24/-stdev!B24)^2) -> 2.1618567 | R24: H2O_spw92 | S24: 1.0355761
A25: CO2_spw92 | B25: 22 | C25: =SQRT((quadrupoles_dft!J25/-stdev!B25)-(dipoles_dft!H25/-stdev!B25)^2) -> 0.95434974 | D25: =SQRT((quadrupoles_dft!K25/-stdev!B25)-(dipoles_dft!I25/-stdev!B25)^2) -> 0.95434974 | E25: =SQRT((quadrupoles_dft!L25/-stdev!B25)-(dipoles_dft!J25/-stdev!B25)^2) -> 2.1615756 | R25: OH_scan0 | S25: 1.1001792
A26: CO_ccsd | B26: 14 | C26: =SQRT((quadrupoles_dft!J26/-stdev!B26)-(dipoles_dft!H26/-stdev!B26)^2) -> 0.99089544 | D26: =SQRT((quadrupoles_dft!K26/-stdev!B26)-(dipoles_dft!I26/-stdev!B26)^2) -> 0.99089544 | E26: =SQRT((quadrupoles_dft!L26/-stdev!B26)-(dipoles_dft!J26/-stdev!B26)^2) -> 1.5255082 | R26: OH_scan | S26: 1.1028063
A27: CO_pbe0 | B27: 14 | C27: =SQRT((quadrupoles_dft!J27/-stdev!B27)-(dipoles_dft!H27/-stdev!B27)^2) -> 0.99232492 | D27: =SQRT((quadrupoles_dft!K27/-stdev!B27)-(dipoles_dft!I27/-stdev!B27)^2) -> 0.99232492 | E27: =SQRT((quadrupoles_dft!L27/-stdev!B27)-(dipoles_dft!J27/-stdev!B27)^2) -> 1.5090007 | R27: OH_pbe0 | S27: 1.1036553
A28: CO_pbe | B28: 14 | C28: =SQRT((quadrupoles_dft!J28/-stdev!B28)-(dipoles_dft!H28/-stdev!B28)^2) -> 0.99653238 | D28: =SQRT((quadrupoles_dft!K28/-stdev!B28)-(dipoles_dft!I28/-stdev!B28)^2) -> 0.99653238 | E28: =SQRT((quadrupoles_dft!L28/-stdev!B28)-(dipoles_dft!J28/-stdev!B28)^2) -> 1.5072807 | R28: OH_ccsd | S28: 1.1053465
... A66: OH_scan | B66: 9 | C66: =SQRT((quadrupoles_dft!J66/-stdev!B66)-(dipoles_dft!H66/-stdev!B66)^2) -> 0.90784187 | D66: =SQRT((quadrupoles_dft!K66/-stdev!B66)-(dipoles_dft!I66/-stdev!B66)^2) -> 1.0128018 | E66: =SQRT((quadrupoles_dft!L66/-stdev!B66)-(dipoles_dft!J66/-stdev!B66)^2) -> 1.1028063 | R66: CO2_ccsd | S66: 2.1741663
A67: OH_spw92 | B67: 9 | C67: =SQRT((quadrupoles_dft!J67/-stdev!B67)-(dipoles_dft!H67/-stdev!B67)^2) -> 0.91812175 | D67: =SQRT((quadrupoles_dft!K67/-stdev!B67)-(dipoles_dft!I67/-stdev!B67)^2) -> 1.0230861 | E67: =SQRT((quadrupoles_dft!L67/-stdev!B67)-(dipoles_dft!J67/-stdev!B67)^2) -> 1.1096507 | R67: HCO_ccsd | S67: #VALUE!

Sheet energies
B1: 0 field | C1: XX | D1: -XX | E1: YY | F1: -YY | G1: ZZ | H1: -ZZ
A2: C2H_ccsd | B2: -76.178381 | C2: -76.179345 | D2: -76.177417 | E2: -76.179345 | F2: -76.177417 | G2: -76.179049 | H2: -76.177715
A3: C2H_pbe0 | B3: -76.535956 | C3: -76.536914 | D3: -76.534998 | E3: -76.536914 | F3: -76.534998 | G3: -76.53662 | H3: -76.535294
A4: C2H_pbe | B4: -76.533695 | C4: -76.534655 | D4: -76.532736 | E4: -76.534655 | F4: -76.532736 | G4: -76.534377 | H4: -76.533016
A5: C2H_scan0 | B5: -76.585898 | C5: -76.586855 | D5: -76.584942 | E5: -76.586855 | F5: -76.584942 | G5: -76.586552 | H5: -76.585246
A6: C2H_scan | B6: -76.599782 | C6: -76.600736 | D6: -76.598829 | E6: -76.600736 | F6: -76.598829 | G6: -76.600444 | H6: -76.599123
A7: C2H_spw92 | B7: -76.533695 | C7: -76.534655 | D7: -76.532736 | E7: -76.534655 | F7: -76.532736 | G7: -76.534377 | H7: -76.533016
A8: CH4_ccsd | B8: -40.213794 | C8: -40.21442 | D8: -40.213169 | E8: -40.21442 | F8: -40.213169 | G8: -40.21442 | H8: -40.213169
A9: CH4_pbe0 | B9: -40.47542 | C9: -40.476045 | D9: -40.474797 | E9: -40.476045 | F9: -40.474797 | G9: -40.476045 | H9: -40.474797
A10: CH4_pbe | B10: -40.464719 | C10: -40.465351 | D10: -40.464088 | E10: -40.465351 | F10: -40.464088 | G10: -40.465351 | H10: -40.464088
A11: CH4_scan0 | B11: -40.502495 | C11: -40.503116 | D11: -40.501875 | E11: -40.503116 | F11: -40.501875 | G11: -40.503116 | H11: -40.501875
A12: CH4_scan | B12: -40.506761 | C12: -40.507384 | D12: -40.506139 | E12: -40.507384 | F12: -40.506139 | G12: -40.507384 | H12: -40.506139
A13: CH4_spw92 | B13: -40.464719 | C13: -40.465351 | D13: -40.464088 | E13: -40.465351 | F13: -40.464088 | G13: -40.465351 | H13: -40.464088
... A26: CO_ccsd | B26: -112.7821 | C26: -112.78286 | D26: -112.78134 | E26: -112.78286 | F26: -112.78134 | G26: -112.78304 | H26: -112.78116
A27: CO_pbe0 | B27: -113.23798
A28: CO_pbe | B28: -113.24257
A29: CO_scan0 | B29: -113.29694
A30: CO_scan | B30: -113.32026
A31: CO_spw92 | B31: -112.47406
A32: H2O_ccsd | B32: -76.060798 | C32: -76.06136 | D32: -76.060236 | E32: -76.061114 | F32: -76.060483 | G32: -76.061262 | H32: -76.060334
A33: H2O_pbe0 | B33: -76.381048 | C33: -76.381622 | D33: -76.380474 | E33: -76.381377 | F33: -76.380719 | G33: -76.381525 | H33: -76.380571
A34: H2O_pbe | B34: -76.381692 | C34: -76.382277 | D34: -76.381107 | E34: -76.382031 | F34: -76.381352 | G34: -76.382179 | H34: -76.381205
A35: H2O_scan0 | B35: -76.418713 | C35: -76.419282 | D35: -76.418144 | E35: -76.419035 | F35: -76.41839 | G35: -76.419184 | H35: -76.418242
A36: H2O_scan | B36: -76.433622 | C36: -76.434196 | D36: -76.433049 | E36: -76.43395 | F36: -76.433295 | G36: -76.434099 | H36: -76.433146
A37: H2O_spw92 | B37: -76.381692 | C37: -76.382277 | D37: -76.381107 | E37: -76.382031 | F37: -76.381352 | G37: -76.382179 | H37: -76.381205
A38: HCO_ccsd | B38: -113.29072 | C38: -113.29156 | D38: -113.28988 | E38: -113.29174 | F38: -113.28969 | G38: -113.29153 | H38: -113.2899
A39: HCO_pbe0 | B39: -113.7676 | C39: -113.76843 | D39: -113.76676 | E39: -113.76859 | F39: -113.7666 | G39: -113.76841 | H39: -113.76678
A40: HCO_pbe | B40: -113.77339 | C40: -113.77424 | D40: -113.77255 | E40: -113.77439 | F40: -113.7724 | G40: -113.77422 | H40: -113.77257
A41: HCO_scan0 | B41: -113.82846 | C41: -113.82929 | D41: -113.82764 | E41: -113.82946 | F41: -113.82747 | G41: -113.82928 | H41: -113.82765
A42: HCO_scan | B42: -113.85391 | C42: -113.85475 | D42: -113.85308 | E42: -113.85491 | F42: -113.85292 | G42: -113.85473 | H42: -113.8531
A43: HCO_spw92 | B43: -113.77339 | C43: -113.77424 | D43: -113.77255 | E43: -113.77439 | F43: -113.7724 | G43: -113.77422 | H43: -113.77257
... A67: OH_spw92 | B67: -75.683904 | C67: -75.684323 | D67: -75.683485 | E67: -75.684425 | F67: -75.683383 | G67: -75.684467 | H67: -75.683341

Sheet dipoles_hf
A1: Column1 | B1: X | C1: Y | D1: Z | E1: total
A2: HF_hf_5z | B2: 0 | C2: 0 | D2: 1.9215 | E2: 1.9215
A3: HF_hf_dz | B3: 0 | C3: 0 | D3: 1.9315 | E3: 1.9315
A4: HF_hf_qz | B4: 0 | C4: 0 | D4: 1.9219 | E4: 1.9219
A5: HF_hf_tz | B5: 0 | C5: 0 | D5: 1.9247 | E5: 1.9247
A6: NH_hf_5z | B6: 0 | C6: 0 | D6: 1.6329 | E6: 1.6329
A7: NH_hf_dz | B7: 0 | C7: 0 | D7: 1.6421 | E7: 1.6421
A8: NH_hf_qz | B8: 0 | C8: 0 | D8: 1.6326 | E8: 1.6326
A9: NH_hf_tz | B9: 0 | C9: 0 | D9: 1.634 | E9: 1.634
A10: OH_hf_5z | B10: 0 | C10: 0 | D10: -1.7572 | E10: 1.7572
A11: OH_hf_dz | B11: 0 | C11: 0 | D11: -1.7714 | E11: 1.7714
A12: OH_hf_qz | B12: 0 | C12: 0 | D12: -1.7574 | E12: 1.7574
A13: OH_hf_tz | B13: 0 | C13: 0 | D13: -1.7598 | E13: 1.7598
... A17: PH_hf_tz | B17: 0 | C17: 0 | D17: -0.5189 | E17: 0.5189

Sheet quadrupoles_hf
A1: Column1 | B1: XX | C1: XY | D1: YY | E1: XZ | F1: YZ | G1: ZZ
A2: HF_hf_5z | B2: -5.6852 | C2: 0 | D2: -5.6852 | E2: 0 | F2: 0 | G2: -3.1779
A3: HF_hf_dz | B3: -5.7233 | C3: 0 | D3: -5.7233 | E3: 0 | F3: 0 | G3: -3.2118
A4: HF_hf_qz | B4: -5.6897 | C4: 0 | D4: -5.6897 | E4: 0 | F4: 0 | G4: -3.1793
A5: HF_hf_tz | B5: -5.6962 | C5: 0 | D5: -5.6962 | E5: 0 | F5: 0 | G5: -3.1858
A6: NH_hf_5z | B6: -6.269 | C6: 0 | D6: -6.269 | E6: 0 | F6: 0 | G6: -5.4578
A7: NH_hf_dz | B7: -6.2876 | C7: 0 | D7: -6.2876 | E7: 0 | F7: 0 | G7: -5.5205
A8: NH_hf_qz | B8: -6.2725 | C8: 0 | D8: -6.2725 | E8: 0 | F8: 0 | G8: -5.4586
A9: NH_hf_tz | B9: -6.2787 | C9: 0 | D9: -6.2787 | E9: 0 | F9: 0 | G9: -5.464
A10: OH_hf_5z | B10: -5.4102 | C10: -0.0024 | D10: -6.7119 | E10: 0 | F10: 0 | G10: -7.5533
A11: OH_hf_dz | B11: -5.4024 | C11: 0 | D11: -6.78 | E11: 0 | F11: 0 | G11: -7.6335
A12: OH_hf_qz | B12: -5.4127 | C12: -0.0001 | D12: -6.7167 | E12: 0 | F12: 0 | G12: -7.5559
A13: OH_hf_tz | B13: -5.4154 | C13: 0.0098 | D13: -6.727 | E13: 0 | F13: 0 | G13: -7.5673
... A17: PH_hf_tz | B17: -14.4267 | C17: 0 | D17: -14.4267 | E17: 0 | F17: 0 | G17: -15.5055

Sheet cbs_limit(energy)
A1: CCSD(T)
A2: molecule_method_basis | B2: 0 field | C2: XX | D2: -XX | E2: ZZ | F2: -ZZ | G2: Z | H2: -Z | L2: ea02 to debye-ang
A3: HF_ccsdT_5z | B3: -100.45182 | C3: -100.45226 | D3: -100.45139 | E3: -100.45207 | F3: -100.45157 | G3: -100.45175 | H3: -100.45189 | L3: 1.3450337
A4: HF_ccsdT_dz | B4: -100.30598 | C4: -100.26773 | D4: -100.26685 | E4: -100.26755 | F4: -100.26704 | G4: -100.26722 | H4: -100.26736
A5: HF_ccsdT_qz | B5: -100.44205 | C5: -100.44248 | D5: -100.44162 | E5: -100.4423 | F5: -100.4418 | G5: -100.44198 | H5: -100.44212 | L5: step size
A6: HF_ccsdT_tz | B6: -100.41083 | C6: -100.41127 | D6: -100.4104 | E6: -100.41108 | F6: -100.41058 | G6: -100.41076 | H6: -100.4109 | L6: 0.0001
A7: NH_ccsdT_5z | B7: -55.217532 | C7: -55.218005 | D7: -55.217059 | E7: -55.217941 | F7: -55.217123 | G7: -55.217471 | H7: -55.217592
A8: NH_ccsdT_dz | B8: -55.145079 | C8: -55.145559 | D8: -55.144599 | E8: -55.145504 | F8: -55.144654 | G8: -55.14502 | H8: -55.145138 | L8: ea0 to debye
A9: NH_ccsdT_qz | B9: -55.21313 | C9: -55.213603 | D9: -55.212656 | E9: -55.21354 | F9: -55.21272 | G9: -55.213069 | H9: -55.21319 | L9: 2.5417462
A10: NH_ccsdT_tz | B10: -55.19812 | C10: -55.198595 | D10: -55.197645 | E10: -55.198533 | F10: -55.197707 | G10: -55.19806 | H10: -55.19818
A11: OH_ccsdT_5z | B11: -75.732192 | C11: -75.732701 | D11: -75.731684 | E11: -75.73275 | F11: -75.731636 | G11: -75.732257 | H11: -75.732128
A12: OH_ccsdT_dz | B12: -75.624873 | C12: -75.625287 | D12: -75.624458 | E12: -75.62544 | F12: -75.624307 | G12: -75.624937 | H12: -75.624809
A13: OH_ccsdT_qz | B13: -75.72521 | C13: -75.725621 | D13: -75.724798 | E13: -75.725768 | F13: -75.724653 | G13: -75.725275 | H13: -75.725145
A14: OH_ccsdT_tz | B14: -75.702595 | C14: -75.703107 | D14: -75.702083 | E14: -75.703154 | F14: -75.702036 | G14: -75.702659 | H14: -75.70253
A15: PH_ccsdT_5z | B15: -341.85346 | C15: -341.85452 | D15: -341.8524 | E15: -341.85458 | F15: -341.85235 | G15: -341.85348 | H15: -341.85344
A16: PH_ccsdT_dz | B16: -341.61157 | C16: -341.61265 | D16: -341.61049 | E16: -341.61271 | F16: -341.61043 | G16: -341.61159 | H16: -341.61155
A17: PH_ccsdT_qz | B17: -341.82674 | C17: -341.8278 | D17: -341.82567 | E17: -341.82786 | F17: -341.82562 | G17: -341.82675 | H17: -341.82672
A18: PH_ccsdT_tz | B18: -341.76332 | C18: -341.76439 | D18: -341.76225 | E18: -341.76444 | F18: -341.7622 | G18: -341.76333 | H18: -341.7633
A20: CCSD
A21: Column1 | B21: Column2 | C21: Column3 | D21: Column4 | E21: Column5 | F21: Column6 | G21: Column7 | H21: Column8
A22: HF_ccsdT_5z | B22: -100.44278 | C22: -100.44321 | D22: -100.44235 | E22: -100.44302 | F22: -100.44253 | G22: -100.44271 | H22: -100.44285
A23: HF_ccsdT_dz | B23: -100.30159 | C23: -100.26346 | D23: -100.26259 | E23: -100.26328 | F23: -100.26277 | G23: -100.26295 | H23: -100.2631
A24: HF_ccsdT_qz | B24: -100.43324 | C24: -100.43367 | D24: -100.4328 | E24: -100.43348 | F24: -100.43299 | G24: -100.43316 | H24: -100.43331
A25: HF_ccsdT_tz | B25: -100.40271 | C25: -100.40314 | D25: -100.40228 | E25: -100.40296 | F25: -100.40246 | G25: -100.40264 | H25: -100.40278
A26: NH_ccsdT_5z | B26: -55.212372 | C26: -55.212844 | D26: -55.2119 | E26: -55.21278 | F26: -55.211964 | G26: -55.212311 | H26: -55.212433
A27: NH_ccsdT_dz | B27: -55.142428 | C27: -55.142907 | D27: -55.14195 | E27: -55.142852 | F27: -55.142005 | G27: -55.142368 | H27: -55.142488
A28: NH_ccsdT_qz | B28: -55.208102 | C28: -55.208575 | D28: -55.20763 | E28: -55.208511 | F28: -55.207694 | G28: -55.208041 | H28: -55.208163
A29: NH_ccsdT_tz | B29: -55.193516 | C29: -55.19399 | D29: -55.193042 | E29: -55.193927 | F29: -55.193105 | G29: -55.193456 | H29: -55.193577
A30: OH_ccsdT_5z | B30: -75.725054 | C30: -75.725561 | D30: -75.724548 | E30: -75.725612 | F30: -75.724498 | G30: -75.72512 | H30: -75.724989
A31: OH_ccsdT_dz | B31: -75.621293 | C31: -75.621706 | D31: -75.62088 | E31: -75.62186 | F31: -75.620727 | G31: -75.621358 | H31: -75.621228
A32: OH_ccsdT_qz | B32: -75.718258 | C32: -75.718668 | D32: -75.717848 | E32: -75.718816 | F32: -75.717701 | G32: -75.718323 | H32: -75.718192
A33: OH_ccsdT_tz | B33: -75.696202 | C33: -75.696712 | D33: -75.695692 | E33: -75.696761 | F33: -75.695643 | G33: -75.696267 | H33: -75.696137
... A37: PH_ccsdT_tz | B37: -341.75591 | C37: -341.75698 | D37: -341.75484 | E37: -341.75703 | F37: -341.75479 | G37: -341.75592 | H37: -341.75589
A39: MP2
A40: Column1 | B40: Column2 | C40: Column3 | D40: Column4 | E40: Column5 | F40: Column6 | G40: Column7 | H40: Column8
A41: HF_ccsdT_5z | B41: -100.44486 | C41: -100.44529 | D41: -100.44442 | E41: -100.44511 | F41: -100.44461 | G41: -100.44479 | H41: -100.44493
A42: HF_ccsdT_dz | B42: -100.29736 | C42: -100.26025 | D42: -100.25936 | E42: -100.26006 | F42: -100.25955 | G42: -100.25973 | H42: -100.25987
A43: HF_ccsdT_qz | B43: -100.43355 | C43: -100.43399 | D43: -100.43312 | E43: -100.4338 | F43: -100.4333 | G43: -100.43348 | H43: -100.43362
A44: HF_ccsdT_tz | B44: -100.40113 | C44: -100.40157 | D44: -100.40069 | E44: -100.40139 | F44: -100.40088 | G44: -100.40106 | H44: -100.4012
A45: NH_ccsdT_5z | B45: -55.195425 | C45: -55.195899 | D45: -55.194952 | E45: -55.195832 | F45: -55.195019 | G45: -55.195363 | H45: -55.195488
...

Sheet cbs_limit
A1: XX/5z | B1: HF | C1: MP2 | D1: CCSD | E1: CCSD(T) | G1: XX/4z | H1: HF | I1: MP2 | J1: CCSD | K1: CCSD(T) | M1: XX/3z | N1: HF | O1: MP2 | P1: CCSD | Q1: CCSD(T) | S1: XX/cbs | T1: HF | U1: MP2 | V1: CCSD | W1: CCSD(T) | Y1: XX/r.e | Z1: HF | AA1: MP2 | AB1: CCSD | AC1: CCSD(T)
A2: HF | B2: =quadrupoles__2[[#This Row],[XX]] -> -5.6852 | C2: =(OFFSET('cbs_limit(energy)'!$C$41,(ROW('cbs_limit(energy)'!C41)-ROW('cbs_limit(energy)'!$C$41))*4,0)-OFFSET('cbs_limit(energy)'!$D$41,(ROW('cbs_limit(energy)'!D41)-ROW('cbs_limit(energy)'!$D$41))*4,0))/(2*'cbs_limit(energy)'!$L$6)*'cbs_limit(energy)'!$L$3 -> -5.8664316 | D2: =(OFFSET('cbs_limit(energy)'!$C$22,(ROW('cbs_limit(energy)'!C22)-ROW('cbs_limit(energy)'!$C$22))*4,0)-OFFSET('cbs_limit(energy)'!$D$22,(ROW('cbs_limit(energy)'!D22)-ROW('cbs_limit(energy)'!$D$22))*4,0))/(2*'cbs_limit(energy)'!$L$6)*'cbs_limit(energy)'!$L$3 -> -5.7950103 | E2: =(OFFSET('cbs_limit(energy)'!$C$3,(ROW('cbs_limit(energy)'!C3)-ROW('cbs_limit(energy)'!$C$3))*4,0)-OFFSET('cbs_limit(energy)'!$D$3,(ROW('cbs_limit(energy)'!D3)-ROW('cbs_limit(energy)'!$D$3))*4,0))/(2*'cbs_limit(energy)'!$L$6)*'cbs_limit(energy)'!$L$3 -> -5.821373 | H2: =quadrupoles_hf!B4 -> -5.6897 | I2: =(OFFSET('cbs_limit(energy)'!$C$43,(ROW('cbs_limit(energy)'!C43)-ROW('cbs_limit(energy)'!$C$43))*4,0)-OFFSET('cbs_limit(energy)'!$D$43,(ROW('cbs_limit(energy)'!D43)-ROW('cbs_limit(energy)'!$D$43))*4,0))/(2*'cbs_limit(energy)'!$L$6)*'cbs_limit(energy)'!$L$3 -> -5.8750398 | J2: =(OFFSET('cbs_limit(energy)'!$C$24,(ROW('cbs_limit(energy)'!C24)-ROW('cbs_limit(energy)'!$C$24))*4,0)-OFFSET('cbs_limit(energy)'!$D$24,(ROW('cbs_limit(energy)'!D24)-ROW('cbs_limit(energy)'!$D$24))*4,0))/(2*'cbs_limit(energy)'!$L$6)*'cbs_limit(energy)'!$L$3 -> -5.8052998 | K2: =(OFFSET('cbs_limit(energy)'!$C$5,(ROW('cbs_limit(energy)'!C5)-ROW('cbs_limit(energy)'!$C$5))*4,0)-OFFSET('cbs_limit(energy)'!$D$5,(ROW('cbs_limit(energy)'!D5)-ROW('cbs_limit(energy)'!$D$5))*4,0))/(2*'cbs_limit(energy)'!$L$6)*'cbs_limit(energy)'!$L$3 -> -5.8313935 | N2: =quadrupoles_hf!B5 -> -5.6962 | O2: =(OFFSET('cbs_limit(energy)'!$C$44,(ROW('cbs_limit(energy)'!C44)-ROW('cbs_limit(energy)'!$C$44))*4,0)-OFFSET('cbs_limit(energy)'!$D$44,(ROW('cbs_limit(energy)'!D44)-ROW('cbs_limit(energy)'!$D$44))*4,0))/(2*'cbs_limit(energy)'!$L$6)*'cbs_limit(energy)'!$L$3 -> -5.8923235 | P2: =(OFFSET('cbs_limit(energy)'!$C$25,(ROW('cbs_limit(energy)'!C25)-ROW('cbs_limit(energy)'!$C$25))*4,0)-OFFSET('cbs_limit(energy)'!$D$25,(ROW('cbs_limit(energy)'!D25)-ROW('cbs_limit(energy)'!$D$25))*4,0))/(2*'cbs_limit(energy)'!$L$6)*'cbs_limit(energy)'!$L$3 -> -5.8274256 | Q2: =(OFFSET('cbs_limit(energy)'!$C$6,(ROW('cbs_limit(energy)'!C6)-ROW('cbs_limit(energy)'!$C$6))*4,0)-OFFSET('cbs_limit(energy)'!$D$6,(ROW('cbs_limit(energy)'!D6)-ROW('cbs_limit(energy)'!$D$6))*4,0))/(2*'cbs_limit(energy)'!$L$6)*'cbs_limit(energy)'!$L$3 -> -5.852914 | T2: =B2 -> -5.6852 | U2: =((C2-B2)*5^3-(I2-H2)*4^3)/(5^3-4^3)+T2 -> -5.8621213 | V2: =((D2-B2)*5^3-(J2-H2)*4^3)/(5^3-4^3)+T2 -> -5.7889361 | W2: =((E2-B2)*5^3-(K2-H2)*4^3)/(5^3-4^3)+T2 -> -5.815581 | Z2: =ABS(T2-B2)/ABS(B2) -> 0 | AA2: =ABS(U2-C2)/ABS(C2) -> 0.00073473265 | AB2: =ABS(V2-D2)/ABS(D2) -> 0.0010481841 | AC2: =ABS(W2-E2)/ABS(E2) -> 0.00099495444
A3: NH | B3: =quadrupoles_hf!B6 -> -6.269 | C3: =(OFFSET('cbs_limit(energy)'!$C$41,(ROW('cbs_limit(energy)'!C42)-ROW('cbs_limit(energy)'!$C$41))*4,0)-OFFSET('cbs_limit(energy)'!$D$41,(ROW('cbs_limit(energy)'!D42)-ROW('cbs_limit(energy)'!$D$41))*4,0))/(2*'cbs_limit(energy)'!$L$6)*'cbs_limit(energy)'!$L$3 -> -6.3728368 | D3: =(OFFSET('cbs_limit(energy)'!$C$22,(ROW('cbs_limit(energy)'!C23)-ROW('cbs_limit(energy)'!$C$22))*4,0)-OFFSET('cbs_limit(energy)'!$D$22,(ROW('cbs_limit(energy)'!D23)-ROW('cbs_limit(energy)'!$D$22))*4,0))/(2*'cbs_limit(energy)'!$L$6)*'cbs_limit(energy)'!$L$3 -> -6.3470121 | E3: =(OFFSET('cbs_limit(energy)'!$C$3,(ROW('cbs_limit(energy)'!C4)-ROW('cbs_limit(energy)'!$C$3))*4,0)-OFFSET('cbs_limit(energy)'!$D$3,(ROW('cbs_limit(energy)'!D4)-ROW('cbs_limit(energy)'!$D$3))*4,0))/(2*'cbs_limit(energy)'!$L$6)*'cbs_limit(energy)'!$L$3 -> -6.3652373 | H3: =quadrupoles_hf!B8 -> -6.2725 | I3: =(OFFSET('cbs_limit(energy)'!$C$43,(ROW('cbs_limit(energy)'!C44)-ROW('cbs_limit(energy)'!$C$43))*4,0)-OFFSET('cbs_limit(energy)'!$D$43,(ROW('cbs_limit(energy)'!D44)-ROW('cbs_limit(energy)'!$D$43))*4,0))/(2*'cbs_limit(energy)'!$L$6)*'cbs_limit(energy)'!$L$3 -> -6.3805707 | J3: =(OFFSET('cbs_limit(energy)'!$C$24,(ROW('cbs_limit(energy)'!C25)-ROW('cbs_limit(energy)'!$C$24))*4,0)-OFFSET('cbs_limit(energy)'!$D$24,(ROW('cbs_limit(energy)'!D25)-ROW('cbs_limit(energy)'!$D$24))*4,0))/(2*'cbs_limit(energy)'!$L$6)*'cbs_limit(energy)'!$L$3 -> -6.3552841 | K3: =(OFFSET('cbs_limit(energy)'!$C$5,(ROW('cbs_limit(energy)'!C6)-ROW('cbs_limit(energy)'!$C$5))*4,0)-OFFSET('cbs_limit(energy)'!$D$5,(ROW('cbs_limit(energy)'!D6)-ROW('cbs_limit(energy)'!$D$5))*4,0))/(2*'cbs_limit(energy)'!$L$6)*'cbs_limit(energy)'!$L$3 -> -6.3733748 | N3: =quadrupoles_hf!B9 -> -6.2787 | O3: =(OFFSET('cbs_limit(energy)'!$C$44,(ROW('cbs_limit(energy)'!C45)-ROW('cbs_limit(energy)'!$C$44))*4,0)-OFFSET('cbs_limit(energy)'!$D$44,(ROW('cbs_limit(energy)'!D45)-ROW('cbs_limit(energy)'!$D$44))*4,0))/(2*'cbs_limit(energy)'!$L$6)*'cbs_limit(energy)'!$L$3 -> -6.3983252 | P3: =(OFFSET('cbs_limit(energy)'!$C$25,(ROW('cbs_limit(energy)'!C26)-ROW('cbs_limit(energy)'!$C$25))*4,0)-OFFSET('cbs_limit(energy)'!$D$25,(ROW('cbs_limit(energy)'!D26)-ROW('cbs_limit(energy)'!$D$25))*4,0))/(2*'cbs_limit(energy)'!$L$6)*'cbs_limit(energy)'!$L$3 -> -6.3755268 | Q3: =(OFFSET('cbs_limit(energy)'!$C$6,(ROW('cbs_limit(energy)'!C7)-ROW('cbs_limit(energy)'!$C$6))*4,0)-OFFSET('cbs_limit(energy)'!$D$6,(ROW('cbs_limit(energy)'!D7)-ROW('cbs_limit(energy)'!$D$6))*4,0))/(2*'cbs_limit(energy)'!$L$6)*'cbs_limit(energy)'!$L$3 -> -6.3935503 | T3: =B3 -> -6.269 | U3: =((C3-B3)*5^3-(I3-H3)*4^3)/(5^3-4^3)+T3 -> -6.3683946 | V3: =((D3-B3)*5^3-(J3-H3)*4^3)/(5^3-4^3)+T3 -> -6.3420055 | W3: =((E3-B3)*5^3-(K3-H3)*4^3)/(5^3-4^3)+T3 -> -6.3603718 | Z3: =ABS(T3-B3)/ABS(B3) -> 0 | AA3: =ABS(U3-C3)/ABS(C3) -> 0.00069704756 | AB3: =ABS(V3-D3)/ABS(D3) -> 0.00078881896 | AC3: =ABS(W3-E3)/ABS(E3) -> 0.00076439022
A4: OH | B4: =quadrupoles_hf!B10 -> -5.4102 | C4: =(OFFSET('cbs_limit(energy)'!$C$41,(ROW('cbs_limit(energy)'!C43)-ROW('cbs_limit(energy)'!$C$41))*4,0)-OFFSET('cbs_limit(energy)'!$D$41,(ROW('cbs_limit(energy)'!D43)-ROW('cbs_limit(energy)'!$D$41))*4,0))/(2*'cbs_limit(energy)'!$L$6)*'cbs_limit(energy)'!$L$3 -> -6.8702975 | D4: =(OFFSET('cbs_limit(energy)'!$C$22,(ROW('cbs_limit(energy)'!C24)-ROW('cbs_limit(energy)'!$C$22))*4,0)-OFFSET('cbs_limit(energy)'!$D$22,(ROW('cbs_limit(energy)'!D24)-ROW('cbs_limit(energy)'!$D$22))*4,0))/(2*'cbs_limit(energy)'!$L$6)*'cbs_limit(energy)'!$L$3 -> -6.8152856 | E4: =(OFFSET('cbs_limit(energy)'!$C$3,(ROW('cbs_limit(energy)'!C5)-ROW('cbs_limit(energy)'!$C$3))*4,0)-OFFSET('cbs_limit(energy)'!$D$3,(ROW('cbs_limit(energy)'!D5)-ROW('cbs_limit(energy)'!$D$3))*4,0))/(2*'cbs_limit(energy)'!$L$6)*'cbs_limit(energy)'!$L$3 -> -6.8444056 | H4: =quadrupoles_hf!B12 -> -5.4127 | I4: =(OFFSET('cbs_limit(energy)'!$C$43,(ROW('cbs_limit(energy)'!C45)-ROW('cbs_limit(energy)'!$C$43))*4,0)-OFFSET('cbs_limit(energy)'!$D$43,(ROW('cbs_limit(energy)'!D45)-ROW('cbs_limit(energy)'!$D$43))*4,0))/(2*'cbs_limit(energy)'!$L$6)*'cbs_limit(energy)'!$L$3 -> -5.5514247 | J4: =(OFFSET('cbs_limit(energy)'!$C$24,(ROW('cbs_limit(energy)'!C26)-ROW('cbs_limit(energy)'!$C$24))*4,0)-OFFSET('cbs_limit(energy)'!$D$24,(ROW('cbs_limit(energy)'!D26)-ROW('cbs_limit(energy)'!$D$24))*4,0))/(2*'cbs_limit(energy)'!$L$6)*'cbs_limit(energy)'!$L$3 -> -5.5133603 | K4: =(OFFSET('cbs_limit(energy)'!$C$5,(ROW('cbs_limit(energy)'!C7)-ROW('cbs_limit(energy)'!$C$5))*4,0)-OFFSET('cbs_limit(energy)'!$D$5,(ROW('cbs_limit(energy)'!D7)-ROW('cbs_limit(energy)'!$D$5))*4,0))/(2*'cbs_limit(energy)'!$L$6)*'cbs_limit(energy)'!$L$3 -> -5.534141 | N4: =quadrupoles_hf!B13 -> -5.4154 | O4: =(OFFSET('cbs_limit(energy)'!$C$44,(ROW('cbs_limit(energy)'!C46)-ROW('cbs_limit(energy)'!$C$44))*4,0)-OFFSET('cbs_limit(energy)'!$D$44,(ROW('cbs_limit(energy)'!D46)-ROW('cbs_limit(energy)'!$D$44))*4,0))/(2*'cbs_limit(energy)'!$L$6)*'cbs_limit(energy)'!$L$3 -> -6.9083619 | P4: =(OFFSET('cbs_limit(energy)'!$C$25,(ROW('cbs_limit(energy)'!C27)-ROW('cbs_limit(energy)'!$C$25))*4,0)-OFFSET('cbs_limit(energy)'!$D$25,(ROW('cbs_limit(energy)'!D27)-ROW('cbs_limit(energy)'!$D$25))*4,0))/(2*'cbs_limit(energy)'!$L$6)*'cbs_limit(energy)'!$L$3 -> -6.859201 | Q4: =(OFFSET('cbs_limit(energy)'!$C$6,(ROW('cbs_limit(energy)'!C8)-ROW('cbs_limit(energy)'!$C$6))*4,0)-OFFSET('cbs_limit(energy)'!$D$6,(ROW('cbs_limit(energy)'!D8)-ROW('cbs_limit(energy)'!$D$6))*4,0))/(2*'cbs_limit(energy)'!$L$6)*'cbs_limit(energy)'!$L$3 -> -6.8881864 | T4: =B4 -> -5.4102 | U4: =((C4-B4)*5^3-(I4-H4)*4^3)/(5^3-4^3)+T4 -> -8.2566558 | V4: =((D4-B4)*5^3-(J4-H4)*4^3)/(5^3-4^3)+T4 -> -8.183863 | W4: =((E4-B4)*5^3-(K4-H4)*4^3)/(5^3-4^3)+T4 -> -8.2217323 | Z4: =ABS(T4-B4)/ABS(B4) -> 0 | AA4: =ABS(U4-C4)/ABS(C4) -> 0.20179014 | AB4: =ABS(V4-D4)/ABS(D4) -> 0.20080999 | AC4: =ABS(W4-E4)/ABS(E4) -> 0.20123395
A5: PH | B5: =quadrupoles_hf!B14 -> -14.4015 | C5: =(OFFSET('cbs_limit(energy)'!$C$41,(ROW('cbs_limit(energy)'!C44)-ROW('cbs_limit(energy)'!$C$41))*4,0)-OFFSET('cbs_limit(energy)'!$D$41,(ROW('cbs_limit(energy)'!D44)-ROW('cbs_limit(energy)'!$D$41))*4,0))/(2*'cbs_limit(energy)'!$L$6)*'cbs_limit(energy)'!$L$3 -> -14.363615 | D5: =(OFFSET('cbs_limit(energy)'!$C$22,(ROW('cbs_limit(energy)'!C25)-ROW('cbs_limit(energy)'!$C$22))*4,0)-OFFSET('cbs_limit(energy)'!$D$22,(ROW('cbs_limit(energy)'!D25)-ROW('cbs_limit(energy)'!$D$22))*4,0))/(2*'cbs_limit(energy)'!$L$6)*'cbs_limit(energy)'!$L$3 -> -14.302954 | E5: =(OFFSET('cbs_limit(energy)'!$C$3,(ROW('cbs_limit(energy)'!C6)-ROW('cbs_limit(energy)'!$C$3))*4,0)-OFFSET('cbs_limit(energy)'!$D$3,(ROW('cbs_limit(energy)'!D6)-ROW('cbs_limit(energy)'!$D$3))*4,0))/(2*'cbs_limit(energy)'!$L$6)*'cbs_limit(energy)'!$L$3 -> -14.315261 | H5: =quadrupoles_hf!B16 -> -14.4047 | I5: =(OFFSET('cbs_limit(energy)'!$C$43,(ROW('cbs_limit(energy)'!C46)-ROW('cbs_limit(energy)'!$C$43))*4,0)-OFFSET('cbs_limit(energy)'!$D$43,(ROW('cbs_limit(energy)'!D46)-ROW('cbs_limit(energy)'!$D$43))*4,0))/(2*'cbs_limit(energy)'!$L$6)*'cbs_limit(energy)'!$L$3 -> -14.382714 | J5: =(OFFSET('cbs_limit(energy)'!$C$24,(ROW('cbs_limit(energy)'!C27)-ROW('cbs_limit(energy)'!$C$24))*4,0)-OFFSET('cbs_limit(energy)'!$D$24,(ROW('cbs_limit(energy)'!D27)-ROW('cbs_limit(energy)'!$D$24))*4,0))/(2*'cbs_limit(energy)'!$L$6)*'cbs_limit(energy)'!$L$3 -> -14.320641 | K5: =(OFFSET('cbs_limit(energy)'!$C$5,(ROW('cbs_limit(energy)'!C8)-ROW('cbs_limit(energy)'!$C$5))*4,0)-OFFSET('cbs_limit(energy)'!$D$5,(ROW('cbs_limit(energy)'!D8)-ROW('cbs_limit(energy)'!$D$5))*4,0))/(2*'cbs_limit(energy)'!$L$6)*'cbs_limit(energy)'!$L$3 -> -14.333822 | N5: =quadrupoles_hf!B17 -> -14.4267 | O5: =(OFFSET('cbs_limit(energy)'!$C$44,(ROW('cbs_limit(energy)'!C47)-ROW('cbs_limit(energy)'!$C$44))*4,0)-OFFSET('cbs_limit(energy)'!$D$44,(ROW('cbs_limit(energy)'!D47)-ROW('cbs_limit(energy)'!$D$44))*4,0))/(2*'cbs_limit(energy)'!$L$6)*'cbs_limit(energy)'!$L$3 -> -14.441828 | P5: =(OFFSET('cbs_limit(energy)'!$C$25,(ROW('cbs_limit(energy)'!C28)-ROW('cbs_limit(energy)'!$C$25))*4,0)-OFFSET('cbs_limit(energy)'!$D$25,(ROW('cbs_limit(energy)'!D28)-ROW('cbs_limit(energy)'!$D$25))*4,0))/(2*'cbs_limit(energy)'!$L$6)*'cbs_limit(energy)'!$L$3 -> -14.382311 | Q5: =(OFFSET('cbs_limit(energy)'!$C$6,(ROW('cbs_limit(energy)'!C9)-ROW('cbs_limit(energy)'!$C$6))*4,0)-OFFSET('cbs_limit(energy)'!$D$6,(ROW('cbs_limit(energy)'!D9)-ROW('cbs_limit(energy)'!$D$6))*4,0))/(2*'cbs_limit(energy)'!$L$6)*'cbs_limit(energy)'!$L$3 -> -14.397577 | T5: =B5 -> -14.4015 | U5: =((C5-B5)*5^3-(I5-H5)*4^3)/(5^3-4^3)+T5 -> -14.346933 | V5: =((D5-B5)*5^3-(J5-H5)*4^3)/(5^3-4^3)+T5 -> -14.287754 | W5: =((E5-B5)*5^3-(K5-H5)*4^3)/(5^3-4^3)+T5 -> -14.299144 | Z5: =ABS(T5-B5)/ABS(B5) -> 0 | AA5: =ABS(U5-C5)/ABS(C5) -> 0.0011613664 | AB5: =ABS(V5-D5)/ABS(D5) -> 0.001062695 | AC5: =ABS(W5-E5)/ABS(E5) -> 0.0011258577
A9: YY
A10: HF | B10: =OFFSET(quadrupoles_hf!$D$2, (ROW([1]quadrpoles_hf!D2)-ROW(dipoles_hf!$D$2))*4,0) -> -5.6852
A11: NH | B11: =OFFSET(quadrupoles_hf!$D$2, (ROW([1]quadrpoles_hf!D3)-ROW(dipoles_hf!$D$2))*4,0) -> -6.269
A12: OH | B12: =OFFSET(quadrupoles_hf!$D$2, (ROW([1]quadrpoles_hf!D4)-ROW(dipoles_hf!$D$2))*4,0) -> -6.7119
A13: PH | B13: =OFFSET(quadrupoles_hf!$D$2, (ROW([1]quadrpoles_hf!D5)-ROW(dipoles_hf!$D$2))*4,0) -> -14.4015
A15: ZZ/5z | G15: ZZ/4z | M15: ZZ/3z | S15: ZZ/cb2 | Y15: ZZ/r.e | Z15: HF | AA15: MP2 | AB15: CCSD | AC15: CCSD(T)
A16: HF | B16: =OFFSET(quadrupoles_hf!$G$2, (ROW([1]quadrpoles_hf!G2)-ROW(dipoles_hf!$G$2))*4,0) -> -3.1779 | C16: =(OFFSET('cbs_limit(energy)'!$E$41,(ROW('cbs_limit(energy)'!E41)-ROW('cbs_limit(energy)'!$E$41))*4,0)-OFFSET('cbs_limit(energy)'!$F$41,(ROW('cbs_limit(energy)'!F41)-ROW('cbs_limit(energy)'!$F$41))*4,0))/(2*'cbs_limit(energy)'!$L$6)*'cbs_limit(energy)'!$L$3 -> -3.365476 | D16: =(OFFSET('cbs_limit(energy)'!$E$22,(ROW('cbs_limit(energy)'!E22)-ROW('cbs_limit(energy)'!$E$22))*4,0)-OFFSET('cbs_limit(energy)'!$F$22,(ROW('cbs_limit(energy)'!F22)-ROW('cbs_limit(energy)'!$F$22))*4,0))/(2*'cbs_limit(energy)'!$L$6)*'cbs_limit(energy)'!$L$3 -> -3.3206191 | E16: =(OFFSET('cbs_limit(energy)'!$E$3,(ROW('cbs_limit(energy)'!E3)-ROW('cbs_limit(energy)'!$E$3))*4,0)-OFFSET('cbs_limit(energy)'!$F$3,(ROW('cbs_limit(energy)'!F3)-ROW('cbs_limit(energy)'!$F$3))*4,0))/(2*'cbs_limit(energy)'!$L$6)*'cbs_limit(energy)'!$L$3 -> -3.3514876 | H16: =OFFSET(quadrupoles_hf!$G$4, (ROW([1]quadrpoles_hf!G4)-ROW(dipoles_hf!$G$4))*4,0) -> -3.1793 | I16: =(OFFSET('cbs_limit(energy)'!$E$43,(ROW('cbs_limit(energy)'!E43)-ROW('cbs_limit(energy)'!$E$43))*4,0)-OFFSET('cbs_limit(energy)'!$F$43,(ROW('cbs_limit(energy)'!F43)-ROW('cbs_limit(energy)'!$F$43))*4,0))/(2*'cbs_limit(energy)'!$L$6)*'cbs_limit(energy)'!$L$3 -> -3.3739497 | J16: =(OFFSET('cbs_limit(energy)'!$E$24,(ROW('cbs_limit(energy)'!E24)-ROW('cbs_limit(energy)'!$E$24))*4,0)-OFFSET('cbs_limit(energy)'!$F$24,(ROW('cbs_limit(energy)'!F24)-ROW('cbs_limit(energy)'!$F$24))*4,0))/(2*'cbs_limit(energy)'!$L$6)*'cbs_limit(energy)'!$L$3 -> -3.3295636 | K16: =(OFFSET('cbs_limit(energy)'!$E$5,(ROW('cbs_limit(energy)'!E5)-ROW('cbs_limit(energy)'!$E$5))*4,0)-OFFSET('cbs_limit(energy)'!$F$5,(ROW('cbs_limit(energy)'!F5)-ROW('cbs_limit(energy)'!$F$5))*4,0))/(2*'cbs_limit(energy)'!$L$6)*'cbs_limit(energy)'!$L$3 -> -3.3604994 | N16: =OFFSET(quadrupoles_hf!$G$5, (ROW([1]quadrpoles_hf!G5)-ROW(dipoles_hf!$G$5))*4,0) -> -3.1858 | O16: =(OFFSET('cbs_limit(energy)'!$E$44,(ROW('cbs_limit(energy)'!E44)-ROW('cbs_limit(energy)'!$E$44))*4,0)-OFFSET('cbs_limit(energy)'!$F$44,(ROW('cbs_limit(energy)'!F44)-ROW('cbs_limit(energy)'!$F$44))*4,0))/(2*'cbs_limit(energy)'!$L$6)*'cbs_limit(energy)'!$L$3 -> -3.3986311 | P16: =(OFFSET('cbs_limit(energy)'!$E$25,(ROW('cbs_limit(energy)'!E25)-ROW('cbs_limit(energy)'!$E$25))*4,0)-OFFSET('cbs_limit(energy)'!$F$25,(ROW('cbs_limit(energy)'!F25)-ROW('cbs_limit(energy)'!$F$25))*4,0))/(2*'cbs_limit(energy)'!$L$6)*'cbs_limit(energy)'!$L$3 -> -3.3593561 | Q16: =(OFFSET('cbs_limit(energy)'!$E$6,(ROW('cbs_limit(energy)'!E6)-ROW('cbs_limit(energy)'!$E$6))*4,0)-OFFSET('cbs_limit(energy)'!$F$6,(ROW('cbs_limit(energy)'!F6)-ROW('cbs_limit(energy)'!$F$6))*4,0))/(2*'cbs_limit(energy)'!$L$6)*'cbs_limit(energy)'!$L$3 -> -3.3903591 | T16: =B16 -> -3.1779 | U16: =((C16-$B16)*5^3-(I16-$H16)*4^3)/(5^3-4^3)+$T16 -> -3.3580544 | V16: =((D16-$B16)*5^3-(J16-$H16)*4^3)/(5^3-4^3)+$T16 -> -3.3127036 | W16: =((E16-$B16)*5^3-(K16-$H16)*4^3)/(5^3-4^3)+$T16 -> -3.3435016 | Z16: =ABS(T16-B16)/ABS(B16) -> 0 | AA16: =ABS(U16-C16)/ABS(C16) -> 0.0022052155 | AB16: =ABS(V16-D16)/ABS(D16) -> 0.0023837463 | AC16: =ABS(W16-E16)/ABS(E16) -> 0.0023828442
