Workbook
Name quadrupoles: quadrupoles!$A$2:$G$67
Name totalenergies: energies!$A$2:$H$67

Sheet dipoles
A1: molecule_method | B1: X | C1: Y | D1: Z | E1: total | G1: electronic part: | H1: X | I1: Y | J1: Z | O1: debye to e
A2: C2H_ccsd | B2: 0 | C2: 0 | D2: -0.767 | E2: 0.767 | H2: =dipoles[[#This Row],[X]]*$O$2-'q,d_sum'!B2 -> 0 | I2: =dipoles[[#This Row],[Y]]*$O$2-'q,d_sum'!C2 -> 0 | J2: =dipoles[[#This Row],[Z]]*$O$2-'q,d_sum'!D2 -> 11.513776 | O2: 0.3934303
A3: C2H_pbe0 | B3: 0.0000 | C3: -0.0000 | D3: 0.7553 | E3: 0.7553 | H3: =dipoles[[#This Row],[X]]*$O$2-'q,d_sum'!B3 -> 0 | I3: =dipoles[[#This Row],[Y]]*$O$2-'q,d_sum'!C3 -> 0 | J3: =dipoles[[#This Row],[Z]]*$O$2-'q,d_sum'!D3 -> 12.112695
A4: C2H_pbe | B4: 0.0000 | C4: -0.0000 | D4: 0.7654 | E4: 0.7654 | H4: =dipoles[[#This Row],[X]]*$O$2-'q,d_sum'!B4 -> 0 | I4: =dipoles[[#This Row],[Y]]*$O$2-'q,d_sum'!C4 -> 0 | J4: =dipoles[[#This Row],[Z]]*$O$2-'q,d_sum'!D4 -> 12.116668
A5: C2H_scan0 | B5: -0.0000 | C5: -0.0000 | D5: 0.7451 | E5: 0.7451 | H5: =dipoles[[#This Row],[X]]*$O$2-'q,d_sum'!B5 -> 0 | I5: =dipoles[[#This Row],[Y]]*$O$2-'q,d_sum'!C5 -> 0 | J5: =dipoles[[#This Row],[Z]]*$O$2-'q,d_sum'!D5 -> 12.108682
A6: C2H_scan | B6: 0.0000 | C6: 0.0000 | D6: 0.7502 | E6: 0.7502 | H6: =dipoles[[#This Row],[X]]*$O$2-'q,d_sum'!B6 -> 0 | I6: =dipoles[[#This Row],[Y]]*$O$2-'q,d_sum'!C6 -> 0 | J6: =dipoles[[#This Row],[Z]]*$O$2-'q,d_sum'!D6 -> 12.110688
A7: C2H_spw92 | B7: 0.0000 | C7: 0.0000 | D7: 0.7654 | E7: 0.7654 | H7: =dipoles[[#This Row],[X]]*$O$2-'q,d_sum'!B7 -> 0 | I7: =dipoles[[#This Row],[Y]]*$O$2-'q,d_sum'!C7 -> 0 | J7: =dipoles[[#This Row],[Z]]*$O$2-'q,d_sum'!D7 -> 12.116668
A8: CH4_ccsd | B8: 0 | C8: 0 | D8: 0 | E8: 0 | H8: =dipoles[[#This Row],[X]]*$O$2-'q,d_sum'!B8 -> 0 | I8: =dipoles[[#This Row],[Y]]*$O$2-'q,d_sum'!C8 -> 0 | J8: =dipoles[[#This Row],[Z]]*$O$2-'q,d_sum'!D8 -> 0
A9: CH4_pbe0 | B9: -0.0000 | C9: -0.0000 | D9: -0.0000 | E9: 0.0000 | H9: =dipoles[[#This Row],[X]]*$O$2-'q,d_sum'!B9 -> 0 | I9: =dipoles[[#This Row],[Y]]*$O$2-'q,d_sum'!C9 -> 0 | J9: =dipoles[[#This Row],[Z]]*$O$2-'q,d_sum'!D9 -> 0
A10: CH4_pbe | B10: -0.0000 | C10: -0.0000 | D10: 0.0000 | E10: 0.0000 | H10: =dipoles[[#This Row],[X]]*$O$2-'q,d_sum'!B10 -> 0 | I10: =dipoles[[#This Row],[Y]]*$O$2-'q,d_sum'!C10 -> 0 | J10: =dipoles[[#This Row],[Z]]*$O$2-'q,d_sum'!D10 -> 0
A11: CH4_scan0 | B11: -0.0000 | C11: 0.0000 | D11: -0.0000 | E11: 0.0000 | H11: =dipoles[[#This Row],[X]]*$O$2-'q,d_sum'!B11 -> 0 | I11: =dipoles[[#This Row],[Y]]*$O$2-'q,d_sum'!C11 -> 0 | J11: =dipoles[[#This Row],[Z]]*$O$2-'q,d_sum'!D11 -> 0
A12: CH4_scan | B12: -0.0000 | C12: -0.0000 | D12: -0.0000 | E12: 0.0000 | H12: =dipoles[[#This Row],[X]]*$O$2-'q,d_sum'!B12 -> 0 | I12: =dipoles[[#This Row],[Y]]*$O$2-'q,d_sum'!C12 -> 0 | J12: =dipoles[[#This Row],[Z]]*$O$2-'q,d_sum'!D12 -> 0
A13: CH4_spw92 | B13: 0.0000 | C13: -0.0000 | D13: -0.0000 | E13: 0.0000 | H13: =dipoles[[#This Row],[X]]*$O$2-'q,d_sum'!B13 -> 0 | I13: =dipoles[[#This Row],[Y]]*$O$2-'q,d_sum'!C13 -> 0 | J13: =dipoles[[#This Row],[Z]]*$O$2-'q,d_sum'!D13 -> 0
A14: CN_ccsd | B14: 0 | C14: 0 | D14: -1.566 | E14: 1.566 | H14: =dipoles[[#This Row],[X]]*$O$2-'q,d_sum'!B14 -> 0 | I14: =dipoles[[#This Row],[Y]]*$O$2-'q,d_sum'!C14 -> 0 | J14: =dipoles[[#This Row],[Z]]*$O$2-'q,d_sum'!D14 -> -13.902426
A15: CN_pbe0 | B15: -0.0000 | C15: -0.0000 | D15: 1.4805 | E15: 1.4805 | H15: =dipoles[[#This Row],[X]]*$O$2-'q,d_sum'!B15 -> 0 | I15: =dipoles[[#This Row],[Y]]*$O$2-'q,d_sum'!C15 -> 0 | J15: =dipoles[[#This Row],[Z]]*$O$2-'q,d_sum'!D15 -> -12.70384
A16: CN_pbe | B16: 0.0000 | C16: -0.0000 | D16: 1.1524 | E16: 1.1524 | H16: =dipoles[[#This Row],[X]]*$O$2-'q,d_sum'!B16 -> 0 | I16: =dipoles[[#This Row],[Y]]*$O$2-'q,d_sum'!C16 -> 0 | J16: =dipoles[[#This Row],[Z]]*$O$2-'q,d_sum'!D16 -> -12.832925
A17: CN_scan0 | B17: -0.0000 | C17: 0.0000 | D17: 1.7024 | E17: 1.7024 | H17: =dipoles[[#This Row],[X]]*$O$2-'q,d_sum'!B17 -> 0 | I17: =dipoles[[#This Row],[Y]]*$O$2-'q,d_sum'!C17 -> 0 | J17: =dipoles[[#This Row],[Z]]*$O$2-'q,d_sum'!D17 -> -12.616538
A18: CN_scan | B18: 0.0000 | C18: -0.0000 | D18: 1.4404 | E18: 1.4404 | H18: =dipoles[[#This Row],[X]]*$O$2-'q,d_sum'!B18 -> 0 | I18: =dipoles[[#This Row],[Y]]*$O$2-'q,d_sum'!C18 -> 0 | J18: =dipoles[[#This Row],[Z]]*$O$2-'q,d_sum'!D18 -> -12.719617
A19: CN_spw92 | B19: 0.0000 | C19: -0.0000 | D19: 1.1524 | E19: 1.1524 | H19: =dipoles[[#This Row],[X]]*$O$2-'q,d_sum'!B19 -> 0 | I19: =dipoles[[#This Row],[Y]]*$O$2-'q,d_sum'!C19 -> 0 | J19: =dipoles[[#This Row],[Z]]*$O$2-'q,d_sum'!D19 -> -12.832925
A20: CO_ccsd | B20: 0 | C20: 0 | D20: 0.068 | E20: 0.068 | H20: =dipoles[[#This Row],[X]]*$O$2-'q,d_sum'!B20 -> 0 | I20: =dipoles[[#This Row],[Y]]*$O$2-'q,d_sum'!C20 -> 0 | J20: =dipoles[[#This Row],[Z]]*$O$2-'q,d_sum'!D20 -> 0.02675326
A21: CO_pbe0 | B21: 0.0000 | C21: -0.0000 | D21: 0.1018 | E21: 0.1018 | H21: =dipoles[[#This Row],[X]]*$O$2-'q,d_sum'!B21 -> 0 | I21: =dipoles[[#This Row],[Y]]*$O$2-'q,d_sum'!C21 -> 0 | J21: =dipoles[[#This Row],[Z]]*$O$2-'q,d_sum'!D21 -> 0.040051205
A22: CO_pbe | B22: -0.0000 | C22: 0.0000 | D22: 0.2239 | E22: 0.2239 | H22: =dipoles[[#This Row],[X]]*$O$2-'q,d_sum'!B22 -> 0 | I22: =dipoles[[#This Row],[Y]]*$O$2-'q,d_sum'!C22 -> 0 | J22: =dipoles[[#This Row],[Z]]*$O$2-'q,d_sum'!D22 -> 0.088089044
A23: CO_scan0 | B23: 0.0000 | C23: 0.0000 | D23: 0.0322 | E23: 0.0322 | H23: =dipoles[[#This Row],[X]]*$O$2-'q,d_sum'!B23 -> 0 | I23: =dipoles[[#This Row],[Y]]*$O$2-'q,d_sum'!C23 -> 0 | J23: =dipoles[[#This Row],[Z]]*$O$2-'q,d_sum'!D23 -> 0.012668456
A24: CO_scan | B24: -0.0000 | C24: -0.0000 | D24: 0.1318 | E24: 0.1318 | H24: =dipoles[[#This Row],[X]]*$O$2-'q,d_sum'!B24 -> 0 | I24: =dipoles[[#This Row],[Y]]*$O$2-'q,d_sum'!C24 -> 0 | J24: =dipoles[[#This Row],[Z]]*$O$2-'q,d_sum'!D24 -> 0.051854114
A25: CO_spw92 | B25: -0.0000 | C25: 0.0000 | D25: 0.2290 | E25: 0.2290 | H25: =dipoles[[#This Row],[X]]*$O$2-'q,d_sum'!B25 -> 0 | I25: =dipoles[[#This Row],[Y]]*$O$2-'q,d_sum'!C25 -> 0 | J25: =dipoles[[#This Row],[Z]]*$O$2-'q,d_sum'!D25 -> 0.090095539
A26: CO2_ccsd | B26: 0 | C26: 0 | D26: 0 | E26: 0 | H26: =dipoles[[#This Row],[X]]*$O$2-'q,d_sum'!B26 -> 0 | I26: =dipoles[[#This Row],[Y]]*$O$2-'q,d_sum'!C26 -> 0 | J26: =dipoles[[#This Row],[Z]]*$O$2-'q,d_sum'!D26 -> -17.055947
A27: CO2_pbe0 | B27: -0.0000 | C27: -0.0000 | D27: 0.0000 | E27: 0.0000 | H27: =dipoles[[#This Row],[X]]*$O$2-'q,d_sum'!B27 -> 0 | I27: =dipoles[[#This Row],[Y]]*$O$2-'q,d_sum'!C27 -> 0 | J27: =dipoles[[#This Row],[Z]]*$O$2-'q,d_sum'!D27 -> -17.055947
A28: CO2_pbe | B28: 0.0000 | C28: 0.0000 | D28: -0.0000 | E28: 0.0000 | H28: =dipoles[[#This Row],[X]]*$O$2-'q,d_sum'!B28 -> 0 | I28: =dipoles[[#This Row],[Y]]*$O$2-'q,d_sum'!C28 -> 0 | J28: =dipoles[[#This Row],[Z]]*$O$2-'q,d_sum'!D28 -> -17.055947
A29: CO2_scan0 | B29: 0.0000 | C29: 0.0000 | D29: 0.0000 | E29: 0.0000 | H29: =dipoles[[#This Row],[X]]*$O$2-'q,d_sum'!B29 -> 0 | I29: =dipoles[[#This Row],[Y]]*$O$2-'q,d_sum'!C29 -> 0 | J29: =dipoles[[#This Row],[Z]]*$O$2-'q,d_sum'!D29 -> -17.055947
A30: CO2_scan | B30: -0.0000 | C30: -0.0000 | D30: 0.0000 | E30: 0.0000 | H30: =dipoles[[#This Row],[X]]*$O$2-'q,d_sum'!B30 -> 0 | I30: =dipoles[[#This Row],[Y]]*$O$2-'q,d_sum'!C30 -> 0 | J30: =dipoles[[#This Row],[Z]]*$O$2-'q,d_sum'!D30 -> -17.055947
A31: CO2_spw92 | B31: 0.0000 | C31: -0.0000 | D31: 0.0000 | E31: 0.0000 | H31: =dipoles[[#This Row],[X]]*$O$2-'q,d_sum'!B31 -> 0 | I31: =dipoles[[#This Row],[Y]]*$O$2-'q,d_sum'!C31 -> 0 | J31: =dipoles[[#This Row],[Z]]*$O$2-'q,d_sum'!D31 -> -17.055947
A32: H2O_ccsd | B32: 0 | C32: 0 | D32: -1.863 | E32: 1.863 | H32: =dipoles[[#This Row],[X]]*$O$2-'q,d_sum'!B32 -> 0 | I32: =dipoles[[#This Row],[Y]]*$O$2-'q,d_sum'!C32 -> 0 | J32: =dipoles[[#This Row],[Z]]*$O$2-'q,d_sum'!D32 -> -0.73296065
A33: H2O_pbe0 | B33: 0.0000 | C33: -0.0000 | D33: -1.8579 | E33: 1.8579 | H33: =dipoles[[#This Row],[X]]*$O$2-'q,d_sum'!B33 -> 0 | I33: =dipoles[[#This Row],[Y]]*$O$2-'q,d_sum'!C33 -> 0 | J33: =dipoles[[#This Row],[Z]]*$O$2-'q,d_sum'!D33 -> -0.73095415
A34: H2O_pbe | B34: -0.0000 | C34: -0.0000 | D34: -1.7949 | E34: 1.7949 | H34: =dipoles[[#This Row],[X]]*$O$2-'q,d_sum'!B34 -> 0 | I34: =dipoles[[#This Row],[Y]]*$O$2-'q,d_sum'!C34 -> 0 | J34: =dipoles[[#This Row],[Z]]*$O$2-'q,d_sum'!D34 -> -0.70616805
A35: H2O_scan0 | B35: -0.0000 | C35: 0.0000 | D35: -1.8853 | E35: 1.8853 | H35: =dipoles[[#This Row],[X]]*$O$2-'q,d_sum'!B35 -> 0 | I35: =dipoles[[#This Row],[Y]]*$O$2-'q,d_sum'!C35 -> 0 | J35: =dipoles[[#This Row],[Z]]*$O$2-'q,d_sum'!D35 -> -0.74173414
A36: H2O_scan | B36: -0.0000 | C36: -0.0000 | D36: -1.8396 | E36: 1.8396 | H36: =dipoles[[#This Row],[X]]*$O$2-'q,d_sum'!B36 -> 0 | I36: =dipoles[[#This Row],[Y]]*$O$2-'q,d_sum'!C36 -> 0 | J36: =dipoles[[#This Row],[Z]]*$O$2-'q,d_sum'!D36 -> -0.72375438
A37: H2O_spw92 | B37: -0.0000 | C37: 0.0000 | D37: -1.7949 | E37: 1.7949 | H37: =dipoles[[#This Row],[X]]*$O$2-'q,d_sum'!B37 -> 0 | I37: =dipoles[[#This Row],[Y]]*$O$2-'q,d_sum'!C37 -> 0 | J37: =dipoles[[#This Row],[Z]]*$O$2-'q,d_sum'!D37 -> -0.70616805
A38: HCO_ccsd | H38: =dipoles[[#This Row],[X]]*$O$2-'q,d_sum'!B38 -> #VALUE! | I38: =dipoles[[#This Row],[Y]]*$O$2-'q,d_sum'!C38 -> #VALUE! | J38: =dipoles[[#This Row],[Z]]*$O$2-'q,d_sum'!D38 -> #VALUE!
A39: HCO_pbe0 | B39: 1.5806 | C39: -0.6828 | D39: 0.0000 | E39: 1.7218 | H39: =dipoles[[#This Row],[X]]*$O$2-'q,d_sum'!B39 -> 7.4989613 | I39: =dipoles[[#This Row],[Y]]*$O$2-'q,d_sum'!C39 -> -16.032006 | J39: =dipoles[[#This Row],[Z]]*$O$2-'q,d_sum'!D39 -> 0
A40: HCO_pbe | B40: 1.4661 | C40: -0.5192 | D40: -0.0000 | E40: 1.5553 | H40: =dipoles[[#This Row],[X]]*$O$2-'q,d_sum'!B40 -> 7.4539136 | I40: =dipoles[[#This Row],[Y]]*$O$2-'q,d_sum'!C40 -> -15.967641 | J40: =dipoles[[#This Row],[Z]]*$O$2-'q,d_sum'!D40 -> 0
...

Sheet quadrupoles
B1: XX | C1: XY | D1: YY | E1: XZ | F1: XZ | G1: ZZ | I1: electronic part: | J1: XX | K1: YY | L1: ZZ | N1: ea0 to debye-ang
A2: C2H_ccsd | B2: =(energies!C2-energies!D2)/(2*$N$5)*$N$2 -> -12.967347 | C2: 0 | D2: =(energies!E2-energies!F2)/(2*$N$5)*$N$2 -> -12.967347 | E2: 0 | F2: 0 | G2: =(energies!G2-energies!H2)/(2*$N$5)*$N$2 -> -8.9708897 | J2: =B2*$N$2-'q,d_sum'!E2 -> -17.441518 | K2: =D2*$N$2-'q,d_sum'!F2 -> -17.441518 | L2: =G2*$N$2-'q,d_sum'!G2 -> -47.685509 | N2: 1.3450337
A3: C2H_pbe0 | B3: =(energies!C3-energies!D3)/(2*$N$5)*$N$2 -> -12.887028 | C3: 0 | D3: -12.887 | E3: 0 | F3: 0 | G3: -8.9179 | J3: =B3*$N$2-'q,d_sum'!E3 -> -17.333486 | K3: =D3*$N$2-'q,d_sum'!F3 -> -17.333449 | L3: =G3*$N$2-'q,d_sum'!G3 -> -47.614236
A4: C2H_pbe | B4: =(energies!C4-energies!D4)/(2*$N$5)*$N$2 -> -12.900974 | C4: 0 | D4: -12.901 | E4: 0 | F4: 0 | G4: -9.1582 | J4: =B4*$N$2-'q,d_sum'!E4 -> -17.352244 | K4: =D4*$N$2-'q,d_sum'!F4 -> -17.352279 | L4: =G4*$N$2-'q,d_sum'!G4 -> -47.937447 | N4: step size
A5: C2H_scan0 | B5: =(energies!C5-energies!D5)/(2*$N$5)*$N$2 -> -12.866433 | C5: 0 | D5: -12.8664 | E5: 0 | F5: 0 | G5: -8.7862 | J5: =B5*$N$2-'q,d_sum'!E5 -> -17.305785 | K5: =D5*$N$2-'q,d_sum'!F5 -> -17.305741 | L5: =G5*$N$2-'q,d_sum'!G5 -> -47.437095 | N5: 0.0001
A6: C2H_scan | B6: =(energies!C6-energies!D6)/(2*$N$5)*$N$2 -> -12.830029 | C6: 0 | D6: -12.83 | E6: 0 | F6: 0 | G6: -8.8822 | J6: =B6*$N$2-'q,d_sum'!E6 -> -17.256821 | K6: =D6*$N$2-'q,d_sum'!F6 -> -17.256782 | L6: =G6*$N$2-'q,d_sum'!G6 -> -47.566218
A7: C2H_spw92 | B7: =(energies!C7-energies!D7)/(2*$N$5)*$N$2 -> -12.900974 | C7: 0 | D7: -12.901 | E7: 0 | F7: 0 | G7: -9.1582 | J7: =B7*$N$2-'q,d_sum'!E7 -> -17.352244 | K7: =D7*$N$2-'q,d_sum'!F7 -> -17.352279 | L7: =G7*$N$2-'q,d_sum'!G7 -> -47.937447
A8: CH4_ccsd | B8: =(energies!C8-energies!D8)/(2*$N$5)*$N$2 -> -8.4109421 | C8: 0 | D8: =(energies!E8-energies!F8)/(2*$N$5)*$N$2 -> -8.4109421 | E8: 0 | F8: 0 | G8: =(energies!G8-energies!H8)/(2*$N$5)*$N$2 -> -8.4109421 | J8: =B8*$N$2-'q,d_sum'!E8 -> -16.939333 | K8: =D8*$N$2-'q,d_sum'!F8 -> -16.939333 | L8: =G8*$N$2-'q,d_sum'!G8 -> -16.939333
A9: CH4_pbe0 | B9: -8.3942 | C9: 0 | D9: -8.3942 | E9: 0 | F9: 0 | G9: -8.3942 | J9: =B9*$N$2-'q,d_sum'!E9 -> -16.916814 | K9: =D9*$N$2-'q,d_sum'!F9 -> -16.916814 | L9: =G9*$N$2-'q,d_sum'!G9 -> -16.916814
A10: CH4_pbe | B10: -8.4939 | C10: 0 | D10: -8.4939 | E10: 0 | F10: 0 | G10: -8.4939 | J10: =B10*$N$2-'q,d_sum'!E10 -> -17.050914 | K10: =D10*$N$2-'q,d_sum'!F10 -> -17.050914 | L10: =G10*$N$2-'q,d_sum'!G10 -> -17.050914
A11: CH4_scan0 | B11: -8.347 | C11: 0 | D11: -8.347 | E11: 0 | F11: 0 | G11: -8.347 | J11: =B11*$N$2-'q,d_sum'!E11 -> -16.853328 | K11: =D11*$N$2-'q,d_sum'!F11 -> -16.853328 | L11: =G11*$N$2-'q,d_sum'!G11 -> -16.853328
A12: CH4_scan | B12: -8.3783 | C12: 0 | D12: -8.3783 | E12: 0 | F12: 0 | G12: -8.3783 | J12: =B12*$N$2-'q,d_sum'!E12 -> -16.895428 | K12: =D12*$N$2-'q,d_sum'!F12 -> -16.895428 | L12: =G12*$N$2-'q,d_sum'!G12 -> -16.895428
A13: CH4_spw92 | B13: -8.4939 | C13: 0 | D13: -8.4939 | E13: 0 | F13: 0 | G13: -8.4939 | J13: =B13*$N$2-'q,d_sum'!E13 -> -17.050914 | K13: =D13*$N$2-'q,d_sum'!F13 -> -17.050914 | L13: =G13*$N$2-'q,d_sum'!G13 -> -17.050914
A14: CN_ccsd | B14: =(energies!C14-energies!D14)/(2*$N$5)*$N$2 -> -11.043129 | C14: 0 | D14: =(energies!E14-energies!F14)/(2*$N$5)*$N$2 -> -11.043129 | E14: 0 | F14: 0 | G14: =(energies!G14-energies!H14)/(2*$N$5)*$N$2 -> -8.0484333 | J14: =B14*$N$2-'q,d_sum'!E14 -> -14.85338 | K14: =D14*$N$2-'q,d_sum'!F14 -> -14.85338 | L14: =G14*$N$2-'q,d_sum'!G14 -> -40.246436
A15: CN_pbe0 | B15: -11.0323 | C15: 0 | D15: -11.0323 | E15: 0 | F15: 0 | G15: -8.7607 | J15: =B15*$N$2-'q,d_sum'!E15 -> -14.838815 | K15: =D15*$N$2-'q,d_sum'!F15 -> -14.838815 | L15: =G15*$N$2-'q,d_sum'!G15 -> -41.204458
A16: CN_pbe | B16: -11.0544 | C16: 0 | D16: -11.0544 | E16: 0 | F16: 0 | G16: -9.3233 | J16: =B16*$N$2-'q,d_sum'!E16 -> -14.86854 | K16: =D16*$N$2-'q,d_sum'!F16 -> -14.86854 | L16: =G16*$N$2-'q,d_sum'!G16 -> -41.961174
A17: CN_scan0 | B17: -10.9977 | C17: 0 | D17: -10.9977 | E17: 0 | F17: 0 | G17: -8.3959 | J17: =B17*$N$2-'q,d_sum'!E17 -> -14.792277 | K17: =D17*$N$2-'q,d_sum'!F17 -> -14.792277 | L17: =G17*$N$2-'q,d_sum'!G17 -> -40.71379
A18: CN_scan | B18: -10.9701 | C18: 0 | D18: -10.9701 | E18: 0 | F18: 0 | G18: -8.7925 | J18: =B18*$N$2-'q,d_sum'!E18 -> -14.755154 | K18: =D18*$N$2-'q,d_sum'!F18 -> -14.755154 | L18: =G18*$N$2-'q,d_sum'!G18 -> -41.24723
A19: CN_spw92 | B19: -11.0544 | C19: 0 | D19: -11.0544 | E19: 0 | F19: 0 | G19: -9.3233 | J19: =B19*$N$2-'q,d_sum'!E19 -> -14.86854 | K19: =D19*$N$2-'q,d_sum'!F19 -> -14.86854 | L19: =G19*$N$2-'q,d_sum'!G19 -> -41.961174
A20: CO2_ccsd | B20: =(energies!C20-energies!D20)/(2*$N$5)*$N$2 -> -14.814998 | C20: 0 | D20: =(energies!E20-energies!F20)/(2*$N$5)*$N$2 -> -14.814998 | E20: 0 | F20: 0 | G20: =(energies!G20-energies!H20)/(2*$N$5)*$N$2 -> -19.948552 | J20: =B20*$N$2-'q,d_sum'!E20 -> -19.926671 | K20: =D20*$N$2-'q,d_sum'!F20 -> -19.926671 | L20: =G20*$N$2-'q,d_sum'!G20 -> -103.99401
A21: CO2_pbe0 | B21: -14.8102 | C21: 0 | D21: -14.8102 | E21: 0 | F21: 0 | G21: -19.1668 | J21: =B21*$N$2-'q,d_sum'!E21 -> -19.920218 | K21: =D21*$N$2-'q,d_sum'!F21 -> -19.920218 | L21: =G21*$N$2-'q,d_sum'!G21 -> -102.94253
A22: CO2_pbe | B22: -14.8972 | C22: 0 | D22: -14.8972 | E22: 0 | F22: 0 | G22: -19.0559 | J22: =B22*$N$2-'q,d_sum'!E22 -> -20.037236 | K22: =D22*$N$2-'q,d_sum'!F22 -> -20.037236 | L22: =G22*$N$2-'q,d_sum'!G22 -> -102.79336
A23: CO2_scan0 | B23: -14.7407 | C23: 0 | D23: -14.7407 | E23: 0 | F23: 0 | G23: -19.2046 | J23: =B23*$N$2-'q,d_sum'!E23 -> -19.826738 | K23: =D23*$N$2-'q,d_sum'!F23 -> -19.826738 | L23: =G23*$N$2-'q,d_sum'!G23 -> -102.99337
A24: CO2_scan | B24: -14.7535 | C24: 0 | D24: -14.7535 | E24: 0 | F24: 0 | G24: -19.0756 | J24: =B24*$N$2-'q,d_sum'!E24 -> -19.843954 | K24: =D24*$N$2-'q,d_sum'!F24 -> -19.843954 | L24: =G24*$N$2-'q,d_sum'!G24 -> -102.81986
A25: CO2_spw92 | B25: -14.8972 | C25: 0 | D25: -14.8972 | E25: 0 | F25: 0 | G25: -19.0559 | J25: =B25*$N$2-'q,d_sum'!E25 -> -20.037236 | K25: =D25*$N$2-'q,d_sum'!F25 -> -20.037236 | L25: =G25*$N$2-'q,d_sum'!G25 -> -102.79336
A26: CO_ccsd | B26: =(energies!C26-energies!D26)/(2*$N$5)*$N$2 -> -10.219992 | C26: 0 | D26: =(energies!E26-energies!F26)/(2*$N$5)*$N$2 -> -10.219992 | E26: 0 | F26: 0 | G26: =(energies!G26-energies!H26)/(2*$N$5)*$N$2 -> -12.636292 | J26: =B26*$N$2-'q,d_sum'!E26 -> -13.746233 | K26: =D26*$N$2-'q,d_sum'!F26 -> -13.746233 | L26: =G26*$N$2-'q,d_sum'!G26 -> -53.359405
A27: CO_pbe0 | B27: -10.2495 | C27: -0.0000 | D27: -10.2495 | E27: -0.0000 | F27: 0.0000 | G27: -12.1149 | J27: =B27*$N$2-'q,d_sum'!E27 -> -13.785923 | K27: =D27*$N$2-'q,d_sum'!F27 -> -13.785923 | L27: =G27*$N$2-'q,d_sum'!G27 -> -52.658115
A28: CO_pbe | B28: -10.3366 | C28: 0.0000 | D28: -10.3366 | E28: -0.0000 | F28: -0.0000 | G28: -12.0609 | J28: =B28*$N$2-'q,d_sum'!E28 -> -13.903075 | K28: =D28*$N$2-'q,d_sum'!F28 -> -13.903075 | L28: =G28*$N$2-'q,d_sum'!G28 -> -52.585483
A29: CO_scan0 | B29: -10.1947 | C29: -0.0000 | D29: -10.1947 | E29: -0.0000 | F29: -0.0000 | G29: -12.1498 | J29: =B29*$N$2-'q,d_sum'!E29 -> -13.712215 | K29: =D29*$N$2-'q,d_sum'!F29 -> -13.712215 | L29: =G29*$N$2-'q,d_sum'!G29 -> -52.705056
A30: CO_scan | B30: -10.2171 | C30: -0.0000 | D30: -10.2171 | E30: -0.0000 | F30: 0.0000 | G30: -12.0790 | J30: =B30*$N$2-'q,d_sum'!E30 -> -13.742343 | K30: =D30*$N$2-'q,d_sum'!F30 -> -13.742343 | L30: =G30*$N$2-'q,d_sum'!G30 -> -52.609828
A31: CO_spw92 | B31: -10.3949 | C31: -0.0000 | D31: -10.3949 | E31: -0.0000 | F31: -0.0000 | G31: -12.0857 | J31: =B31*$N$2-'q,d_sum'!E31 -> -13.98149 | K31: =D31*$N$2-'q,d_sum'!F31 -> -13.98149 | L31: =G31*$N$2-'q,d_sum'!G31 -> -52.61884
A32: H2O_ccsd | B32: =(energies!C32-energies!D32)/(2*$N$5)*$N$2 -> -7.5589514 | C32: 0 | D32: =(energies!E32-energies!F32)/(2*$N$5)*$N$2 -> -4.2447117 | E32: 0 | F32: 0 | G32: =(energies!G32-energies!H32)/(2*$N$5)*$N$2 -> -6.2426147 | J32: =B32*$N$2-'q,d_sum'!E32 -> -10.167044 | K32: =D32*$N$2-'q,d_sum'!F32 -> -9.8042502 | L32: =G32*$N$2-'q,d_sum'!G32 -> -10.361948
A33: H2O_pbe0 | B33: -7.726 | C33: 0 | D33: -4.4247 | E33: 0 | F33: 0 | G33: -6.4106 | J33: =B33*$N$2-'q,d_sum'!E33 -> -10.39173 | K33: =D33*$N$2-'q,d_sum'!F33 -> -10.04634 | L33: =G33*$N$2-'q,d_sum'!G33 -> -10.587894
A34: H2O_pbe | B34: -7.8672 | C34: 0 | D34: -4.5662 | E34: 0 | F34: 0 | G34: -6.549 | J34: =B34*$N$2-'q,d_sum'!E34 -> -10.581649 | K34: =D34*$N$2-'q,d_sum'!F34 -> -10.236663 | L34: =G34*$N$2-'q,d_sum'!G34 -> -10.774046
A35: H2O_scan0 | B35: -7.6496 | C35: 0 | D35: -4.3385 | E35: 0 | F35: 0 | G35: -6.338 | J35: =B35*$N$2-'q,d_sum'!E35 -> -10.28897 | K35: =D35*$N$2-'q,d_sum'!F35 -> -9.9303985 | L35: =G35*$N$2-'q,d_sum'!G35 -> -10.490244
A36: H2O_scan | B36: -7.7149 | C36: 0 | D36: -4.4075 | E36: 0 | F36: 0 | G36: -6.4065 | J36: =B36*$N$2-'q,d_sum'!E36 -> -10.3768 | K36: =D36*$N$2-'q,d_sum'!F36 -> -10.023206 | L36: =G36*$N$2-'q,d_sum'!G36 -> -10.582379
A37: H2O_spw92 | B37: -7.8672 | C37: 0 | D37: -4.5662 | E37: 0 | F37: 0 | G37: -6.549 | J37: =B37*$N$2-'q,d_sum'!E37 -> -10.581649 | K37: =D37*$N$2-'q,d_sum'!F37 -> -10.236663 | L37: =G37*$N$2-'q,d_sum'!G37 -> -10.774046
A38: HCO_ccsd | B38: =(energies!C38-energies!D38)/(2*$N$5)*$N$2 -> -11.287553 | D38: =(energies!E38-energies!F38)/(2*$N$5)*$N$2 -> -13.754912 | G38: =(energies!G38-energies!H38)/(2*$N$5)*$N$2 -> -10.980702 | J38: =B38*$N$2-'q,d_sum'!E38 -> -29.288818 | K38: =D38*$N$2-'q,d_sum'!F38 -> -49.561306 | L38: =G38*$N$2-'q,d_sum'!G38 -> -14.769414
A39: HCO_pbe0 | B39: -11.2044 | C39: 0.6098 | D39: -13.4142 | E39: 0 | F39: 0 | G39: -11.0017 | J39: =B39*$N$2-'q,d_sum'!E39 -> -29.176974 | K39: =D39*$N$2-'q,d_sum'!F39 -> -49.103037 | L39: =G39*$N$2-'q,d_sum'!G39 -> -14.797657
A40: HCO_pbe | B40: -11.3376 | C40: 0.5275 | D40: -13.4217 | E40: 0 | F40: 0 | G40: -11.085 | J40: =B40*$N$2-'q,d_sum'!E40 -> -29.356132 | K40: =D40*$N$2-'q,d_sum'!F40 -> -49.113125 | L40: =G40*$N$2-'q,d_sum'!G40 -> -14.909698
...

Sheet stdev
B1: tot_e | C1: XX | D1: YY | E1: ZZ | M1: Conversion factor: | Q1: Sorted: | S1: ZZ
A2: C2H_ccsd | B2: 13 | C2: =SQRT((quadrupoles!J2/-stdev!B2)-(dipoles!H2/-stdev!B2)^2) -> 1.1582984 | D2: =SQRT((quadrupoles!K2/-stdev!B2)-(dipoles!I2/-stdev!B2)^2) -> 1.1582984 | E2: =SQRT((quadrupoles!L2/-stdev!B2)-(dipoles!J2/-stdev!B2)^2) -> 1.6981448 | M2: ea0 to debye-ang | N2: =1/0.3934303*0.529177 -> 1.3450337 | R2: HF_ccsd | S2: 0.81785934
A3: C2H_pbe0 | B3: 13 | C3: =SQRT((quadrupoles!J3/-stdev!B3)-(dipoles!H3/-stdev!B3)^2) -> 1.1547056 | D3: =SQRT((quadrupoles!K3/-stdev!B3)-(dipoles!I3/-stdev!B3)^2) -> 1.1547044 | E3: =SQRT((quadrupoles!L3/-stdev!B3)-(dipoles!J3/-stdev!B3)^2) -> 1.6716708 | R3: HF_scan0 | S3: 0.85837319
A4: C2H_pbe | B4: 13 | C4: =SQRT((quadrupoles!J4/-stdev!B4)-(dipoles!H4/-stdev!B4)^2) -> 1.1553303 | D4: =SQRT((quadrupoles!K4/-stdev!B4)-(dipoles!I4/-stdev!B4)^2) -> 1.1553314 | E4: =SQRT((quadrupoles!L4/-stdev!B4)-(dipoles!J4/-stdev!B4)^2) -> 1.6789211 | R4: HF_scan | S4: 0.86415389
A5: C2H_scan0 | B5: 13 | C5: =SQRT((quadrupoles!J5/-stdev!B5)-(dipoles!H5/-stdev!B5)^2) -> 1.1537826 | D5: =SQRT((quadrupoles!K5/-stdev!B5)-(dipoles!I5/-stdev!B5)^2) -> 1.1537811 | E5: =SQRT((quadrupoles!L5/-stdev!B5)-(dipoles!J5/-stdev!B5)^2) -> 1.6677627 | R5: HF_pbe0 | S5: 0.86484406
A6: C2H_scan | B6: 13 | C6: =SQRT((quadrupoles!J6/-stdev!B6)-(dipoles!H6/-stdev!B6)^2) -> 1.1521492 | D6: =SQRT((quadrupoles!K6/-stdev!B6)-(dipoles!I6/-stdev!B6)^2) -> 1.1521479 | E6: =SQRT((quadrupoles!L6/-stdev!B6)-(dipoles!J6/-stdev!B6)^2) -> 1.6706518 | M6: debye to e | N6: 0.3934303 | R6: HF_pbe | S6: 0.8752982
A7: C2H_spw92 | B7: 13 | C7: =SQRT((quadrupoles!J7/-stdev!B7)-(dipoles!H7/-stdev!B7)^2) -> 1.1553303 | D7: =SQRT((quadrupoles!K7/-stdev!B7)-(dipoles!I7/-stdev!B7)^2) -> 1.1553314 | E7: =SQRT((quadrupoles!L7/-stdev!B7)-(dipoles!J7/-stdev!B7)^2) -> 1.6789211 | R7: HF_spw92 | S7: 0.8752982
A8: CH4_ccsd | B8: 10 | C8: =SQRT((quadrupoles!J8/-stdev!B8)-(dipoles!H8/-stdev!B8)^2) -> 1.3015119 | D8: =SQRT((quadrupoles!K8/-stdev!B8)-(dipoles!I8/-stdev!B8)^2) -> 1.3015119 | E8: =SQRT((quadrupoles!L8/-stdev!B8)-(dipoles!J8/-stdev!B8)^2) -> 1.3015119 | R8: HO2_ccsd | S8: 0.92994696
A9: CH4_pbe0 | B9: 10 | C9: =SQRT((quadrupoles!J9/-stdev!B9)-(dipoles!H9/-stdev!B9)^2) -> 1.3006465 | D9: =SQRT((quadrupoles!K9/-stdev!B9)-(dipoles!I9/-stdev!B9)^2) -> 1.3006465 | E9: =SQRT((quadrupoles!L9/-stdev!B9)-(dipoles!J9/-stdev!B9)^2) -> 1.3006465 | R9: HO2_scan0 | S9: 0.93295812
A10: CH4_pbe | B10: 10 | C10: =SQRT((quadrupoles!J10/-stdev!B10)-(dipoles!H10/-stdev!B10)^2) -> 1.3057915 | D10: =SQRT((quadrupoles!K10/-stdev!B10)-(dipoles!I10/-stdev!B10)^2) -> 1.3057915 | E10: =SQRT((quadrupoles!L10/-stdev!B10)-(dipoles!J10/-stdev!B10)^2) -> 1.3057915 | R10: HO2_scan | S10: 0.93452993
A11: CH4_scan0 | B11: 10 | C11: =SQRT((quadrupoles!J11/-stdev!B11)-(dipoles!H11/-stdev!B11)^2) -> 1.2982037 | D11: =SQRT((quadrupoles!K11/-stdev!B11)-(dipoles!I11/-stdev!B11)^2) -> 1.2982037 | E11: =SQRT((quadrupoles!L11/-stdev!B11)-(dipoles!J11/-stdev!B11)^2) -> 1.2982037 | R11: HO2_pbe0 | S11: 0.93650471
A12: CH4_scan | B12: 10 | C12: =SQRT((quadrupoles!J12/-stdev!B12)-(dipoles!H12/-stdev!B12)^2) -> 1.2998241 | D12: =SQRT((quadrupoles!K12/-stdev!B12)-(dipoles!I12/-stdev!B12)^2) -> 1.2998241 | E12: =SQRT((quadrupoles!L12/-stdev!B12)-(dipoles!J12/-stdev!B12)^2) -> 1.2998241 | M12: A to Bohr | N12: 1.88973 | R12: HO2_pbe | S12: 0.94113565
A13: CH4_spw92 | B13: 10 | C13: =SQRT((quadrupoles!J13/-stdev!B13)-(dipoles!H13/-stdev!B13)^2) -> 1.3057915 | D13: =SQRT((quadrupoles!K13/-stdev!B13)-(dipoles!I13/-stdev!B13)^2) -> 1.3057915 | E13: =SQRT((quadrupoles!L13/-stdev!B13)-(dipoles!J13/-stdev!B13)^2) -> 1.3057915 | R13: HO2_spw92 | S13: 0.94113565
A14: CN_ccsd | B14: 13 | C14: =SQRT((quadrupoles!J14/-stdev!B14)-(dipoles!H14/-stdev!B14)^2) -> 1.0689096 | D14: =SQRT((quadrupoles!K14/-stdev!B14)-(dipoles!I14/-stdev!B14)^2) -> 1.0689096 | E14: =SQRT((quadrupoles!L14/-stdev!B14)-(dipoles!J14/-stdev!B14)^2) -> 1.3972209 | R14: HCO_scan0 | S14: 0.99048855
A15: CN_pbe0 | B15: 13 | C15: =SQRT((quadrupoles!J15/-stdev!B15)-(dipoles!H15/-stdev!B15)^2) -> 1.0683854 | D15: =SQRT((quadrupoles!K15/-stdev!B15)-(dipoles!I15/-stdev!B15)^2) -> 1.0683854 | E15: =SQRT((quadrupoles!L15/-stdev!B15)-(dipoles!J15/-stdev!B15)^2) -> 1.4881592 | R15: HCO_scan | S15: 0.99099538
A16: CN_pbe | B16: 13 | C16: =SQRT((quadrupoles!J16/-stdev!B16)-(dipoles!H16/-stdev!B16)^2) -> 1.0694549 | D16: =SQRT((quadrupoles!K16/-stdev!B16)-(dipoles!I16/-stdev!B16)^2) -> 1.0694549 | E16: =SQRT((quadrupoles!L16/-stdev!B16)-(dipoles!J16/-stdev!B16)^2) -> 1.5011067 | N16: =0.9697*N12 -> 1.8324712 | R16: HCO_pbe0 | S16: 0.99323233
A17: CN_scan0 | B17: 13 | C17: =SQRT((quadrupoles!J17/-stdev!B17)-(dipoles!H17/-stdev!B17)^2) -> 1.0667087 | D17: =SQRT((quadrupoles!K17/-stdev!B17)-(dipoles!I17/-stdev!B17)^2) -> 1.0667087 | E17: =SQRT((quadrupoles!L17/-stdev!B17)-(dipoles!J17/-stdev!B17)^2) -> 1.4798493 | R17: HCO_pbe | S17: 0.9969854
A18: CN_scan | B18: 13 | C18: =SQRT((quadrupoles!J18/-stdev!B18)-(dipoles!H18/-stdev!B18)^2) -> 1.0653693 | D18: =SQRT((quadrupoles!K18/-stdev!B18)-(dipoles!I18/-stdev!B18)^2) -> 1.0653693 | E18: =SQRT((quadrupoles!L18/-stdev!B18)-(dipoles!J18/-stdev!B18)^2) -> 1.4884672 | R18: HCO_spw92 | S18: 0.9969854
A19: CN_spw92 | B19: 13 | C19: =SQRT((quadrupoles!J19/-stdev!B19)-(dipoles!H19/-stdev!B19)^2) -> 1.0694549 | D19: =SQRT((quadrupoles!K19/-stdev!B19)-(dipoles!I19/-stdev!B19)^2) -> 1.0694549 | E19: =SQRT((quadrupoles!L19/-stdev!B19)-(dipoles!J19/-stdev!B19)^2) -> 1.5011067 | R19: H2O_ccsd | S19: 1.0152943
A20: CO2_ccsd | B20: 22 | C20: =SQRT((quadrupoles!J20/-stdev!B20)-(dipoles!H20/-stdev!B20)^2) -> 0.95171307 | D20: =SQRT((quadrupoles!K20/-stdev!B20)-(dipoles!I20/-stdev!B20)^2) -> 0.95171307 | E20: =SQRT((quadrupoles!L20/-stdev!B20)-(dipoles!J20/-stdev!B20)^2) -> 2.1741663 | R20: H2O_scan0 | S20: 1.0215296
A21: CO2_pbe0 | B21: 22 | C21: =SQRT((quadrupoles!J21/-stdev!B21)-(dipoles!H21/-stdev!B21)^2) -> 0.95155895 | D21: =SQRT((quadrupoles!K21/-stdev!B21)-(dipoles!I21/-stdev!B21)^2) -> 0.95155895 | E21: =SQRT((quadrupoles!L21/-stdev!B21)-(dipoles!J21/-stdev!B21)^2) -> 2.1631464 | R21: H2O_scan | S21: 1.0261577
A22: CO2_pbe | B22: 22 | C22: =SQRT((quadrupoles!J22/-stdev!B22)-(dipoles!H22/-stdev!B22)^2) -> 0.95434974 | D22: =SQRT((quadrupoles!K22/-stdev!B22)-(dipoles!I22/-stdev!B22)^2) -> 0.95434974 | E22: =SQRT((quadrupoles!L22/-stdev!B22)-(dipoles!J22/-stdev!B22)^2) -> 2.1615757 | R22: H2O_pbe0 | S22: 1.0263754
A23: CO2_scan0 | B23: 22 | C23: =SQRT((quadrupoles!J23/-stdev!B23)-(dipoles!H23/-stdev!B23)^2) -> 0.94932363 | D23: =SQRT((quadrupoles!K23/-stdev!B23)-(dipoles!I23/-stdev!B23)^2) -> 0.94932363 | E23: =SQRT((quadrupoles!L23/-stdev!B23)-(dipoles!J23/-stdev!B23)^2) -> 2.1636812 | R23: H2O_pbe | S23: 1.0355761
A24: CO2_scan | B24: 22 | C24: =SQRT((quadrupoles!J24/-stdev!B24)-(dipoles!H24/-stdev!B24)^2) -> 0.94973571 | D24: =SQRT((quadrupoles!K24/-stdev!B24)-(dipoles!I24/-stdev!B24)^2) -> 0.94973571 | E24: =SQRT((quadrupoles!L24/-stdev!B24)-(dipoles!J24/-stdev!B24)^2) -> 2.1618567 | R24: H2O_spw92 | S24: 1.0355761
A25: CO2_spw92 | B25: 22 | C25: =SQRT((quadrupoles!J25/-stdev!B25)-(dipoles!H25/-stdev!B25)^2) -> 0.95434974 | D25: =SQRT((quadrupoles!K25/-stdev!B25)-(dipoles!I25/-stdev!B25)^2) -> 0.95434974 | E25: =SQRT((quadrupoles!L25/-stdev!B25)-(dipoles!J25/-stdev!B25)^2) -> 2.1615756 | R25: OH_scan0 | S25: 1.1001792
A26: CO_ccsd | B26: 14 | C26: =SQRT((quadrupoles!J26/-stdev!B26)-(dipoles!H26/-stdev!B26)^2) -> 0.99089544 | D26: =SQRT((quadrupoles!K26/-stdev!B26)-(dipoles!I26/-stdev!B26)^2) -> 0.99089544 | E26: =SQRT((quadrupoles!L26/-stdev!B26)-(dipoles!J26/-stdev!B26)^2) -> 1.5255082 | R26: OH_scan | S26: 1.1028063
A27: CO_pbe0 | B27: 14 | C27: =SQRT((quadrupoles!J27/-stdev!B27)-(dipoles!H27/-stdev!B27)^2) -> 0.99232492 | D27: =SQRT((quadrupoles!K27/-stdev!B27)-(dipoles!I27/-stdev!B27)^2) -> 0.99232492 | E27: =SQRT((quadrupoles!L27/-stdev!B27)-(dipoles!J27/-stdev!B27)^2) -> 1.5090007 | R27: OH_pbe0 | S27: 1.1036553
A28: CO_pbe | B28: 14 | C28: =SQRT((quadrupoles!J28/-stdev!B28)-(dipoles!H28/-stdev!B28)^2) -> 0.99653238 | D28: =SQRT((quadrupoles!K28/-stdev!B28)-(dipoles!I28/-stdev!B28)^2) -> 0.99653238 | E28: =SQRT((quadrupoles!L28/-stdev!B28)-(dipoles!J28/-stdev!B28)^2) -> 1.5072807 | R28: OH_ccsd | S28: 1.1053465
... A66: OH_scan | B66: 9 | C66: =SQRT((quadrupoles!J66/-stdev!B66)-(dipoles!H66/-stdev!B66)^2) -> 0.90784187 | D66: =SQRT((quadrupoles!K66/-stdev!B66)-(dipoles!I66/-stdev!B66)^2) -> 1.0128018 | E66: =SQRT((quadrupoles!L66/-stdev!B66)-(dipoles!J66/-stdev!B66)^2) -> 1.1028063 | R66: CO2_ccsd | S66: 2.1741663
A67: OH_spw92 | B67: 9 | C67: =SQRT((quadrupoles!J67/-stdev!B67)-(dipoles!H67/-stdev!B67)^2) -> 0.91812175 | D67: =SQRT((quadrupoles!K67/-stdev!B67)-(dipoles!I67/-stdev!B67)^2) -> 1.0230861 | E67: =SQRT((quadrupoles!L67/-stdev!B67)-(dipoles!J67/-stdev!B67)^2) -> 1.1096507 | R67: HCO_ccsd | S67: #VALUE!

Sheet energies
B1: 0 field | C1: XX | D1: -XX | E1: YY | F1: -YY | G1: ZZ | H1: -ZZ
A2: C2H_ccsd | B2: -76.178381 | C2: -76.179345 | D2: -76.177417 | E2: -76.179345 | F2: -76.177417 | G2: -76.179049 | H2: -76.177715
A3: C2H_pbe0 | B3: -76.535956 | C3: -76.536914 | D3: -76.534998 | E3: -76.536914 | F3: -76.534998 | G3: -76.53662 | H3: -76.535294
A4: C2H_pbe | B4: -76.533695 | C4: -76.534655 | D4: -76.532736 | E4: -76.534655 | F4: -76.532736 | G4: -76.534377 | H4: -76.533016
A5: C2H_scan0 | B5: -76.585898 | C5: -76.586855 | D5: -76.584942 | E5: -76.586855 | F5: -76.584942 | G5: -76.586552 | H5: -76.585246
A6: C2H_scan | B6: -76.599782 | C6: -76.600736 | D6: -76.598829 | E6: -76.600736 | F6: -76.598829 | G6: -76.600444 | H6: -76.599123
A7: C2H_spw92 | B7: -76.533695 | C7: -76.534655 | D7: -76.532736 | E7: -76.534655 | F7: -76.532736 | G7: -76.534377 | H7: -76.533016
A8: CH4_ccsd | B8: -40.213794 | C8: -40.21442 | D8: -40.213169 | E8: -40.21442 | F8: -40.213169 | G8: -40.21442 | H8: -40.213169
A9: CH4_pbe0 | B9: -40.47542 | C9: -40.476045 | D9: -40.474797 | E9: -40.476045 | F9: -40.474797 | G9: -40.476045 | H9: -40.474797
A10: CH4_pbe | B10: -40.464719 | C10: -40.465351 | D10: -40.464088 | E10: -40.465351 | F10: -40.464088 | G10: -40.465351 | H10: -40.464088
A11: CH4_scan0 | B11: -40.502495 | C11: -40.503116 | D11: -40.501875 | E11: -40.503116 | F11: -40.501875 | G11: -40.503116 | H11: -40.501875
A12: CH4_scan | B12: -40.506761 | C12: -40.507384 | D12: -40.506139 | E12: -40.507384 | F12: -40.506139 | G12: -40.507384 | H12: -40.506139
A13: CH4_spw92 | B13: -40.464719 | C13: -40.465351 | D13: -40.464088 | E13: -40.465351 | F13: -40.464088 | G13: -40.465351 | H13: -40.464088
... A26: CO_ccsd | B26: -112.7821 | C26: -112.78286 | D26: -112.78134 | E26: -112.78286 | F26: -112.78134 | G26: -112.78304 | H26: -112.78116
A27: CO_pbe0 | B27: -113.23798
A28: CO_pbe | B28: -113.24257
A29: CO_scan0 | B29: -113.29694
A30: CO_scan | B30: -113.32026
A31: CO_spw92 | B31: -112.47406
A32: H2O_ccsd | B32: -76.060798 | C32: -76.06136 | D32: -76.060236 | E32: -76.061114 | F32: -76.060483 | G32: -76.061262 | H32: -76.060334
A33: H2O_pbe0 | B33: -76.381048 | C33: -76.381622 | D33: -76.380474 | E33: -76.381377 | F33: -76.380719 | G33: -76.381525 | H33: -76.380571
A34: H2O_pbe | B34: -76.381692 | C34: -76.382277 | D34: -76.381107 | E34: -76.382031 | F34: -76.381352 | G34: -76.382179 | H34: -76.381205
A35: H2O_scan0 | B35: -76.418713 | C35: -76.419282 | D35: -76.418144 | E35: -76.419035 | F35: -76.41839 | G35: -76.419184 | H35: -76.418242
A36: H2O_scan | B36: -76.433622 | C36: -76.434196 | D36: -76.433049 | E36: -76.43395 | F36: -76.433295 | G36: -76.434099 | H36: -76.433146
A37: H2O_spw92 | B37: -76.381692 | C37: -76.382277 | D37: -76.381107 | E37: -76.382031 | F37: -76.381352 | G37: -76.382179 | H37: -76.381205
A38: HCO_ccsd | B38: -113.29072 | C38: -113.29156 | D38: -113.28988 | E38: -113.29174 | F38: -113.28969 | G38: -113.29153 | H38: -113.2899
A39: HCO_pbe0 | B39: -113.7676 | C39: -113.76843 | D39: -113.76676 | E39: -113.76859 | F39: -113.7666 | G39: -113.76841 | H39: -113.76678
A40: HCO_pbe | B40: -113.77339 | C40: -113.77424 | D40: -113.77255 | E40: -113.77439 | F40: -113.7724 | G40: -113.77422 | H40: -113.77257
A41: HCO_scan0 | B41: -113.82846 | C41: -113.82929 | D41: -113.82764 | E41: -113.82946 | F41: -113.82747 | G41: -113.82928 | H41: -113.82765
A42: HCO_scan | B42: -113.85391 | C42: -113.85475 | D42: -113.85308 | E42: -113.85491 | F42: -113.85292 | G42: -113.85473 | H42: -113.8531
A43: HCO_spw92 | B43: -113.77339 | C43: -113.77424 | D43: -113.77255 | E43: -113.77439 | F43: -113.7724 | G43: -113.77422 | H43: -113.77257
... A67: OH_spw92 | B67: -75.683904 | C67: -75.684323 | D67: -75.683485 | E67: -75.684425 | F67: -75.683383 | G67: -75.684467 | H67: -75.683341

Sheet q,d_sum
B1: X | C1: Y | D1: Z | E1: XX | F1: YY | G1: ZZ | S1: Ang to bohr | U1: Ang2 to bohr2
A2: C2H_ccsd | B2: =K2*$S$2 -> 0 | C2: =L2*$S$2 -> 0 | D2: =M2*$S$2 -> -11.815537 | E2: =N2*$U$2 -> 0 | F2: =O2*$U$2 -> 0 | G2: =P2*$U$2 -> 35.61936 | K2: 0 | L2: 0 | M2: -6.2525 | N2: 0 | O2: 0 | P2: 9.9743957 | S2: 1.88973 | U2: =S2^2 -> 3.5710795
A3: C2H_pbe0 | B3: =K3*$S$2 -> 0 | C3: =L3*$S$2 -> 0 | D3: =M3*$S$2 -> -11.815537 | E3: =N3*$U$2 -> 0 | F3: =O3*$U$2 -> 0 | G3: =P3*$U$2 -> 35.61936 | K3: 0 | L3: 0 | M3: -6.2525 | N3: 0 | O3: 0 | P3: 9.9743957
A4: C2H_pbe | B4: =K4*$S$2 -> 0 | C4: =L4*$S$2 -> 0 | D4: =M4*$S$2 -> -11.815537 | E4: =N4*$U$2 -> 0 | F4: =O4*$U$2 -> 0 | G4: =P4*$U$2 -> 35.61936 | K4: 0 | L4: 0 | M4: -6.2525 | N4: 0 | O4: 0 | P4: 9.9743957
A5: C2H_scan0 | B5: =K5*$S$2 -> 0 | C5: =L5*$S$2 -> 0 | D5: =M5*$S$2 -> -11.815537 | E5: =N5*$U$2 -> 0 | F5: =O5*$U$2 -> 0 | G5: =P5*$U$2 -> 35.61936 | K5: 0 | L5: 0 | M5: -6.2525 | N5: 0 | O5: 0 | P5: 9.9743957
A6: C2H_scan | B6: =K6*$S$2 -> 0 | C6: =L6*$S$2 -> 0 | D6: =M6*$S$2 -> -11.815537 | E6: =N6*$U$2 -> 0 | F6: =O6*$U$2 -> 0 | G6: =P6*$U$2 -> 35.61936 | K6: 0 | L6: 0 | M6: -6.2525 | N6: 0 | O6: 0 | P6: 9.9743957
A7: C2H_spw92 | B7: =K7*$S$2 -> 0 | C7: =L7*$S$2 -> 0 | D7: =M7*$S$2 -> -11.815537 | E7: =N7*$U$2 -> 0 | F7: =O7*$U$2 -> 0 | G7: =P7*$U$2 -> 35.61936 | K7: 0 | L7: 0 | M7: -6.2525 | N7: 0 | O7: 0 | P7: 9.9743957
A8: CH4_ccsd | B8: =K8*$S$2 -> 0 | C8: =L8*$S$2 -> 0 | D8: =M8*$S$2 -> 0 | E8: =N8*$U$2 -> 5.6263323 | F8: =O8*$U$2 -> 5.6263323 | G8: =P8*$U$2 -> 5.6263323 | K8: 0 | L8: 0 | M8: 0 | N8: 1.575527 | O8: 1.575527 | P8: 1.575527
A9: CH4_pbe0 | B9: =K9*$S$2 -> 0 | C9: =L9*$S$2 -> 0 | D9: =M9*$S$2 -> 0 | E9: =N9*$U$2 -> 5.6263323 | F9: =O9*$U$2 -> 5.6263323 | G9: =P9*$U$2 -> 5.6263323 | K9: 0 | L9: 0 | M9: 0 | N9: 1.575527 | O9: 1.575527 | P9: 1.575527
A10: CH4_pbe | B10: =K10*$S$2 -> 0 | C10: =L10*$S$2 -> 0 | D10: =M10*$S$2 -> 0 | E10: =N10*$U$2 -> 5.6263323 | F10: =O10*$U$2 -> 5.6263323 | G10: =P10*$U$2 -> 5.6263323 | K10: 0 | L10: 0 | M10: 0 | N10: 1.575527 | O10: 1.575527 | P10: 1.575527
A11: CH4_scan0 | B11: =K11*$S$2 -> 0 | C11: =L11*$S$2 -> 0 | D11: =M11*$S$2 -> 0 | E11: =N11*$U$2 -> 5.6263323 | F11: =O11*$U$2 -> 5.6263323 | G11: =P11*$U$2 -> 5.6263323 | K11: 0 | L11: 0 | M11: 0 | N11: 1.575527 | O11: 1.575527 | P11: 1.575527
A12: CH4_scan | B12: =K12*$S$2 -> 0 | C12: =L12*$S$2 -> 0 | D12: =M12*$S$2 -> 0 | E12: =N12*$U$2 -> 5.6263323 | F12: =O12*$U$2 -> 5.6263323 | G12: =P12*$U$2 -> 5.6263323 | K12: 0 | L12: 0 | M12: 0 | N12: 1.575527 | O12: 1.575527 | P12: 1.575527
A13: CH4_spw92 | B13: =K13*$S$2 -> 0 | C13: =L13*$S$2 -> 0 | D13: =M13*$S$2 -> 0 | E13: =N13*$U$2 -> 5.6263323 | F13: =O13*$U$2 -> 5.6263323 | G13: =P13*$U$2 -> 5.6263323 | K13: 0 | L13: 0 | M13: 0 | N13: 1.575527 | O13: 1.575527 | P13: 1.575527
A14: CN_ccsd | B14: =K14*$S$2 -> 0 | C14: =L14*$S$2 -> 0 | D14: =M14*$S$2 -> 13.286314 | E14: =N14*$U$2 -> 0 | F14: =O14*$U$2 -> 0 | G14: =P14*$U$2 -> 29.421022 | K14: 0 | L14: 0 | M14: 7.0308 | N14: 0 | O14: 0 | P14: 8.2386914
... A67: OH_spw92 | B67: =K67*$S$2 -> 0 | C67: =L67*$S$2 -> 0 | D67: =M67*$S$2 -> 14.659769 | E67: =N67*$U$2 -> 0 | F67: =O67*$U$2 -> 0 | G67: =P67*$U$2 -> 26.863605 | K67: 0 | L67: 0 | M67: 7.7576 | N67: 0 | O67: 0 | P67: 7.5225447

Sheet sample
A1: Conversion factor: | D1: X | E1: Y | F1: Z
A2: =1/0.3934303*0.529177 -> 1.3450337 | D2: 0 | E2: 0 | F2: -1.5939
C3: Atomic_unit | F3: =F2*A6 -> -0.62708856
C4: Electronic | F4: =F3-F16 -> -15.286858
C5: per charge | D5: 0 | E5: 0 | F5: =F4/-9 -> 1.6985398
A6: 0.3934303 | D6: XX | E6: YY | F6: ZZ
D7: -5.6404 | E7: -7.0038 | F7: -7.5713
C8: Atomic_unit | D8: =D7/A2 -> -4.193501 | E8: =E7/A2 -> -5.2071559 | F8: =F7/A2 -> -5.6290784 | G8: =F7*I8 -> -5.6294435 | I8: 0.74352403
C9: Electronic | F9: =F8-F15 -> -32.492683
C10: per charge | D10: =D8/-9 -> 0.46594455 | E10: =E8/-9 -> 0.57857288 | F10: =F9/-9 -> 3.6102982
C11: std_dev | D11: =SQRT(D10-D5^2) -> 0.68260131 | E11: =SQRT(E10-E5^2) -> 0.76063978 | F11: =SQRT(F10-F5^2) -> 0.85162244
A12: A to Bohr
A13: 1.88973 | F13: 0.9697
F14: =F13*A13 -> 1.8324712
E15: sum_q: | F15: =8*F14^2 -> 26.863605
A16: =0.9697*A13 -> 1.8324712 | E16: sum_d: | F16: =8*F14 -> 14.659769

Sheet cbs_limit
A1: molecule_method | B1: XX | C1: YY | D1: ZZ | G1: cbs_limit | H1: XX | I1: YY | J1: ZZ
