Workbook

Sheet wft_table
A1: method | C1: HF | D1: HF | E1: HF | F1: MP2 | G1: MP2 | H1: MP2 | I1: CCSD | J1: CCSD | K1: CCSD | L1: CCSD\(T\) | M1: CCSD\(T\) | N1: CCSD\(T\)
A2: component | C2: XX | D2: YY | E2: ZZ | F2: XX | G2: YY | H2: ZZ | I2: XX | J2: YY | K2: ZZ | L2: XX | M2: YY | N2: ZZ
A3: molecule | B3: basis
A4: Ar | B4: 5Z | C4: 0.69439921 | D4: 0.69439921 | E4: 0.69439921 | F4: 0.69386453 | G4: 0.69386453 | H4: 0.69386453 | I4: 0.69292912 | J4: 0.69292912 | K4: 0.69292912 | L4: 0.6933419 | M4: 0.6933419 | N4: 0.6933419
A5: Ar | B5: QZ | C5: 0.69447654 | D5: 0.69447654 | E5: 0.69447654 | F5: 0.69438277 | G5: 0.69438277 | H5: 0.69438277 | I5: 0.69344405 | J5: 0.69344405 | K5: 0.69344405 | L5: 0.69388455 | M5: 0.69388455 | N5: 0.69388455
A6: Ar | B6: TZ | C6: 0.69479763 | D6: 0.69479763 | E6: 0.69479763 | F6: 0.69562777 | G6: 0.69562777 | H6: 0.69562777 | I6: 0.69500056 | J6: 0.69500056 | K6: 0.69500056 | L6: 0.69546603 | M6: 0.69546603 | N6: 0.69546603
A7: Ar | B7: CBS | C7: 0.69439922 | D7: 0.69439922 | E7: 0.69439922 | F7: 0.69340193 | G7: 0.69340193 | H7: 0.69340193 | I7: 0.69246999 | J7: 0.69246999 | K7: 0.69246999 | L7: 0.69285369 | M7: 0.69285369 | N7: 0.69285369
A8: Be | B8: 5Z | C8: 0 | D8: 0 | E8: 0 | F8: 0 | G8: 0 | H8: 0 | I8: 0 | J8: 0 | K8: 0 | L8: 0 | M8: 0 | N8: 0
A9: Be | B9: QZ | C9: 1.1867627 | D9: 1.222718 | E9: 1.1867627 | F9: 1.0685162 | G9: 1.2527829 | H9: 1.2527829 | I9: 1.1638899 | J9: 1.165489 | K9: 1.165489 | L9: 1.1641798 | M9: 1.1642013 | N9: 1.1642013
A10: Be | B10: TZ | C10: 1.2190795 | D10: 1.1870994 | E10: 1.1906873 | F10: 1.0726436 | G10: 1.2533066 | H10: 1.2533066 | I10: 1.1652638 | J10: 1.1666736 | K10: 1.1666736 | L10: 1.1656231 | M10: 1.1656767 | N10: 1.1656767
A11: Be | B11: CBS | C11: 0 | D11: 0 | E11: 0 | F11: 0 | G11: 0 | H11: 0 | I11: 0 | J11: 0 | K11: 0 | L11: 0 | M11: 0 | N11: 0
A12: BeH | B12: 5Z | C12: 0 | D12: 0 | E12: 0 | F12: 0 | G12: 0 | H12: 0 | I12: 0 | J12: 0 | K12: 0 | L12: 0 | M12: 0 | N12: 0
A13: BeH | B13: QZ | C13: 0.98912645 | D13: 0.98912645 | E13: 1.6467417 | F13: 0.99039465 | G13: 0.99039465 | H13: 1.6346673 | I13: 0.99330337 | J13: 0.99330337 | K13: 1.6278297 | L13: 0.99418891 | M13: 0.99418891 | N13: 1.6265946
A14: BeH | B14: TZ | C14: 0.98951722 | D14: 0.98951722 | E14: 1.6473933 | F14: 0.99193325 | G14: 0.99193325 | H14: 1.6390438 | I14: 0.99499326 | J14: 0.99499326 | K14: 1.6299186 | L14: 0.99587227 | M14: 0.99587227 | N14: 1.6288733
A15: BeH | B15: CBS | C15: 0 | D15: 0 | E15: 0 | F15: 0 | G15: 0 | H15: 0 | I15: 0 | J15: 0 | K15: 0 | L15: 0 | M15: 0 | N15: 0
... A30: BO | B30: TZ | C30: 0.76782817 | D30: 0.76782817 | E30: 1.3416501 | F30: 0.77367566 | G30: 0.77367566 | H30: 1.3473871 | I30: 0.77230486 | J30: 0.77230486 | K30: 1.3454676 | L30: 0.77347181 | M30: 0.77347181 | N30: 1.3471267
A31: BO | B31: CBS | C31: 0.76755999 | D31: 0.76755999 | E31: 1.3414078 | F31: =((F$29-C$29)*64-(F$30-C$30)*27)/(64-27)+C$31 -> 0.77143995 | G31: =((G$29-D$29)*64-(G$30-D$30)*27)/(64-27)+D$31 -> 0.77143995 | H31: =((H$29-E$29)*64-(H$30-E$30)*27)/(64-27)+E$31 -> 1.3457744 | I31: =((I$29-C$29)*64-(I$30-C$30)*27)/(64-27)+C$31 -> 0.76982316 | J31: =((J$29-D$29)*64-(J$30-D$30)*27)/(64-27)+D$31 -> 0.76982316 | K31: =((K$29-E$29)*64-(K$30-E$30)*27)/(64-27)+E$31 -> 1.3436379 | L31: =((L$29-C$29)*64-(L$30-C$30)*27)/(64-27)+C$31 -> 0.77094245 | M31: =((M$29-D$29)*64-(M$30-D$30)*27)/(64-27)+D$31 -> 0.77094245 | N31: =((N$29-E$29)*64-(N$30-E$30)*27)/(64-27)+E$31 -> 1.3452716
A32: BS | B32: 5Z | C32: 0.82972192 | D32: 0.82972192 | E32: 1.501898 | F32: 0.82594168 | G32: 0.82594168 | H32: 1.5007437 | I32: 0.82327663 | J32: 0.82327663 | K32: 1.5045359 | L32: 0.82284271 | M32: 0.82284271 | N32: 1.5065563
A33: BS | B33: QZ | C33: 0.82982645 | D33: 0.82982645 | E33: 1.5018733 | F33: 0.82660588 | G33: 0.82660588 | H33: 1.5301388 | I33: 0.82390108 | J33: 0.82390108 | K33: 1.5050078 | L33: 0.82350941 | M33: 0.82350941 | N33: 1.5070479
A34: BS | B34: TZ | C34: 0.83009306 | D34: 0.83009306 | E34: 1.5020054 | F34: 0.82818571 | G34: 0.82818571 | H34: 1.5029013 | I34: 0.82563317 | J34: 0.82563317 | K34: 1.5065338 | L34: 0.82534907 | M34: 0.82534907 | N34: 1.5086252
A35: BS | B35: CBS | C35: 0.82972192 | D35: 0.82972192 | E35: 1.501898 | F35: =((F$32-C$32)*125-(F$33-C$33)*64)/(125-64)+C$35 -> 0.82535449 | G35: =((G$32-D$32)*125-(G$33-D$33)*64)/(125-64)+D$35 -> 0.82535449 | H35: =((H$32-E$32)*125-(H$33-E$33)*64)/(125-64)+E$35 -> 1.469877 | I35: =((I$32-C$32)*125-(I$33-C$33)*64)/(125-64)+C$35 -> 0.82273115 | J35: =((J$32-D$32)*125-(J$33-D$33)*64)/(125-64)+D$35 -> 0.82273115 | K35: =((K$32-E$32)*125-(K$33-E$33)*64)/(125-64)+E$35 -> 1.5040148 | L35: =((L$32-C$32)*125-(L$33-C$33)*64)/(125-64)+C$35 -> 0.8222529 | M35: =((M$32-D$32)*125-(M$33-D$33)*64)/(125-64)+D$35 -> 0.8222529 | N35: =((N$32-E$32)*125-(N$33-E$33)*64)/(125-64)+E$35 -> 1.5060146
A36: C2H | B36: 5Z | C36: 0 | D36: 0 | E36: 0 | F36: 0 | G36: 0 | H36: 0 | I36: 0 | J36: 0 | K36: 0 | L36: 0 | M36: 0 | N36: 0
A37: C2H | B37: QZ | C37: 0.86066777 | D37: 0.86066777 | E37: 1.5450159 | F37: 0.87042058 | G37: 0.87042058 | H37: 1.5476203 | I37: 0.85555493 | J37: 0.85555493 | K37: 1.5573541 | L37: 0.85579766 | M37: 0.85579766 | N37: 1.5583959
A38: C2H | B38: TZ | C38: 0.86116599 | D38: 0.86116599 | E38: 1.5449312 | F38: 0.87170989 | G38: 0.87170989 | H38: 1.5487395 | I38: 0.85716282 | J38: 0.85716282 | K38: 1.5583182 | L38: 0.85754862 | M38: 0.85754862 | N38: 1.5593619
A39: C2H | B39: CBS | C39: 0.86066777 | D39: 0.86066777 | E39: 1.5450159 | F39: 0.86984329 | G39: 0.86984329 | H39: 1.5467418 | I39: 0.85474518 | J39: 0.85474518 | K39: 1.5565887 | L39: 0.8548835 | M39: 0.8548835 | N39: 1.5576292
A40: C2H2 | B40: 5Z | C40: 0 | D40: 0 | E40: 0 | F40: 0 | G40: 0 | H40: 0 | I40: 0 | J40: 0 | K40: 0 | L40: 0 | M40: 0 | N40: 0
A41: C2H2 | B41: QZ | C41: 0.86288526 | D41: 0.86288526 | E41: 1.6954865 | F41: 0.85162937 | G41: 0.85162937 | H41: 1.7023491 | I41: 0.85071886 | J41: 0.85071886 | K41: 1.7002814 | L41: 0.85076084 | M41: 0.85076084 | N41: 1.7016976
A42: C2H2 | B42: TZ | C42: 0.86326675 | D42: 0.86326675 | E42: 1.6954175 | F42: 0.85335331 | G42: 0.85335331 | H42: 1.70323 | I42: 0.85227285 | J42: 0.85227285 | K42: 1.7012683 | L42: 0.85242579 | M42: 0.85242579 | N42: 1.7027099
A43: C2H2 | B43: CBS | C43: 0.86288526 | D43: 0.86288526 | E43: 1.6954865 | F43: 0.85064974 | G43: 0.85064974 | H43: 1.701656 | I43: 0.84986325 | J43: 0.84986325 | K43: 1.6995109 | L43: 0.84982426 | M43: 0.84982426 | N43: 1.7009085
A44: CH3 | B44: 5Z | C44: 0 | D44: 0 | E44: 0 | F44: 0 | G44: 0 | H44: 0 | I44: 0 | J44: 0 | K44: 0 | L44: 0 | M44: 0 | N44: 0
A45: CH3 | B45: QZ | C45: 1.1350553 | D45: 1.1350355 | E45: 0.86410775 | F45: 1.1353807 | G45: 1.1353585 | H45: 0.87011882 | I45: 1.1345926 | J45: 1.1345729 | K45: 0.86619928 | L45: 1.1352486 | M45: 1.1352288 | N45: 0.86736259
A46: CH3 | B46: TZ | C46: 1.1350917 | D46: 1.1350719 | E46: 0.86460951 | F46: 1.1365617 | G46: 1.1365396 | H46: 0.87159885 | I46: 1.1358087 | J46: 1.1357866 | K46: 0.86781084 | L46: 1.1364958 | M46: 1.1364761 | N46: 0.86897199
A47: CH3 | B47: CBS | C47: 1.1350553 | D47: 1.1350355 | E47: 0.86410776 | F47: 1.1345454 | G47: 1.1345232 | H47: 0.86940495 | I47: 1.1337317 | J47: 1.1337138 | K47: 0.86538943 | L47: 1.134365 | M47: 1.1343453 | N47: 0.86655431
... A58: CO | B58: TZ | C58: 0.73670768 | D58: 0.73670768 | E58: 1.3288576 | F58: 0.74100377 | G58: 0.74100377 | H58: 1.3158997 | I58: 0.73836268 | J58: 0.73836268 | K58: 1.3261847 | L58: 0.73913619 | M58: 0.73913619 | N58: 1.3234634
A59: CO | B59: CBS | C59: 0.73651303 | D59: 0.73651303 | E59: 1.3284592 | F59: =((F$57-C$57)*64-(F$58-C$58)*27)/(64-27)+C$59 -> 0.73912672 | G59: =((G$57-D$57)*64-(G$58-D$58)*27)/(64-27)+D$59 -> 0.73912672 | H59: =((H$57-E$57)*64-(H$58-E$58)*27)/(64-27)+E$59 -> 1.3146839 | I59: =((I$57-C$57)*64-(I$58-C$58)*27)/(64-27)+C$59 -> 0.73632754 | J59: =((J$57-D$57)*64-(J$58-D$58)*27)/(64-27)+D$59 -> 0.73632754 | K59: =((K$57-E$57)*64-(K$58-E$58)*27)/(64-27)+E$59 -> 1.3223536 | L59: =((L$57-C$57)*64-(L$58-C$58)*27)/(64-27)+C$59 -> 0.7370531 | M59: =((M$57-D$57)*64-(M$58-D$58)*27)/(64-27)+D$59 -> 0.7370531 | N59: =((N$57-E$57)*64-(N$58-E$58)*27)/(64-27)+E$59 -> 1.3197891
A60: F2 | B60: 5Z | C60: 0 | D60: 0 | E60: 0 | F60: 0 | G60: 0 | H60: 0 | I60: 0 | J60: 0 | K60: 0 | L60: 0 | M60: 0 | N60: 0
A61: F2 | B61: QZ | C61: 0.62589639 | D61: 0.62589639 | E61: 1.4616053 | F61: 0.63342374 | G61: 0.63342374 | H61: 1.4666846 | I61: 0.63172653 | J61: 0.63172653 | K61: 1.4631311 | L61: 0.63298506 | M61: 0.63298506 | N61: 1.4630229
A62: F2 | B62: TZ | C62: 0.62673723 | D62: 0.62673723 | E62: 1.4616081 | F62: 0.63475549 | G62: 0.63475549 | H62: 1.4669204 | I62: 0.63329217 | J62: 0.63329217 | K62: 1.4634737 | L62: 0.63449943 | M62: 0.63449943 | N62: 1.4634101
A63: F2 | B63: CBS | C63: 0.62589639 | D63: 0.62589639 | E63: 1.4616053 | F63: 0.63306551 | G63: 0.63306551 | H63: 1.4665146 | I63: 0.63119763 | J63: 0.63119763 | K63: 1.4628831 | L63: 0.63249356 | M63: 0.63249356 | N63: 1.4627423
A64: H | B64: 5Z | C64: 1.0000626 | D64: 1.0000626 | E64: 1.0000626 | F64: 1.0000758 | G64: 1.0000758 | H64: 1.0000758 | I64: 1.0000758 | J64: 1.0000758 | K64: 1.0000758 | L64: 1.0000758 | M64: 1.0000758 | N64: 1.0000758
...

Sheet dft_values
A1: method | B1: Slater | C1: Slater | D1: Slater | E1: SPW92 | F1: SPW92 | G1: SPW92 | H1: B97-D3 | I1: B97-D3 | J1: B97-D3 | K1: BLYP | L1: BLYP | M1: BLYP | N1: BPBE | O1: BPBE | P1: BPBE | Q1: mPW91 | R1: mPW91 | S1: mPW91 | T1: PBE | U1: PBE | V1: PBE | W1: B97M-rV | X1: B97M-rV | Y1: B97M-rV | Z1: B97M-V | AA1: B97M-V | AB1: B97M-V | AC1: M06-L | AD1: M06-L | AE1: M06-L | AF1: mBEEF | AG1: mBEEF | AH1: mBEEF | AI1: MGGA_MS2 | AJ1: MGGA_MS2 | AK1: MGGA_MS2 | AL1: MN15-L | AM1: MN15-L | AN1: MN15-L | AO1: revM06-L | AP1: revM06-L | AQ1: revM06-L | AR1: SCAN | AS1: SCAN | AT1: SCAN | AU1: TPSS | AV1: TPSS | AW1: TPSS | AX1: B3LYP | AY1: B3LYP | AZ1: B3LYP | BA1: B3LYP5 | BB1: B3LYP5 | BC1: B3LYP5 | BD1: M06-2X | BE1: M06-2X | BF1: M06-2X | BG1: PBE0 | BH1: PBE0 | BI1: PBE0 | BJ1: M08-HX | BK1: M08-HX | BL1: M08-HX | BM1: MN15 | BN1: MN15 | BO1: MN15 | BP1: SCAN0 | BQ1: SCAN0 | BR1: SCAN0 | BS1: CAM-B3LYP | BT1: CAM-B3LYP | BU1: CAM-B3LYP | BV1: wB97X-D | BW1: wB97X-D | BX1: wB97X-D | BY1: wB97X-V | BZ1: wB97X-V | CA1: wB97X-V | CB1: wB97M-V | CC1: wB97M-V | CD1: wB97M-V
A2: component | B2: XX | C2: YY | D2: ZZ | E2: XX | F2: YY | G2: ZZ | H2: XX | I2: YY | J2: ZZ | K2: XX | L2: YY | M2: ZZ | N2: XX | O2: YY | P2: ZZ | Q2: XX | R2: YY | S2: ZZ | T2: XX | U2: YY | V2: ZZ | W2: XX | X2: YY | Y2: ZZ | Z2: XX | AA2: YY | AB2: ZZ | AC2: XX | AD2: YY | AE2: ZZ | AF2: XX | AG2: YY | AH2: ZZ | AI2: XX | AJ2: YY | AK2: ZZ | AL2: XX | AM2: YY | AN2: ZZ | AO2: XX | AP2: YY | AQ2: ZZ | AR2: XX | AS2: YY | AT2: ZZ | AU2: XX | AV2: YY | AW2: ZZ | AX2: XX | AY2: YY | AZ2: ZZ | BA2: XX | BB2: YY | BC2: ZZ | BD2: XX | BE2: YY | BF2: ZZ | BG2: XX | BH2: YY | BI2: ZZ | BJ2: XX | BK2: YY | BL2: ZZ | BM2: XX | BN2: YY | BO2: ZZ | BP2: XX | BQ2: YY | BR2: ZZ | BS2: XX | BT2: YY | BU2: ZZ | BV2: XX | BW2: YY | BX2: ZZ | BY2: XX | BZ2: YY | CA2: ZZ | CB2: XX | CC2: YY | CD2: ZZ
A3: molecule
A4: Ar | B4: 0 | C4: 0 | D4: 0 | E4: 0 | F4: 0 | G4: 0 | H4: 0 | I4: 0 | J4: 0 | K4: 0.6990825 | L4: 0.6990825 | M4: 0.6990825 | N4: 0.69502052 | O4: 0.69502052 | P4: 0.69502052 | Q4: 0.69601821 | R4: 0.69601821 | S4: 0.69601821 | T4: 0 | U4: 0 | V4: 0 | W4: 0 | X4: 0 | Y4: 0 | Z4: 0 | AA4: 0 | AB4: 0 | AC4: 0 | AD4: 0 | AE4: 0 | AF4: 0.69100341 | AG4: 0.69100341 | AH4: 0.69100341 | AI4: 0 | AJ4: 0 | AK4: 0 | AL4: 0 | AM4: 0 | AN4: 0 | AO4: 0 | AP4: 0 | AQ4: 0 | AR4: 0 | AS4: 0 | AT4: 0 | AU4: 0.69509778 | AV4: 0.69509778 | AW4: 0.69509778 | AX4: 0.69678036 | AY4: 0.69678036 | AZ4: 0.69678036 | BA4: 0.69692854 | BB4: 0.69692854 | BC4: 0.69692854 | BD4: 0 | BE4: 0 | BF4: 0 | BG4: 0 | BH4: 0 | BI4: 0 | BJ4: 0 | BK4: 0 | BL4: 0 | BM4: 0 | BN4: 0 | BO4: 0 | BP4: 0 | BQ4: 0 | BR4: 0 | BS4: 0 | BT4: 0 | BU4: 0 | BV4: 0 | BW4: 0 | BX4: 0 | BY4: 0.69548688 | BZ4: 0.69548688 | CA4: 0.69548688 | CB4: 0 | CC4: 0 | CD4: 0
A5: Be | B5: 1.222163 | C5: 1.222163 | D5: 1.222163 | E5: 0 | F5: 0 | G5: 0 | H5: 1.1888048 | I5: 1.1888048 | J5: 1.1888048 | K5: 0 | L5: 0 | M5: 0 | N5: 0 | O5: 0 | P5: 0 | Q5: 0 | R5: 0 | S5: 0 | T5: 1.18255 | U5: 1.18255 | V5: 1.18255 | W5: 0 | X5: 0 | Y5: 0 | Z5: 0 | AA5: 0 | AB5: 0 | AC5: 1.1778174 | AD5: 1.1778174 | AE5: 1.1778174 | AF5: 0 | AG5: 0 | AH5: 0 | AI5: 1.1765226 | AJ5: 1.1765226 | AK5: 1.1765226 | AL5: 1.2174699 | AM5: 1.2174699 | AN5: 1.2174699 | AO5: 1.1858148 | AP5: 1.1858148 | AQ5: 1.1858148 | AR5: 0 | AS5: 0 | AT5: 0 | AU5: 0 | AV5: 0 | AW5: 0 | AX5: 0 | AY5: 0 | AZ5: 0 | BA5: 0 | BB5: 0 | BC5: 0 | BD5: 1.1770596 | BE5: 1.1770596 | BF5: 1.1770596 | BG5: 0 | BH5: 0 | BI5: 0 | BJ5: 0 | BK5: 0 | BL5: 0 | BM5: 1.2026394 | BN5: 1.2026394 | BO5: 1.2026394 | BP5: 0 | BQ5: 0 | BR5: 0 | BS5: 1.1837753 | BT5: 1.1837753 | BU5: 1.1837753 | BV5: 0 | BW5: 0 | BX5: 0 | BY5: 0 | BZ5: 0 | CA5: 0 | CB5: 0 | CC5: 0 | CD5: 0
A6: BeH | B6: 1.0396475 | C6: 1.0396475 | D6: 1.6487272 | E6: 0 | F6: 0 | G6: 0 | H6: 1.0119905 | I6: 1.0119905 | J6: 1.6222705 | K6: 1.0097988 | L6: 1.0097988 | M6: 1.6220269 | N6: 1.003358 | O6: 1.003358 | P6: 1.6180907 | Q6: 1.0067682 | R6: 1.0067682 | S6: 1.6192359 | T6: 0 | U6: 0 | V6: 0 | W6: 0 | X6: 0 | Y6: 0 | Z6: 0 | AA6: 0 | AB6: 0 | AC6: 0.98396417 | AD6: 0.98396417 | AE6: 1.6156648 | AF6: 0.99777769 | AG6: 0.99777769 | AH6: 1.6238103 | AI6: 0.99506171 | AJ6: 0.99506171 | AK6: 1.619569 | AL6: 1.022515 | AM6: 1.022515 | AN6: 1.6504464 | AO6: 0.99820977 | AP6: 0.99820977 | AQ6: 1.6408482 | AR6: 0 | AS6: 0 | AT6: 0 | AU6: 1.0007835 | AV6: 1.0007835 | AW6: 1.616571 | AX6: 1.0027428 | AY6: 1.0027428 | AZ6: 1.6225195 | BA6: 1.0037581 | BB6: 1.0037581 | BC6: 1.6230084 | BD6: 1.0068716 | BE6: 1.0068716 | BF6: 1.6161825 | BG6: 0 | BH6: 0 | BI6: 0 | BJ6: 0 | BK6: 0 | BL6: 0 | BM6: 1.0328818 | BN6: 1.0328818 | BO6: 1.6270494 | BP6: 0 | BQ6: 0 | BR6: 0 | BS6: 1.0025723 | BT6: 1.0025723 | BU6: 1.6254349 | BV6: 0 | BW6: 0 | BX6: 0 | BY6: 1.0009469 | BZ6: 1.0009469 | CA6: 1.6335338 | CB6: 0 | CC6: 0 | CD6: 0
A7: BeH2 | B7: 0.94719506 | C7: 0.94719506 | D7: 1.893168 | E7: 0 | F7: 0 | G7: 0 | H7: 0.9115222 | I7: 0.9115222 | J7: 1.8912197 | K7: 0.91563193 | L7: 0.91563193 | M7: 1.8910035 | N7: 0 | O7: 0 | P7: 0 | Q7: 0 | R7: 0 | S7: 0 | T7: 0 | U7: 0 | V7: 0 | W7: 0 | X7: 0 | Y7: 0 | Z7: 0 | AA7: 0 | AB7: 0 | AC7: 0.89443749 | AD7: 0.89443749 | AE7: 1.8851264 | AF7: 0 | AG7: 0 | AH7: 0 | AI7: 0.9036581 | AJ7: 0.9036581 | AK7: 1.8834067 | AL7: 0.91865159 | AM7: 0.91865159 | AN7: 1.917911 | AO7: 0.8996383 | AP7: 0.8996383 | AQ7: 1.9102882 | AR7: 0 | AS7: 0 | AT7: 0 | AU7: 0 | AV7: 0 | AW7: 0 | AX7: 0 | AY7: 0 | AZ7: 0 | BA7: 0 | BB7: 0 | BC7: 0 | BD7: 0.90832198 | BE7: 0.90832198 | BF7: 1.8836567 | BG7: 0 | BH7: 0 | BI7: 0 | BJ7: 0 | BK7: 0 | BL7: 0 | BM7: 0.91536123 | BN7: 0.91536123 | BO7: 1.9019803 | BP7: 0 | BQ7: 0 | BR7: 0 | BS7: 0.91240539 | BT7: 0.91240539 | BU7: 1.8910887 | BV7: 0 | BW7: 0 | BX7: 0 | BY7: 0 | BZ7: 0 | CA7: 0 | CB7: 0 | CC7: 0 | CD7: 0
A8: BF | B8: 0.77247994 | C8: 0.77247994 | D8: 1.4444191 | E8: 0 | F8: 0 | G8: 0 | H8: 0.7532669 | I8: 0.7532669 | J8: 1.4383296 | K8: 0.7582629 | L8: 0.7582629 | M8: 1.4395646 | N8: 0 | O8: 0 | P8: 0 | Q8: 0 | R8: 0 | S8: 0 | T8: 0 | U8: 0 | V8: 0 | W8: 0 | X8: 0 | Y8: 0 | Z8: 0 | AA8: 0 | AB8: 0 | AC8: 0.74378129 | AD8: 0.74378129 | AE8: 1.4366986 | AF8: 0 | AG8: 0 | AH8: 0 | AI8: 0.74953525 | AJ8: 0.74953525 | AK8: 1.4386869 | AL8: 0.75746057 | AM8: 0.75746057 | AN8: 1.4462153 | AO8: 0.74475882 | AP8: 0.74475882 | AQ8: 1.4446815 | AR8: 0 | AS8: 0 | AT8: 0 | AU8: 0 | AV8: 0 | AW8: 0 | AX8: 0 | AY8: 0 | AZ8: 0 | BA8: 0 | BB8: 0 | BC8: 0 | BD8: 0.74975485 | BE8: 0.74975485 | BF8: 1.4367377 | BG8: 0 | BH8: 0 | BI8: 0 | BJ8: 0 | BK8: 0 | BL8: 0 | BM8: 0.75258274 | BN8: 0.75258274 | BO8: 1.4380334 | BP8: 0 | BQ8: 0 | BR8: 0 | BS8: 0.75320697 | BT8: 0.75320697 | BU8: 1.4407064 | BV8: 0 | BW8: 0 | BX8: 0 | BY8: 0 | BZ8: 0 | CA8: 0 | CB8: 0 | CC8: 0 | CD8: 0
A9: BH3 | B9: 1.3609008 | C9: 1.3608807 | D9: 0.84338232 | E9: 0 | F9: 0 | G9: 0 | H9: 1.3488594 | I9: 1.3488391 | J9: 0.81659324 | K9: 1.3520319 | L9: 1.3520116 | M9: 0.82146674 | N9: 1.3458555 | O9: 1.3458352 | P9: 0.81682082 | Q9: 1.3472497 | R9: 1.3472293 | S9: 0.81900808 | T9: 0 | U9: 0 | V9: 0 | W9: 0 | X9: 0 | Y9: 0 | Z9: 0 | AA9: 0 | AB9: 0 | AC9: 1.3433258 | AD9: 1.3433054 | AE9: 0.8037804 | AF9: 1.3479221 | AG9: 1.3478914 | AH9: 0.81189082 | AI9: 1.3443735 | AJ9: 1.3443359 | AK9: 0.81150727 | AL9: 1.3615733 | AM9: 1.3615532 | AN9: 0.82106502 | AO9: 1.3541954 | AP9: 1.3541752 | AQ9: 0.80793781 | AR9: 0 | AS9: 0 | AT9: 0 | AU9: 1.3462283 | AV9: 1.3462115 | AW9: 0.81278317 | AX9: 1.3492762 | AY9: 1.3492559 | AZ9: 0.81815092 | BA9: 1.3495689 | BB9: 1.3495486 | BC9: 0.81849162 | BD9: 1.3471013 | BE9: 1.347081 | BF9: 0.81863922 | BG9: 0 | BH9: 0 | BI9: 0 | BJ9: 0 | BK9: 0 | BL9: 0 | BM9: 1.3514578 | BN9: 1.3514376 | BO9: 0.82013636 | BP9: 0 | BQ9: 0 | BR9: 0 | BS9: 1.3499751 | BT9: 1.3499548 | BU9: 0.8211782 | BV9: 0 | BW9: 0 | BX9: 0 | BY9: 0 | BZ9: 0 | CA9: 0 | CB9: 0 | CC9: 0 | CD9: 0
A10: BO | B10: 0.78698471 | C10: 0.78698471 | D10: 1.3564866 | E10: 0.77789565 | F10: 0.77789565 | G10: 1.3490207 | H10: 0.77286166 | I10: 0.77286166 | J10: 1.3478662 | K10: 0 | L10: 0 | M10: 0 | N10: 0 | O10: 0 | P10: 0 | Q10: 0 | R10: 0 | S10: 0 | T10: 0.7758528 | U10: 0.7758528 | V10: 1.3484466 | W10: 0 | X10: 0 | Y10: 0 | Z10: 0 | AA10: 0 | AB10: 0 | AC10: 0.76392275 | AD10: 0.76392275 | AE10: 1.3436147 | AF10: 0 | AG10: 0 | AH10: 0 | AI10: 0.77021167 | AJ10: 0.77021167 | AK10: 1.3455 | AL10: 0.77783684 | AM10: 0.77783684 | AN10: 1.3475969 | AO10: 0.76673248 | AP10: 0.76673248 | AQ10: 1.3447858 | AR10: 0.77079434 | AS10: 0.77079434 | AT10: 1.343494 | AU10: 0 | AV10: 0 | AW10: 0 | AX10: 0 | AY10: 0 | AZ10: 0 | BA10: 0 | BB10: 0 | BC10: 0 | BD10: 0.77259522 | BE10: 0.77259522 | BF10: 1.3422314 | BG10: 0.77141363 | BH10: 0.77141363 | BI10: 1.3442355 | BJ10: 0 | BK10: 0 | BL10: 0 | BM10: 0.77451376 | BN10: 0.77451376 | BO10: 1.3423694 | BP10: 0.76901899 | BQ10: 0.76901899 | BR10: 1.3411026 | BS10: 0.77432913 | BT10: 0.77432913 | BU10: 1.3456458 | BV10: 0 | BW10: 0 | BX10: 0 | BY10: 0 | BZ10: 0 | CA10: 0 | CB10: 0 | CC10: 0 | CD10: 0
A11: BS | B11: 0.83499403 | C11: 0.83499403 | D11: 1.5164507 | E11: 0.82525736 | F11: 0.82525736 | G11: 1.5101725 | H11: 0 | I11: 0 | J11: 0 | K11: 0.8260292 | L11: 0.8260292 | M11: 1.510934 | N11: 0.82091301 | O11: 0.82091301 | P11: 1.5073817 | Q11: 0.82229408 | R11: 0.82229408 | S11: 1.5082435 | T11: 0.82352237 | U11: 0.82352237 | V11: 1.509216 | W11: 0 | X11: 0 | Y11: 0 | Z11: 0 | AA11: 0 | AB11: 0 | AC11: 0 | AD11: 0 | AE11: 0 | AF11: 0.81797511 | AG11: 0.81797511 | AH11: 1.5036399 | AI11: 0 | AJ11: 0 | AK11: 0 | AL11: 0 | AM11: 0 | AN11: 0 | AO11: 0 | AP11: 0 | AQ11: 0 | AR11: 0.82170186 | AS11: 0.82170186 | AT11: 1.5045637 | AU11: 0.82138512 | AV11: 0.82138512 | AW11: 1.5077407 | AX11: 0.82521232 | AY11: 0.82521232 | AZ11: 1.5070735 | BA11: 0.82549114 | BB11: 0.82549114 | BC11: 1.5072626 | BD11: 0 | BE11: 0 | BF11: 0 | BG11: 0.82305579 | BH11: 0.82305579 | BI11: 1.5048568 | BJ11: 0 | BK11: 0 | BL11: 0 | BM11: 0 | BN11: 0 | BO11: 0 | BP11: 0.82291168 | BQ11: 0.82291168 | BR11: 1.5022308 | BS11: 0 | BT11: 0 | BU11: 0 | BV11: 0 | BW11: 0 | BX11: 0 | BY11: 0.82530455 | BZ11: 0.82530455 | CA11: 1.5043921 | CB11: 0 | CC11: 0 | CD11: 0
A12: C2H | B12: 0.87268425 | C12: 0.87268425 | D12: 1.5542355 | E12: 0.8607774 | F12: 0.8607774 | G12: 1.5476206 | H12: 0.85644454 | I12: 0.85644454 | J12: 1.5465062 | K12: 0 | L12: 0 | M12: 0 | N12: 0 | O12: 0 | P12: 0 | Q12: 0.8570987 | R12: 0.8570987 | S12: 1.5468959 | T12: 0.85859539 | U12: 0.85859539 | V12: 1.5475259 | W12: 0.85936438 | X12: 0.85936438 | Y12: 1.544933 | Z12: 0.85928785 | AA12: 0.85928785 | AB12: 1.5449144 | AC12: 0.84767864 | AD12: 0.84767864 | AE12: 1.5427839 | AF12: 0.85298185 | AG12: 0.85298185 | AH12: 1.5428353 | AI12: 0.85478353 | AJ12: 0.85478353 | AK12: 1.5436219 | AL12: 0.86863468 | AM12: 0.86863468 | AN12: 1.5474372 | AO12: 0.85254257 | AP12: 0.85254257 | AQ12: 1.5424924 | AR12: 0.85613063 | AS12: 0.85613063 | AT12: 1.542885 | AU12: 0.85648461 | AV12: 0.85648461 | AW12: 1.5455952 | AX12: 0 | AY12: 0 | AZ12: 0 | BA12: 0 | BB12: 0 | BC12: 0 | BD12: 0.86057806 | BE12: 0.86057806 | BF12: 1.5440491 | BG12: 0.85803569 | BH12: 0.85803569 | BI12: 1.5433064 | BJ12: 0.8617668 | BK12: 0.8617668 | BL12: 1.5444026 | BM12: 0.85944091 | BN12: 0.85944091 | BO12: 1.5463041 | BP12: 0.85723548 | BQ12: 0.85723548 | BR12: 1.5411847 | BS12: 0.86152786 | BT12: 0.86152786 | BU12: 1.5455975 | BV12: 0.85749896 | BW12: 0.85749896 | BX12: 1.5420896 | BY12: 0.86076744 | BZ12: 0.86076744 | CA12: 1.5442492 | CB12: 0.86443384 | CC12: 0.86443384 | CD12: 1.5464392
A13: C2H2 | B13: 0.86817721 | C13: 0.86817721 | D13: 1.7087401 | E13: 0 | F13: 0 | G13: 0 | H13: 0.85132679 | I13: 0.85132679 | J13: 1.7037743 | K13: 0.85569464 | L13: 0.85569464 | M13: 1.7073643 | N13: 0 | O13: 0 | P13: 0 | Q13: 0 | R13: 0 | S13: 0 | T13: 0 | U13: 0 | V13: 0 | W13: 0 | X13: 0 | Y13: 0 | Z13: 0 | AA13: 0 | AB13: 0 | AC13: 0.8420976 | AD13: 0.8420976 | AE13: 1.7005998 | AF13: 0 | AG13: 0 | AH13: 0 | AI13: 0.84978774 | AJ13: 0.84978774 | AK13: 1.7009136 | AL13: 0.86242971 | AM13: 0.86242971 | AN13: 1.7052838 | AO13: 0.84664166 | AP13: 0.84664166 | AQ13: 1.7011665 | AR13: 0 | AS13: 0 | AT13: 0 | AU13: 0 | AV13: 0 | AW13: 0 | AX13: 0 | AY13: 0 | AZ13: 0 | BA13: 0 | BB13: 0 | BC13: 0 | BD13: 0.85449291 | BE13: 0.85449291 | BF13: 1.6998252 | BG13: 0 | BH13: 0 | BI13: 0 | BJ13: 0 | BK13: 0 | BL13: 0 | BM13: 0.85336728 | BN13: 0.85336728 | BO13: 1.7033051 | BP13: 0 | BQ13: 0 | BR13: 0 | BS13: 0.85644836 | BT13: 0.85644836 | BU13: 1.7018984 | BV13: 0 | BW13: 0 | BX13: 0 | BY13: 0 | BZ13: 0 | CA13: 0 | CB13: 0 | CC13: 0 | CD13: 0
A14: CH3 | B14: 1.1508656 | C14: 1.1508461 | D14: 0.89533522 | E14: 1.1406455 | F14: 1.1406258 | G14: 0.87982483 | H14: 0 | I14: 0 | J14: 0 | K14: 1.1429535 | L14: 1.1429338 | M14: 0.87559421 | N14: 1.1370186 | O14: 1.1369952 | P14: 0.86909324 | Q14: 1.138507 | R14: 1.1384873 | S14: 0.87112971 | T14: 1.1395586 | U14: 1.1395389 | V14: 0.87353032 | W14: 0 | X14: 0 | Y14: 0 | Z14: 0 | AA14: 0 | AB14: 0 | AC14: 0 | AD14: 0 | AE14: 0 | AF14: 1.1350371 | AG14: 1.1350173 | AH14: 0.85942021 | AI14: 0 | AJ14: 0 | AK14: 0 | AL14: 0 | AM14: 0 | AN14: 0 | AO14: 0 | AP14: 0 | AQ14: 0 | AR14: 1.134866 | AS14: 1.1348681 | AT14: 0.86338567 | AU14: 1.1371603 | AV14: 1.1371405 | AW14: 0.86653259 | AX14: 0 | AY14: 0 | AZ14: 0 | BA14: 1.1393774 | BB14: 1.1393541 | BC14: 0.87095426 | BD14: 0 | BE14: 0 | BF14: 0 | BG14: 1.1354991 | BH14: 1.1354794 | BI14: 0.86768534 | BJ14: 1.1387319 | BK14: 1.1387086 | BL14: 0.870959 | BM14: 0 | BN14: 0 | BO14: 0 | BP14: 1.1334238 | BQ14: 1.1334223 | BR14: 0.86223196 | BS14: 0 | BT14: 0 | BU14: 0 | BV14: 1.1342726 | BW14: 1.1342528 | BX14: 0.86576959 | BY14: 0 | BZ14: 0 | CA14: 0 | CB14: 0 | CC14: 0 | CD14: 0
A15: CH4 | B15: 1.1046643 | C15: 1.1046643 | D15: 1.1046643 | E15: 1.094495 | F15: 1.094495 | G15: 1.094495 | H15: 1.0907117 | I15: 1.0907117 | J15: 1.0907117 | K15: 0 | L15: 0 | M15: 0 | N15: 0 | O15: 0 | P15: 0 | Q15: 0 | R15: 0 | S15: 0 | T15: 1.0925914 | U15: 1.0925914 | V15: 1.0925914 | W15: 0 | X15: 0 | Y15: 0 | Z15: 0 | AA15: 0 | AB15: 0 | AC15: 1.0838429 | AD15: 1.0838429 | AE15: 1.0838429 | AF15: 0 | AG15: 0 | AH15: 0 | AI15: 1.088255 | AJ15: 1.088255 | AK15: 1.088255 | AL15: 1.0966225 | AM15: 1.0966225 | AN15: 1.0966225 | AO15: 1.0880876 | AP15: 1.0880876 | AQ15: 1.0880876 | AR15: 1.0886477 | AS15: 1.0886477 | AT15: 1.0886477 | AU15: 0 | AV15: 0 | AW15: 0 | AX15: 1.092343 | AY15: 1.092343 | AZ15: 1.092343 | BA15: 0 | BB15: 0 | BC15: 0 | BD15: 1.0910149 | BE15: 1.0910149 | BF15: 1.0910149 | BG15: 1.0891974 | BH15: 1.0891974 | BI15: 1.0891974 | BJ15: 0 | BK15: 0 | BL15: 0 | BM15: 1.0916928 | BN15: 1.0916928 | BO15: 1.0916928 | BP15: 1.087575 | BQ15: 1.087575 | BR15: 1.087575 | BS15: 1.0930132 | BT15: 1.0930132 | BU15: 1.0930132 | BV15: 0 | BW15: 0 | BX15: 0 | BY15: 0 | BZ15: 0 | CA15: 0 | CB15: 0 | CC15: 0 | CD15: 0
... A43: SiO | B43: 0 | C43: 0 | D43: 0 | E43: 0 | F43: 0 | G43: 0 | H43: 0 | I43: 0 | J43: 0 | K43: 0 | L43: 0 | M43: 0 | N43: 0 | O43: 0 | P43: 0 | Q43: 0 | R43: 0 | S43: 0 | T43: 0 | U43: 0 | V43: 0 | W43: 0 | X43: 0 | Y43: 0 | Z43: 0 | AA43: 0 | AB43: 0 | AC43: 0 | AD43: 0 | AE43: 0 | AF43: 0 | AG43: 0 | AH43: 0 | AI43: 0 | AJ43: 0 | AK43: 0 | AL43: 0 | AM43: 0 | AN43: 0 | AO43: 0 | AP43: 0 | AQ43: 0 | AR43: 0 | AS43: 0 | AT43: 0 | AU43: 0 | AV43: 0 | AW43: 0 | AX43: 0 | AY43: 0 | AZ43: 0 | BA43: 0 | BB43: 0 | BC43: 0 | BD43: 0 | BE43: 0 | BF43: 0 | BG43: 0 | BH43: 0 | BI43: 0 | BJ43: 0 | BK43: 0 | BL43: 0 | BM43: 0 | BN43: 0 | BO43: 0 | BP43: 0 | BQ43: 0 | BR43: 0 | BS43: 0 | BT43: 0 | BU43: 0 | BV43: 0 | BW43: 0 | BX43: 0 | BY43: 0 | BZ43: 0 | CA43: 0 | CB43: 0 | CC43: 0 | CD43: 0

Sheet combine_values
A1: method | B1: CCSD\(T\) | C1: CCSD\(T\) | D1: CCSD\(T\) | F1: HF | G1: HF | H1: HF | I1: MP2 | J1: MP2 | K1: MP2 | L1: CCSD | M1: CCSD | N1: CCSD | O1: Slater | P1: Slater | Q1: Slater | R1: SPW92 | S1: SPW92 | T1: SPW92 | U1: B97-D3 | V1: B97-D3 | W1: B97-D3 | X1: BLYP | Y1: BLYP | Z1: BLYP | AA1: BPBE | AB1: BPBE | AC1: BPBE | AD1: mPW91 | AE1: mPW91 | AF1: mPW91 | AG1: PBE | AH1: PBE | AI1: PBE | AJ1: B97M-rV | AK1: B97M-rV | AL1: B97M-rV | AM1: B97M-V | AN1: B97M-V | AO1: B97M-V | AP1: M06-L | AQ1: M06-L | AR1: M06-L | AS1: mBEEF | AT1: mBEEF | AU1: mBEEF | AV1: MGGA_MS2 | AW1: MGGA_MS2 | AX1: MGGA_MS2 | AY1: MN15-L | AZ1: MN15-L | BA1: MN15-L | BB1: revM06-L | BC1: revM06-L | BD1: revM06-L | BE1: SCAN | BF1: SCAN | BG1: SCAN | BH1: TPSS | BI1: TPSS | BJ1: TPSS | BK1: B3LYP | BL1: B3LYP | BM1: B3LYP | BN1: B3LYP5 | BO1: B3LYP5 | BP1: B3LYP5 | BQ1: M06-2X | BR1: M06-2X | BS1: M06-2X | BT1: PBE0 | BU1: PBE0 | BV1: PBE0 | BW1: M08-HX | BX1: M08-HX | BY1: M08-HX | BZ1: MN15 | CA1: MN15 | CB1: MN15 | CC1: SCAN0 | CD1: SCAN0 | CE1: SCAN0 | CF1: CAM-B3LYP | CG1: CAM-B3LYP | CH1: CAM-B3LYP | CI1: wB97X-D | CJ1: wB97X-D | CK1: wB97X-D | CL1: wB97X-V | CM1: wB97X-V | CN1: wB97X-V | CO1: wB97M-V | CP1: wB97M-V | CQ1: wB97M-V
A2: component | B2: XX | C2: YY | D2: ZZ | F2: XX | G2: YY | H2: ZZ | I2: XX | J2: YY | K2: ZZ | L2: XX | M2: YY | N2: ZZ | O2: XX | P2: YY | Q2: ZZ | R2: XX | S2: YY | T2: ZZ | U2: XX | V2: YY | W2: ZZ | X2: XX | Y2: YY | Z2: ZZ | AA2: XX | AB2: YY | AC2: ZZ | AD2: XX | AE2: YY | AF2: ZZ | AG2: XX | AH2: YY | AI2: ZZ | AJ2: XX | AK2: YY | AL2: ZZ | AM2: XX | AN2: YY | AO2: ZZ | AP2: XX | AQ2: YY | AR2: ZZ | AS2: XX | AT2: YY | AU2: ZZ | AV2: XX | AW2: YY | AX2: ZZ | AY2: XX | AZ2: YY | BA2: ZZ | BB2: XX | BC2: YY | BD2: ZZ | BE2: XX | BF2: YY | BG2: ZZ | BH2: XX | BI2: YY | BJ2: ZZ | BK2: XX | BL2: YY | BM2: ZZ | BN2: XX | BO2: YY | BP2: ZZ | BQ2: XX | BR2: YY | BS2: ZZ | BT2: XX | BU2: YY | BV2: ZZ | BW2: XX | BX2: YY | BY2: ZZ | BZ2: XX | CA2: YY | CB2: ZZ | CC2: XX | CD2: YY | CE2: ZZ | CF2: XX | CG2: YY | CH2: ZZ | CI2: XX | CJ2: YY | CK2: ZZ | CL2: XX | CM2: YY | CN2: ZZ | CO2: XX | CP2: YY | CQ2: ZZ
A3: molecule
A4: Ar | B4: =OFFSET(wft_table!L$7,(ROW(wft_table!L1)-1)*4,0) -> 0.69285369 | C4: =OFFSET(wft_table!M$7,(ROW(wft_table!M1)-1)*4,0) -> 0.69285369 | D4: =OFFSET(wft_table!N$7,(ROW(wft_table!N1)-1)*4,0) -> 0.69285369 | F4: =OFFSET(wft_table!C$7,(ROW(wft_table!C1)-1)*4,0) -> 0.69439922 | G4: =OFFSET(wft_table!D$7,(ROW(wft_table!D1)-1)*4,0) -> 0.69439922 | H4: =OFFSET(wft_table!E$7,(ROW(wft_table!E1)-1)*4,0) -> 0.69439922 | I4: =OFFSET(wft_table!F$7,(ROW(wft_table!F1)-1)*4,0) -> 0.69340193 | J4: =OFFSET(wft_table!G$7,(ROW(wft_table!G1)-1)*4,0) -> 0.69340193 | K4: =OFFSET(wft_table!H$7,(ROW(wft_table!H1)-1)*4,0) -> 0.69340193 | L4: =OFFSET(wft_table!I$7,(ROW(wft_table!I1)-1)*4,0) -> 0.69246999 | M4: =OFFSET(wft_table!J$7,(ROW(wft_table!J1)-1)*4,0) -> 0.69246999 | N4: =OFFSET(wft_table!K$7,(ROW(wft_table!K1)-1)*4,0) -> 0.69246999 | O4: 0 | P4: 0 | Q4: 0 | R4: 0 | S4: 0 | T4: 0 | U4: 0 | V4: 0 | W4: 0 | X4: 0.6990825 | Y4: 0.6990825 | Z4: 0.6990825 | AA4: 0.69502052 | AB4: 0.69502052 | AC4: 0.69502052 | AD4: 0.69601821 | AE4: 0.69601821 | AF4: 0.69601821 | AG4: 0 | AH4: 0 | AI4: 0 | AJ4: 0 | AK4: 0 | AL4: 0 | AM4: 0 | AN4: 0 | AO4: 0 | AP4: 0 | AQ4: 0 | AR4: 0 | AS4: 0.69100341 | AT4: 0.69100341 | AU4: 0.69100341 | AV4: 0 | AW4: 0 | AX4: 0 | AY4: 0 | AZ4: 0 | BA4: 0 | BB4: 0 | BC4: 0 | BD4: 0 | BE4: 0 | BF4: 0 | BG4: 0 | BH4: 0.69509778 | BI4: 0.69509778 | BJ4: 0.69509778 | BK4: 0.69678036 | BL4: 0.69678036 | BM4: 0.69678036 | BN4: 0.69692854 | BO4: 0.69692854 | BP4: 0.69692854 | BQ4: 0 | BR4: 0 | BS4: 0 | BT4: 0 | BU4: 0 | BV4: 0 | BW4: 0 | BX4: 0 | BY4: 0 | BZ4: 0 | CA4: 0 | CB4: 0 | CC4: 0 | CD4: 0 | CE4: 0 | CF4: 0 | CG4: 0 | CH4: 0 | CI4: 0 | CJ4: 0 | CK4: 0 | CL4: 0.69548688 | CM4: 0.69548688 | CN4: 0.69548688 | CO4: 0 | CP4: 0 | CQ4: 0
A5: Be | B5: =OFFSET(wft_table!L$7,(ROW(wft_table!L2)-1)*4,0) -> 0 | C5: =OFFSET(wft_table!M$7,(ROW(wft_table!M2)-1)*4,0) -> 0 | D5: =OFFSET(wft_table!N$7,(ROW(wft_table!N2)-1)*4,0) -> 0 | F5: =OFFSET(wft_table!C$7,(ROW(wft_table!C2)-1)*4,0) -> 0 | G5: =OFFSET(wft_table!D$7,(ROW(wft_table!D2)-1)*4,0) -> 0 | H5: =OFFSET(wft_table!E$7,(ROW(wft_table!E2)-1)*4,0) -> 0 | I5: =OFFSET(wft_table!F$7,(ROW(wft_table!F2)-1)*4,0) -> 0 | J5: =OFFSET(wft_table!G$7,(ROW(wft_table!G2)-1)*4,0) -> 0 | K5: =OFFSET(wft_table!H$7,(ROW(wft_table!H2)-1)*4,0) -> 0 | L5: =OFFSET(wft_table!I$7,(ROW(wft_table!I2)-1)*4,0) -> 0 | M5: =OFFSET(wft_table!J$7,(ROW(wft_table!J2)-1)*4,0) -> 0 | N5: =OFFSET(wft_table!K$7,(ROW(wft_table!K2)-1)*4,0) -> 0 | O5: 1.222163 | P5: 1.222163 | Q5: 1.222163 | R5: 0 | S5: 0 | T5: 0 | U5: 1.1888048 | V5: 1.1888048 | W5: 1.1888048 | X5: 0 | Y5: 0 | Z5: 0 | AA5: 0 | AB5: 0 | AC5: 0 | AD5: 0 | AE5: 0 | AF5: 0 | AG5: 1.18255 | AH5: 1.18255 | AI5: 1.18255 | AJ5: 0 | AK5: 0 | AL5: 0 | AM5: 0 | AN5: 0 | AO5: 0 | AP5: 1.1778174 | AQ5: 1.1778174 | AR5: 1.1778174 | AS5: 0 | AT5: 0 | AU5: 0 | AV5: 1.1765226 | AW5: 1.1765226 | AX5: 1.1765226 | AY5: 1.2174699 | AZ5: 1.2174699 | BA5: 1.2174699 | BB5: 1.1858148 | BC5: 1.1858148 | BD5: 1.1858148 | BE5: 0 | BF5: 0 | BG5: 0 | BH5: 0 | BI5: 0 | BJ5: 0 | BK5: 0 | BL5: 0 | BM5: 0 | BN5: 0 | BO5: 0 | BP5: 0 | BQ5: 1.1770596 | BR5: 1.1770596 | BS5: 1.1770596 | BT5: 0 | BU5: 0 | BV5: 0 | BW5: 0 | BX5: 0 | BY5: 0 | BZ5: 1.2026394 | CA5: 1.2026394 | CB5: 1.2026394 | CC5: 0 | CD5: 0 | CE5: 0 | CF5: 1.1837753 | CG5: 1.1837753 | CH5: 1.1837753 | CI5: 0 | CJ5: 0 | CK5: 0 | CL5: 0 | CM5: 0 | CN5: 0 | CO5: 0 | CP5: 0 | CQ5: 0
A6: BeH | B6: =OFFSET(wft_table!L$7,(ROW(wft_table!L3)-1)*4,0) -> 0 | C6: =OFFSET(wft_table!M$7,(ROW(wft_table!M3)-1)*4,0) -> 0 | D6: =OFFSET(wft_table!N$7,(ROW(wft_table!N3)-1)*4,0) -> 0 | F6: =OFFSET(wft_table!C$7,(ROW(wft_table!C3)-1)*4,0) -> 0 | G6: =OFFSET(wft_table!D$7,(ROW(wft_table!D3)-1)*4,0) -> 0 | H6: =OFFSET(wft_table!E$7,(ROW(wft_table!E3)-1)*4,0) -> 0 | I6: =OFFSET(wft_table!F$7,(ROW(wft_table!F3)-1)*4,0) -> 0 | J6: =OFFSET(wft_table!G$7,(ROW(wft_table!G3)-1)*4,0) -> 0 | K6: =OFFSET(wft_table!H$7,(ROW(wft_table!H3)-1)*4,0) -> 0 | L6: =OFFSET(wft_table!I$7,(ROW(wft_table!I3)-1)*4,0) -> 0 | M6: =OFFSET(wft_table!J$7,(ROW(wft_table!J3)-1)*4,0) -> 0 | N6: =OFFSET(wft_table!K$7,(ROW(wft_table!K3)-1)*4,0) -> 0 | O6: 1.0396475 | P6: 1.0396475 | Q6: 1.6487272 | R6: 0 | S6: 0 | T6: 0 | U6: 1.0119905 | V6: 1.0119905 | W6: 1.6222705 | X6: 1.0097988 | Y6: 1.0097988 | Z6: 1.6220269 | AA6: 1.003358 | AB6: 1.003358 | AC6: 1.6180907 | AD6: 1.0067682 | AE6: 1.0067682 | AF6: 1.6192359 | AG6: 0 | AH6: 0 | AI6: 0 | AJ6: 0 | AK6: 0 | AL6: 0 | AM6: 0 | AN6: 0 | AO6: 0 | AP6: 0.98396417 | AQ6: 0.98396417 | AR6: 1.6156648 | AS6: 0.99777769 | AT6: 0.99777769 | AU6: 1.6238103 | AV6: 0.99506171 | AW6: 0.99506171 | AX6: 1.619569 | AY6: 1.022515 | AZ6: 1.022515 | BA6: 1.6504464 | BB6: 0.99820977 | BC6: 0.99820977 | BD6: 1.6408482 | BE6: 0 | BF6: 0 | BG6: 0 | BH6: 1.0007835 | BI6: 1.0007835 | BJ6: 1.616571 | BK6: 1.0027428 | BL6: 1.0027428 | BM6: 1.6225195 | BN6: 1.0037581 | BO6: 1.0037581 | BP6: 1.6230084 | BQ6: 1.0068716 | BR6: 1.0068716 | BS6: 1.6161825 | BT6: 0 | BU6: 0 | BV6: 0 | BW6: 0 | BX6: 0 | BY6: 0 | BZ6: 1.0328818 | CA6: 1.0328818 | CB6: 1.6270494 | CC6: 0 | CD6: 0 | CE6: 0 | CF6: 1.0025723 | CG6: 1.0025723 | CH6: 1.6254349 | CI6: 0 | CJ6: 0 | CK6: 0 | CL6: 1.0009469 | CM6: 1.0009469 | CN6: 1.6335338 | CO6: 0 | CP6: 0 | CQ6: 0
A7: BeH2 | B7: =OFFSET(wft_table!L$7,(ROW(wft_table!L4)-1)*4,0) -> 0 | C7: =OFFSET(wft_table!M$7,(ROW(wft_table!M4)-1)*4,0) -> 0 | D7: =OFFSET(wft_table!N$7,(ROW(wft_table!N4)-1)*4,0) -> 0 | F7: =OFFSET(wft_table!C$7,(ROW(wft_table!C4)-1)*4,0) -> 0 | G7: =OFFSET(wft_table!D$7,(ROW(wft_table!D4)-1)*4,0) -> 0 | H7: =OFFSET(wft_table!E$7,(ROW(wft_table!E4)-1)*4,0) -> 0 | I7: =OFFSET(wft_table!F$7,(ROW(wft_table!F4)-1)*4,0) -> 0 | J7: =OFFSET(wft_table!G$7,(ROW(wft_table!G4)-1)*4,0) -> 0 | K7: =OFFSET(wft_table!H$7,(ROW(wft_table!H4)-1)*4,0) -> 0 | L7: =OFFSET(wft_table!I$7,(ROW(wft_table!I4)-1)*4,0) -> 0 | M7: =OFFSET(wft_table!J$7,(ROW(wft_table!J4)-1)*4,0) -> 0 | N7: =OFFSET(wft_table!K$7,(ROW(wft_table!K4)-1)*4,0) -> 0 | O7: 0.94719506 | P7: 0.94719506 | Q7: 1.893168 | R7: 0 | S7: 0 | T7: 0 | U7: 0.9115222 | V7: 0.9115222 | W7: 1.8912197 | X7: 0.91563193 | Y7: 0.91563193 | Z7: 1.8910035 | AA7: 0 | AB7: 0 | AC7: 0 | AD7: 0 | AE7: 0 | AF7: 0 | AG7: 0 | AH7: 0 | AI7: 0 | AJ7: 0 | AK7: 0 | AL7: 0 | AM7: 0 | AN7: 0 | AO7: 0 | AP7: 0.89443749 | AQ7: 0.89443749 | AR7: 1.8851264 | AS7: 0 | AT7: 0 | AU7: 0 | AV7: 0.9036581 | AW7: 0.9036581 | AX7: 1.8834067 | AY7: 0.91865159 | AZ7: 0.91865159 | BA7: 1.917911 | BB7: 0.8996383 | BC7: 0.8996383 | BD7: 1.9102882 | BE7: 0 | BF7: 0 | BG7: 0 | BH7: 0 | BI7: 0 | BJ7: 0 | BK7: 0 | BL7: 0 | BM7: 0 | BN7: 0 | BO7: 0 | BP7: 0 | BQ7: 0.90832198 | BR7: 0.90832198 | BS7: 1.8836567 | BT7: 0 | BU7: 0 | BV7: 0 | BW7: 0 | BX7: 0 | BY7: 0 | BZ7: 0.91536123 | CA7: 0.91536123 | CB7: 1.9019803 | CC7: 0 | CD7: 0 | CE7: 0 | CF7: 0.91240539 | CG7: 0.91240539 | CH7: 1.8910887 | CI7: 0 | CJ7: 0 | CK7: 0 | CL7: 0 | CM7: 0 | CN7: 0 | CO7: 0 | CP7: 0 | CQ7: 0
A8: BF | B8: =OFFSET(wft_table!L$7,(ROW(wft_table!L5)-1)*4,0) -> 0.74695003 | C8: =OFFSET(wft_table!M$7,(ROW(wft_table!M5)-1)*4,0) -> 0.74695003 | D8: =OFFSET(wft_table!N$7,(ROW(wft_table!N5)-1)*4,0) -> 1.4332355 | F8: =OFFSET(wft_table!C$7,(ROW(wft_table!C5)-1)*4,0) -> 0.74361706 | G8: =OFFSET(wft_table!D$7,(ROW(wft_table!D5)-1)*4,0) -> 0.74361706 | H8: =OFFSET(wft_table!E$7,(ROW(wft_table!E5)-1)*4,0) -> 1.4472532 | I8: =OFFSET(wft_table!F$7,(ROW(wft_table!F5)-1)*4,0) -> 0.75015004 | J8: =OFFSET(wft_table!G$7,(ROW(wft_table!G5)-1)*4,0) -> 0.75015004 | K8: =OFFSET(wft_table!H$7,(ROW(wft_table!H5)-1)*4,0) -> 1.4386132 | L8: =OFFSET(wft_table!I$7,(ROW(wft_table!I5)-1)*4,0) -> 0.74514177 | M8: =OFFSET(wft_table!J$7,(ROW(wft_table!J5)-1)*4,0) -> 0.74514177 | N8: =OFFSET(wft_table!K$7,(ROW(wft_table!K5)-1)*4,0) -> 1.4346041 | O8: 0.77247994 | P8: 0.77247994 | Q8: 1.4444191 | R8: 0 | S8: 0 | T8: 0 | U8: 0.7532669 | V8: 0.7532669 | W8: 1.4383296 | X8: 0.7582629 | Y8: 0.7582629 | Z8: 1.4395646 | AA8: 0 | AB8: 0 | AC8: 0 | AD8: 0 | AE8: 0 | AF8: 0 | AG8: 0 | AH8: 0 | AI8: 0 | AJ8: 0 | AK8: 0 | AL8: 0 | AM8: 0 | AN8: 0 | AO8: 0 | AP8: 0.74378129 | AQ8: 0.74378129 | AR8: 1.4366986 | AS8: 0 | AT8: 0 | AU8: 0 | AV8: 0.74953525 | AW8: 0.74953525 | AX8: 1.4386869 | AY8: 0.75746057 | AZ8: 0.75746057 | BA8: 1.4462153 | BB8: 0.74475882 | BC8: 0.74475882 | BD8: 1.4446815 | BE8: 0 | BF8: 0 | BG8: 0 | BH8: 0 | BI8: 0 | BJ8: 0 | BK8: 0 | BL8: 0 | BM8: 0 | BN8: 0 | BO8: 0 | BP8: 0 | BQ8: 0.74975485 | BR8: 0.74975485 | BS8: 1.4367377 | BT8: 0 | BU8: 0 | BV8: 0 | BW8: 0 | BX8: 0 | BY8: 0 | BZ8: 0.75258274 | CA8: 0.75258274 | CB8: 1.4380334 | CC8: 0 | CD8: 0 | CE8: 0 | CF8: 0.75320697 | CG8: 0.75320697 | CH8: 1.4407064 | CI8: 0 | CJ8: 0 | CK8: 0 | CL8: 0 | CM8: 0 | CN8: 0 | CO8: 0 | CP8: 0 | CQ8: 0
A9: BH3 | B9: =OFFSET(wft_table!L$7,(ROW(wft_table!L6)-1)*4,0) -> 1.3440818 | C9: =OFFSET(wft_table!M$7,(ROW(wft_table!M6)-1)*4,0) -> 1.3440637 | D9: =OFFSET(wft_table!N$7,(ROW(wft_table!N6)-1)*4,0) -> 0.81370034 | F9: =OFFSET(wft_table!C$7,(ROW(wft_table!C6)-1)*4,0) -> 1.3505842 | G9: =OFFSET(wft_table!D$7,(ROW(wft_table!D6)-1)*4,0) -> 1.3505639 | H9: =OFFSET(wft_table!E$7,(ROW(wft_table!E6)-1)*4,0) -> 0.8130404 | I9: =OFFSET(wft_table!F$7,(ROW(wft_table!F6)-1)*4,0) -> 1.3452256 | J9: =OFFSET(wft_table!G$7,(ROW(wft_table!G6)-1)*4,0) -> 1.3452019 | K9: =OFFSET(wft_table!H$7,(ROW(wft_table!H6)-1)*4,0) -> 0.81356797 | L9: =OFFSET(wft_table!I$7,(ROW(wft_table!I6)-1)*4,0) -> 1.3440869 | M9: =OFFSET(wft_table!J$7,(ROW(wft_table!J6)-1)*4,0) -> 1.3440706 | N9: =OFFSET(wft_table!K$7,(ROW(wft_table!K6)-1)*4,0) -> 0.81290361 | O9: 1.3609008 | P9: 1.3608807 | Q9: 0.84338232 | R9: 0 | S9: 0 | T9: 0 | U9: 1.3488594 | V9: 1.3488391 | W9: 0.81659324 | X9: 1.3520319 | Y9: 1.3520116 | Z9: 0.82146674 | AA9: 1.3458555 | AB9: 1.3458352 | AC9: 0.81682082 | AD9: 1.3472497 | AE9: 1.3472293 | AF9: 0.81900808 | AG9: 0 | AH9: 0 | AI9: 0 | AJ9: 0 | AK9: 0 | AL9: 0 | AM9: 0 | AN9: 0 | AO9: 0 | AP9: 1.3433258 | AQ9: 1.3433054 | AR9: 0.8037804 | AS9: 1.3479221 | AT9: 1.3478914 | AU9: 0.81189082 | AV9: 1.3443735 | AW9: 1.3443359 | AX9: 0.81150727 | AY9: 1.3615733 | AZ9: 1.3615532 | BA9: 0.82106502 | BB9: 1.3541954 | BC9: 1.3541752 | BD9: 0.80793781 | BE9: 0 | BF9: 0 | BG9: 0 | BH9: 1.3462283 | BI9: 1.3462115 | BJ9: 0.81278317 | BK9: 1.3492762 | BL9: 1.3492559 | BM9: 0.81815092 | BN9: 1.3495689 | BO9: 1.3495486 | BP9: 0.81849162 | BQ9: 1.3471013 | BR9: 1.347081 | BS9: 0.81863922 | BT9: 0 | BU9: 0 | BV9: 0 | BW9: 0 | BX9: 0 | BY9: 0 | BZ9: 1.3514578 | CA9: 1.3514376 | CB9: 0.82013636 | CC9: 0 | CD9: 0 | CE9: 0 | CF9: 1.3499751 | CG9: 1.3499548 | CH9: 0.8211782 | CI9: 0 | CJ9: 0 | CK9: 0 | CL9: 0 | CM9: 0 | CN9: 0 | CO9: 0 | CP9: 0 | CQ9: 0
A10: BO | B10: =OFFSET(wft_table!L$7,(ROW(wft_table!L7)-1)*4,0) -> 0.77094245 | C10: =OFFSET(wft_table!M$7,(ROW(wft_table!M7)-1)*4,0) -> 0.77094245 | D10: =OFFSET(wft_table!N$7,(ROW(wft_table!N7)-1)*4,0) -> 1.3452716 | F10: =OFFSET(wft_table!C$7,(ROW(wft_table!C7)-1)*4,0) -> 0.76755999 | G10: =OFFSET(wft_table!D$7,(ROW(wft_table!D7)-1)*4,0) -> 0.76755999 | H10: =OFFSET(wft_table!E$7,(ROW(wft_table!E7)-1)*4,0) -> 1.3414078 | I10: =OFFSET(wft_table!F$7,(ROW(wft_table!F7)-1)*4,0) -> 0.77143995 | J10: =OFFSET(wft_table!G$7,(ROW(wft_table!G7)-1)*4,0) -> 0.77143995 | K10: =OFFSET(wft_table!H$7,(ROW(wft_table!H7)-1)*4,0) -> 1.3457744 | L10: =OFFSET(wft_table!I$7,(ROW(wft_table!I7)-1)*4,0) -> 0.76982316 | M10: =OFFSET(wft_table!J$7,(ROW(wft_table!J7)-1)*4,0) -> 0.76982316 | N10: =OFFSET(wft_table!K$7,(ROW(wft_table!K7)-1)*4,0) -> 1.3436379 | O10: 0.78698471 | P10: 0.78698471 | Q10: 1.3564866 | R10: 0.77789565 | S10: 0.77789565 | T10: 1.3490207 | U10: 0.77286166 | V10: 0.77286166 | W10: 1.3478662 | X10: 0 | Y10: 0 | Z10: 0 | AA10: 0 | AB10: 0 | AC10: 0 | AD10: 0 | AE10: 0 | AF10: 0 | AG10: 0.7758528 | AH10: 0.7758528 | AI10: 1.3484466 | AJ10: 0 | AK10: 0 | AL10: 0 | AM10: 0 | AN10: 0 | AO10: 0 | AP10: 0.76392275 | AQ10: 0.76392275 | AR10: 1.3436147 | AS10: 0 | AT10: 0 | AU10: 0 | AV10: 0.77021167 | AW10: 0.77021167 | AX10: 1.3455 | AY10: 0.77783684 | AZ10: 0.77783684 | BA10: 1.3475969 | BB10: 0.76673248 | BC10: 0.76673248 | BD10: 1.3447858 | BE10: 0.77079434 | BF10: 0.77079434 | BG10: 1.343494 | BH10: 0 | BI10: 0 | BJ10: 0 | BK10: 0 | BL10: 0 | BM10: 0 | BN10: 0 | BO10: 0 | BP10: 0 | BQ10: 0.77259522 | BR10: 0.77259522 | BS10: 1.3422314 | BT10: 0.77141363 | BU10: 0.77141363 | BV10: 1.3442355 | BW10: 0 | BX10: 0 | BY10: 0 | BZ10: 0.77451376 | CA10: 0.77451376 | CB10: 1.3423694 | CC10: 0.76901899 | CD10: 0.76901899 | CE10: 1.3411026 | CF10: 0.77432913 | CG10: 0.77432913 | CH10: 1.3456458 | CI10: 0 | CJ10: 0 | CK10: 0 | CL10: 0 | CM10: 0 | CN10: 0 | CO10: 0 | CP10: 0 | CQ10: 0
A11: BS | B11: =OFFSET(wft_table!L$7,(ROW(wft_table!L8)-1)*4,0) -> 0.8222529 | C11: =OFFSET(wft_table!M$7,(ROW(wft_table!M8)-1)*4,0) -> 0.8222529 | D11: =OFFSET(wft_table!N$7,(ROW(wft_table!N8)-1)*4,0) -> 1.5060146 | F11: =OFFSET(wft_table!C$7,(ROW(wft_table!C8)-1)*4,0) -> 0.82972192 | G11: =OFFSET(wft_table!D$7,(ROW(wft_table!D8)-1)*4,0) -> 0.82972192 | H11: =OFFSET(wft_table!E$7,(ROW(wft_table!E8)-1)*4,0) -> 1.501898 | I11: =OFFSET(wft_table!F$7,(ROW(wft_table!F8)-1)*4,0) -> 0.82535449 | J11: =OFFSET(wft_table!G$7,(ROW(wft_table!G8)-1)*4,0) -> 0.82535449 | K11: =OFFSET(wft_table!H$7,(ROW(wft_table!H8)-1)*4,0) -> 1.469877 | L11: =OFFSET(wft_table!I$7,(ROW(wft_table!I8)-1)*4,0) -> 0.82273115 | M11: =OFFSET(wft_table!J$7,(ROW(wft_table!J8)-1)*4,0) -> 0.82273115 | N11: =OFFSET(wft_table!K$7,(ROW(wft_table!K8)-1)*4,0) -> 1.5040148 | O11: 0.83499403 | P11: 0.83499403 | Q11: 1.5164507 | R11: 0.82525736 | S11: 0.82525736 | T11: 1.5101725 | U11: 0 | V11: 0 | W11: 0 | X11: 0.8260292 | Y11: 0.8260292 | Z11: 1.510934 | AA11: 0.82091301 | AB11: 0.82091301 | AC11: 1.5073817 | AD11: 0.82229408 | AE11: 0.82229408 | AF11: 1.5082435 | AG11: 0.82352237 | AH11: 0.82352237 | AI11: 1.509216 | AJ11: 0 | AK11: 0 | AL11: 0 | AM11: 0 | AN11: 0 | AO11: 0 | AP11: 0 | AQ11: 0 | AR11: 0 | AS11: 0.81797511 | AT11: 0.81797511 | AU11: 1.5036399 | AV11: 0 | AW11: 0 | AX11: 0 | AY11: 0 | AZ11: 0 | BA11: 0 | BB11: 0 | BC11: 0 | BD11: 0 | BE11: 0.82170186 | BF11: 0.82170186 | BG11: 1.5045637 | BH11: 0.82138512 | BI11: 0.82138512 | BJ11: 1.5077407 | BK11: 0.82521232 | BL11: 0.82521232 | BM11: 1.5070735 | BN11: 0.82549114 | BO11: 0.82549114 | BP11: 1.5072626 | BQ11: 0 | BR11: 0 | BS11: 0 | BT11: 0.82305579 | BU11: 0.82305579 | BV11: 1.5048568 | BW11: 0 | BX11: 0 | BY11: 0 | BZ11: 0 | CA11: 0 | CB11: 0 | CC11: 0.82291168 | CD11: 0.82291168 | CE11: 1.5022308 | CF11: 0 | CG11: 0 | CH11: 0 | CI11: 0 | CJ11: 0 | CK11: 0 | CL11: 0.82530455 | CM11: 0.82530455 | CN11: 1.5043921 | CO11: 0 | CP11: 0 | CQ11: 0
A12: C2H | B12: =OFFSET(wft_table!L$7,(ROW(wft_table!L9)-1)*4,0) -> 0.8548835 | C12: =OFFSET(wft_table!M$7,(ROW(wft_table!M9)-1)*4,0) -> 0.8548835 | D12: =OFFSET(wft_table!N$7,(ROW(wft_table!N9)-1)*4,0) -> 1.5576292 | F12: =OFFSET(wft_table!C$7,(ROW(wft_table!C9)-1)*4,0) -> 0.86066777 | G12: =OFFSET(wft_table!D$7,(ROW(wft_table!D9)-1)*4,0) -> 0.86066777 | H12: =OFFSET(wft_table!E$7,(ROW(wft_table!E9)-1)*4,0) -> 1.5450159 | I12: =OFFSET(wft_table!F$7,(ROW(wft_table!F9)-1)*4,0) -> 0.86984329 | J12: =OFFSET(wft_table!G$7,(ROW(wft_table!G9)-1)*4,0) -> 0.86984329 | K12: =OFFSET(wft_table!H$7,(ROW(wft_table!H9)-1)*4,0) -> 1.5467418 | L12: =OFFSET(wft_table!I$7,(ROW(wft_table!I9)-1)*4,0) -> 0.85474518 | M12: =OFFSET(wft_table!J$7,(ROW(wft_table!J9)-1)*4,0) -> 0.85474518 | N12: =OFFSET(wft_table!K$7,(ROW(wft_table!K9)-1)*4,0) -> 1.5565887 | O12: 0.87268425 | P12: 0.87268425 | Q12: 1.5542355 | R12: 0.8607774 | S12: 0.8607774 | T12: 1.5476206 | U12: 0.85644454 | V12: 0.85644454 | W12: 1.5465062 | X12: 0 | Y12: 0 | Z12: 0 | AA12: 0 | AB12: 0 | AC12: 0 | AD12: 0.8570987 | AE12: 0.8570987 | AF12: 1.5468959 | AG12: 0.85859539 | AH12: 0.85859539 | AI12: 1.5475259 | AJ12: 0.85936438 | AK12: 0.85936438 | AL12: 1.544933 | AM12: 0.85928785 | AN12: 0.85928785 | AO12: 1.5449144 | AP12: 0.84767864 | AQ12: 0.84767864 | AR12: 1.5427839 | AS12: 0.85298185 | AT12: 0.85298185 | AU12: 1.5428353 | AV12: 0.85478353 | AW12: 0.85478353 | AX12: 1.5436219 | AY12: 0.86863468 | AZ12: 0.86863468 | BA12: 1.5474372 | BB12: 0.85254257 | BC12: 0.85254257 | BD12: 1.5424924 | BE12: 0.85613063 | BF12: 0.85613063 | BG12: 1.542885 | BH12: 0.85648461 | BI12: 0.85648461 | BJ12: 1.5455952 | BK12: 0 | BL12: 0 | BM12: 0 | BN12: 0 | BO12: 0 | BP12: 0 | BQ12: 0.86057806 | BR12: 0.86057806 | BS12: 1.5440491 | BT12: 0.85803569 | BU12: 0.85803569 | BV12: 1.5433064 | BW12: 0.8617668 | BX12: 0.8617668 | BY12: 1.5444026 | BZ12: 0.85944091 | CA12: 0.85944091 | CB12: 1.5463041 | CC12: 0.85723548 | CD12: 0.85723548 | CE12: 1.5411847 | CF12: 0.86152786 | CG12: 0.86152786 | CH12: 1.5455975 | CI12: 0.85749896 | CJ12: 0.85749896 | CK12: 1.5420896 | CL12: 0.86076744 | CM12: 0.86076744 | CN12: 1.5442492 | CO12: 0.86443384 | CP12: 0.86443384 | CQ12: 1.5464392
A13: C2H2 | B13: =OFFSET(wft_table!L$7,(ROW(wft_table!L10)-1)*4,0) -> 0.84982426 | C13: =OFFSET(wft_table!M$7,(ROW(wft_table!M10)-1)*4,0) -> 0.84982426 | D13: =OFFSET(wft_table!N$7,(ROW(wft_table!N10)-1)*4,0) -> 1.7009085 | F13: =OFFSET(wft_table!C$7,(ROW(wft_table!C10)-1)*4,0) -> 0.86288526 | G13: =OFFSET(wft_table!D$7,(ROW(wft_table!D10)-1)*4,0) -> 0.86288526 | H13: =OFFSET(wft_table!E$7,(ROW(wft_table!E10)-1)*4,0) -> 1.6954865 | I13: =OFFSET(wft_table!F$7,(ROW(wft_table!F10)-1)*4,0) -> 0.85064974 | J13: =OFFSET(wft_table!G$7,(ROW(wft_table!G10)-1)*4,0) -> 0.85064974 | K13: =OFFSET(wft_table!H$7,(ROW(wft_table!H10)-1)*4,0) -> 1.701656 | L13: =OFFSET(wft_table!I$7,(ROW(wft_table!I10)-1)*4,0) -> 0.84986325 | M13: =OFFSET(wft_table!J$7,(ROW(wft_table!J10)-1)*4,0) -> 0.84986325 | N13: =OFFSET(wft_table!K$7,(ROW(wft_table!K10)-1)*4,0) -> 1.6995109 | O13: 0.86817721 | P13: 0.86817721 | Q13: 1.7087401 | R13: 0 | S13: 0 | T13: 0 | U13: 0.85132679 | V13: 0.85132679 | W13: 1.7037743 | X13: 0.85569464 | Y13: 0.85569464 | Z13: 1.7073643 | AA13: 0 | AB13: 0 | AC13: 0 | AD13: 0 | AE13: 0 | AF13: 0 | AG13: 0 | AH13: 0 | AI13: 0 | AJ13: 0 | AK13: 0 | AL13: 0 | AM13: 0 | AN13: 0 | AO13: 0 | AP13: 0.8420976 | AQ13: 0.8420976 | AR13: 1.7005998 | AS13: 0 | AT13: 0 | AU13: 0 | AV13: 0.84978774 | AW13: 0.84978774 | AX13: 1.7009136 | AY13: 0.86242971 | AZ13: 0.86242971 | BA13: 1.7052838 | BB13: 0.84664166 | BC13: 0.84664166 | BD13: 1.7011665 | BE13: 0 | BF13: 0 | BG13: 0 | BH13: 0 | BI13: 0 | BJ13: 0 | BK13: 0 | BL13: 0 | BM13: 0 | BN13: 0 | BO13: 0 | BP13: 0 | BQ13: 0.85449291 | BR13: 0.85449291 | BS13: 1.6998252 | BT13: 0 | BU13: 0 | BV13: 0 | BW13: 0 | BX13: 0 | BY13: 0 | BZ13: 0.85336728 | CA13: 0.85336728 | CB13: 1.7033051 | CC13: 0 | CD13: 0 | CE13: 0 | CF13: 0.85644836 | CG13: 0.85644836 | CH13: 1.7018984 | CI13: 0 | CJ13: 0 | CK13: 0 | CL13: 0 | CM13: 0 | CN13: 0 | CO13: 0 | CP13: 0 | CQ13: 0
A14: CH3 | B14: =OFFSET(wft_table!L$7,(ROW(wft_table!L11)-1)*4,0) -> 1.134365 | C14: =OFFSET(wft_table!M$7,(ROW(wft_table!M11)-1)*4,0) -> 1.1343453 | D14: =OFFSET(wft_table!N$7,(ROW(wft_table!N11)-1)*4,0) -> 0.86655431 | F14: =OFFSET(wft_table!C$7,(ROW(wft_table!C11)-1)*4,0) -> 1.1350553 | G14: =OFFSET(wft_table!D$7,(ROW(wft_table!D11)-1)*4,0) -> 1.1350355 | H14: =OFFSET(wft_table!E$7,(ROW(wft_table!E11)-1)*4,0) -> 0.86410776 | I14: =OFFSET(wft_table!F$7,(ROW(wft_table!F11)-1)*4,0) -> 1.1345454 | J14: =OFFSET(wft_table!G$7,(ROW(wft_table!G11)-1)*4,0) -> 1.1345232 | K14: =OFFSET(wft_table!H$7,(ROW(wft_table!H11)-1)*4,0) -> 0.86940495 | L14: =OFFSET(wft_table!I$7,(ROW(wft_table!I11)-1)*4,0) -> 1.1337317 | M14: =OFFSET(wft_table!J$7,(ROW(wft_table!J11)-1)*4,0) -> 1.1337138 | N14: =OFFSET(wft_table!K$7,(ROW(wft_table!K11)-1)*4,0) -> 0.86538943 | O14: 1.1508656 | P14: 1.1508461 | Q14: 0.89533522 | R14: 1.1406455 | S14: 1.1406258 | T14: 0.87982483 | U14: 0 | V14: 0 | W14: 0 | X14: 1.1429535 | Y14: 1.1429338 | Z14: 0.87559421 | AA14: 1.1370186 | AB14: 1.1369952 | AC14: 0.86909324 | AD14: 1.138507 | AE14: 1.1384873 | AF14: 0.87112971 | AG14: 1.1395586 | AH14: 1.1395389 | AI14: 0.87353032 | AJ14: 0 | AK14: 0 | AL14: 0 | AM14: 0 | AN14: 0 | AO14: 0 | AP14: 0 | AQ14: 0 | AR14: 0 | AS14: 1.1350371 | AT14: 1.1350173 | AU14: 0.85942021 | AV14: 0 | AW14: 0 | AX14: 0 | AY14: 0 | AZ14: 0 | BA14: 0 | BB14: 0 | BC14: 0 | BD14: 0 | BE14: 1.134866 | BF14: 1.1348681 | BG14: 0.86338567 | BH14: 1.1371603 | BI14: 1.1371405 | BJ14: 0.86653259 | BK14: 0 | BL14: 0 | BM14: 0 | BN14: 1.1393774 | BO14: 1.1393541 | BP14: 0.87095426 | BQ14: 0 | BR14: 0 | BS14: 0 | BT14: 1.1354991 | BU14: 1.1354794 | BV14: 0.86768534 | BW14: 1.1387319 | BX14: 1.1387086 | BY14: 0.870959 | BZ14: 0 | CA14: 0 | CB14: 0 | CC14: 1.1334238 | CD14: 1.1334223 | CE14: 0.86223196 | CF14: 0 | CG14: 0 | CH14: 0 | CI14: 1.1342726 | CJ14: 1.1342528 | CK14: 0.86576959 | CL14: 0 | CM14: 0 | CN14: 0 | CO14: 0 | CP14: 0 | CQ14: 0
A15: CH4 | B15: =OFFSET(wft_table!L$7,(ROW(wft_table!L12)-1)*4,0) -> 1.0883268 | C15: =OFFSET(wft_table!M$7,(ROW(wft_table!M12)-1)*4,0) -> 1.0883268 | D15: =OFFSET(wft_table!N$7,(ROW(wft_table!N12)-1)*4,0) -> 1.0883268 | F15: =OFFSET(wft_table!C$7,(ROW(wft_table!C12)-1)*4,0) -> 1.0898013 | G15: =OFFSET(wft_table!D$7,(ROW(wft_table!D12)-1)*4,0) -> 1.0898013 | H15: =OFFSET(wft_table!E$7,(ROW(wft_table!E12)-1)*4,0) -> 1.0898013 | I15: =OFFSET(wft_table!F$7,(ROW(wft_table!F12)-1)*4,0) -> 1.0892216 | J15: =OFFSET(wft_table!G$7,(ROW(wft_table!G12)-1)*4,0) -> 1.0892216 | K15: =OFFSET(wft_table!H$7,(ROW(wft_table!H12)-1)*4,0) -> 1.0892216 | L15: =OFFSET(wft_table!I$7,(ROW(wft_table!I12)-1)*4,0) -> 1.0876924 | M15: =OFFSET(wft_table!J$7,(ROW(wft_table!J12)-1)*4,0) -> 1.0876924 | N15: =OFFSET(wft_table!K$7,(ROW(wft_table!K12)-1)*4,0) -> 1.0876924 | O15: 1.1046643 | P15: 1.1046643 | Q15: 1.1046643 | R15: 1.094495 | S15: 1.094495 | T15: 1.094495 | U15: 1.0907117 | V15: 1.0907117 | W15: 1.0907117 | X15: 0 | Y15: 0 | Z15: 0 | AA15: 0 | AB15: 0 | AC15: 0 | AD15: 0 | AE15: 0 | AF15: 0 | AG15: 1.0925914 | AH15: 1.0925914 | AI15: 1.0925914 | AJ15: 0 | AK15: 0 | AL15: 0 | AM15: 0 | AN15: 0 | AO15: 0 | AP15: 1.0838429 | AQ15: 1.0838429 | AR15: 1.0838429 | AS15: 0 | AT15: 0 | AU15: 0 | AV15: 1.088255 | AW15: 1.088255 | AX15: 1.088255 | AY15: 1.0966225 | AZ15: 1.0966225 | BA15: 1.0966225 | BB15: 1.0880876 | BC15: 1.0880876 | BD15: 1.0880876 | BE15: 1.0886477 | BF15: 1.0886477 | BG15: 1.0886477 | BH15: 0 | BI15: 0 | BJ15: 0 | BK15: 1.092343 | BL15: 1.092343 | BM15: 1.092343 | BN15: 0 | BO15: 0 | BP15: 0 | BQ15: 1.0910149 | BR15: 1.0910149 | BS15: 1.0910149 | BT15: 1.0891974 | BU15: 1.0891974 | BV15: 1.0891974 | BW15: 0 | BX15: 0 | BY15: 0 | BZ15: 1.0916928 | CA15: 1.0916928 | CB15: 1.0916928 | CC15: 1.087575 | CD15: 1.087575 | CE15: 1.087575 | CF15: 1.0930132 | CG15: 1.0930132 | CH15: 1.0930132 | CI15: 0 | CJ15: 0 | CK15: 0 | CL15: 0 | CM15: 0 | CN15: 0 | CO15: 0 | CP15: 0 | CQ15: 0
... A43: SiO | B43: =OFFSET(wft_table!L$7,(ROW(wft_table!L40)-1)*4,0) -> 0 | C43: =OFFSET(wft_table!M$7,(ROW(wft_table!M40)-1)*4,0) -> 0 | D43: =OFFSET(wft_table!N$7,(ROW(wft_table!N40)-1)*4,0) -> 0 | F43: =OFFSET(wft_table!C$7,(ROW(wft_table!C40)-1)*4,0) -> 0 | G43: =OFFSET(wft_table!D$7,(ROW(wft_table!D40)-1)*4,0) -> 0 | H43: =OFFSET(wft_table!E$7,(ROW(wft_table!E40)-1)*4,0) -> 0 | I43: =OFFSET(wft_table!F$7,(ROW(wft_table!F40)-1)*4,0) -> 0 | J43: =OFFSET(wft_table!G$7,(ROW(wft_table!G40)-1)*4,0) -> 0 | K43: =OFFSET(wft_table!H$7,(ROW(wft_table!H40)-1)*4,0) -> 0 | L43: =OFFSET(wft_table!I$7,(ROW(wft_table!I40)-1)*4,0) -> 0 | M43: =OFFSET(wft_table!J$7,(ROW(wft_table!J40)-1)*4,0) -> 0 | N43: =OFFSET(wft_table!K$7,(ROW(wft_table!K40)-1)*4,0) -> 0 | O43: 0 | P43: 0 | Q43: 0 | R43: 0 | S43: 0 | T43: 0 | U43: 0 | V43: 0 | W43: 0 | X43: 0 | Y43: 0 | Z43: 0 | AA43: 0 | AB43: 0 | AC43: 0 | AD43: 0 | AE43: 0 | AF43: 0 | AG43: 0 | AH43: 0 | AI43: 0 | AJ43: 0 | AK43: 0 | AL43: 0 | AM43: 0 | AN43: 0 | AO43: 0 | AP43: 0 | AQ43: 0 | AR43: 0 | AS43: 0 | AT43: 0 | AU43: 0 | AV43: 0 | AW43: 0 | AX43: 0 | AY43: 0 | AZ43: 0 | BA43: 0 | BB43: 0 | BC43: 0 | BD43: 0 | BE43: 0 | BF43: 0 | BG43: 0 | BH43: 0 | BI43: 0 | BJ43: 0 | BK43: 0 | BL43: 0 | BM43: 0 | BN43: 0 | BO43: 0 | BP43: 0 | BQ43: 0 | BR43: 0 | BS43: 0 | BT43: 0 | BU43: 0 | BV43: 0 | BW43: 0 | BX43: 0 | BY43: 0 | BZ43: 0 | CA43: 0 | CB43: 0 | CC43: 0 | CD43: 0 | CE43: 0 | CF43: 0 | CG43: 0 | CH43: 0 | CI43: 0 | CJ43: 0 | CK43: 0 | CL43: 0 | CM43: 0 | CN43: 0 | CO43: 0 | CP43: 0 | CQ43: 0

Sheet relative_error
A1: method | B1: CCSD\(T\) | C1: CCSD\(T\) | D1: CCSD\(T\) | E1: Error: | F1: HF | G1: HF | H1: HF | I1: MP2 | J1: MP2 | K1: MP2 | L1: CCSD | M1: CCSD | N1: CCSD | O1: Slater | P1: Slater | Q1: Slater | R1: SPW92 | S1: SPW92 | T1: SPW92 | U1: B97-D3 | V1: B97-D3 | W1: B97-D3 | X1: BLYP | Y1: BLYP | Z1: BLYP | AA1: BPBE | AB1: BPBE | AC1: BPBE | AD1: mPW91 | AE1: mPW91 | AF1: mPW91 | AG1: PBE | AH1: PBE | AI1: PBE | AJ1: B97M-rV | AK1: B97M-rV | AL1: B97M-rV | AM1: B97M-V | AN1: B97M-V | AO1: B97M-V | AP1: M06-L | AQ1: M06-L | AR1: M06-L | AS1: mBEEF | AT1: mBEEF | AU1: mBEEF | AV1: MGGA_MS2 | AW1: MGGA_MS2 | AX1: MGGA_MS2 | AY1: MN15-L | AZ1: MN15-L | BA1: MN15-L | BB1: revM06-L | BC1: revM06-L | BD1: revM06-L | BE1: SCAN | BF1: SCAN | BG1: SCAN | BH1: TPSS | BI1: TPSS | BJ1: TPSS | BK1: B3LYP | BL1: B3LYP | BM1: B3LYP | BN1: B3LYP5 | BO1: B3LYP5 | BP1: B3LYP5 | BQ1: M06-2X | BR1: M06-2X | BS1: M06-2X | BT1: PBE0 | BU1: PBE0 | BV1: PBE0 | BW1: M08-HX | BX1: M08-HX | BY1: M08-HX | BZ1: MN15 | CA1: MN15 | CB1: MN15 | CC1: SCAN0 | CD1: SCAN0 | CE1: SCAN0 | CF1: CAM-B3LYP | CG1: CAM-B3LYP | CH1: CAM-B3LYP | CI1: wB97X-D | CJ1: wB97X-D | CK1: wB97X-D | CL1: wB97X-V | CM1: wB97X-V | CN1: wB97X-V | CO1: wB97M-V | CP1: wB97M-V | CQ1: wB97M-V
A2: component | B2: XX | C2: YY | D2: ZZ | F2: XX | G2: YY | H2: ZZ | I2: XX | J2: YY | K2: ZZ | L2: XX | M2: YY | N2: ZZ | O2: XX | P2: YY | Q2: ZZ | R2: XX | S2: YY | T2: ZZ | U2: XX | V2: YY | W2: ZZ | X2: XX | Y2: YY | Z2: ZZ | AA2: XX | AB2: YY | AC2: ZZ | AD2: XX | AE2: YY | AF2: ZZ | AG2: XX | AH2: YY | AI2: ZZ | AJ2: XX | AK2: YY | AL2: ZZ | AM2: XX | AN2: YY | AO2: ZZ | AP2: XX | AQ2: YY | AR2: ZZ | AS2: XX | AT2: YY | AU2: ZZ | AV2: XX | AW2: YY | AX2: ZZ | AY2: XX | AZ2: YY | BA2: ZZ | BB2: XX | BC2: YY | BD2: ZZ | BE2: XX | BF2: YY | BG2: ZZ | BH2: XX | BI2: YY | BJ2: ZZ | BK2: XX | BL2: YY | BM2: ZZ | BN2: XX | BO2: YY | BP2: ZZ | BQ2: XX | BR2: YY | BS2: ZZ | BT2: XX | BU2: YY | BV2: ZZ | BW2: XX | BX2: YY | BY2: ZZ | BZ2: XX | CA2: YY | CB2: ZZ | CC2: XX | CD2: YY | CE2: ZZ | CF2: XX | CG2: YY | CH2: ZZ | CI2: XX | CJ2: YY | CK2: ZZ | CL2: XX | CM2: YY | CN2: ZZ | CO2: XX | CP2: YY | CQ2: ZZ
A3: molecule
