Workbook

Sheet wft_table
A1: method | C1: hf | D1: hf | E1: hf | F1: MP2 | G1: MP2 | H1: MP2 | I1: CCSD | J1: CCSD | K1: CCSD | L1: CCSD\(T\) | M1: CCSD\(T\) | N1: CCSD\(T\)
A2: component | C2: XX | D2: YY | E2: ZZ | F2: XX | G2: YY | H2: ZZ | I2: XX | J2: YY | K2: ZZ | L2: XX | M2: YY | N2: ZZ
A3: molecule | B3: basis
A4: AlF | B4: 5Z | C4: 0.72854306 | D4: 0.72854306 | E4: 1.7621938 | F4: 0 | G4: 0 | H4: 0 | I4: 0 | J4: 0 | K4: 0 | L4: 0 | M4: 0 | N4: 0
A5: AlF | B5: QZ | C5: 0.72861959 | D5: 0.72861959 | E5: 1.7622297 | F5: 0.73147015 | G5: 0.73147015 | H5: 1.7523137 | I5: 0.72835177 | J5: 0.72835177 | K5: 1.7524499 | L5: 0.72993209 | M5: 0.72993209 | N5: 1.7510654
A6: AlF | B6: TZ | C6: 0.72917827 | D6: 0.72917827 | E6: 1.7623956 | F6: 0.73343739 | G6: 0.73343739 | H6: 1.7534159 | I6: 0.73029785 | J6: 0.73029785 | K6: 1.7533173 | L6: 0.7319283 | M6: 0.7319283 | N6: 1.7520994
A7: AlF | B7: CBS | C7: 0.72854306 | D7: 0.72854306 | E7: 1.7621938 | F7: 0.73036575 | G7: 0.73036575 | H7: 1.7515945 | I7: 0.72726282 | J7: 0.72726282 | K7: 1.751902 | L7: 0.72880654 | M7: 0.72880654 | N7: 1.750396
A8: Ar | B8: 5Z | C8: 0.69439921 | D8: 0.69439921 | E8: 0.69439921 | F8: 0.69386453 | G8: 0.69386453 | H8: 0.69386453 | I8: 0.69292912 | J8: 0.69292912 | K8: 0.69292912 | L8: 0.6933419 | M8: 0.6933419 | N8: 0.6933419
A9: Ar | B9: QZ | C9: 0.69447654 | D9: 0.69447654 | E9: 0.69447654 | F9: 0.69438277 | G9: 0.69438277 | H9: 0.69438277 | I9: 0.69344405 | J9: 0.69344405 | K9: 0.69344405 | L9: 0.69388455 | M9: 0.69388455 | N9: 0.69388455
A10: Ar | B10: TZ | C10: 0.69479763 | D10: 0.69479763 | E10: 0.69479763 | F10: 0.69562777 | G10: 0.69562777 | H10: 0.69562777 | I10: 0.69500056 | J10: 0.69500056 | K10: 0.69500056 | L10: 0.69546603 | M10: 0.69546603 | N10: 0.69546603
A11: Ar | B11: CBS | C11: 0.69439921 | D11: 0.69439921 | E11: 0.69439921 | F11: 0.69340193 | G11: 0.69340193 | H11: 0.69340193 | I11: 0.69246999 | J11: 0.69246999 | K11: 0.69246999 | L11: 0.69285369 | M11: 0.69285369 | N11: 0.69285369
A12: BeH | B12: 5Z | C12: 0.98914899 | D12: 0.98914899 | E12: 1.6465447 | F12: 0.99014219 | G12: 0.99014219 | H12: 1.6340304 | I12: 0.99306172 | J12: 0.99306172 | K12: 1.6273622 | L12: 0.9939525 | M12: 0.9939525 | N12: 1.6261185
A13: BeH | B13: QZ | C13: 0.98912644 | D13: 0.98912644 | E13: 1.6467417 | F13: 0.99039465 | G13: 0.99039465 | H13: 1.6346673 | I13: 0.99330337 | J13: 0.99330337 | K13: 1.6278297 | L13: 0.9941889 | M13: 0.9941889 | N13: 1.6265946
A14: BeH | B14: TZ | C14: 0.98951723 | D14: 0.98951723 | E14: 1.6473933 | F14: 0.99193325 | G14: 0.99193325 | H14: 1.6390438 | I14: 0.99499326 | J14: 0.99499326 | K14: 1.6299186 | L14: 0.99587227 | M14: 0.99587227 | N14: 1.6288733
A15: BeH | B15: CBS | C15: 0.98914899 | D15: 0.98914899 | E15: 1.6465447 | F15: 0.98985366 | G15: 0.98985366 | H15: 1.6335688 | I15: 0.99278453 | J15: 0.99278453 | K15: 1.6270783 | L15: 0.99368082 | M15: 0.99368082 | N15: 1.6258257
... A72: CN | B72: 5Z | C72: 0.79423291 | D72: 0.79423291 | E72: 1.3449232 | F72: 0.80454064 | G72: 0.80454064 | H72: 1.3301664 | I72: 0.79183152 | J72: 0.79183152 | K72: 1.3438848 | L72: 0.79242874 | M72: 0.79242874 | N72: 1.345286
A73: CN | B73: QZ | C73: 0.79441291 | D73: 0.79441291 | E73: 1.3449275 | F73: 0.80495406 | G73: 0.80495645 | H73: 1.3306168 | I73: 0.79234137 | J73: 0.79234137 | K73: 1.3442121 | L73: 0.79298186 | M73: 0.79298186 | N73: 1.3455965 | T73: 0.761014 | U73: 0.761014 | V73: 1.596252 | W73: 0.766903 | X73: 0.766903 | Y73: 1.598887 | Z73: 0.763161 | AA73: 0.763161 | AB73: 1.5967 | AC73: 0.764286 | AD73: 0.764286 | AE73: 1.597599
A74: CN | B74: TZ | C74: 0.79470802 | D74: 0.79470802 | E74: 1.3451762 | F74: 0.80587809 | G74: 0.80587809 | H74: 1.3319041 | I74: 0.79360245 | J74: 0.79360245 | K74: 1.3453473 | L74: 0.79435572 | M74: 0.79435814 | N74: 1.3467083 | T74: 0.761262 | U74: 0.761262 | V74: 1.596361 | W74: 0.768257 | X74: 0.768257 | Y74: 1.599782 | Z74: 0.764681 | AA74: 0.764681 | AB74: 1.597664 | AC74: 0.765833 | AD74: 0.765833 | AE74: 1.598608
A75: CN | B75: CBS | C75: 0.79423291 | D75: 0.79423291 | E75: 1.3449232 | F75: 0.80429575 | G75: 0.80429324 | H75: 1.3296984 | I75: 0.79148544 | J75: 0.79148544 | K75: 1.3435458 | L75: 0.79203727 | M75: 0.79203727 | N75: 1.3449648
A76: CO | B76: 5Z | C76: 0.73637602 | D76: 0.73637602 | E76: 1.328403 | F76: 0 | G76: 0 | H76: 0 | I76: 0 | J76: 0 | K76: 0 | L76: 0 | M76: 0 | N76: 0
A77: CO | B77: QZ | C77: 0.73651303 | D77: 0.73651303 | E77: 1.3284592 | F77: 0.73983648 | G77: 0.73983648 | H77: 1.3150287 | I77: 0.73710399 | J77: 0.73710399 | K77: 1.3238018 | L77: 0.73784978 | M77: 0.73784978 | N77: 1.3211711
A78: CO | B78: TZ | C78: 0.73670768 | D78: 0.73670768 | E78: 1.3288576 | F78: 0.74100377 | G78: 0.74100377 | H78: 1.3158997 | I78: 0.73836268 | J78: 0.73836268 | K78: 1.3261847 | L78: 0.73913619 | M78: 0.73913619 | N78: 1.3234634
A79: CO | B79: CBS | C79: 0.73637602 | D79: 0.73637602 | E79: 1.328403 | F79: 0.73898971 | G79: 0.73898971 | H79: 1.3146277 | I79: 0.73619053 | J79: 0.73619053 | K79: 1.3222974 | L79: 0.73691609 | M79: 0.73691609 | N79: 1.3197329
A80: CO2 | B80: 5Z | C80: 0.70734459 | D80: 0.70734459 | E80: 2.0445844 | F80: 0 | G80: 0 | H80: 0 | I80: 0 | J80: 0 | K80: 0 | L80: 0 | M80: 0 | N80: 0
A81: CO2 | B81: QZ | C81: 0.70744969 | D81: 0.70744969 | E81: 2.0446068 | F81: 0.71037339 | G81: 0.71037339 | H81: 2.0373719 | I81: 0.70834691 | J81: 0.70834691 | K81: 2.0391899 | L81: 0.70895947 | M81: 0.70895947 | N81: 2.0381096
A82: CO2 | B82: TZ | C82: 0.70757626 | D82: 0.70757626 | E82: 2.0448803 | F82: 0.71135491 | G82: 0.71135491 | H82: 2.0379608 | I82: 0.70944978 | J82: 0.70944978 | K82: 2.0397281 | L82: 0.71009339 | M82: 0.71009339 | N82: 2.0386972
A83: CO2 | B83: CBS | C83: 0.70734459 | D83: 0.70734459 | E83: 2.0445844 | F83: 0.70964441 | G83: 0.70964441 | H83: 2.0371194 | I83: 0.70752938 | J83: 0.70752938 | K83: 2.0389744 | L83: 0.70811928 | M83: 0.70811928 | N83: 2.0378582
A84: F2 | B84: 5Z | C84: 0.62537814 | D84: 0.62537814 | E84: 1.4616788 | F84: 0.63268438 | G84: 0.63268438 | H84: 1.4666657 | I84: 0.63093456 | J84: 0.63093456 | K84: 1.463076 | L84: 0.63221662 | M84: 0.63221662 | N84: 1.4629526
A85: F2 | B85: QZ | C85: 0.62589639 | D85: 0.62589639 | E85: 1.4616053 | F85: 0.63342375 | G85: 0.63342375 | H85: 1.4666846 | I85: 0.63172654 | J85: 0.63172654 | K85: 1.4631311 | L85: 0.63298506 | M85: 0.63298506 | N85: 1.4630229
A86: F2 | B86: TZ | C86: 0.62673723 | D86: 0.62673723 | E86: 1.4616081 | F86: 0.63475549 | G86: 0.63475549 | H86: 1.4669204 | I86: 0.63329217 | J86: 0.63329217 | K86: 1.4634737 | L86: 0.63449943 | M86: 0.63449943 | N86: 1.4634101
... A139: Mg | B139: CBS | C139: 0.90697042 | D139: 0.90697042 | E139: 0.90697042 | F139: 0.88451912 | G139: 0.88451912 | H139: 0.88451912 | I139: 0.88475302 | J139: 0.88475302 | K139: 0.88475302 | L139: 0.88342042 | M139: 0.88342042 | N139: 0.88342042
A140: Mg2 | B140: 5Z | C140: 0.9000342 | D140: 0.9000342 | E140: 3.7941872 | F140: 0 | G140: 0 | I140: 0 | J140: 0 | L140: 0 | M140: 0
A141: Mg2 | B141: QZ | C141: 0.9000428 | D141: 0.9000428 | E141: 3.7941863 | F141: 0.88245231 | G141: 0.88245231 | H141: 3.7856981 | I141: 0.8822705 | J141: 0.8822705 | K141: 3.7859702 | L141: 0.88144365 | M141: 0.88144365 | N141: 3.7852
A142: Mg2 | B142: TZ | C142: 0.90014433 | D142: 0.90014433 | E142: 3.7941729 | F142: 0.88517136 | G142: 0.88517136 | H142: 3.7866275 | I142: 0.88435546 | J142: 0.88435546 | K142: 3.7865922 | L142: 0.88377929 | M142: 0.88377929 | N142: 3.7859559
A143: Mg2 | B143: CBS | C143: 0.9000342 | D143: 0.9000342 | E143: 3.7941872 | F143: 0.88053362 | G143: 0.88053362 | H143: =((H141-E141)*64-(H142-E142)*27)/(64-27)+E143 -> 3.7850109 | I143: 0.88081453 | J143: 0.88081453 | K143: =((K141-E141)*64-(K142-E142)*27)/(64-27)+E143 -> 3.7855073 | L143: 0.87980475 | M143: 0.87980475 | N143: =((N141-E141)*64-(N142-E142)*27)/(64-27)+E143 -> 3.7846394
A144: N | B144: 5Z | C144: 0.75839596 | D144: 0.75839596 | E144: 0.75839596 | F144: 0.76110413 | G144: 0.76110413 | H144: 0.76110413 | I144: 0.76122612 | J144: 0.76122612 | K144: 0.76122612 | L144: 0.76200455 | M144: 0.76200455 | N144: 0.76200455
A145: N | B145: QZ | C145: 0.758697 | D145: 0.758697 | E145: 0.758697 | F145: 0.76168108 | G145: 0.76168108 | H145: 0.76168108 | I145: 0.76180298 | J145: 0.76180298 | K145: 0.76180298 | L145: 0.76258082 | M145: 0.76258082 | N145: 0.76258082
A146: N | B146: TZ | C146: 0.75927075 | D146: 0.75927075 | E146: 0.75927075 | F146: 0.76298816 | G146: 0.76298816 | H146: 0.76298816 | I146: 0.76316601 | J146: 0.76316601 | K146: 0.76316601 | L146: 0.76393778 | M146: 0.76393778 | N146: 0.76393778
A147: N | B147: CBS | C147: 0.75839596 | D147: 0.75839596 | E147: 0.75839596 | F147: 0.76081465 | G147: 0.76081465 | H147: 0.76081465 | I147: 0.76093674 | J147: 0.76093674 | K147: 0.76093674 | L147: 0.76171578 | M147: 0.76171578 | N147: 0.76171578
A148: N2 | B148: 5Z | C148: 0.7425093 | D148: 0.7425093 | E148: 1.3012616 | F148: 0.73666295 | G148: 0.73666295 | H148: 1.3050455 | I148: 0.73698043 | J148: 0.73698043 | K148: 1.3027954 | L148: 0.73736075 | M148: 0.73736317 | N148: 1.3034929
...

Sheet dft_values
A1: method | B1: Slater | C1: Slater | D1: Slater | E1: SPW92 | F1: SPW92 | G1: SPW92 | H1: B97-D3 | I1: B97-D3 | J1: B97-D3 | K1: BLYP | L1: BLYP | M1: BLYP | N1: BPBE | O1: BPBE | P1: BPBE | Q1: mPW91 | R1: mPW91 | S1: mPW91 | T1: PBE | U1: PBE | V1: PBE | W1: B97M-V | X1: B97M-V | Y1: B97M-V | Z1: M06-L | AA1: M06-L | AB1: M06-L | AC1: mBEEF | AD1: mBEEF | AE1: mBEEF | AF1: MGGA_MS2 | AG1: MGGA_MS2 | AH1: MGGA_MS2 | AI1: MN15-L | AJ1: MN15-L | AK1: MN15-L | AL1: revM06-L | AM1: revM06-L | AN1: revM06-L | AO1: SCAN | AP1: SCAN | AQ1: SCAN | AR1: TPSS | AS1: TPSS | AT1: TPSS | AU1: B3LYP | AV1: B3LYP | AW1: B3LYP | AX1: M06-2X | AY1: M06-2X | AZ1: M06-2X | BA1: PBE0 | BB1: PBE0 | BC1: PBE0 | BD1: M08-HX | BE1: M08-HX | BF1: M08-HX | BG1: MN15 | BH1: MN15 | BI1: MN15 | BJ1: SCAN0 | BK1: SCAN0 | BL1: SCAN0 | BM1: CAM-B3LYP | BN1: CAM-B3LYP | BO1: CAM-B3LYP | BP1: wB97X-D | BQ1: wB97X-D | BR1: wB97X-D | BS1: wB97X-V | BT1: wB97X-V | BU1: wB97X-V | BV1: wB97M-V | BW1: wB97M-V | BX1: wB97M-V
A2: component | B2: XX | C2: YY | D2: ZZ | E2: XX | F2: YY | G2: ZZ | H2: XX | I2: YY | J2: ZZ | K2: XX | L2: YY | M2: ZZ | N2: XX | O2: YY | P2: ZZ | Q2: XX | R2: YY | S2: ZZ | T2: XX | U2: YY | V2: ZZ | W2: XX | X2: YY | Y2: ZZ | Z2: XX | AA2: YY | AB2: ZZ | AC2: XX | AD2: YY | AE2: ZZ | AF2: XX | AG2: YY | AH2: ZZ | AI2: XX | AJ2: YY | AK2: ZZ | AL2: XX | AM2: YY | AN2: ZZ | AO2: XX | AP2: YY | AQ2: ZZ | AR2: XX | AS2: YY | AT2: ZZ | AU2: XX | AV2: YY | AW2: ZZ | AX2: XX | AY2: YY | AZ2: ZZ | BA2: XX | BB2: YY | BC2: ZZ | BD2: XX | BE2: YY | BF2: ZZ | BG2: XX | BH2: YY | BI2: ZZ | BJ2: XX | BK2: YY | BL2: ZZ | BM2: XX | BN2: YY | BO2: ZZ | BP2: XX | BQ2: YY | BR2: ZZ | BS2: XX | BT2: YY | BU2: ZZ | BV2: XX | BW2: YY | BX2: ZZ
A3: molecule
A4: AlF | B4: 0.74836109 | C4: 0.74836109 | D4: 1.7521481 | E4: 0.73560133 | F4: 0.73560133 | G4: 1.7471144 | H4: 0.73412284 | I4: 0.73412284 | J4: 1.7504678 | K4: 0.73648058 | L4: 0.73648058 | M4: 1.7501495 | N4: 0.73291115 | O4: 0.73291115 | P4: 1.7488949 | Q4: 0.7342195 | R4: 0.7342195 | S4: 1.7491885 | T4: 0.735831 | U4: 0.735831 | V4: 1.7495727 | W4: 0.73350342 | X4: 0.73350342 | Y4: 1.7538892 | Z4: 0.72483431 | AA4: 0.72483431 | AB4: 1.7488584 | AC4: 0.73059971 | AD4: 0.73059971 | AE4: 1.751904 | AF4: 0.73202531 | AG4: 0.73202531 | AH4: 1.751487 | AI4: 0.74585289 | AJ4: 0.74585289 | AK4: 1.7597504 | AL4: 0.72853378 | AM4: 0.72853378 | AN4: 1.7583675 | AO4: 0.73217302 | AP4: 0.73217302 | AQ4: 1.7510181 | AR4: 0.73362781 | AS4: 0.73362781 | AT4: 1.7512682 | AU4: 0.73206455 | AV4: 0.73206455 | AW4: 1.7512251 | AX4: 0.72809761 | AY4: 0.72809761 | AZ4: 1.7501184 | BA4: 0.73092111 | BB4: 0.73092111 | BC4: 1.7515189 | BD4: 0.73084482 | BE4: 0.73084482 | BF4: 1.7543406 | BG4: 0.73740003 | BH4: 0.73740003 | BI4: 1.7509029 | BJ4: 0.72929876 | BK4: 0.72929876 | BL4: 1.7523173 | BM4: 0.73135329 | BN4: 0.73135329 | BO4: 1.7523969 | BP4: 0.729456 | BQ4: 0.729456 | BR4: 1.752647 | BS4: 0.7315866 | BT4: 0.7315866 | BU4: 1.7543901 | BV4: 0.73365545 | BW4: 0.73365545 | BX4: 1.7507439
A5: Ar | B5: 0.70452653 | C5: 0.70452653 | D5: 0.70452653 | E5: 0.69790575 | F5: 0.69790575 | G5: 0.69790575 | H5: 0.69342004 | I5: 0.69342004 | J5: 0.69342004 | K5: 0.6990825 | L5: 0.6990825 | M5: 0.6990825 | N5: 0.69502052 | O5: 0.69502052 | P5: 0.69502052 | Q5: 0.69601821 | R5: 0.69601821 | S5: 0.69601821 | T5: 0.69692854 | U5: 0.69692854 | V5: 0.69692854 | W5: 0.69387855 | X5: 0.69387855 | Y5: 0.69387855 | Z5: 0.69055795 | AA5: 0.69055795 | AB5: 0.69055795 | AC5: 0.69100341 | AD5: 0.69100341 | AE5: 0.69100341 | AF5: 0.6930268 | AG5: 0.6930268 | AH5: 0.6930268 | AI5: 0.69633563 | AJ5: 0.69633563 | AK5: 0.69633563 | AL5: 0.69181586 | AM5: 0.69181586 | AN5: 0.69181586 | AO5: 0.69374758 | AP5: 0.69374758 | AQ5: 0.69374758 | AR5: 0.69509778 | AS5: 0.69509778 | AT5: 0.69509778 | AU5: 0.69678036 | AV5: 0.69678036 | AW5: 0.69678036 | AX5: 0.69494029 | AY5: 0.69494029 | AZ5: 0.69494029 | BA5: 0.69450627 | BB5: 0.69450627 | BC5: 0.69450627 | BD5: 0.695668 | BE5: 0.695668 | BF5: 0.695668 | BG5: 0.69166957 | BH5: 0.69166957 | BI5: 0.69166957 | BJ5: 0.69312513 | BK5: 0.69312513 | BL5: 0.69312513 | BM5: 0.69720704 | BN5: 0.69720704 | BO5: 0.69720704 | BP5: 0.69332175 | BQ5: 0.69332175 | BR5: 0.69332175 | BS5: 0.69548688 | BT5: 0.69548688 | BU5: 0.69548688 | BV5: 0.69756536 | BW5: 0.69756536 | BX5: 0.69756536
A6: BeH | B6: 1.0396475 | C6: 1.0396475 | D6: 1.6487272 | E6: 1.021016 | F6: 1.021016 | G6: 1.6229892 | H6: 1.0119905 | I6: 1.0119905 | J6: 1.6222705 | K6: 1.0097988 | L6: 1.0097988 | M6: 1.6220269 | N6: 1.003358 | O6: 1.003358 | P6: 1.6180907 | Q6: 1.0067682 | R6: 1.0067682 | S6: 1.6192359 | T6: 1.0102993 | U6: 1.0102993 | V6: 1.6202855 | W6: 1.0273244 | X6: 1.0273244 | Y6: 1.6426538 | Z6: 0.98396417 | AA6: 0.98396417 | AB6: 1.6156648 | AC6: 0.99777769 | AD6: 0.99777769 | AE6: 1.6238103 | AF6: 0.99506171 | AG6: 0.99506171 | AH6: 1.619569 | AI6: 1.022515 | AJ6: 1.022515 | AK6: 1.6504464 | AL6: 0.99820977 | AM6: 0.99820977 | AN6: 1.6408482 | AO6: 1.0013182 | AP6: 1.0013182 | AQ6: 1.6198093 | AR6: 1.0007835 | AS6: 1.0007835 | AT6: 1.616571 | AU6: 1.0027428 | AV6: 1.0027428 | AW6: 1.6225195 | AX6: 1.0068716 | AY6: 1.0068716 | AZ6: 1.6161825 | BA6: 1.0020011 | BB6: 1.0020011 | BC6: 1.6218952 | BD6: 1.0071817 | BE6: 1.0071817 | BF6: 1.6338911 | BG6: 1.0328818 | BH6: 1.0328818 | BI6: 1.6270494 | BJ6: 0.99855977 | BK6: 0.99855977 | BL6: 1.6204713 | BM6: 1.0025723 | BN6: 1.0025723 | BO6: 1.6254349 | BP6: 1.0028021 | BQ6: 1.0028021 | BR6: 1.6340919 | BS6: 1.0009469 | BT6: 1.0009469 | BU6: 1.6335338 | BV6: 1.0251655 | BW6: 1.0251655 | BX6: 1.6307032
A7: BeH2 | B7: 0.94719506 | C7: 0.94719506 | D7: 1.893168 | E7: 0.92643523 | F7: 0.92643523 | G7: 1.8818534 | H7: 0.9115222 | I7: 0.9115222 | J7: 1.8912197 | K7: 0.91563193 | L7: 0.91563193 | M7: 1.8910035 | N7: 0.91034555 | O7: 0.91034555 | P7: 1.8836271 | Q7: 0.91305704 | R7: 0.91305704 | S7: 1.8848141 | T7: 0.91599725 | U7: 0.91599725 | V7: 1.8846629 | W7: 0.91207259 | X7: 0.91207259 | Y7: 1.9129686 | Z7: 0.89443749 | AA7: 0.89443749 | AB7: 1.8851264 | AC7: 0.90459006 | AD7: 0.90459006 | AE7: 1.8937668 | AF7: 0.9036581 | AG7: 0.9036581 | AH7: 1.8834067 | AI7: 0.91865159 | AJ7: 0.91865159 | AK7: 1.917911 | AL7: 0.8996383 | AM7: 0.8996383 | AN7: 1.9102882 | AO7: 0.90742116 | AP7: 0.90742116 | AQ7: 1.8884462 | AR7: 0.90386376 | AS7: 0.90386376 | AT7: 1.8837521 | AU7: 0.90999158 | AV7: 0.90999158 | AW7: 1.8901252 | AX7: 0.90832198 | AY7: 0.90832198 | AZ7: 1.8836567 | BA7: 0.90894248 | BB7: 0.90894248 | BC7: 1.8850738 | BD7: 0.91118908 | BE7: 0.91118908 | BF7: 1.8973294 | BG7: 0.91536123 | BH7: 0.91536123 | BI7: 1.9019803 | BJ7: 0.90497353 | BK7: 0.90497353 | BL7: 1.8886759 | BM7: 0.91240539 | BN7: 0.91240539 | BO7: 1.8910887 | BP7: 0.90920827 | BQ7: 0.90920827 | BR7: 1.8904333 | BS7: 0.90971239 | BT7: 0.90971239 | BU7: 1.8905906 | BV7: 0.91713287 | BW7: 0.91713287 | BX7: 1.8952024
A8: BF | B8: 0.77247994 | C8: 0.77247994 | D8: 1.4444191 | E8: 0.75966232 | F8: 0.75966232 | G8: 1.4375948 | H8: 0.7532669 | I8: 0.7532669 | J8: 1.4383296 | K8: 0.7582629 | L8: 0.7582629 | M8: 1.4395646 | N8: 0.75319992 | O8: 0.75319992 | P8: 1.4369398 | Q8: 0.75492184 | R8: 0.75492184 | S8: 1.4374046 | T8: 0.75668546 | U8: 0.75668546 | V8: 1.4378281 | W8: 0.75197917 | X8: 0.75197917 | Y8: 1.4408906 | Z8: 0.74378129 | AA8: 0.74378129 | AB8: 1.4366986 | AC8: 0.74865263 | AD8: 0.74865263 | AE8: 1.4375306 | AF8: 0.74953525 | AG8: 0.74953525 | AH8: 1.4386869 | AI8: 0.75746057 | AJ8: 0.75746057 | AK8: 1.4462153 | AL8: 0.74475882 | AM8: 0.74475882 | AN8: 1.4446815 | AO8: 0.75085899 | AP8: 0.75085899 | AQ8: 1.438264 | AR8: 0.75154119 | AS8: 0.75154119 | AT8: 1.4385424 | AU8: 0.75297427 | AV8: 0.75297427 | AW8: 1.4395486 | AX8: 0.74975485 | AY8: 0.74975485 | AZ8: 1.4367377 | BA8: 0.75058665 | BB8: 0.75058665 | BC8: 1.4383892 | BD8: 0.74963089 | BE8: 0.74963089 | BF8: 1.4405094 | BG8: 0.75258274 | BH8: 0.75258274 | BI8: 1.4380334 | BJ8: 0.74780803 | BK8: 0.74780803 | BL8: 1.4387325 | BM8: 0.75320697 | BN8: 0.75320697 | BO8: 1.4407064 | BP8: 0.74939707 | BQ8: 0.74939707 | BR8: 1.4396531 | BS8: 0.75174255 | BT8: 0.75174255 | BU8: 1.4410043 | BV8: 0.75547034 | BW8: 0.75547034 | BX8: 1.4391603
A9: BH2 | B9: 0.87257331 | C9: 1.1208751 | D9: 1.4474003 | E9: 0.85805283 | F9: 1.1003279 | G9: 1.4354672 | H9: 0.84424532 | I9: 1.089979 | J9: 1.4352489 | K9: 0.85069341 | L9: 1.0958837 | M9: 1.4402022 | N9: 0.84489297 | O9: 1.0901286 | P9: 1.4332902 | Q9: 0.84737209 | R9: 1.0920414 | S9: 1.4347826 | T9: 0.84991897 | U9: 1.0947161 | V9: 1.4354598 | W9: 0.8471151 | X9: 1.0975841 | Y9: 1.4443114 | Z9: 0.82663759 | AA9: 1.0769512 | AB9: 1.4315626 | AC9: 0.83771591 | AD9: 1.085949 | AE9: 1.4353007 | AF9: 0.83755741 | AG9: 1.0869707 | AH9: 1.4309689 | AI9: 0.85203451 | AJ9: 1.1048814 | AK9: 1.4521696 | AL9: 0.83117993 | AM9: 1.0856539 | AN9: 1.4427552 | AO9: 0.83992542 | AP9: 1.0862001 | AQ9: 1.4333384 | AR9: 0.84039948 | AS9: 1.0880124 | AT9: 1.4333495 | AU9: 0.84568457 | AV9: 1.0911962 | AW9: 1.4370349 | AX9: 0.84789837 | AY9: 1.0902305 | AZ9: 1.435075 | BA9: 0.84379859 | BB9: 1.0895058 | BC9: 1.4325823 | BD9: 0.84991897 | BE9: 1.0913214 | BF9: 1.438505 | BG9: 0.85402045 | BH9: 1.0955661 | BI9: 1.4422435 | BJ9: 0.83870426 | BK9: 1.0845393 | BL9: 1.4324118 | BM9: 0.84754129 | BN9: 1.0917128 | BO9: 1.4370534 | BP9: 0.84245068 | BQ9: 1.0897051 | BR9: 1.4331012 | BS9: 0.84633112 | BT9: 1.0935931 | BU9: 1.4353969 | BV9: 0.85655376 | BW9: 1.0997194 | BX9: 1.4410869
A10: BH2F | B10: 0.73159988 | C10: 1.056076 | D10: 1.6248068 | E10: 0.72188754 | F10: 1.0469018 | G10: 1.6196385 | H10: 0.7133174 | I10: 1.0464445 | J10: 1.6194735 | K10: 0.71858751 | L10: 1.050044 | M10: 1.6217286 | N10: 0.71476211 | O10: 1.0453605 | P10: 1.6187842 | Q10: 0.71618443 | R10: 1.0463024 | S10: 1.6193772 | T10: 0.71788232 | U10: 1.0471903 | V10: 1.6198321 | W10: 0.71211451 | X10: 1.0503825 | Y10: 1.6212465 | Z10: 0.70502212 | AA10: 1.0435542 | AB10: 1.6175295 | AC10: 0.70968951 | AD10: 1.0455294 | AE10: 1.6184859 | AF10: 0.71143882 | AG10: 1.0438592 | AH10: 1.6174539 | AI10: 0.7151813 | AJ10: 1.05509 | AK10: 1.6235938 | AL10: 0.70754194 | AM10: 1.0511873 | AN10: 1.6214473 | AO10: 0.71165759 | AP10: 1.0443621 | AQ10: 1.6181887 | AR10: 0.71300465 | AS10: 1.045296 | AT10: 1.6185764 | AU10: 0.7142711 | AV10: 1.0464157 | AW10: 1.6200569 | AX10: 0.71196768 | AY10: 1.0436099 | AZ10: 1.6186659 | BA10: 0.71259069 | BB10: 1.0433917 | BC10: 1.6182027 | BD10: 0.71398155 | BE10: 1.0461847 | BF10: 1.6207075 | BG10: 0.71364955 | BH10: 1.0468996 | BI10: 1.6197556 | BJ10: 0.70932275 | BK10: 1.0423535 | BL10: 1.617581 | BM10: 0.71578205 | BN10: 1.0465156 | BO10: 1.6202595 | BP10: 0.71090958 | BQ10: 1.0430175 | BR10: 1.6180471 | BS10: 0.73847794 | BT10: 1.065409 | BU10: 1.6308994 | BV10: 0.739198 | BW10: 1.066497 | BX10: 1.631131
A11: BH3 | B11: 1.3609008 | C11: 1.3608807 | D11: 0.84338232 | E11: 1.3490351 | F11: 1.3490148 | G11: 0.82963951 | H11: 1.3488594 | I11: 1.3488391 | J11: 0.81659324 | K11: 1.3520319 | L11: 1.3520116 | M11: 0.82146674 | N11: 1.3458555 | O11: 1.3458352 | P11: 0.81682082 | Q11: 1.3472497 | R11: 1.3472293 | S11: 0.81900808 | T11: 1.3482357 | U11: 1.3482189 | V11: 0.82131965 | W11: 1.3538556 | X11: 1.3538354 | Y11: 0.81576772 | Z11: 1.3433258 | AA11: 1.3433054 | AB11: 0.8037804 | AC11: 1.3479221 | AD11: 1.3478914 | AE11: 0.81189082 | AF11: 1.3443735 | AG11: 1.3443359 | AH11: 0.81150727 | AI11: 1.3615733 | AJ11: 1.3615532 | AK11: 0.82106502 | AL11: 1.3541954 | AM11: 1.3541752 | AN11: 0.80793781 | AO11: 1.3461559 | AP11: 1.3461562 | AQ11: 0.81421689 | AR11: 1.3462283 | AS11: 1.3462115 | AT11: 0.81278317 | AU11: 1.3492762 | AV11: 1.3492559 | AW11: 0.81815092 | AX11: 1.3471013 | AY11: 1.347081 | AZ11: 0.81863922 | BA11: 1.3456483 | BB11: 1.3456314 | BC11: 0.81707109 | BD11: 1.3500061 | BE11: 1.3499823 | BF11: 0.82137057 | BG11: 1.3514578 | BH11: 1.3514376 | BI11: 0.82013636 | BJ11: 1.3453824 | BK11: 1.3453793 | BL11: 0.81376591 | BM11: 1.3499751 | BN11: 1.3499548 | BO11: 0.8211782 | BP11: 1.3458797 | BQ11: 1.3458628 | BR11: 0.81538599 | BS11: 1.368589 | BT11: 1.368569 | BU11: 0.845199 | BV11: 1.3523034 | BW11: 1.3522831 | BX11: 0.82443112
A12: BO | B12: 0.78698471 | C12: 0.78698471 | D12: 1.3564866 | E12: 0.77789565 | F12: 0.77789565 | G12: 1.3490207 | H12: 0.77286166 | I12: 0.77286166 | J12: 1.3478662 | K12: 0.77766403 | L12: 0.77766403 | M12: 1.3495621 | N12: 0.77295415 | O12: 0.77295415 | P12: 1.3466995 | Q12: 0.77433652 | R12: 0.77433652 | S12: 1.3474993 | T12: 0.7758528 | U12: 0.7758528 | V12: 1.3484466 | W12: 0.77424788 | X12: 0.77424788 | Y12: 1.3459615 | Z12: 0.76392275 | AA12: 0.76392275 | AB12: 1.3436147 | AC12: 0.76836055 | AD12: 0.76836055 | AE12: 1.3433437 | AF12: 0.77021167 | AG12: 0.77021167 | AH12: 1.3455 | AI12: 0.77783684 | AJ12: 0.77783684 | AK12: 1.3475969 | AL12: 0.76673248 | AM12: 0.76673248 | AN12: 1.3447858 | AO12: 0.77079434 | AP12: 0.77079434 | AQ12: 1.343494 | AR12: 0.77275805 | AS12: 0.77275805 | AT12: 1.3470988 | AU12: 0.77371587 | AV12: 0.77371587 | AW12: 1.3459127 | AX12: 0.77259522 | AY12: 0.77259522 | AZ12: 1.3422314 | BA12: 0.77141363 | BB12: 0.77141363 | BC12: 1.3442355 | BD12: 0.77440668 | BE12: 0.77440668 | BF12: 1.3440784 | BG12: 0.77451376 | BH12: 0.77451376 | BI12: 1.3423694 | BJ12: 0.76901899 | BK12: 0.76901899 | BL12: 1.3411026 | BM12: 0.77432913 | BN12: 0.77432913 | BO12: 1.3456458 | BP12: 0.77053089 | BQ12: 0.77053089 | BR12: 1.3434275 | BS12: 0.7739967 | BT12: 0.7739967 | BU12: 1.3459736 | BV12: 0.77820438 | BW12: 0.77820438 | BX12: 1.3455695
A13: BS | B13: 0.83499403 | C13: 0.83499403 | D13: 1.5164507 | E13: 0.82525736 | F13: 0.82525736 | G13: 1.5101725 | H13: 0.82161999 | I13: 0.82161999 | J13: 1.5088705 | K13: 0.8260292 | L13: 0.8260292 | M13: 1.510934 | N13: 0.82091301 | O13: 0.82091301 | P13: 1.5073817 | Q13: 0.82229408 | R13: 0.82229408 | S13: 1.5082435 | T13: 0.82352237 | U13: 0.82352237 | V13: 1.509216 | W13: 0.82412187 | X13: 0.82412187 | Y13: 1.5070707 | Z13: 0.81487239 | AA13: 0.81487239 | AB13: 1.5041364 | AC13: 0.81797511 | AD13: 0.81797511 | AE13: 1.5036399 | AF13: 0.81964841 | AG13: 0.81964841 | AH13: 1.5055985 | AI13: 0.83141842 | AJ13: 0.83141842 | AK13: 1.5081547 | AL13: 0.81861976 | AM13: 0.81861976 | AN13: 1.5050028 | AO13: 0.82170186 | AP13: 0.82170186 | AQ13: 1.5045637 | AR13: 0.82138512 | AS13: 0.82138512 | AT13: 1.5077407 | AU13: 0.82521232 | AV13: 0.82521232 | AW13: 1.5070735 | AX13: 0.82543752 | AY13: 0.82543752 | AZ13: 1.5040098 | BA13: 0.82305579 | BB13: 0.82305579 | BC13: 1.5048568 | BD13: 0.82774397 | BE13: 0.82774397 | BF13: 1.5056627 | BG13: 0.82520803 | BH13: 0.82520803 | BI13: 1.5032026 | BJ13: 0.82291168 | BK13: 0.82291168 | BL13: 1.5022308 | BM13: 0.82613849 | BN13: 0.82613849 | BO13: 1.5054245 | BP13: 0.82301063 | BQ13: 0.82301063 | BR13: 1.5031525 | BS13: 0.82530455 | BT13: 0.82530455 | BU13: 1.5043921 | BV13: 0.8293997 | BW13: 0.8293997 | BX13: 1.5059323
A14: C2H | B14: 0.87268425 | C14: 0.87268425 | D14: 1.5542355 | E14: 0.8607774 | F14: 0.8607774 | G14: 1.5476206 | H14: 0.85644454 | I14: 0.85644454 | J14: 1.5465062 | K14: 0.86110954 | L14: 0.86110954 | M14: 1.5502138 | N14: 0.8555125 | O14: 0.8555125 | P14: 1.5458932 | Q14: 0.8570987 | R14: 0.8570987 | S14: 1.5468959 | T14: 0.85859539 | U14: 0.85859539 | V14: 1.5475259 | W14: 0.85928785 | X14: 0.85928785 | Y14: 1.5449144 | Z14: 0.84767864 | AA14: 0.84767864 | AB14: 1.5427839 | AC14: 0.85298185 | AD14: 0.85298185 | AE14: 1.5428353 | AF14: 0.85478353 | AG14: 0.85478353 | AH14: 1.5436219 | AI14: 0.86863468 | AJ14: 0.86863468 | AK14: 1.5474372 | AL14: 0.85254257 | AM14: 0.85254257 | AN14: 1.5424924 | AO14: 0.85613063 | AP14: 0.85613063 | AQ14: 1.542885 | AR14: 0.85648461 | AS14: 0.85648461 | AT14: 1.5455952 | AU14: 0.86024239 | AV14: 0.86024239 | AW14: 1.5464047 | AX14: 0.86057806 | AY14: 0.86057806 | AZ14: 1.5440491 | BA14: 0.85803569 | BB14: 0.85803569 | BC14: 1.5433064 | BD14: 0.8617668 | BE14: 0.8617668 | BF14: 1.5444026 | BG14: 0.85944091 | BH14: 0.85944091 | BI14: 1.5463041 | BJ14: 0.85723548 | BK14: 0.85723548 | BL14: 1.5411847 | BM14: 0.86152786 | BN14: 0.86152786 | BO14: 1.5455975 | BP14: 0.85749896 | BQ14: 0.85749896 | BR14: 1.5420896 | BS14: 0.86076744 | BT14: 0.86076744 | BU14: 1.5442492 | BV14: 0.86443384 | BW14: 0.86443384 | BX14: 1.5464392
A15: C2H2 | B15: 0.86817721 | C15: 0.86817721 | D15: 1.7087401 | E15: 0.85557672 | F15: 0.85557672 | G15: 1.7027797 | H15: 0.85132679 | I15: 0.85132679 | J15: 1.7037743 | K15: 0.85569464 | L15: 0.85569464 | M15: 1.7073643 | N15: 0.84986898 | O15: 0.84986898 | P15: 1.7026144 | Q15: 0.85158875 | R15: 0.85158875 | S15: 1.7035685 | T15: 0.85314634 | U15: 0.85314634 | V15: 1.7040392 | W15: 0.8531619 | X15: 0.8531619 | Y15: 1.7022728 | Z15: 0.8420976 | AA15: 0.8420976 | AB15: 1.7005998 | AC15: 0.8480925 | AD15: 0.8480925 | AE15: 1.7009058 | AF15: 0.84978774 | AG15: 0.84978774 | AH15: 1.7009136 | AI15: 0.86242971 | AJ15: 0.86242971 | AK15: 1.7052838 | AL15: 0.84664166 | AM15: 0.84664166 | AN15: 1.7011665 | AO15: 0.85101172 | AP15: 0.85101172 | AQ15: 1.6991628 | AR15: 0.85097428 | AS15: 0.85097428 | AT15: 1.7025317 | AU15: 0.85500238 | AV15: 0.85500238 | AW15: 1.7032256 | AX15: 0.85449291 | AY15: 0.85449291 | AZ15: 1.6998252 | BA15: 0.85285061 | BB15: 0.85285061 | BC15: 1.6995534 | BD15: 0.85548982 | BE15: 0.85548982 | BF15: 1.6999346 | BG15: 0.85336728 | BH15: 0.85336728 | BI15: 1.7033051 | BJ15: 0.85267002 | BK15: 0.85267002 | BL15: 1.6970362 | BM15: 0.85644836 | BN15: 0.85644836 | BO15: 1.7018984 | BP15: 0.85203139 | BQ15: 0.85203139 | BR15: 1.6981811 | BS15: 0.85509865 | BT15: 0.85509865 | BU15: 1.7001501 | BV15: 0.85864059 | BW15: 0.85864059 | BX15: 1.7020341
... A54: LiH | B54: 1.0802771 | C54: 1.0802771 | D54: 1.6767796 | E54: 1.0334611 | F54: 1.0334611 | G54: 1.6543187 | H54: 1.0171274 | I54: 1.0171274 | J54: 1.6535085 | K54: 1.0241297 | L54: 1.0241297 | M54: 1.6568466 | N54: 1.0126588 | O54: 1.0126588 | P54: 1.6472563 | Q54: 1.0175294 | R54: 1.0175294 | S54: 1.6511885 | T54: 1.0219495 | U54: 1.0219495 | V54: 1.652162 | W54: 1.0062049 | X54: 1.0062049 | Y54: 1.6569263 | Z54: 0.98539309 | AA54: 0.98539309 | AB54: 1.6459379 | AC54: 4.0790949 | AD54: 4.0790949 | AE54: 5.8895221 | AF54: 0.99799748 | AG54: 0.99799748 | AH54: 1.6427018 | AI54: 1.0197282 | AJ54: 1.0197282 | AK54: 1.6651913 | AL54: 0.97981287 | AM54: 0.97981287 | AN54: 1.647621 | AO54: 1.0049111 | AP54: 1.0049111 | AQ54: 1.6484281 | AR54: 0.99940262 | AS54: 0.99940262 | AT54: 1.6432762 | AU54: 1.0084376 | AV54: 1.0084376 | AW54: 1.6512195 | AX54: 1.0035784 | AY54: 1.0035784 | AZ54: 1.6503548 | BA54: 1.0040506 | BB54: 1.0040506 | BC54: 1.6468778 | BD54: 0.99486369 | BE54: 0.99486369 | BF54: 1.6543191 | BG54: 1.0158109 | BH54: 1.0158109 | BI54: 1.6600059 | BJ54: 0.99608666 | BK54: 0.99608666 | BL54: 1.6468836 | BM54: 1.0053918 | BN54: 1.0053918 | BO54: 1.651272 | BP54: 1.0061311 | BQ54: 1.0061311 | BR54: 1.6528726 | BS54: 0.99782053 | BT54: 0.99782053 | BU54: 1.6484836 | BV54: 1.0159024 | BW54: 1.0159024 | BX54: 1.6593702

Sheet combine_values
A1: method | B1: CCSD\(T\) | C1: CCSD\(T\) | D1: CCSD\(T\) | F1: HF | G1: HF | H1: HF | I1: MP2 | J1: MP2 | K1: MP2 | L1: CCSD | M1: CCSD | N1: CCSD | O1: Slater | P1: Slater | Q1: Slater | R1: SPW92 | S1: SPW92 | T1: SPW92 | U1: B97-D3 | V1: B97-D3 | W1: B97-D3 | X1: BLYP | Y1: BLYP | Z1: BLYP | AA1: BPBE | AB1: BPBE | AC1: BPBE | AD1: mPW91 | AE1: mPW91 | AF1: mPW91 | AG1: PBE | AH1: PBE | AI1: PBE | AJ1: B97M-V | AK1: B97M-V | AL1: B97M-V | AM1: M06-L | AN1: M06-L | AO1: M06-L | AP1: mBEEF | AQ1: mBEEF | AR1: mBEEF | AS1: MGGA_MS2 | AT1: MGGA_MS2 | AU1: MGGA_MS2 | AV1: MN15-L | AW1: MN15-L | AX1: MN15-L | AY1: revM06-L | AZ1: revM06-L | BA1: revM06-L | BB1: SCAN | BC1: SCAN | BD1: SCAN | BE1: TPSS | BF1: TPSS | BG1: TPSS | BH1: B3LYP | BI1: B3LYP | BJ1: B3LYP | BK1: M06-2X | BL1: M06-2X | BM1: M06-2X | BN1: PBE0 | BO1: PBE0 | BP1: PBE0 | BQ1: M08-HX | BR1: M08-HX | BS1: M08-HX | BT1: MN15 | BU1: MN15 | BV1: MN15 | BW1: SCAN0 | BX1: SCAN0 | BY1: SCAN0 | BZ1: CAM-B3LYP | CA1: CAM-B3LYP | CB1: CAM-B3LYP | CC1: wB97X-D | CD1: wB97X-D | CE1: wB97X-D | CF1: wB97X-V | CG1: wB97X-V | CH1: wB97X-V | CI1: wB97M-V | CJ1: wB97M-V | CK1: wB97M-V
A2: component | B2: XX | C2: YY | D2: ZZ | F2: XX | G2: YY | H2: ZZ | I2: XX | J2: YY | K2: ZZ | L2: XX | M2: YY | N2: ZZ | O2: XX | P2: YY | Q2: ZZ | R2: XX | S2: YY | T2: ZZ | U2: XX | V2: YY | W2: ZZ | X2: XX | Y2: YY | Z2: ZZ | AA2: XX | AB2: YY | AC2: ZZ | AD2: XX | AE2: YY | AF2: ZZ | AG2: XX | AH2: YY | AI2: ZZ | AJ2: XX | AK2: YY | AL2: ZZ | AM2: XX | AN2: YY | AO2: ZZ | AP2: XX | AQ2: YY | AR2: ZZ | AS2: XX | AT2: YY | AU2: ZZ | AV2: XX | AW2: YY | AX2: ZZ | AY2: XX | AZ2: YY | BA2: ZZ | BB2: XX | BC2: YY | BD2: ZZ | BE2: XX | BF2: YY | BG2: ZZ | BH2: XX | BI2: YY | BJ2: ZZ | BK2: XX | BL2: YY | BM2: ZZ | BN2: XX | BO2: YY | BP2: ZZ | BQ2: XX | BR2: YY | BS2: ZZ | BT2: XX | BU2: YY | BV2: ZZ | BW2: XX | BX2: YY | BY2: ZZ | BZ2: XX | CA2: YY | CB2: ZZ | CC2: XX | CD2: YY | CE2: ZZ | CF2: XX | CG2: YY | CH2: ZZ | CI2: XX | CJ2: YY | CK2: ZZ
A3: molecule
A4: AlF | B4: =OFFSET(wft_table!L$7,(ROW(wft_table!L1)-1)*4,0) -> 0.72880654 | C4: =OFFSET(wft_table!M$7,(ROW(wft_table!M1)-1)*4,0) -> 0.72880654 | D4: =OFFSET(wft_table!N$7,(ROW(wft_table!N1)-1)*4,0) -> 1.750396 | F4: =OFFSET(wft_table!C$7,(ROW(wft_table!C1)-1)*4,0) -> 0.72854306 | G4: =OFFSET(wft_table!D$7,(ROW(wft_table!D1)-1)*4,0) -> 0.72854306 | H4: =OFFSET(wft_table!E$7,(ROW(wft_table!E1)-1)*4,0) -> 1.7621938 | I4: =OFFSET(wft_table!F$7,(ROW(wft_table!F1)-1)*4,0) -> 0.73036575 | J4: =OFFSET(wft_table!G$7,(ROW(wft_table!G1)-1)*4,0) -> 0.73036575 | K4: =OFFSET(wft_table!H$7,(ROW(wft_table!H1)-1)*4,0) -> 1.7515945 | L4: =OFFSET(wft_table!I$7,(ROW(wft_table!I1)-1)*4,0) -> 0.72726282 | M4: =OFFSET(wft_table!J$7,(ROW(wft_table!J1)-1)*4,0) -> 0.72726282 | N4: =OFFSET(wft_table!K$7,(ROW(wft_table!K1)-1)*4,0) -> 1.751902 | O4: 0.74836109 | P4: 0.74836109 | Q4: 1.7521481 | R4: 0.73560133 | S4: 0.73560133 | T4: 1.7471144 | U4: 0.73412284 | V4: 0.73412284 | W4: 1.7504678 | X4: 0.73648058 | Y4: 0.73648058 | Z4: 1.7501495 | AA4: 0.73291115 | AB4: 0.73291115 | AC4: 1.7488949 | AD4: 0.7342195 | AE4: 0.7342195 | AF4: 1.7491885 | AG4: 0.735831 | AH4: 0.735831 | AI4: 1.7495727 | AJ4: 0.73350342 | AK4: 0.73350342 | AL4: 1.7538892 | AM4: 0.72483431 | AN4: 0.72483431 | AO4: 1.7488584 | AP4: 0.73059971 | AQ4: 0.73059971 | AR4: 1.751904 | AS4: 0.73202531 | AT4: 0.73202531 | AU4: 1.751487 | AV4: 0.74585289 | AW4: 0.74585289 | AX4: 1.7597504 | AY4: 0.72853378 | AZ4: 0.72853378 | BA4: 1.7583675 | BB4: 0.73217302 | BC4: 0.73217302 | BD4: 1.7510181 | BE4: 0.73362781 | BF4: 0.73362781 | BG4: 1.7512682 | BH4: 0.73206455 | BI4: 0.73206455 | BJ4: 1.7512251 | BK4: 0.72809761 | BL4: 0.72809761 | BM4: 1.7501184 | BN4: 0.73092111 | BO4: 0.73092111 | BP4: 1.7515189 | BQ4: 0.73084482 | BR4: 0.73084482 | BS4: 1.7543406 | BT4: 0.73740003 | BU4: 0.73740003 | BV4: 1.7509029 | BW4: 0.72929876 | BX4: 0.72929876 | BY4: 1.7523173 | BZ4: 0.73135329 | CA4: 0.73135329 | CB4: 1.7523969 | CC4: 0.729456 | CD4: 0.729456 | CE4: 1.752647 | CF4: 0.7315866 | CG4: 0.7315866 | CH4: 1.7543901 | CI4: 0.73365545 | CJ4: 0.73365545 | CK4: 1.7507439
A5: Ar | B5: =OFFSET(wft_table!L$7,(ROW(wft_table!L2)-1)*4,0) -> 0.69285369 | C5: =OFFSET(wft_table!M$7,(ROW(wft_table!M2)-1)*4,0) -> 0.69285369 | D5: =OFFSET(wft_table!N$7,(ROW(wft_table!N2)-1)*4,0) -> 0.69285369 | F5: =OFFSET(wft_table!C$7,(ROW(wft_table!C2)-1)*4,0) -> 0.69439921 | G5: =OFFSET(wft_table!D$7,(ROW(wft_table!D2)-1)*4,0) -> 0.69439921 | H5: =OFFSET(wft_table!E$7,(ROW(wft_table!E2)-1)*4,0) -> 0.69439921 | I5: =OFFSET(wft_table!F$7,(ROW(wft_table!F2)-1)*4,0) -> 0.69340193 | J5: =OFFSET(wft_table!G$7,(ROW(wft_table!G2)-1)*4,0) -> 0.69340193 | K5: =OFFSET(wft_table!H$7,(ROW(wft_table!H2)-1)*4,0) -> 0.69340193 | L5: =OFFSET(wft_table!I$7,(ROW(wft_table!I2)-1)*4,0) -> 0.69246999 | M5: =OFFSET(wft_table!J$7,(ROW(wft_table!J2)-1)*4,0) -> 0.69246999 | N5: =OFFSET(wft_table!K$7,(ROW(wft_table!K2)-1)*4,0) -> 0.69246999 | O5: 0.70452653 | P5: 0.70452653 | Q5: 0.70452653 | R5: 0.69790575 | S5: 0.69790575 | T5: 0.69790575 | U5: 0.69342004 | V5: 0.69342004 | W5: 0.69342004 | X5: 0.6990825 | Y5: 0.6990825 | Z5: 0.6990825 | AA5: 0.69502052 | AB5: 0.69502052 | AC5: 0.69502052 | AD5: 0.69601821 | AE5: 0.69601821 | AF5: 0.69601821 | AG5: 0.69692854 | AH5: 0.69692854 | AI5: 0.69692854 | AJ5: 0.69387855 | AK5: 0.69387855 | AL5: 0.69387855 | AM5: 0.69055795 | AN5: 0.69055795 | AO5: 0.69055795 | AP5: 0.69100341 | AQ5: 0.69100341 | AR5: 0.69100341 | AS5: 0.6930268 | AT5: 0.6930268 | AU5: 0.6930268 | AV5: 0.69633563 | AW5: 0.69633563 | AX5: 0.69633563 | AY5: 0.69181586 | AZ5: 0.69181586 | BA5: 0.69181586 | BB5: 0.69374758 | BC5: 0.69374758 | BD5: 0.69374758 | BE5: 0.69509778 | BF5: 0.69509778 | BG5: 0.69509778 | BH5: 0.69678036 | BI5: 0.69678036 | BJ5: 0.69678036 | BK5: 0.69494029 | BL5: 0.69494029 | BM5: 0.69494029 | BN5: 0.69450627 | BO5: 0.69450627 | BP5: 0.69450627 | BQ5: 0.695668 | BR5: 0.695668 | BS5: 0.695668 | BT5: 0.69166957 | BU5: 0.69166957 | BV5: 0.69166957 | BW5: 0.69312513 | BX5: 0.69312513 | BY5: 0.69312513 | BZ5: 0.69720704 | CA5: 0.69720704 | CB5: 0.69720704 | CC5: 0.69332175 | CD5: 0.69332175 | CE5: 0.69332175 | CF5: 0.69548688 | CG5: 0.69548688 | CH5: 0.69548688 | CI5: 0.69756536 | CJ5: 0.69756536 | CK5: 0.69756536
A6: BeH | B6: =OFFSET(wft_table!L$7,(ROW(wft_table!L3)-1)*4,0) -> 0.99368082 | C6: =OFFSET(wft_table!M$7,(ROW(wft_table!M3)-1)*4,0) -> 0.99368082 | D6: =OFFSET(wft_table!N$7,(ROW(wft_table!N3)-1)*4,0) -> 1.6258257 | F6: =OFFSET(wft_table!C$7,(ROW(wft_table!C3)-1)*4,0) -> 0.98914899 | G6: =OFFSET(wft_table!D$7,(ROW(wft_table!D3)-1)*4,0) -> 0.98914899 | H6: =OFFSET(wft_table!E$7,(ROW(wft_table!E3)-1)*4,0) -> 1.6465447 | I6: =OFFSET(wft_table!F$7,(ROW(wft_table!F3)-1)*4,0) -> 0.98985366 | J6: =OFFSET(wft_table!G$7,(ROW(wft_table!G3)-1)*4,0) -> 0.98985366 | K6: =OFFSET(wft_table!H$7,(ROW(wft_table!H3)-1)*4,0) -> 1.6335688 | L6: =OFFSET(wft_table!I$7,(ROW(wft_table!I3)-1)*4,0) -> 0.99278453 | M6: =OFFSET(wft_table!J$7,(ROW(wft_table!J3)-1)*4,0) -> 0.99278453 | N6: =OFFSET(wft_table!K$7,(ROW(wft_table!K3)-1)*4,0) -> 1.6270783 | O6: 1.0396475 | P6: 1.0396475 | Q6: 1.6487272 | R6: 1.021016 | S6: 1.021016 | T6: 1.6229892 | U6: 1.0119905 | V6: 1.0119905 | W6: 1.6222705 | X6: 1.0097988 | Y6: 1.0097988 | Z6: 1.6220269 | AA6: 1.003358 | AB6: 1.003358 | AC6: 1.6180907 | AD6: 1.0067682 | AE6: 1.0067682 | AF6: 1.6192359 | AG6: 1.0102993 | AH6: 1.0102993 | AI6: 1.6202855 | AJ6: 1.0273244 | AK6: 1.0273244 | AL6: 1.6426538 | AM6: 0.98396417 | AN6: 0.98396417 | AO6: 1.6156648 | AP6: 0.99777769 | AQ6: 0.99777769 | AR6: 1.6238103 | AS6: 0.99506171 | AT6: 0.99506171 | AU6: 1.619569 | AV6: 1.022515 | AW6: 1.022515 | AX6: 1.6504464 | AY6: 0.99820977 | AZ6: 0.99820977 | BA6: 1.6408482 | BB6: 1.0013182 | BC6: 1.0013182 | BD6: 1.6198093 | BE6: 1.0007835 | BF6: 1.0007835 | BG6: 1.616571 | BH6: 1.0027428 | BI6: 1.0027428 | BJ6: 1.6225195 | BK6: 1.0068716 | BL6: 1.0068716 | BM6: 1.6161825 | BN6: 1.0020011 | BO6: 1.0020011 | BP6: 1.6218952 | BQ6: 1.0071817 | BR6: 1.0071817 | BS6: 1.6338911 | BT6: 1.0328818 | BU6: 1.0328818 | BV6: 1.6270494 | BW6: 0.99855977 | BX6: 0.99855977 | BY6: 1.6204713 | BZ6: 1.0025723 | CA6: 1.0025723 | CB6: 1.6254349 | CC6: 1.0028021 | CD6: 1.0028021 | CE6: 1.6340919 | CF6: 1.0009469 | CG6: 1.0009469 | CH6: 1.6335338 | CI6: 1.0251655 | CJ6: 1.0251655 | CK6: 1.6307032
A7: BeH2 | B7: =OFFSET(wft_table!L$7,(ROW(wft_table!L4)-1)*4,0) -> 0.90145481 | C7: =OFFSET(wft_table!M$7,(ROW(wft_table!M4)-1)*4,0) -> 0.90145481 | D7: =OFFSET(wft_table!N$7,(ROW(wft_table!N4)-1)*4,0) -> 1.8867482 | F7: =OFFSET(wft_table!C$7,(ROW(wft_table!C4)-1)*4,0) -> 0.9016951 | G7: =OFFSET(wft_table!D$7,(ROW(wft_table!D4)-1)*4,0) -> 0.9016951 | H7: =OFFSET(wft_table!E$7,(ROW(wft_table!E4)-1)*4,0) -> 1.9001487 | I7: =OFFSET(wft_table!F$7,(ROW(wft_table!F4)-1)*4,0) -> 0.89990146 | J7: =OFFSET(wft_table!G$7,(ROW(wft_table!G4)-1)*4,0) -> 0.89990146 | K7: =OFFSET(wft_table!H$7,(ROW(wft_table!H4)-1)*4,0) -> 1.8900465 | L7: =OFFSET(wft_table!I$7,(ROW(wft_table!I4)-1)*4,0) -> 0.90086783 | M7: =OFFSET(wft_table!J$7,(ROW(wft_table!J4)-1)*4,0) -> 0.90086783 | N7: =OFFSET(wft_table!K$7,(ROW(wft_table!K4)-1)*4,0) -> 1.8875948 | O7: 0.94719506 | P7: 0.94719506 | Q7: 1.893168 | R7: 0.92643523 | S7: 0.92643523 | T7: 1.8818534 | U7: 0.9115222 | V7: 0.9115222 | W7: 1.8912197 | X7: 0.91563193 | Y7: 0.91563193 | Z7: 1.8910035 | AA7: 0.91034555 | AB7: 0.91034555 | AC7: 1.8836271 | AD7: 0.91305704 | AE7: 0.91305704 | AF7: 1.8848141 | AG7: 0.91599725 | AH7: 0.91599725 | AI7: 1.8846629 | AJ7: 0.91207259 | AK7: 0.91207259 | AL7: 1.9129686 | AM7: 0.89443749 | AN7: 0.89443749 | AO7: 1.8851264 | AP7: 0.90459006 | AQ7: 0.90459006 | AR7: 1.8937668 | AS7: 0.9036581 | AT7: 0.9036581 | AU7: 1.8834067 | AV7: 0.91865159 | AW7: 0.91865159 | AX7: 1.917911 | AY7: 0.8996383 | AZ7: 0.8996383 | BA7: 1.9102882 | BB7: 0.90742116 | BC7: 0.90742116 | BD7: 1.8884462 | BE7: 0.90386376 | BF7: 0.90386376 | BG7: 1.8837521 | BH7: 0.90999158 | BI7: 0.90999158 | BJ7: 1.8901252 | BK7: 0.90832198 | BL7: 0.90832198 | BM7: 1.8836567 | BN7: 0.90894248 | BO7: 0.90894248 | BP7: 1.8850738 | BQ7: 0.91118908 | BR7: 0.91118908 | BS7: 1.8973294 | BT7: 0.91536123 | BU7: 0.91536123 | BV7: 1.9019803 | BW7: 0.90497353 | BX7: 0.90497353 | BY7: 1.8886759 | BZ7: 0.91240539 | CA7: 0.91240539 | CB7: 1.8910887 | CC7: 0.90920827 | CD7: 0.90920827 | CE7: 1.8904333 | CF7: 0.90971239 | CG7: 0.90971239 | CH7: 1.8905906 | CI7: 0.91713287 | CJ7: 0.91713287 | CK7: 1.8952024
A8: BF | B8: =OFFSET(wft_table!L$7,(ROW(wft_table!L5)-1)*4,0) -> 0.74685888 | C8: =OFFSET(wft_table!M$7,(ROW(wft_table!M5)-1)*4,0) -> 0.74685888 | D8: =OFFSET(wft_table!N$7,(ROW(wft_table!N5)-1)*4,0) -> 1.433292 | F8: =OFFSET(wft_table!C$7,(ROW(wft_table!C5)-1)*4,0) -> 0.74345993 | G8: =OFFSET(wft_table!D$7,(ROW(wft_table!D5)-1)*4,0) -> 0.74345993 | H8: =OFFSET(wft_table!E$7,(ROW(wft_table!E5)-1)*4,0) -> 1.4472363 | I8: =OFFSET(wft_table!F$7,(ROW(wft_table!F5)-1)*4,0) -> 0.7499455 | J8: =OFFSET(wft_table!G$7,(ROW(wft_table!G5)-1)*4,0) -> 0.7499455 | K8: =OFFSET(wft_table!H$7,(ROW(wft_table!H5)-1)*4,0) -> 1.4386517 | L8: =OFFSET(wft_table!I$7,(ROW(wft_table!I5)-1)*4,0) -> 0.7450559 | M8: =OFFSET(wft_table!J$7,(ROW(wft_table!J5)-1)*4,0) -> 0.7450559 | N8: =OFFSET(wft_table!K$7,(ROW(wft_table!K5)-1)*4,0) -> 1.4346532 | O8: 0.77247994 | P8: 0.77247994 | Q8: 1.4444191 | R8: 0.75966232 | S8: 0.75966232 | T8: 1.4375948 | U8: 0.7532669 | V8: 0.7532669 | W8: 1.4383296 | X8: 0.7582629 | Y8: 0.7582629 | Z8: 1.4395646 | AA8: 0.75319992 | AB8: 0.75319992 | AC8: 1.4369398 | AD8: 0.75492184 | AE8: 0.75492184 | AF8: 1.4374046 | AG8: 0.75668546 | AH8: 0.75668546 | AI8: 1.4378281 | AJ8: 0.75197917 | AK8: 0.75197917 | AL8: 1.4408906 | AM8: 0.74378129 | AN8: 0.74378129 | AO8: 1.4366986 | AP8: 0.74865263 | AQ8: 0.74865263 | AR8: 1.4375306 | AS8: 0.74953525 | AT8: 0.74953525 | AU8: 1.4386869 | AV8: 0.75746057 | AW8: 0.75746057 | AX8: 1.4462153 | AY8: 0.74475882 | AZ8: 0.74475882 | BA8: 1.4446815 | BB8: 0.75085899 | BC8: 0.75085899 | BD8: 1.438264 | BE8: 0.75154119 | BF8: 0.75154119 | BG8: 1.4385424 | BH8: 0.75297427 | BI8: 0.75297427 | BJ8: 1.4395486 | BK8: 0.74975485 | BL8: 0.74975485 | BM8: 1.4367377 | BN8: 0.75058665 | BO8: 0.75058665 | BP8: 1.4383892 | BQ8: 0.74963089 | BR8: 0.74963089 | BS8: 1.4405094 | BT8: 0.75258274 | BU8: 0.75258274 | BV8: 1.4380334 | BW8: 0.74780803 | BX8: 0.74780803 | BY8: 1.4387325 | BZ8: 0.75320697 | CA8: 0.75320697 | CB8: 1.4407064 | CC8: 0.74939707 | CD8: 0.74939707 | CE8: 1.4396531 | CF8: 0.75174255 | CG8: 0.75174255 | CH8: 1.4410043 | CI8: 0.75547034 | CJ8: 0.75547034 | CK8: 1.4391603
A9: BH2 | B9: =OFFSET(wft_table!L$7,(ROW(wft_table!L6)-1)*4,0) -> 0.83980428 | C9: =OFFSET(wft_table!M$7,(ROW(wft_table!M6)-1)*4,0) -> 1.0858154 | D9: =OFFSET(wft_table!N$7,(ROW(wft_table!N6)-1)*4,0) -> 1.4313086 | F9: =OFFSET(wft_table!C$7,(ROW(wft_table!C6)-1)*4,0) -> 0.83593901 | G9: =OFFSET(wft_table!D$7,(ROW(wft_table!D6)-1)*4,0) -> 1.0905731 | H9: =OFFSET(wft_table!E$7,(ROW(wft_table!E6)-1)*4,0) -> 1.4378514 | I9: =OFFSET(wft_table!F$7,(ROW(wft_table!F6)-1)*4,0) -> 0.8383993 | J9: =OFFSET(wft_table!G$7,(ROW(wft_table!G6)-1)*4,0) -> 1.0872283 | K9: =OFFSET(wft_table!H$7,(ROW(wft_table!H6)-1)*4,0) -> 1.4323084 | L9: =OFFSET(wft_table!I$7,(ROW(wft_table!I6)-1)*4,0) -> 0.83882565 | M9: =OFFSET(wft_table!J$7,(ROW(wft_table!J6)-1)*4,0) -> 1.0855037 | N9: =OFFSET(wft_table!K$7,(ROW(wft_table!K6)-1)*4,0) -> 1.4313894 | O9: 0.87257331 | P9: 1.1208751 | Q9: 1.4474003 | R9: 0.85805283 | S9: 1.1003279 | T9: 1.4354672 | U9: 0.84424532 | V9: 1.089979 | W9: 1.4352489 | X9: 0.85069341 | Y9: 1.0958837 | Z9: 1.4402022 | AA9: 0.84489297 | AB9: 1.0901286 | AC9: 1.4332902 | AD9: 0.84737209 | AE9: 1.0920414 | AF9: 1.4347826 | AG9: 0.84991897 | AH9: 1.0947161 | AI9: 1.4354598 | AJ9: 0.8471151 | AK9: 1.0975841 | AL9: 1.4443114 | AM9: 0.82663759 | AN9: 1.0769512 | AO9: 1.4315626 | AP9: 0.83771591 | AQ9: 1.085949 | AR9: 1.4353007 | AS9: 0.83755741 | AT9: 1.0869707 | AU9: 1.4309689 | AV9: 0.85203451 | AW9: 1.1048814 | AX9: 1.4521696 | AY9: 0.83117993 | AZ9: 1.0856539 | BA9: 1.4427552 | BB9: 0.83992542 | BC9: 1.0862001 | BD9: 1.4333384 | BE9: 0.84039948 | BF9: 1.0880124 | BG9: 1.4333495 | BH9: 0.84568457 | BI9: 1.0911962 | BJ9: 1.4370349 | BK9: 0.84789837 | BL9: 1.0902305 | BM9: 1.435075 | BN9: 0.84379859 | BO9: 1.0895058 | BP9: 1.4325823 | BQ9: 0.84991897 | BR9: 1.0913214 | BS9: 1.438505 | BT9: 0.85402045 | BU9: 1.0955661 | BV9: 1.4422435 | BW9: 0.83870426 | BX9: 1.0845393 | BY9: 1.4324118 | BZ9: 0.84754129 | CA9: 1.0917128 | CB9: 1.4370534 | CC9: 0.84245068 | CD9: 1.0897051 | CE9: 1.4331012 | CF9: 0.84633112 | CG9: 1.0935931 | CH9: 1.4353969 | CI9: 0.85655376 | CJ9: 1.0997194 | CK9: 1.4410869
A10: BH2F | B10: =OFFSET(wft_table!L$7,(ROW(wft_table!L7)-1)*4,0) -> 0.71030281 | C10: =OFFSET(wft_table!M$7,(ROW(wft_table!M7)-1)*4,0) -> 1.0424695 | D10: =OFFSET(wft_table!N$7,(ROW(wft_table!N7)-1)*4,0) -> 1.6173207 | F10: =OFFSET(wft_table!C$7,(ROW(wft_table!C7)-1)*4,0) -> 0.70462986 | G10: =OFFSET(wft_table!D$7,(ROW(wft_table!D7)-1)*4,0) -> 1.0430242 | H10: =OFFSET(wft_table!E$7,(ROW(wft_table!E7)-1)*4,0) -> 1.6194996 | I10: =OFFSET(wft_table!F$7,(ROW(wft_table!F7)-1)*4,0) -> 0.71151499 | J10: =OFFSET(wft_table!G$7,(ROW(wft_table!G7)-1)*4,0) -> 1.0438336 | K10: =OFFSET(wft_table!H$7,(ROW(wft_table!H7)-1)*4,0) -> 1.6180727 | L10: =OFFSET(wft_table!I$7,(ROW(wft_table!I7)-1)*4,0) -> 0.70877714 | M10: =OFFSET(wft_table!J$7,(ROW(wft_table!J7)-1)*4,0) -> 1.041721 | N10: =OFFSET(wft_table!K$7,(ROW(wft_table!K7)-1)*4,0) -> 1.6172764 | O10: 0.73159988 | P10: 1.056076 | Q10: 1.6248068 | R10: 0.72188754 | S10: 1.0469018 | T10: 1.6196385 | U10: 0.7133174 | V10: 1.0464445 | W10: 1.6194735 | X10: 0.71858751 | Y10: 1.050044 | Z10: 1.6217286 | AA10: 0.71476211 | AB10: 1.0453605 | AC10: 1.6187842 | AD10: 0.71618443 | AE10: 1.0463024 | AF10: 1.6193772 | AG10: 0.71788232 | AH10: 1.0471903 | AI10: 1.6198321 | AJ10: 0.71211451 | AK10: 1.0503825 | AL10: 1.6212465 | AM10: 0.70502212 | AN10: 1.0435542 | AO10: 1.6175295 | AP10: 0.70968951 | AQ10: 1.0455294 | AR10: 1.6184859 | AS10: 0.71143882 | AT10: 1.0438592 | AU10: 1.6174539 | AV10: 0.7151813 | AW10: 1.05509 | AX10: 1.6235938 | AY10: 0.70754194 | AZ10: 1.0511873 | BA10: 1.6214473 | BB10: 0.71165759 | BC10: 1.0443621 | BD10: 1.6181887 | BE10: 0.71300465 | BF10: 1.045296 | BG10: 1.6185764 | BH10: 0.7142711 | BI10: 1.0464157 | BJ10: 1.6200569 | BK10: 0.71196768 | BL10: 1.0436099 | BM10: 1.6186659 | BN10: 0.71259069 | BO10: 1.0433917 | BP10: 1.6182027 | BQ10: 0.71398155 | BR10: 1.0461847 | BS10: 1.6207075 | BT10: 0.71364955 | BU10: 1.0468996 | BV10: 1.6197556 | BW10: 0.70932275 | BX10: 1.0423535 | BY10: 1.617581 | BZ10: 0.71578205 | CA10: 1.0465156 | CB10: 1.6202595 | CC10: 0.71090958 | CD10: 1.0430175 | CE10: 1.6180471 | CF10: 0.73847794 | CG10: 1.065409 | CH10: 1.6308994 | CI10: 0.739198 | CJ10: 1.066497 | CK10: 1.631131
A11: BH3 | B11: =OFFSET(wft_table!L$7,(ROW(wft_table!L8)-1)*4,0) -> 1.3443331 | C11: =OFFSET(wft_table!M$7,(ROW(wft_table!M8)-1)*4,0) -> 1.3443115 | D11: =OFFSET(wft_table!N$7,(ROW(wft_table!N8)-1)*4,0) -> 0.81380583 | F11: =OFFSET(wft_table!C$7,(ROW(wft_table!C8)-1)*4,0) -> 1.3505532 | G11: =OFFSET(wft_table!D$7,(ROW(wft_table!D8)-1)*4,0) -> 1.3505364 | H11: =OFFSET(wft_table!E$7,(ROW(wft_table!E8)-1)*4,0) -> 0.81298896 | I11: =OFFSET(wft_table!F$7,(ROW(wft_table!F8)-1)*4,0) -> 1.3453047 | J11: =OFFSET(wft_table!G$7,(ROW(wft_table!G8)-1)*4,0) -> 1.3452855 | K11: =OFFSET(wft_table!H$7,(ROW(wft_table!H8)-1)*4,0) -> 0.81353896 | L11: =OFFSET(wft_table!I$7,(ROW(wft_table!I8)-1)*4,0) -> 1.3443245 | M11: =OFFSET(wft_table!J$7,(ROW(wft_table!J8)-1)*4,0) -> 1.3442981 | N11: =OFFSET(wft_table!K$7,(ROW(wft_table!K8)-1)*4,0) -> 0.81302242 | O11: 1.3609008 | P11: 1.3608807 | Q11: 0.84338232 | R11: 1.3490351 | S11: 1.3490148 | T11: 0.82963951 | U11: 1.3488594 | V11: 1.3488391 | W11: 0.81659324 | X11: 1.3520319 | Y11: 1.3520116 | Z11: 0.82146674 | AA11: 1.3458555 | AB11: 1.3458352 | AC11: 0.81682082 | AD11: 1.3472497 | AE11: 1.3472293 | AF11: 0.81900808 | AG11: 1.3482357 | AH11: 1.3482189 | AI11: 0.82131965 | AJ11: 1.3538556 | AK11: 1.3538354 | AL11: 0.81576772 | AM11: 1.3433258 | AN11: 1.3433054 | AO11: 0.8037804 | AP11: 1.3479221 | AQ11: 1.3478914 | AR11: 0.81189082 | AS11: 1.3443735 | AT11: 1.3443359 | AU11: 0.81150727 | AV11: 1.3615733 | AW11: 1.3615532 | AX11: 0.82106502 | AY11: 1.3541954 | AZ11: 1.3541752 | BA11: 0.80793781 | BB11: 1.3461559 | BC11: 1.3461562 | BD11: 0.81421689 | BE11: 1.3462283 | BF11: 1.3462115 | BG11: 0.81278317 | BH11: 1.3492762 | BI11: 1.3492559 | BJ11: 0.81815092 | BK11: 1.3471013 | BL11: 1.347081 | BM11: 0.81863922 | BN11: 1.3456483 | BO11: 1.3456314 | BP11: 0.81707109 | BQ11: 1.3500061 | BR11: 1.3499823 | BS11: 0.82137057 | BT11: 1.3514578 | BU11: 1.3514376 | BV11: 0.82013636 | BW11: 1.3453824 | BX11: 1.3453793 | BY11: 0.81376591 | BZ11: 1.3499751 | CA11: 1.3499548 | CB11: 0.8211782 | CC11: 1.3458797 | CD11: 1.3458628 | CE11: 0.81538599 | CF11: 1.368589 | CG11: 1.368569 | CH11: 0.845199 | CI11: 1.3523034 | CJ11: 1.3522831 | CK11: 0.82443112
A12: BO | B12: =OFFSET(wft_table!L$7,(ROW(wft_table!L9)-1)*4,0) -> 0.77081205 | C12: =OFFSET(wft_table!M$7,(ROW(wft_table!M9)-1)*4,0) -> 0.77081205 | D12: =OFFSET(wft_table!N$7,(ROW(wft_table!N9)-1)*4,0) -> 1.3452128 | F12: =OFFSET(wft_table!C$7,(ROW(wft_table!C9)-1)*4,0) -> 0.76742958 | G12: =OFFSET(wft_table!D$7,(ROW(wft_table!D9)-1)*4,0) -> 0.76742958 | H12: =OFFSET(wft_table!E$7,(ROW(wft_table!E9)-1)*4,0) -> 1.341349 | I12: =OFFSET(wft_table!F$7,(ROW(wft_table!F9)-1)*4,0) -> 0.77130955 | J12: =OFFSET(wft_table!G$7,(ROW(wft_table!G9)-1)*4,0) -> 0.77130955 | K12: =OFFSET(wft_table!H$7,(ROW(wft_table!H9)-1)*4,0) -> 1.3457156 | L12: =OFFSET(wft_table!I$7,(ROW(wft_table!I9)-1)*4,0) -> 0.76969276 | M12: =OFFSET(wft_table!J$7,(ROW(wft_table!J9)-1)*4,0) -> 0.76969276 | N12: =OFFSET(wft_table!K$7,(ROW(wft_table!K9)-1)*4,0) -> 1.3435791 | O12: 0.78698471 | P12: 0.78698471 | Q12: 1.3564866 | R12: 0.77789565 | S12: 0.77789565 | T12: 1.3490207 | U12: 0.77286166 | V12: 0.77286166 | W12: 1.3478662 | X12: 0.77766403 | Y12: 0.77766403 | Z12: 1.3495621 | AA12: 0.77295415 | AB12: 0.77295415 | AC12: 1.3466995 | AD12: 0.77433652 | AE12: 0.77433652 | AF12: 1.3474993 | AG12: 0.7758528 | AH12: 0.7758528 | AI12: 1.3484466 | AJ12: 0.77424788 | AK12: 0.77424788 | AL12: 1.3459615 | AM12: 0.76392275 | AN12: 0.76392275 | AO12: 1.3436147 | AP12: 0.76836055 | AQ12: 0.76836055 | AR12: 1.3433437 | AS12: 0.77021167 | AT12: 0.77021167 | AU12: 1.3455 | AV12: 0.77783684 | AW12: 0.77783684 | AX12: 1.3475969 | AY12: 0.76673248 | AZ12: 0.76673248 | BA12: 1.3447858 | BB12: 0.77079434 | BC12: 0.77079434 | BD12: 1.343494 | BE12: 0.77275805 | BF12: 0.77275805 | BG12: 1.3470988 | BH12: 0.77371587 | BI12: 0.77371587 | BJ12: 1.3459127 | BK12: 0.77259522 | BL12: 0.77259522 | BM12: 1.3422314 | BN12: 0.77141363 | BO12: 0.77141363 | BP12: 1.3442355 | BQ12: 0.77440668 | BR12: 0.77440668 | BS12: 1.3440784 | BT12: 0.77451376 | BU12: 0.77451376 | BV12: 1.3423694 | BW12: 0.76901899 | BX12: 0.76901899 | BY12: 1.3411026 | BZ12: 0.77432913 | CA12: 0.77432913 | CB12: 1.3456458 | CC12: 0.77053089 | CD12: 0.77053089 | CE12: 1.3434275 | CF12: 0.7739967 | CG12: 0.7739967 | CH12: 1.3459736 | CI12: 0.77820438 | CJ12: 0.77820438 | CK12: 1.3455695
A13: BS | B13: =OFFSET(wft_table!L$7,(ROW(wft_table!L10)-1)*4,0) -> 0.8222529 | C13: =OFFSET(wft_table!M$7,(ROW(wft_table!M10)-1)*4,0) -> 0.8222529 | D13: =OFFSET(wft_table!N$7,(ROW(wft_table!N10)-1)*4,0) -> 1.5060146 | F13: =OFFSET(wft_table!C$7,(ROW(wft_table!C10)-1)*4,0) -> 0.82972192 | G13: =OFFSET(wft_table!D$7,(ROW(wft_table!D10)-1)*4,0) -> 0.82972192 | H13: =OFFSET(wft_table!E$7,(ROW(wft_table!E10)-1)*4,0) -> 1.501898 | I13: =OFFSET(wft_table!F$7,(ROW(wft_table!F10)-1)*4,0) -> 0.82535449 | J13: =OFFSET(wft_table!G$7,(ROW(wft_table!G10)-1)*4,0) -> 0.82535449 | K13: =OFFSET(wft_table!H$7,(ROW(wft_table!H10)-1)*4,0) -> 1.469877 | L13: =OFFSET(wft_table!I$7,(ROW(wft_table!I10)-1)*4,0) -> 0.82273115 | M13: =OFFSET(wft_table!J$7,(ROW(wft_table!J10)-1)*4,0) -> 0.82273115 | N13: =OFFSET(wft_table!K$7,(ROW(wft_table!K10)-1)*4,0) -> 1.5040148 | O13: 0.83499403 | P13: 0.83499403 | Q13: 1.5164507 | R13: 0.82525736 | S13: 0.82525736 | T13: 1.5101725 | U13: 0.82161999 | V13: 0.82161999 | W13: 1.5088705 | X13: 0.8260292 | Y13: 0.8260292 | Z13: 1.510934 | AA13: 0.82091301 | AB13: 0.82091301 | AC13: 1.5073817 | AD13: 0.82229408 | AE13: 0.82229408 | AF13: 1.5082435 | AG13: 0.82352237 | AH13: 0.82352237 | AI13: 1.509216 | AJ13: 0.82412187 | AK13: 0.82412187 | AL13: 1.5070707 | AM13: 0.81487239 | AN13: 0.81487239 | AO13: 1.5041364 | AP13: 0.81797511 | AQ13: 0.81797511 | AR13: 1.5036399 | AS13: 0.81964841 | AT13: 0.81964841 | AU13: 1.5055985 | AV13: 0.83141842 | AW13: 0.83141842 | AX13: 1.5081547 | AY13: 0.81861976 | AZ13: 0.81861976 | BA13: 1.5050028 | BB13: 0.82170186 | BC13: 0.82170186 | BD13: 1.5045637 | BE13: 0.82138512 | BF13: 0.82138512 | BG13: 1.5077407 | BH13: 0.82521232 | BI13: 0.82521232 | BJ13: 1.5070735 | BK13: 0.82543752 | BL13: 0.82543752 | BM13: 1.5040098 | BN13: 0.82305579 | BO13: 0.82305579 | BP13: 1.5048568 | BQ13: 0.82774397 | BR13: 0.82774397 | BS13: 1.5056627 | BT13: 0.82520803 | BU13: 0.82520803 | BV13: 1.5032026 | BW13: 0.82291168 | BX13: 0.82291168 | BY13: 1.5022308 | BZ13: 0.82613849 | CA13: 0.82613849 | CB13: 1.5054245 | CC13: 0.82301063 | CD13: 0.82301063 | CE13: 1.5031525 | CF13: 0.82530455 | CG13: 0.82530455 | CH13: 1.5043921 | CI13: 0.8293997 | CJ13: 0.8293997 | CK13: 1.5059323
A14: C2H | B14: =OFFSET(wft_table!L$7,(ROW(wft_table!L11)-1)*4,0) -> 0.85471404 | C14: =OFFSET(wft_table!M$7,(ROW(wft_table!M11)-1)*4,0) -> 0.85471404 | D14: =OFFSET(wft_table!N$7,(ROW(wft_table!N11)-1)*4,0) -> 1.557618 | F14: =OFFSET(wft_table!C$7,(ROW(wft_table!C11)-1)*4,0) -> 0.86049831 | G14: =OFFSET(wft_table!D$7,(ROW(wft_table!D11)-1)*4,0) -> 0.86049831 | H14: =OFFSET(wft_table!E$7,(ROW(wft_table!E11)-1)*4,0) -> 1.5450047 | I14: =OFFSET(wft_table!F$7,(ROW(wft_table!F11)-1)*4,0) -> 0.86967383 | J14: =OFFSET(wft_table!G$7,(ROW(wft_table!G11)-1)*4,0) -> 0.86967383 | K14: =OFFSET(wft_table!H$7,(ROW(wft_table!H11)-1)*4,0) -> 1.5467306 | L14: =OFFSET(wft_table!I$7,(ROW(wft_table!I11)-1)*4,0) -> 0.85457572 | M14: =OFFSET(wft_table!J$7,(ROW(wft_table!J11)-1)*4,0) -> 0.85457572 | N14: =OFFSET(wft_table!K$7,(ROW(wft_table!K11)-1)*4,0) -> 1.5565775 | O14: 0.87268425 | P14: 0.87268425 | Q14: 1.5542355 | R14: 0.8607774 | S14: 0.8607774 | T14: 1.5476206 | U14: 0.85644454 | V14: 0.85644454 | W14: 1.5465062 | X14: 0.86110954 | Y14: 0.86110954 | Z14: 1.5502138 | AA14: 0.8555125 | AB14: 0.8555125 | AC14: 1.5458932 | AD14: 0.8570987 | AE14: 0.8570987 | AF14: 1.5468959 | AG14: 0.85859539 | AH14: 0.85859539 | AI14: 1.5475259 | AJ14: 0.85928785 | AK14: 0.85928785 | AL14: 1.5449144 | AM14: 0.84767864 | AN14: 0.84767864 | AO14: 1.5427839 | AP14: 0.85298185 | AQ14: 0.85298185 | AR14: 1.5428353 | AS14: 0.85478353 | AT14: 0.85478353 | AU14: 1.5436219 | AV14: 0.86863468 | AW14: 0.86863468 | AX14: 1.5474372 | AY14: 0.85254257 | AZ14: 0.85254257 | BA14: 1.5424924 | BB14: 0.85613063 | BC14: 0.85613063 | BD14: 1.542885 | BE14: 0.85648461 | BF14: 0.85648461 | BG14: 1.5455952 | BH14: 0.86024239 | BI14: 0.86024239 | BJ14: 1.5464047 | BK14: 0.86057806 | BL14: 0.86057806 | BM14: 1.5440491 | BN14: 0.85803569 | BO14: 0.85803569 | BP14: 1.5433064 | BQ14: 0.8617668 | BR14: 0.8617668 | BS14: 1.5444026 | BT14: 0.85944091 | BU14: 0.85944091 | BV14: 1.5463041 | BW14: 0.85723548 | BX14: 0.85723548 | BY14: 1.5411847 | BZ14: 0.86152786 | CA14: 0.86152786 | CB14: 1.5455975 | CC14: 0.85749896 | CD14: 0.85749896 | CE14: 1.5420896 | CF14: 0.86076744 | CG14: 0.86076744 | CH14: 1.5442492 | CI14: 0.86443384 | CJ14: 0.86443384 | CK14: 1.5464392
A15: C2H2 | B15: =OFFSET(wft_table!L$7,(ROW(wft_table!L12)-1)*4,0) -> 0.84973194 | C15: =OFFSET(wft_table!M$7,(ROW(wft_table!M12)-1)*4,0) -> 0.84973194 | D15: =OFFSET(wft_table!N$7,(ROW(wft_table!N12)-1)*4,0) -> 1.7008991 | F15: =OFFSET(wft_table!C$7,(ROW(wft_table!C12)-1)*4,0) -> 0.86279294 | G15: =OFFSET(wft_table!D$7,(ROW(wft_table!D12)-1)*4,0) -> 0.86279294 | H15: =OFFSET(wft_table!E$7,(ROW(wft_table!E12)-1)*4,0) -> 1.6954771 | I15: =OFFSET(wft_table!F$7,(ROW(wft_table!F12)-1)*4,0) -> 0.85055742 | J15: =OFFSET(wft_table!G$7,(ROW(wft_table!G12)-1)*4,0) -> 0.85055742 | K15: =OFFSET(wft_table!H$7,(ROW(wft_table!H12)-1)*4,0) -> 1.7016466 | L15: =OFFSET(wft_table!I$7,(ROW(wft_table!I12)-1)*4,0) -> 0.84977093 | M15: =OFFSET(wft_table!J$7,(ROW(wft_table!J12)-1)*4,0) -> 0.84977093 | N15: =OFFSET(wft_table!K$7,(ROW(wft_table!K12)-1)*4,0) -> 1.6995015 | O15: 0.86817721 | P15: 0.86817721 | Q15: 1.7087401 | R15: 0.85557672 | S15: 0.85557672 | T15: 1.7027797 | U15: 0.85132679 | V15: 0.85132679 | W15: 1.7037743 | X15: 0.85569464 | Y15: 0.85569464 | Z15: 1.7073643 | AA15: 0.84986898 | AB15: 0.84986898 | AC15: 1.7026144 | AD15: 0.85158875 | AE15: 0.85158875 | AF15: 1.7035685 | AG15: 0.85314634 | AH15: 0.85314634 | AI15: 1.7040392 | AJ15: 0.8531619 | AK15: 0.8531619 | AL15: 1.7022728 | AM15: 0.8420976 | AN15: 0.8420976 | AO15: 1.7005998 | AP15: 0.8480925 | AQ15: 0.8480925 | AR15: 1.7009058 | AS15: 0.84978774 | AT15: 0.84978774 | AU15: 1.7009136 | AV15: 0.86242971 | AW15: 0.86242971 | AX15: 1.7052838 | AY15: 0.84664166 | AZ15: 0.84664166 | BA15: 1.7011665 | BB15: 0.85101172 | BC15: 0.85101172 | BD15: 1.6991628 | BE15: 0.85097428 | BF15: 0.85097428 | BG15: 1.7025317 | BH15: 0.85500238 | BI15: 0.85500238 | BJ15: 1.7032256 | BK15: 0.85449291 | BL15: 0.85449291 | BM15: 1.6998252 | BN15: 0.85285061 | BO15: 0.85285061 | BP15: 1.6995534 | BQ15: 0.85548982 | BR15: 0.85548982 | BS15: 1.6999346 | BT15: 0.85336728 | BU15: 0.85336728 | BV15: 1.7033051 | BW15: 0.85267002 | BX15: 0.85267002 | BY15: 1.6970362 | BZ15: 0.85644836 | CA15: 0.85644836 | CB15: 1.7018984 | CC15: 0.85203139 | CD15: 0.85203139 | CE15: 1.6981811 | CF15: 0.85509865 | CG15: 0.85509865 | CH15: 1.7001501 | CI15: 0.85864059 | CJ15: 0.85864059 | CK15: 1.7020341
... A54: LiH | B54: =OFFSET(wft_table!L$7,(ROW(wft_table!L51)-1)*4,0) -> 0.995281 | C54: =OFFSET(wft_table!M$7,(ROW(wft_table!M51)-1)*4,0) -> 0.995281 | D54: =OFFSET(wft_table!N$7,(ROW(wft_table!N51)-1)*4,0) -> 1.690688 | F54: =OFFSET(wft_table!C$7,(ROW(wft_table!C51)-1)*4,0) -> 0.987089 | G54: =OFFSET(wft_table!D$7,(ROW(wft_table!D51)-1)*4,0) -> 0.987089 | H54: =OFFSET(wft_table!E$7,(ROW(wft_table!E51)-1)*4,0) -> 1.651807 | I54: =OFFSET(wft_table!F$7,(ROW(wft_table!F51)-1)*4,0) -> 0.987065 | J54: =OFFSET(wft_table!G$7,(ROW(wft_table!G51)-1)*4,0) -> 0.987065 | K54: =OFFSET(wft_table!H$7,(ROW(wft_table!H51)-1)*4,0) -> 1.676782 | L54: =OFFSET(wft_table!I$7,(ROW(wft_table!I51)-1)*4,0) -> 0.995175 | M54: =OFFSET(wft_table!J$7,(ROW(wft_table!J51)-1)*4,0) -> 0.995175 | N54: =OFFSET(wft_table!K$7,(ROW(wft_table!K51)-1)*4,0) -> 1.689657 | O54: 1.0802771 | P54: 1.0802771 | Q54: 1.6767796 | R54: 1.0334611 | S54: 1.0334611 | T54: 1.6543187 | U54: 1.0171274 | V54: 1.0171274 | W54: 1.6535085 | X54: 1.0241297 | Y54: 1.0241297 | Z54: 1.6568466 | AA54: 1.0126588 | AB54: 1.0126588 | AC54: 1.6472563 | AD54: 1.0175294 | AE54: 1.0175294 | AF54: 1.6511885 | AG54: 1.0219495 | AH54: 1.0219495 | AI54: 1.652162 | AJ54: 1.0062049 | AK54: 1.0062049 | AL54: 1.6569263 | AM54: 0.98539309 | AN54: 0.98539309 | AO54: 1.6459379 | AP54: 1.000945 | AQ54: 1.000945 | AR54: 1.649332 | AS54: 0.99799748 | AT54: 0.99799748 | AU54: 1.6427018 | AV54: 1.0197282 | AW54: 1.0197282 | AX54: 1.6651913 | AY54: 0.97981287 | AZ54: 0.97981287 | BA54: 1.647621 | BB54: 1.0049111 | BC54: 1.0049111 | BD54: 1.6484281 | BE54: 0.99940262 | BF54: 0.99940262 | BG54: 1.6432762 | BH54: 1.0084376 | BI54: 1.0084376 | BJ54: 1.6512195 | BK54: 1.0035784 | BL54: 1.0035784 | BM54: 1.6503548 | BN54: 1.0040506 | BO54: 1.0040506 | BP54: 1.6468778 | BQ54: 0.99486369 | BR54: 0.99486369 | BS54: 1.6543191 | BT54: 1.0158109 | BU54: 1.0158109 | BV54: 1.6600059 | BW54: 0.99608666 | BX54: 0.99608666 | BY54: 1.6468836 | BZ54: 1.0053918 | CA54: 1.0053918 | CB54: 1.651272 | CC54: 1.0061311 | CD54: 1.0061311 | CE54: 1.6528726 | CF54: 0.99782053 | CG54: 0.99782053 | CH54: 1.6484836 | CI54: 1.0159024 | CJ54: 1.0159024 | CK54: 1.6593702

Sheet relative_error
A1: method | B1: CCSD\(T\) | C1: CCSD\(T\) | D1: CCSD\(T\) | E1: Error: | F1: HF | G1: HF | H1: HF | I1: MP2 | J1: MP2 | K1: MP2 | L1: CCSD | M1: CCSD | N1: CCSD | O1: Slater | P1: Slater | Q1: Slater | R1: SPW92 | S1: SPW92 | T1: SPW92 | U1: B97-D3 | V1: B97-D3 | W1: B97-D3 | X1: BLYP | Y1: BLYP | Z1: BLYP | AA1: BPBE | AB1: BPBE | AC1: BPBE | AD1: mPW91 | AE1: mPW91 | AF1: mPW91 | AG1: PBE | AH1: PBE | AI1: PBE | AJ1: B97M-V | AK1: B97M-V | AL1: B97M-V | AM1: M06-L | AN1: M06-L | AO1: M06-L | AP1: mBEEF | AQ1: mBEEF | AR1: mBEEF | AS1: MGGA_MS2 | AT1: MGGA_MS2 | AU1: MGGA_MS2 | AV1: MN15-L | AW1: MN15-L | AX1: MN15-L | AY1: revM06-L | AZ1: revM06-L | BA1: revM06-L | BB1: SCAN | BC1: SCAN | BD1: SCAN | BE1: TPSS | BF1: TPSS | BG1: TPSS | BH1: B3LYP | BI1: B3LYP | BJ1: B3LYP | BK1: M06-2X | BL1: M06-2X | BM1: M06-2X | BN1: PBE0 | BO1: PBE0 | BP1: PBE0 | BQ1: M08-HX | BR1: M08-HX | BS1: M08-HX | BT1: MN15 | BU1: MN15 | BV1: MN15 | BW1: SCAN0 | BX1: SCAN0 | BY1: SCAN0 | BZ1: CAM-B3LYP | CA1: CAM-B3LYP | CB1: CAM-B3LYP | CC1: wB97X-D | CD1: wB97X-D | CE1: wB97X-D | CF1: wB97X-V | CG1: wB97X-V | CH1: wB97X-V | CI1: wB97M-V | CJ1: wB97M-V | CK1: wB97M-V
